<?xml version="1.0" encoding="utf-8"?>
<sdf version="1.5">
  <model name="SimSwerveBot4">
    <pose>0 0 -1.0845302895368E-15 0 0 0</pose>
    <plugin name="clock" filename="libgz_clock.so">
      <topic>/gazebo/frc/time</topic>
    </plugin>
    <link name="Body">
      <gravity>1</gravity>
      <self_collide>0</self_collide>
      <pose>0.00985477473661245 0.0248042978721778 0.0167947827536739 0 0 0</pose>
      <must_be_base_link>1</must_be_base_link>
      <velocity_decay>
        <linear>0</linear>
        <angular>0</angular>
      </velocity_decay>
      <inertial>
        <mass>9.38599863622455</mass>
        <pose>0 0 0 0 0 0</pose>
        <inertia>
          <ixx>0.312378665487255</ixx>
          <ixy>0.00517820636344263</ixy>
          <ixz>0.000722316227901405</ixz>
          <iyy>0.692994181170098</iyy>
          <iyz>0.00477746005334545</iyz>
          <izz>0.450127342651242</izz>
        </inertia>
      </inertial>
      <collision name="Body_collision">
        <pose>-0.466349031070791 -0.0248042978721789 -1.93717245563794 0 0 0</pose>
        <geometry>
          <mesh>
            <scale>1 1 1</scale>
            <uri>model://SimSwerveBot4/meshes/Body_col.STL</uri>
          </mesh>
        </geometry>
        <surface>
          <contact>
            <ode />
          </contact>
          <friction>
            <ode>
              <mu>0</mu>
              <mu2>0</mu2>
            </ode>
          </friction>
        </surface>
      </collision>
      <visual name="Body_visual">
        <pose>-0.466349031070791 -0.0248042978721789 -1.93717245563794 0 0 0</pose>
        <material>
          <ambient>0.501960784313725 0.501960784313725 0.501960784313725 1</ambient>
          <diffuse>0.501960784313725 0.501960784313725 0.501960784313725 1</diffuse>
        </material>
        <geometry>
          <mesh>
            <scale>1 1 1</scale>
            <uri>model://SimSwerveBot4/meshes/Body.STL</uri>
          </mesh>
        </geometry>
      </visual>
    </link>
    <link name="FRdrive">
      <gravity>1</gravity>
      <self_collide>0</self_collide>
      <pose>0.390522917980719 -0.00811354847564073 0.237847957013419 0 0 0</pose>
      <must_be_base_link>0</must_be_base_link>
      <velocity_decay>
        <linear>0</linear>
        <angular>0</angular>
      </velocity_decay>
      <inertial>
        <mass>0.0891523549879112</mass>
        <pose>0 0 0 0 0 0</pose>
        <inertia>
          <ixx>5.87765184421575E-05</ixx>
          <ixy>1.64360345077491E-08</ixy>
          <ixz>2.58129459215765E-07</ixz>
          <iyy>3.42739642067352E-05</iyy>
          <iyz>2.18120030319756E-06</iyz>
          <izz>2.45064425861969E-05</izz>
        </inertia>
      </inertial>
      <visual name="FRdrive_visual">
        <pose>-0.847017174314898 0.00811354847563964 -2.15822562989768 0 0 0</pose>
        <material>
          <ambient>0.501960784313725 0.501960784313725 0.501960784313725 1</ambient>
          <diffuse>0.501960784313725 0.501960784313725 0.501960784313725 1</diffuse>
        </material>
        <geometry>
          <mesh>
            <scale>1 1 1</scale>
            <uri>model://SimSwerveBot4/meshes/FRdrive.STL</uri>
          </mesh>
        </geometry>
      </visual>
    </link>
    <joint name="Body-FRdrive" type="revolute">
      <parent>Body</parent>
      <child>FRdrive</child>
      <pose>2.08201928120211E-06 -1.73472347597681E-18 0.000277042986581488 0 0 0</pose>
      <axis>
        <xyz>0 -1 0</xyz>
        <dynamics>
          <damping>1</damping>
          <friction>1</friction>
        </dynamics>
        <limit>
          <effort>50</effort>
        </limit>
      </axis>
    </joint>
    <link name="FRwheel">
      <gravity>1</gravity>
      <self_collide>0</self_collide>
      <pose>0.390524894652224 -0.045440778296 0.239779131380306 0 0 0</pose>
      <must_be_base_link>0</must_be_base_link>
      <velocity_decay>
        <linear>0</linear>
        <angular>0</angular>
      </velocity_decay>
      <inertial>
        <mass>0.123981366006225</mass>
        <pose>0 0 0 0 0 0</pose>
        <inertia>
          <ixx>3.8827835252021E-06</ixx>
          <ixy>2.45178744083659E-09</ixy>
          <ixz>3.0395979651483E-08</ixz>
          <iyy>3.86178892347243E-06</iyy>
          <iyz>1.19329957459317E-08</iyz>
          <izz>2.19913716679761E-08</izz>
        </inertia>
      </inertial>
      <collision name="FRwheel_collision">
        <pose>-0.847019150986402 0.0454407782959989 -2.16015680426457 0 0 0</pose>
        <geometry>
          <mesh>
            <scale>1 1 1</scale>
            <uri>model://SimSwerveBot4/meshes/FRwheel_col.STL</uri>
          </mesh>
        </geometry>
        <surface>
          <contact>
            <ode />
          </contact>
          <friction>
            <ode>
              <mu>0</mu>
              <mu2>0</mu2>
            </ode>
          </friction>
        </surface>
      </collision>
      <visual name="FRwheel_visual">
        <pose>-0.847019150986402 0.0454407782959989 -2.16015680426457 0 0 0</pose>
        <material>
          <ambient>0 1 0 1</ambient>
          <diffuse>0 1 0 1</diffuse>
        </material>
        <geometry>
          <mesh>
            <scale>1 1 1</scale>
            <uri>model://SimSwerveBot4/meshes/FRwheel.STL</uri>
          </mesh>
        </geometry>
      </visual>
    </link>
    <joint name="FRdrive-FRwheel" type="revolute">
      <parent>FRdrive</parent>
      <child>FRwheel</child>
      <pose>3.5053368525606E-06 0.000114295457558644 -0.00120273472992993 0 0 0</pose>
      <axis>
        <xyz>0.00753194032505162 -5.39495021367634E-16 0.99997163453517</xyz>
        <dynamics>
          <damping>1</damping>
          <friction>1</friction>
        </dynamics>
        <limit>
          <effort>25</effort>
        </limit>
      </axis>
    </joint>
    <link name="FLdrive">
      <gravity>1</gravity>
      <self_collide>0</self_collide>
      <pose>0.390526514220831 -0.00811354846782578 -0.238402046668222 0 0 0</pose>
      <must_be_base_link>0</must_be_base_link>
      <velocity_decay>
        <linear>0</linear>
        <angular>0</angular>
      </velocity_decay>
      <inertial>
        <mass>0.0891523549651857</mass>
        <pose>0 0 0 0 0 0</pose>
        <inertia>
          <ixx>5.87774450060759E-05</ixx>
          <ixy>1.18776834182455E-08</ixy>
          <ixz>1.86751222995135E-07</ixz>
          <iyy>3.42739642082012E-05</iyy>
          <iyz>2.1812299035087E-06</iyz>
          <izz>2.45055159902255E-05</izz>
        </inertia>
      </inertial>
      <visual name="FLdrive_visual">
        <pose>-0.84702077055501 0.0081135484678247 -1.68197562621604 0 0 0</pose>
        <material>
          <ambient>0.501960784313725 0.501960784313725 0.501960784313725 1</ambient>
          <diffuse>0.501960784313725 0.501960784313725 0.501960784313725 1</diffuse>
        </material>
        <geometry>
          <mesh>
            <scale>1 1 1</scale>
            <uri>model://SimSwerveBot4/meshes/FLdrive.STL</uri>
          </mesh>
        </geometry>
      </visual>
    </link>
    <joint name="Body-FLdrive" type="revolute">
      <parent>Body</parent>
      <child>FLdrive</child>
      <pose>-1.51422083138897E-06 6.93889390390723E-18 0.000277046668222258 0 0 0</pose>
      <axis>
        <xyz>1.52655665885957E-16 -1 8.59873560937597E-30</xyz>
        <dynamics>
          <damping>1</damping>
          <friction>1</friction>
        </dynamics>
        <limit>
          <effort>50</effort>
        </limit>
      </axis>
    </joint>
    <link name="FLwheel">
      <gravity>1</gravity>
      <self_collide>0</self_collide>
      <pose>0.390532719294217 -0.0453594163528396 -0.237673541862736 0 0 0</pose>
      <must_be_base_link>0</must_be_base_link>
      <velocity_decay>
        <linear>0</linear>
        <angular>0</angular>
      </velocity_decay>
      <inertial>
        <mass>0.413564687541818</mass>
        <pose>0 0 0 0 0 0</pose>
        <inertia>
          <ixx>4.13843363916966E-06</ixx>
          <ixy>6.43469172968465E-09</ixy>
          <ixz>2.09109243741716E-08</ixz>
          <iyy>4.11963368528873E-06</iyy>
          <iyz>4.92862136385493E-09</iyz>
          <izz>2.30060142709458E-08</izz>
        </inertia>
      </inertial>
      <collision name="FLwheel_collision">
        <pose>-0.847026975628395 0.0453594163528385 -1.68270413102153 0 0 0</pose>
        <geometry>
          <mesh>
            <scale>1 1 1</scale>
            <uri>model://SimSwerveBot4/meshes/FLwheel_col.STL</uri>
          </mesh>
        </geometry>
        <surface>
          <contact>
            <ode />
          </contact>
          <friction>
            <ode>
              <mu>0</mu>
              <mu2>0</mu2>
            </ode>
          </friction>
        </surface>
      </collision>
      <visual name="FLwheel_visual">
        <pose>-0.847026975628395 0.0453594163528385 -1.68270413102153 0 0 0</pose>
        <material>
          <ambient>0 1 0 1</ambient>
          <diffuse>0 1 0 1</diffuse>
        </material>
        <geometry>
          <mesh>
            <scale>1 1 1</scale>
            <uri>model://SimSwerveBot4/meshes/FLwheel.STL</uri>
          </mesh>
        </geometry>
      </visual>
    </link>
    <joint name="FLdrive-FLwheel" type="revolute">
      <parent>FLdrive</parent>
      <child>FLwheel</child>
      <pose>-1.01787932659247E-05 3.29335143967324E-05 -5.54598669211259E-08 0 0 0</pose>
      <axis>
        <xyz>-0.00544848904353874 5.39806568947221E-16 0.999985156873412</xyz>
        <dynamics>
          <damping>1</damping>
          <friction>1</friction>
        </dynamics>
        <limit>
          <effort>25</effort>
        </limit>
      </axis>
    </joint>
    <link name="BRdrive">
      <gravity>1</gravity>
      <self_collide>0</self_collide>
      <pose>-0.38981757481044 -0.0081135495114501 0.238402047413451 0 0 0</pose>
      <must_be_base_link>0</must_be_base_link>
      <velocity_decay>
        <linear>0</linear>
        <angular>0</angular>
      </velocity_decay>
      <inertial>
        <mass>0.0891523590073493</mass>
        <pose>0 0 0 0 0 0</pose>
        <inertia>
          <ixx>5.87772017459105E-05</ixx>
          <ixy>1.32756048702743E-08</ixy>
          <ixz>2.0849346674732E-07</ixz>
          <iyy>3.42739697285893E-05</iyy>
          <iyz>2.18121853503238E-06</iyz>
          <izz>2.45057687024374E-05</izz>
        </inertia>
      </inertial>
      <visual name="BRdrive_visual">
        <pose>-0.066676681523738 0.00811354951144901 -2.15877972029771 0 0 0</pose>
        <material>
          <ambient>0.501960784313725 0.501960784313725 0.501960784313725 1</ambient>
          <diffuse>0.501960784313725 0.501960784313725 0.501960784313725 1</diffuse>
        </material>
        <geometry>
          <mesh>
            <scale>1 1 1</scale>
            <uri>model://SimSwerveBot4/meshes/BRdrive.STL</uri>
          </mesh>
        </geometry>
      </visual>
    </link>
    <joint name="Body-BRdrive" type="revolute">
      <parent>Body</parent>
      <child>BRdrive</child>
      <pose>-1.68152373801467E-06 -8.67361737988404E-18 -0.000277047413450582 0 0 0</pose>
      <axis>
        <xyz>-1.94289029309404E-16 -1 1.57772181044202E-30</xyz>
        <dynamics>
          <damping>1</damping>
          <friction>1</friction>
        </dynamics>
        <limit>
          <effort>50</effort>
        </limit>
      </axis>
    </joint>
    <link name="BRwheel">
      <gravity>1</gravity>
      <self_collide>0</self_collide>
      <pose>-0.389818236008278 -0.0453607471440594 0.237673576041824 0 0 0</pose>
      <must_be_base_link>0</must_be_base_link>
      <velocity_decay>
        <linear>0</linear>
        <angular>0</angular>
      </velocity_decay>
      <inertial>
        <mass>0.413564688849332</mass>
        <pose>0 0 0 0 0 0</pose>
        <inertia>
          <ixx>4.14011800450974E-06</ixx>
          <ixy>2.45548581240248E-09</ixy>
          <ixz>2.44884944262157E-08</ixz>
          <iyy>4.11790975709249E-06</iyy>
          <iyz>5.10641163355616E-09</iyz>
          <izz>2.30458899811423E-08</izz>
        </inertia>
      </inertial>
      <collision name="BRwheel_collision">
        <pose>-0.0666760203259 0.0453607471440583 -2.15805124892609 0 0 0</pose>
        <geometry>
          <mesh>
            <scale>1 1 1</scale>
            <uri>model://SimSwerveBot4/meshes/BRwheel_col.STL</uri>
          </mesh>
        </geometry>
        <surface>
          <contact>
            <ode />
          </contact>
          <friction>
            <ode>
              <mu>0</mu>
              <mu2>0</mu2>
            </ode>
          </friction>
        </surface>
      </collision>
      <visual name="BRwheel_visual">
        <pose>-0.0666760203259 0.0453607471440583 -2.15805124892609 0 0 0</pose>
        <material>
          <ambient>0 1 0 1</ambient>
          <diffuse>0 1 0 1</diffuse>
        </material>
        <geometry>
          <mesh>
            <scale>1 1 1</scale>
            <uri>model://SimSwerveBot4/meshes/BRwheel.STL</uri>
          </mesh>
        </geometry>
      </visual>
    </link>
    <joint name="BRdrive-BRwheel" type="revolute">
      <parent>BRdrive</parent>
      <child>BRwheel</child>
      <pose>-3.7665044388957E-06 3.42643056162745E-05 2.29141998708826E-08 0 0 0</pose>
      <axis>
        <xyz>-0.0060835652850518 5.44873555814072E-16 -0.999981494945493</xyz>
        <dynamics>
          <damping>1</damping>
          <friction>1</friction>
        </dynamics>
        <limit>
          <effort>25</effort>
        </limit>
      </axis>
    </joint>
    <link name="BLdrive">
      <gravity>1</gravity>
      <self_collide>0</self_collide>
      <pose>-0.389815880758476 -0.0071726820171026 -0.237676179491394 0 0 0</pose>
      <must_be_base_link>0</must_be_base_link>
      <velocity_decay>
        <linear>0</linear>
        <angular>0</angular>
      </velocity_decay>
      <inertial>
        <mass>0.0869538722262852</mass>
        <pose>0 0 0 0 0 0</pose>
        <inertia>
          <ixx>5.55510317092367E-05</ixx>
          <ixy>1.21441770461795E-08</ixy>
          <ixz>2.57345351141106E-07</ixz>
          <iyy>3.41699093432883E-05</iyy>
          <iyz>1.61130711801399E-06</iyz>
          <izz>2.13849988987231E-05</izz>
        </inertia>
      </inertial>
      <visual name="BLdrive_visual">
        <pose>-0.0666783755757028 0.00717268201710151 -1.68270149339287 0 0 0</pose>
        <material>
          <ambient>0.501960784313725 0.501960784313725 0.501960784313725 1</ambient>
          <diffuse>0.501960784313725 0.501960784313725 0.501960784313725 1</diffuse>
        </material>
        <geometry>
          <mesh>
            <scale>1 1 1</scale>
            <uri>model://SimSwerveBot4/meshes/BLdrive.STL</uri>
          </mesh>
        </geometry>
      </visual>
    </link>
    <joint name="Body-BLdrive" type="revolute">
      <parent>Body</parent>
      <child>BLdrive</child>
      <pose>-3.37557570311009E-06 -1.73472347597681E-18 -0.00044882050860573 0 0 0</pose>
      <axis>
        <xyz>-1.02695629777827E-15 -1 2.11988446961496E-17</xyz>
        <dynamics>
          <damping>1</damping>
          <friction>1</friction>
        </dynamics>
        <limit>
          <effort>50</effort>
        </limit>
      </axis>
    </joint>
    <link name="BLwheel">
      <gravity>1</gravity>
      <self_collide>0</self_collide>
      <pose>-0.389819150986402 -0.0454407782960015 -0.239779131380305 0 0 0</pose>
      <must_be_base_link>0</must_be_base_link>
      <velocity_decay>
        <linear>0</linear>
        <angular>0</angular>
      </velocity_decay>
      <inertial>
        <mass>0.123981366006226</mass>
        <pose>0 0 0 0 0 0</pose>
        <inertia>
          <ixx>3.88278352520201E-06</ixx>
          <ixy>2.45178744082889E-09</ixy>
          <ixz>3.03959796514774E-08</ixz>
          <iyy>3.86178892347236E-06</iyy>
          <iyz>1.19329957458881E-08</iyz>
          <izz>2.19913716679495E-08</izz>
        </inertia>
      </inertial>
      <collision name="BLwheel_collision">
        <pose>-0.0666751053477763 0.0454407782960004 -1.68059854150396 0 0 0</pose>
        <geometry>
          <mesh>
            <scale>1 1 1</scale>
            <uri>model://SimSwerveBot4/meshes/BLwheel_col.STL</uri>
          </mesh>
        </geometry>
        <surface>
          <contact>
            <ode />
          </contact>
          <friction>
            <ode>
              <mu>0</mu>
              <mu2>0</mu2>
            </ode>
          </friction>
        </surface>
      </collision>
      <visual name="BLwheel_visual">
        <pose>-0.0666751053477763 0.0454407782960004 -1.68059854150396 0 0 0</pose>
        <material>
          <ambient>0 1 0 1</ambient>
          <diffuse>0 1 0 1</diffuse>
        </material>
        <geometry>
          <mesh>
            <scale>1 1 1</scale>
            <uri>model://SimSwerveBot4/meshes/BLwheel.STL</uri>
          </mesh>
        </geometry>
      </visual>
    </link>
    <joint name="BLdrive-BLwheel" type="revolute">
      <parent>BLdrive</parent>
      <child>BLwheel</child>
      <pose>-3.50533685232468E-06 0.000114295457558339 0.00120273472992949 0 0 0</pose>
      <axis>
        <xyz>-0.00753194032505203 -5.52958291197397E-16 -0.99997163453517</xyz>
        <dynamics>
          <damping>1</damping>
          <friction>1</friction>
        </dynamics>
        <limit>
          <effort>25</effort>
        </limit>
      </axis>
    </joint>
    <link name="LowerArm">
      <gravity>1</gravity>
      <self_collide>0</self_collide>
      <pose>-0.102067540968878 0.648286652228778 0.201682058992895 0 0 0</pose>
      <must_be_base_link>0</must_be_base_link>
      <velocity_decay>
        <linear>0</linear>
        <angular>0</angular>
      </velocity_decay>
      <inertial>
        <mass>3.1900657983711</mass>
        <pose>0 0 0 0 0 0</pose>
        <inertia>
          <ixx>0.0805577901164252</ixx>
          <ixy>0.016043902637641</ixy>
          <ixz>0.000750916719201549</ixz>
          <iyy>0.00346837917451623</iyy>
          <iyz>0.00375824822961574</iyz>
          <izz>0.0835009253183457</izz>
        </inertia>
      </inertial>
      <collision name="LowerArm_collision">
        <pose>-0.354426715365301 -0.648286652228779 -2.12205973187716 0 0 0</pose>
        <geometry>
          <mesh>
            <scale>1 1 1</scale>
            <uri>model://SimSwerveBot4/meshes/LowerArm_col.STL</uri>
          </mesh>
        </geometry>
        <surface>
          <contact>
            <ode />
          </contact>
          <friction>
            <ode>
              <mu>0</mu>
              <mu2>0</mu2>
            </ode>
          </friction>
        </surface>
      </collision>
      <visual name="LowerArm_visual">
        <pose>-0.354426715365301 -0.648286652228779 -2.12205973187716 0 0 0</pose>
        <material>
          <ambient>0.250980392156863 0.501960784313725 0.501960784313725 1</ambient>
          <diffuse>0.250980392156863 0.501960784313725 0.501960784313725 1</diffuse>
        </material>
        <geometry>
          <mesh>
            <scale>1 1 1</scale>
            <uri>model://SimSwerveBot4/meshes/LowerArm.STL</uri>
          </mesh>
        </geometry>
      </visual>
    </link>
    <joint name="Body-LowerArm" type="revolute">
      <parent>Body</parent>
      <child>LowerArm</child>
      <pose>0.1003602846347 -0.502236652228779 0 0 0 0</pose>
      <axis>
        <xyz>0 0 -1</xyz>
        <dynamics>
          <damping>0</damping>
          <friction>0</friction>
        </dynamics>
        <limit>
          <upper>0</upper>
          <lower>0</lower>
          <effort>1</effort>
        </limit>
      </axis>
    </joint>
    <link name="UpperArm">
      <gravity>1</gravity>
      <self_collide>0</self_collide>
      <pose>-0.208744947965112 0.865991228362569 0.132747045366589 0 0 0</pose>
      <must_be_base_link>0</must_be_base_link>
      <velocity_decay>
        <linear>0</linear>
        <angular>0</angular>
      </velocity_decay>
      <inertial>
        <mass>2.35701643914108</mass>
        <pose>0 0 0 0 0 0</pose>
        <inertia>
          <ixx>0.0352270743463211</ixx>
          <ixy>0.000773783831346127</ixy>
          <ixz>5.98141090299857E-05</ixz>
          <iyy>0.000273922405237529</iyy>
          <iyz>0.00270385963780976</iyz>
          <izz>0.0349873948280749</izz>
        </inertia>
      </inertial>
      <collision name="UpperArm_collision">
        <pose>-0.247749308369066 -0.86599122836257 -2.05312471825085 0 0 0</pose>
        <geometry>
          <mesh>
            <scale>1 1 1</scale>
            <uri>model://SimSwerveBot4/meshes/UpperArm_col.STL</uri>
          </mesh>
        </geometry>
        <surface>
          <contact>
            <ode />
          </contact>
          <friction>
            <ode>
              <mu>0</mu>
              <mu2>0</mu2>
            </ode>
          </friction>
        </surface>
      </collision>
      <visual name="UpperArm_visual">
        <pose>-0.247749308369066 -0.86599122836257 -2.05312471825085 0 0 0</pose>
        <material>
          <ambient>0.250980392156863 0.501960784313725 0.501960784313725 1</ambient>
          <diffuse>0.250980392156863 0.501960784313725 0.501960784313725 1</diffuse>
        </material>
        <geometry>
          <mesh>
            <scale>1 1 1</scale>
            <uri>model://SimSwerveBot4/meshes/UpperArm.STL</uri>
          </mesh>
        </geometry>
      </visual>
    </link>
    <joint name="LowerArm-UpperArm" type="revolute">
      <parent>LowerArm</parent>
      <child>UpperArm</child>
      <pose>-0.0078763379280225 0.355568315938512 0 0 0 0</pose>
      <axis>
        <xyz>4.37095678986261E-15 0 1</xyz>
        <dynamics>
          <damping>0</damping>
          <friction>0</friction>
        </dynamics>
        <limit>
          <upper>0</upper>
          <lower>0</lower>
          <effort>1</effort>
        </limit>
      </axis>
    </joint>
    <link name="GripperRotate">
      <gravity>1</gravity>
      <self_collide>0</self_collide>
      <pose>-0.198420383100514 0.446967540730028 0.023460469661692 0 0 0</pose>
      <must_be_base_link>0</must_be_base_link>
      <velocity_decay>
        <linear>0</linear>
        <angular>0</angular>
      </velocity_decay>
      <inertial>
        <mass>0.14389059238857</mass>
        <pose>0 0 0 0 0 0</pose>
        <inertia>
          <ixx>0.000128771111330297</ixx>
          <ixy>2.43578389040611E-07</ixy>
          <ixz>2.90812193175965E-06</ixz>
          <iyy>0.000127940160975302</iyy>
          <iyz>1.07104686633862E-05</iyz>
          <izz>9.63223867486635E-07</izz>
        </inertia>
      </inertial>
      <collision name="GripperRotate_collision">
        <pose>-0.258073873233665 -0.446967540730029 -1.94383814254595 0 0 0</pose>
        <geometry>
          <mesh>
            <scale>1 1 1</scale>
            <uri>model://SimSwerveBot4/meshes/GripperRotate_col.STL</uri>
          </mesh>
        </geometry>
        <surface>
          <contact>
            <ode />
          </contact>
          <friction>
            <ode>
              <mu>0</mu>
              <mu2>0</mu2>
            </ode>
          </friction>
        </surface>
      </collision>
      <visual name="GripperRotate_visual">
        <pose>-0.258073873233665 -0.446967540730029 -1.94383814254595 0 0 0</pose>
        <material>
          <ambient>0.752941176470588 0.752941176470588 0.752941176470588 1</ambient>
          <diffuse>0.752941176470588 0.752941176470588 0.752941176470588 1</diffuse>
        </material>
        <geometry>
          <mesh>
            <scale>1 1 1</scale>
            <uri>model://SimSwerveBot4/meshes/GripperRotate.STL</uri>
          </mesh>
        </geometry>
      </visual>
    </link>
    <joint name="UpperArm-GripperRotate" type="revolute">
      <parent>UpperArm</parent>
      <child>GripperRotate</child>
      <pose>-0.000595887983165122 -0.00219462585143981 0 0 0 0</pose>
      <axis>
        <xyz>0 0 -1</xyz>
        <dynamics>
          <damping>0</damping>
          <friction>0</friction>
        </dynamics>
        <limit>
          <upper>0</upper>
          <lower>0</lower>
          <effort>1</effort>
        </limit>
      </axis>
    </joint>
    <link name="GripperTwist">
      <gravity>1</gravity>
      <self_collide>0</self_collide>
      <pose>-0.0625315359320857 0.478638830369111 -0.0199341015108323 0 0 0</pose>
      <must_be_base_link>0</must_be_base_link>
      <velocity_decay>
        <linear>0</linear>
        <angular>0</angular>
      </velocity_decay>
      <inertial>
        <mass>0.357691002526425</mass>
        <pose>0 0 0 0 0 0</pose>
        <inertia>
          <ixx>0.000155070621583242</ixx>
          <ixy>6.26603962093053E-05</ixy>
          <ixz>3.88394912222489E-05</ixz>
          <iyy>0.000226791092242338</iyy>
          <iyz>2.21492998369105E-06</iyz>
          <izz>0.00036528569595978</izz>
        </inertia>
      </inertial>
      <collision name="GripperTwist_collision">
        <pose>-0.393962720402093 -0.478638830369112 -1.90044357137343 0 0 0</pose>
        <geometry>
          <mesh>
            <scale>1 1 1</scale>
            <uri>model://SimSwerveBot4/meshes/GripperTwist_col.STL</uri>
          </mesh>
        </geometry>
        <surface>
          <contact>
            <ode />
          </contact>
          <friction>
            <ode>
              <mu>0</mu>
              <mu2>0</mu2>
            </ode>
          </friction>
        </surface>
      </collision>
      <visual name="GripperTwist_visual">
        <pose>-0.393962720402093 -0.478638830369112 -1.90044357137343 0 0 0</pose>
        <material>
          <ambient>0.752941176470588 0.752941176470588 0.752941176470588 1</ambient>
          <diffuse>0.752941176470588 0.752941176470588 0.752941176470588 1</diffuse>
        </material>
        <geometry>
          <mesh>
            <scale>1 1 1</scale>
            <uri>model://SimSwerveBot4/meshes/GripperTwist.STL</uri>
          </mesh>
        </geometry>
      </visual>
      <sensor name="GripperTwistCamera" type="camera">
        <visualize>1</visualize>
        <always_on>1</always_on>
        <pose>0.0205235796459304 0.0194185226531891 0.000678730782040171 0 0 0</pose>
        <camera name="GripperTwistcamera">
          <horizontal_fov>1.5707963267949</horizontal_fov>
          <image>
            <width>320</width>
            <height>240</height>
          </image>
          <clip>
            <near>0.1</near>
            <far>100</far>
          </clip>
        </camera>
      </sensor>
    </link>
    <joint name="GripperRotate-GripperTwist" type="revolute">
      <parent>GripperRotate</parent>
      <child>GripperTwist</child>
      <pose>0.000738095228608571 -0.0247846584189436 0.0094777154723078 0 0 0</pose>
      <axis>
        <xyz>0.999556860798986 0.0297671300208329 0</xyz>
        <dynamics>
          <damping>0</damping>
          <friction>0</friction>
        </dynamics>
        <limit>
          <upper>0</upper>
          <lower>0</lower>
          <effort>1</effort>
        </limit>
      </axis>
    </joint>
    <link name="LeftGripper">
      <gravity>1</gravity>
      <self_collide>0</self_collide>
      <pose>0.0810671068320737 0.418847304378557 -0.190733921869457 0 0 0</pose>
      <must_be_base_link>0</must_be_base_link>
      <velocity_decay>
        <linear>0</linear>
        <angular>0</angular>
      </velocity_decay>
      <inertial>
        <mass>0.54359376540735</mass>
        <pose>0 0 0 0 0 0</pose>
        <inertia>
          <ixx>5.49725433763315E-06</ixx>
          <ixy>1.22622355617251E-05</ixy>
          <ixz>4.12352761006815E-05</ixz>
          <iyy>0.00036374406554178</iyy>
          <iyz>1.40531985571029E-06</iyz>
          <izz>0.000359085382148384</izz>
        </inertia>
      </inertial>
      <collision name="LeftGripper_collision">
        <pose>-0.537561363166252 -0.418847304378558 -1.72964375101481 0 0 0</pose>
        <geometry>
          <mesh>
            <scale>1 1 1</scale>
            <uri>model://SimSwerveBot4/meshes/LeftGripper_col.STL</uri>
          </mesh>
        </geometry>
        <surface>
          <contact>
            <ode />
          </contact>
          <friction>
            <ode>
              <mu>0</mu>
              <mu2>0</mu2>
            </ode>
          </friction>
        </surface>
      </collision>
      <visual name="LeftGripper_visual">
        <pose>-0.537561363166252 -0.418847304378558 -1.72964375101481 0 0 0</pose>
        <material>
          <ambient>0.752941176470588 0.752941176470588 0.752941176470588 1</ambient>
          <diffuse>0.752941176470588 0.752941176470588 0.752941176470588 1</diffuse>
        </material>
        <geometry>
          <mesh>
            <scale>1 1 1</scale>
            <uri>model://SimSwerveBot4/meshes/LeftGripper.STL</uri>
          </mesh>
        </geometry>
      </visual>
    </link>
    <joint name="GripperTwist-LeftGripper" type="revolute">
      <parent>GripperTwist</parent>
      <child>LeftGripper</child>
      <pose>-0.12664725783566 -0.00349102407337348 0.0198663629541476 0 0 0</pose>
      <axis>
        <xyz>0.0297641644312887 -0.999457278630274 0.0141153359390968</xyz>
        <dynamics>
          <damping>0</damping>
          <friction>0</friction>
        </dynamics>
        <limit>
          <upper>0</upper>
          <lower>0</lower>
          <effort>1</effort>
        </limit>
      </axis>
    </joint>
    <link name="RightGripper">
      <gravity>1</gravity>
      <self_collide>0</self_collide>
      <pose>0.0839620482191449 0.425397534803131 0.138652543294368 0 0 0</pose>
      <must_be_base_link>0</must_be_base_link>
      <velocity_decay>
        <linear>0</linear>
        <angular>0</angular>
      </velocity_decay>
      <inertial>
        <mass>0.543593765407352</mass>
        <pose>0 0 0 0 0 0</pose>
        <inertia>
          <ixx>3.88299266896615E-06</ixx>
          <ixy>9.04941392057971E-06</ixy>
          <ixz>3.45835272351058E-05</ixz>
          <iyy>0.000363935991099367</iyy>
          <iyz>8.73127669922266E-07</iyz>
          <izz>0.000360507718259461</izz>
        </inertia>
      </inertial>
      <collision name="RightGripper_collision">
        <pose>-0.540456304553323 -0.425397534803132 -2.05903021617863 0 0 0</pose>
        <geometry>
          <mesh>
            <scale>1 1 1</scale>
            <uri>model://SimSwerveBot4/meshes/RightGripper_col.STL</uri>
          </mesh>
        </geometry>
        <surface>
          <contact>
            <ode />
          </contact>
          <friction>
            <ode>
              <mu>0</mu>
              <mu2>0</mu2>
            </ode>
          </friction>
        </surface>
      </collision>
      <visual name="RightGripper_visual">
        <pose>-0.540456304553323 -0.425397534803132 -2.05903021617863 0 0 0</pose>
        <material>
          <ambient>0.752941176470588 0.752941176470588 0.752941176470588 1</ambient>
          <diffuse>0.752941176470588 0.752941176470588 0.752941176470588 1</diffuse>
        </material>
        <geometry>
          <mesh>
            <scale>1 1 1</scale>
            <uri>model://SimSwerveBot4/meshes/RightGripper.STL</uri>
          </mesh>
        </geometry>
      </visual>
    </link>
    <joint name="GripperTwist-RightGripper" type="revolute">
      <parent>GripperTwist</parent>
      <child>RightGripper</child>
      <pose>-0.126981660994285 -0.00402853279122511 -0.0174876024108572 0 0 0</pose>
      <axis>
        <xyz>0.0297641644312887 -0.999457278630274 0.0141153359390968</xyz>
        <dynamics>
          <damping>0</damping>
          <friction>0</friction>
        </dynamics>
        <limit>
          <upper>0</upper>
          <lower>0</lower>
          <effort>1</effort>
        </limit>
      </axis>
    </joint>
    <link name="LeftPad">
      <gravity>1</gravity>
      <self_collide>0</self_collide>
      <pose>0.239600029637804 0.424982251188515 -0.154782770122619 0 0 0</pose>
      <must_be_base_link>0</must_be_base_link>
      <velocity_decay>
        <linear>0</linear>
        <angular>0</angular>
      </velocity_decay>
      <inertial>
        <mass>0.0254993671569925</mass>
        <pose>0 0 0 0 0 0</pose>
        <inertia>
          <ixx>0</ixx>
          <ixy>0</ixy>
          <ixz>0</ixz>
          <iyy>0</iyy>
          <iyz>0</iyz>
          <izz>0</izz>
        </inertia>
      </inertial>
      <collision name="LeftPad_collision">
        <pose>-0.696094285971983 -0.424982251188516 -1.76559490276164 0 0 0</pose>
        <geometry>
          <mesh>
            <scale>1 1 1</scale>
            <uri>model://SimSwerveBot4/meshes/LeftPad_col.STL</uri>
          </mesh>
        </geometry>
        <surface>
          <contact>
            <ode />
          </contact>
          <friction>
            <ode>
              <mu>0</mu>
              <mu2>0</mu2>
            </ode>
          </friction>
        </surface>
      </collision>
      <visual name="LeftPad_visual">
        <pose>-0.696094285971983 -0.424982251188516 -1.76559490276164 0 0 0</pose>
        <material>
          <ambient>0 0.501960784313725 0.501960784313725 1</ambient>
          <diffuse>0 0.501960784313725 0.501960784313725 1</diffuse>
        </material>
        <geometry>
          <mesh>
            <scale>1 1 1</scale>
            <uri>model://SimSwerveBot4/meshes/LeftPad.STL</uri>
          </mesh>
        </geometry>
      </visual>
    </link>
    <joint name="LeftGripper-LeftPad" type="revolute">
      <parent>LeftGripper</parent>
      <child>LeftPad</child>
      <pose>2.70894418008538E-14 8.71525074330748E-15 -4.44089209850063E-15 0 0 0</pose>
      <axis>
        <xyz>0.154458439010382 0.0185508776653356 0.9878251138518</xyz>
        <dynamics>
          <damping>0</damping>
          <friction>0</friction>
        </dynamics>
        <limit>
          <upper>0</upper>
          <lower>0</lower>
          <effort>1</effort>
        </limit>
      </axis>
    </joint>
    <link name="RightPad">
      <gravity>1</gravity>
      <self_collide>0</self_collide>
      <pose>0.241878388878302 0.428644634182398 0.0997334452054581 0 0 0</pose>
      <must_be_base_link>0</must_be_base_link>
      <velocity_decay>
        <linear>0</linear>
        <angular>0</angular>
      </velocity_decay>
      <inertial>
        <mass>0.0254993671569941</mass>
        <pose>0 0 0 0 0 0</pose>
        <inertia>
          <ixx>0</ixx>
          <ixy>0</ixy>
          <ixz>0</ixz>
          <iyy>0</iyy>
          <iyz>0</iyz>
          <izz>0</izz>
        </inertia>
      </inertial>
      <collision name="RightPad_collision">
        <pose>-0.69837264521248 -0.428644634182399 -2.02011111808972 0 0 0</pose>
        <geometry>
          <mesh>
            <scale>1 1 1</scale>
            <uri>model://SimSwerveBot4/meshes/RightPad_col.STL</uri>
          </mesh>
        </geometry>
        <surface>
          <contact>
            <ode />
          </contact>
          <friction>
            <ode>
              <mu>0</mu>
              <mu2>0</mu2>
            </ode>
          </friction>
        </surface>
      </collision>
      <visual name="RightPad_visual">
        <pose>-0.69837264521248 -0.428644634182399 -2.02011111808972 0 0 0</pose>
        <material>
          <ambient>0 0.501960784313725 0.501960784313725 1</ambient>
          <diffuse>0 0.501960784313725 0.501960784313725 1</diffuse>
        </material>
        <geometry>
          <mesh>
            <scale>1 1 1</scale>
            <uri>model://SimSwerveBot4/meshes/RightPad.STL</uri>
          </mesh>
        </geometry>
      </visual>
    </link>
    <joint name="RightGripper-RightPad" type="revolute">
      <parent>RightGripper</parent>
      <child>RightPad</child>
      <pose>3.11972669919669E-14 1.01585406753202E-14 3.99680288865056E-15 0 0 0</pose>
      <axis>
        <xyz>0.136747414521 -0.00991724477742757 -0.990556304748926</xyz>
        <dynamics>
          <damping>0</damping>
          <friction>0</friction>
        </dynamics>
        <limit>
          <upper>0</upper>
          <lower>0</lower>
          <effort>1</effort>
        </limit>
      </axis>
    </joint>
    <plugin name="Body_gyro" filename="libgz_gyro.so">
      <link>Body</link>
      <topic>/gazebo/frc/simulator/analog/0</topic>
      <units>degrees</units>
      <axis>yaw</axis>
    </plugin>
  </model>
</sdf>