<?xml version="1.0" encoding="utf-8"?>
<sdf version="1.5">
  <model name="SimSwerveBot4">
    <pose>0 0 -1.0845302895368E-15 0 0 0</pose>
    
    <link name="Body">
      <gravity>1</gravity>
      <self_collide>0</self_collide>
      <pose>0.00985477473661245 0.0248042978721778 0.0167947827536739 0 0 0</pose>
      <must_be_base_link>1</must_be_base_link>
      <velocity_decay>
        <linear>0</linear>
        <angular>0</angular>
      </velocity_decay>
      <inertial>
        <mass>150</mass>
        <pose>0 0 0 0 0 0</pose>
        
      </inertial>
      <collision name="Body_collision">
        <pose>-0.466349031070791 -0.0248042978721789 -1.93717245563794 0 0 0</pose>
        <geometry>
          <mesh>
            <scale>1 1 1</scale>
            <uri>model://SimSwerveBot4/meshes/Body_col.STL</uri>
          </mesh>
        </geometry>
        <surface>
          <contact>
            <ode />
          </contact>
          <friction>
            <ode>
              <mu>0</mu>
              <mu2>0</mu2>
            </ode>
          </friction>
        </surface>
      </collision>
      <visual name="Body_visual">
        <pose>-0.466349031070791 -0.0248042978721789 -1.93717245563794 0 0 0</pose>
        <material>
          <ambient>0.501960784313725 0.501960784313725 0.501960784313725 1</ambient>
          <diffuse>0.501960784313725 0.501960784313725 0.501960784313725 1</diffuse>
        </material>
        <geometry>
          <mesh>
            <scale>1 1 1</scale>
            <uri>model://SimSwerveBot4/meshes/Body.STL</uri>
          </mesh>
        </geometry>
      </visual>
    </link>
    <link name="FRdrive">
      <gravity>1</gravity>
      <self_collide>0</self_collide>
      <pose>0.390522917980719 -0.00811354847564073 0.237847957013419 0 0 0</pose>
      <must_be_base_link>0</must_be_base_link>
      <velocity_decay>
        <linear>0</linear>
        <angular>0.01</angular>
      </velocity_decay>
      <inertial>
        <mass>0.0891523549879112</mass>
        <pose>0 0 0 0 0 0</pose>
        
      </inertial>
      <visual name="FRdrive_visual">
        <pose>-0.847017174314898 0.00811354847563964 -2.15822562989768 0 0 0</pose>
        <material>
          <ambient>0.501960784313725 0.501960784313725 0.501960784313725 1</ambient>
          <diffuse>0.501960784313725 0.501960784313725 0.501960784313725 1</diffuse>
        </material>
        <geometry>
          <mesh>
            <scale>1 1 1</scale>
            <uri>model://SimSwerveBot4/meshes/FRdrive.STL</uri>
          </mesh>
        </geometry>
      </visual>
    </link>
    <joint name="Body-FRdrive" type="revolute">
      <parent>Body</parent>
      <child>FRdrive</child>
      <pose>2.08201928120211E-06 -1.73472347597681E-18 0.000277042986581488 0 0 0</pose>
      <axis>
        <xyz>0 1 0</xyz>
        <dynamics>
          <damping>1</damping>
          <friction>1</friction>
        </dynamics>
      </axis>
    </joint>
    <link name="FRwheel">
      <gravity>1</gravity>
      <self_collide>0</self_collide>
      <pose>0.390524894652224 -0.045440778296 0.239779131380306 0 0 0</pose>
      <must_be_base_link>0</must_be_base_link>
      <velocity_decay>
        <linear>0</linear>
        <angular>0.002</angular>
      </velocity_decay>
      <inertial>
        <mass>0.123981366006225</mass>
        <pose>0 0 0 0 0 0</pose>
        
      </inertial>
      <collision name="FRwheel_collision">
        <pose>-0.847019150986402 0.0454407782959989 -2.16015680426457 0 0 0</pose>
        <geometry>
          <mesh>
            <scale>1 1 1</scale>
            <uri>model://SimSwerveBot4/meshes/FRwheel_col.STL</uri>
          </mesh>
        </geometry>
        <surface>
          <contact>
             <ode>
              <max_vel>0.1</max_vel>
              <soft_cfm>0.8</soft_cfm>
              <soft_erp>0.8</soft_erp>
              <kd>25</kd>
              <kp>1e6</kp>
              <min_depth>0.0001</min_depth>
            </ode>          
          </contact>
          <friction>
            <ode>
              <mu>1</mu>
              <mu2>1</mu2>
            </ode>
          </friction>
        </surface>
      </collision>
      <visual name="FRwheel_visual">
        <pose>-0.847019150986402 0.0454407782959989 -2.16015680426457 0 0 0</pose>
        <material>
          <ambient>0 1 0 1</ambient>
          <diffuse>0 1 0 1</diffuse>
        </material>
        <geometry>
          <mesh>
            <scale>1 1 1</scale>
            <uri>model://SimSwerveBot4/meshes/FRwheel.STL</uri>
          </mesh>
        </geometry>
      </visual>
    </link>
    <joint name="FRdrive-FRwheel" type="revolute">
      <parent>FRdrive</parent>
      <child>FRwheel</child>
      <pose>3.5053368525606E-06 0.000114295457558644 -0.00120273472992993 0 0 0</pose>
      <axis>
        <xyz>0 0 1</xyz>
        <dynamics>
          <damping>1</damping>
          <friction>1</friction>
        </dynamics>  
      </axis>
    </joint>
    <link name="FLdrive">
      <gravity>1</gravity>
      <self_collide>0</self_collide>
      <pose>0.390526514220831 -0.00811354846782578 -0.238402046668222 0 0 0</pose>
      <must_be_base_link>0</must_be_base_link>
      <velocity_decay>
        <linear>0</linear>
        <angular>0.01</angular>
      </velocity_decay>
      <inertial>
        <mass>0.0891523549651857</mass>
        <pose>0 0 0 0 0 0</pose>     
      </inertial>
      <visual name="FLdrive_visual">
        <pose>-0.84702077055501 0.0081135484678247 -1.68197562621604 0 0 0</pose>
        <material>
          <ambient>0.501960784313725 0.501960784313725 0.501960784313725 1</ambient>
          <diffuse>0.501960784313725 0.501960784313725 0.501960784313725 1</diffuse>
        </material>
        <geometry>
          <mesh>
            <scale>1 1 1</scale>
            <uri>model://SimSwerveBot4/meshes/FLdrive.STL</uri>
          </mesh>
        </geometry>
      </visual>
    </link>
    <joint name="Body-FLdrive" type="revolute">
      <parent>Body</parent>
      <child>FLdrive</child>
      <pose>-1.51422083138897E-06 6.93889390390723E-18 0.000277046668222258 0 0 0</pose>
      <axis>
        <xyz>0 1 0</xyz>
        <dynamics>
          <damping>1</damping>
          <friction>1</friction>
        </dynamics>
      </axis>
    </joint>
    <link name="FLwheel">
      <gravity>1</gravity>
      <self_collide>0</self_collide>
      <pose>0.390532719294217 -0.0453594163528396 -0.237673541862736 0 0 0</pose>
      <must_be_base_link>0</must_be_base_link>
      <velocity_decay>
        <linear>0</linear>
        <angular>0.002</angular>
      </velocity_decay>
      <inertial>
        <mass>0.413564687541818</mass>
        <pose>0 0 0 0 0 0</pose>       
      </inertial>
      <collision name="FLwheel_collision">
        <pose>-0.847026975628395 0.0453594163528385 -1.68270413102153 0 0 0</pose>
        <geometry>
          <mesh>
            <scale>1 1 1</scale>
            <uri>model://SimSwerveBot4/meshes/FLwheel_col.STL</uri>
          </mesh>
        </geometry>
        <surface>
          <contact>
             <ode>
              <max_vel>0.1</max_vel>
              <soft_cfm>0.8</soft_cfm>
              <soft_erp>0.8</soft_erp>
              <kd>25</kd>
              <kp>1e6</kp>
              <min_depth>0.001</min_depth>
            </ode>          
          </contact>
          <friction>
            <ode>
              <mu>1</mu>
              <mu2>1</mu2>
            </ode>
          </friction>
        </surface>
      </collision>
      <visual name="FLwheel_visual">
        <pose>-0.847026975628395 0.0453594163528385 -1.68270413102153 0 0 0</pose>
        <material>
          <ambient>0 1 0 1</ambient>
          <diffuse>0 1 0 1</diffuse>
        </material>
        <geometry>
          <mesh>
            <scale>1 1 1</scale>
            <uri>model://SimSwerveBot4/meshes/FLwheel.STL</uri>
          </mesh>
        </geometry>
      </visual>
    </link>
    <joint name="FLdrive-FLwheel" type="revolute">
      <parent>FLdrive</parent>
      <child>FLwheel</child>
      <pose>-1.01787932659247E-05 3.29335143967324E-05 -5.54598669211259E-08 0 0 0</pose>
      <axis>
        <xyz>0 0 1</xyz>
        <dynamics>
          <damping>1</damping>
          <friction>1</friction>
        </dynamics>
      </axis>
    </joint>
    <link name="BRdrive">
      <gravity>1</gravity>
      <self_collide>0</self_collide>
      <pose>-0.38981757481044 -0.0081135495114501 0.238402047413451 0 0 0</pose>
      <must_be_base_link>0</must_be_base_link>
      <velocity_decay>
        <linear>0</linear>
        <angular>0.01</angular>
      </velocity_decay>
      <inertial>
        <mass>0.0891523590073493</mass>
        <pose>0 0 0 0 0 0</pose>
      </inertial>
      <visual name="BRdrive_visual">
        <pose>-0.066676681523738 0.00811354951144901 -2.15877972029771 0 0 0</pose>
        <material>
          <ambient>0.501960784313725 0.501960784313725 0.501960784313725 1</ambient>
          <diffuse>0.501960784313725 0.501960784313725 0.501960784313725 1</diffuse>
        </material>
        <geometry>
          <mesh>
            <scale>1 1 1</scale>
            <uri>model://SimSwerveBot4/meshes/BRdrive.STL</uri>
          </mesh>
        </geometry>
      </visual>
    </link>
    <joint name="Body-BRdrive" type="revolute">
      <parent>Body</parent>
      <child>BRdrive</child>
      <pose>-1.68152373801467E-06 -8.67361737988404E-18 -0.000277047413450582 0 0 0</pose>
      <axis>
        <xyz>0 1 0</xyz>
        <dynamics>
          <damping>1</damping>
          <friction>1</friction>
        </dynamics>
      </axis>
    </joint>
    <link name="BRwheel">
      <gravity>1</gravity>
      <self_collide>0</self_collide>
      <pose>-0.389818236008278 -0.0453607471440594 0.237673576041824 0 0 0</pose>
      <must_be_base_link>0</must_be_base_link>
      <velocity_decay>
        <linear>0</linear>
        <angular>0.002</angular>
      </velocity_decay>
      <inertial>
        <mass>0.413564688849332</mass>
        <pose>0 0 0 0 0 0</pose>
      </inertial>
      <collision name="BRwheel_collision">
        <pose>-0.0666760203259 0.0453607471440583 -2.15805124892609 0 0 0</pose>
        <geometry>
          <mesh>
            <scale>1 1 1</scale>
            <uri>model://SimSwerveBot4/meshes/BRwheel_col.STL</uri>
          </mesh>
        </geometry>
        <surface>
          <contact>
            <ode>
              <max_vel>0.1</max_vel>
              <soft_cfm>0.8</soft_cfm>
              <soft_erp>0.8</soft_erp>
              <kd>25</kd>
              <kp>1e6</kp>
              <min_depth>0.0001</min_depth>
            </ode>          
          </contact>
          <friction>
            <ode>
              <mu>1</mu>
              <mu2>1</mu2>
            </ode>
          </friction>
        </surface>
      </collision>
      <visual name="BRwheel_visual">
        <pose>-0.0666760203259 0.0453607471440583 -2.15805124892609 0 0 0</pose>
        <material>
          <ambient>0 1 0 1</ambient>
          <diffuse>0 1 0 1</diffuse>
        </material>
        <geometry>
          <mesh>
            <scale>1 1 1</scale>
            <uri>model://SimSwerveBot4/meshes/BRwheel.STL</uri>
          </mesh>
        </geometry>
      </visual>
    </link>
    <joint name="BRdrive-BRwheel" type="revolute">
      <parent>BRdrive</parent>
      <child>BRwheel</child>
      <pose>-3.7665044388957E-06 3.42643056162745E-05 2.29141998708826E-08 0 0 0</pose>
      <axis>
        <xyz>0 0 1</xyz>
        <dynamics>
          <damping>1</damping>
          <friction>1</friction>
        </dynamics>
      </axis>
    </joint>
    <link name="BLdrive">
      <gravity>1</gravity>
      <self_collide>0</self_collide>
      <pose>-0.389815880758476 -0.0071726820171026 -0.237676179491394 0 0 0</pose>
      <must_be_base_link>0</must_be_base_link>
      <velocity_decay>
        <linear>0</linear>
        <angular>0.01</angular>
      </velocity_decay>
      <inertial>
        <mass>0.0869538722262852</mass>
        <pose>0 0 0 0 0 0</pose>
      </inertial>
      <visual name="BLdrive_visual">
        <pose>-0.0666783755757028 0.00717268201710151 -1.68270149339287 0 0 0</pose>
        <material>
          <ambient>0.501960784313725 0.501960784313725 0.501960784313725 1</ambient>
          <diffuse>0.501960784313725 0.501960784313725 0.501960784313725 1</diffuse>
        </material>
        <geometry>
          <mesh>
            <scale>1 1 1</scale>
            <uri>model://SimSwerveBot4/meshes/BLdrive.STL</uri>
          </mesh>
        </geometry>
      </visual>
    </link>
    <joint name="Body-BLdrive" type="revolute">
      <parent>Body</parent>
      <child>BLdrive</child>
      <pose>-3.37557570311009E-06 -1.73472347597681E-18 -0.00044882050860573 0 0 0</pose>
      <axis>
        <xyz>0 1 0</xyz>
        <dynamics>
          <damping>1</damping>
          <friction>1</friction>
        </dynamics>
      </axis>
    </joint>
    <link name="BLwheel">
      <gravity>1</gravity>
      <self_collide>0</self_collide>
      <pose>-0.389819150986402 -0.0454407782960015 -0.239779131380305 0 0 0</pose>
      <must_be_base_link>0</must_be_base_link>
      <velocity_decay>
        <linear>0</linear>
        <angular>0.002</angular>
      </velocity_decay>
      <inertial>
        <mass>0.123981366006226</mass>
        <pose>0 0 0 0 0 0</pose>
      </inertial>
      <collision name="BLwheel_collision">
        <pose>-0.0666751053477763 0.0454407782960004 -1.68059854150396 0 0 0</pose>
        <geometry>
          <mesh>
            <scale>1 1 1</scale>
            <uri>model://SimSwerveBot4/meshes/BLwheel_col.STL</uri>
          </mesh>
        </geometry>
        <surface>
          <contact>
             <ode>
              <max_vel>0.1</max_vel>
              <soft_cfm>0.8</soft_cfm>
              <soft_erp>0.8</soft_erp>
              <kd>25</kd>
              <kp>1e6</kp>
              <min_depth>0.0001</min_depth>
            </ode>          
          </contact>
          <friction>
            <ode>
              <mu>1</mu>
              <mu2>1</mu2>
            </ode>
          </friction>
        </surface>
      </collision>
      <visual name="BLwheel_visual">
        <pose>-0.0666751053477763 0.0454407782960004 -1.68059854150396 0 0 0</pose>
        <material>
          <ambient>0 1 0 1</ambient>
          <diffuse>0 1 0 1</diffuse>
        </material>
        <geometry>
          <mesh>
            <scale>1 1 1</scale>
            <uri>model://SimSwerveBot4/meshes/BLwheel.STL</uri>
          </mesh>
        </geometry>
      </visual>
    </link>
    <joint name="BLdrive-BLwheel" type="revolute">
      <parent>BLdrive</parent>
      <child>BLwheel</child>
      <pose>-3.50533685232468E-06 0.000114295457558339 0.00120273472992949 0 0 0</pose>
      <axis>
        <xyz>0 0 1</xyz>
        <dynamics>
          <damping>1</damping>
          <friction>1</friction>
        </dynamics>
      </axis>
    </joint>
    
    <link name="LowerArm">
      <gravity>1</gravity>
      <self_collide>0</self_collide>
      <pose>-0.102067540968878 0.648286652228778 0.201682058992895 0 0 0</pose>
      <must_be_base_link>0</must_be_base_link>
      <velocity_decay>
        <linear>0</linear>
        <angular>0.1</angular>
      </velocity_decay>
      <inertial>
        <mass>3.1900657983711</mass>
        <pose>0 0 0 0 0 0</pose>
       
      </inertial>
      <collision name="LowerArm_collision">
        <pose>-0.354426715365301 -0.648286652228779 -2.12205973187716 0 0 0</pose>
        <geometry>
          <mesh>
            <scale>1 1 1</scale>
            <uri>model://SimSwerveBot4/meshes/LowerArm_col.STL</uri>
          </mesh>
        </geometry>
        <surface>
          <contact>
            <ode />
          </contact>
          <friction>
            <ode>
              <mu>0</mu>
              <mu2>0</mu2>
            </ode>
          </friction>
        </surface>
      </collision>
      <visual name="LowerArm_visual">
        <pose>-0.354426715365301 -0.648286652228779 -2.12205973187716 0 0 0</pose>
        <material>
          <ambient>0.250980392156863 0.501960784313725 0.501960784313725 1</ambient>
          <diffuse>0.250980392156863 0.501960784313725 0.501960784313725 1</diffuse>
        </material>
        <geometry>
          <mesh>
            <scale>1 1 1</scale>
            <uri>model://SimSwerveBot4/meshes/LowerArm.STL</uri>
          </mesh>
        </geometry>
      </visual>
    </link>
    <joint name="Body-LowerArm" type="revolute">
      <parent>Body</parent>
      <child>LowerArm</child>
      <pose>0.1003602846347 -0.502236652228779 0 0 0 0</pose>
      <axis>
        <xyz>0 0 1</xyz>
        <dynamics>
          <damping>2</damping>
          <friction>1</friction>
        </dynamics>
      
        <limit>
         <lower>-1.4</lower>
         <upper>1.0</upper>
        </limit>
       
      </axis>
    </joint>
    
    <link name="UpperArm">
      <gravity>1</gravity>
      <self_collide>0</self_collide>
      <pose>-0.208744947965112 0.865991228362569 0.132747045366589 0 0 0</pose>
      <must_be_base_link>0</must_be_base_link>
      <velocity_decay>
        <linear>0</linear>
        <angular>0.1</angular>
      </velocity_decay>
      <inertial>
        <mass>2.35701643914108</mass>
        <pose>0 0 0 0 0 0</pose>
        
      </inertial>
      <collision name="UpperArm_collision">
        <pose>-0.247749308369066 -0.86599122836257 -2.05312471825085 0 0 0</pose>
        <geometry>
          <mesh>
            <scale>1 1 1</scale>
            <uri>model://SimSwerveBot4/meshes/UpperArm_col.STL</uri>
          </mesh>
        </geometry>
        <surface>
          <contact>
            <ode />
          </contact>
          <friction>
            <ode>
              <mu>1</mu>
              <mu2>1</mu2>
            </ode>
          </friction>
        </surface>
      </collision>
      <visual name="UpperArm_visual">
        <pose>-0.247749308369066 -0.86599122836257 -2.05312471825085 0 0 0</pose>
        <material>
          <ambient>0.250980392156863 0.501960784313725 0.501960784313725 1</ambient>
          <diffuse>0.250980392156863 0.501960784313725 0.501960784313725 1</diffuse>
        </material>
        <geometry>
          <mesh>
            <scale>1 1 1</scale>
            <uri>model://SimSwerveBot4/meshes/UpperArm.STL</uri>
          </mesh>
        </geometry>
      </visual>
    </link>
    <joint name="LowerArm-UpperArm" type="revolute">
      <parent>LowerArm</parent>
      <child>UpperArm</child>
      <pose>-0.0078763379280225 0.355568315938512 0 0 0 0</pose>
      <axis>
        <xyz>0 0 1</xyz>
        <dynamics>
          <damping>2</damping>
          <friction>1</friction>
        </dynamics>
        
        <!--
        <limit>
         <lower>-2.6</lower>
         <upper>2.6</upper>
        </limit>
        -->
      </axis>
    </joint>
    
    <link name="GripperRotate">
      <gravity>1</gravity>
      <self_collide>0</self_collide>
      <pose>-0.198420383100514 0.446967540730028 0.023460469661692 0 0 0</pose>
      <must_be_base_link>0</must_be_base_link>
      <velocity_decay>
        <linear>0</linear>
        <angular>0.05</angular>
      </velocity_decay>
      <inertial>
        <mass>0.14389059238857</mass>
        <pose>0 0 0 0 0 0</pose>
       
      </inertial>
      <collision name="GripperRotate_collision">
        <pose>-0.258073873233665 -0.446967540730029 -1.94383814254595 0 0 0</pose>
        <geometry>
          <mesh>
            <scale>1 1 1</scale>
            <uri>model://SimSwerveBot4/meshes/GripperRotate_col.STL</uri>
          </mesh>
        </geometry>
        <surface>
          <contact>
            <ode />
          </contact>
          <friction>
            <ode>
              <mu>1</mu>
              <mu2>1</mu2>
            </ode>
          </friction>
        </surface>
      </collision>
      <visual name="GripperRotate_visual">
        <pose>-0.258073873233665 -0.446967540730029 -1.94383814254595 0 0 0</pose>
        <material>
          <ambient>0.752941176470588 0.752941176470588 0.752941176470588 1</ambient>
          <diffuse>0.752941176470588 0.752941176470588 0.752941176470588 1</diffuse>
        </material>
        <geometry>
          <mesh>
            <scale>1 1 1</scale>
            <uri>model://SimSwerveBot4/meshes/GripperRotate.STL</uri>
          </mesh>
        </geometry>
      </visual>
    </link>
    <joint name="UpperArm-GripperRotate" type="revolute">
      <parent>UpperArm</parent>
      <child>GripperRotate</child>
      <pose>-0.000595887983165122 -0.00219462585143981 0 0 0 0</pose>
      <axis>
        <xyz>0 0 -1</xyz>
        <dynamics>
          <damping>0</damping>
          <friction>0</friction>
        </dynamics>
       
        <limit>
          <upper>3.14</upper>
          <lower>-3.14</lower>
        </limit>
      </axis>
    </joint>
    
    <link name="GripperTwist">
      <gravity>1</gravity>
      <self_collide>0</self_collide>
      <pose>-0.0625315359320857 0.478638830369111 -0.0199341015108323 0 0 0</pose>
      <must_be_base_link>0</must_be_base_link>
      <velocity_decay>
        <linear>0</linear>
        <angular>0.0</angular>
      </velocity_decay>
      <inertial>
        <mass>0.01</mass>
        <pose>0 0 0 0 0 0</pose>
        
      </inertial>
      <collision name="GripperTwist_collision">
        <pose>-0.393962720402093 -0.478638830369112 -1.90044357137343 0 0 0</pose>
        <geometry>
          <mesh>
            <scale>1 1 1</scale>
            <uri>model://SimSwerveBot4/meshes/GripperTwist_col.STL</uri>
          </mesh>
        </geometry>
        <surface>
          <contact>
            <ode />
          </contact>
          <friction>
            <ode>
              <mu>1</mu>
              <mu2>1</mu2>
            </ode>
          </friction>
        </surface>
      </collision>
      <visual name="GripperTwist_visual">
        <pose>-0.393962720402093 -0.478638830369112 -1.90044357137343 0 0 0</pose>
        <material>
          <ambient>0.752941176470588 0.752941176470588 0.752941176470588 1</ambient>
          <diffuse>0.752941176470588 0.752941176470588 0.752941176470588 1</diffuse>
        </material>
        <geometry>
          <mesh>
            <scale>1 1 1</scale>
            <uri>model://SimSwerveBot4/meshes/GripperTwist.STL</uri>
          </mesh>
        </geometry>
      </visual>
    
      <sensor name="GripperTwistCamera" type="camera">
        <visualize>1</visualize>
        <always_on>1</always_on>
        <!--<pose>0.0205235796459304 0.0194185226531891 0.000678730782040171 -1.57 0.0 0.0</pose>-->

        <pose>0.0205235796459304 0.1 -0.15 -1.57 -0.1 0.0</pose>
        <camera name="GripperTwistcamera">
          <horizontal_fov>1.5707963267949</horizontal_fov>
          <image>
             <width>640</width>
            <height>480</height>
          </image>
          <clip>
            <near>0.05</near>
            <far>30</far>
          </clip>
        </camera>
         <plugin name="camera1" filename="sim_camera.dll">
          <topic>~/gazebo/frc/simulator/camera/0</topic>
          <port>9000</port>
          <fps>20</fps>
          <enabled>true</enabled>
          <savepath>tmp</savepath>
          <maxframes>1</maxframes>
        </plugin>
      </sensor>   
    </link>
    
    <joint name="GripperRotate-GripperTwist" type="revolute">
      <parent>GripperRotate</parent>
      <child>GripperTwist</child>
      <pose>0.000738095228608571 -0.0247846584189436 0.0094777154723078 0 0 0</pose>
      <axis>
        <xyz>1 0 0</xyz>
        <dynamics>
          <damping>0.1</damping>
          <friction>0.1</friction>
        </dynamics>
        <limit>
          <upper>3.14</upper>
          <lower>-3.14</lower>
        </limit>
        
      </axis>
    </joint>
   
    <link name="LeftGripper">
      <gravity>1</gravity>
      <self_collide>0</self_collide>
      <pose>0.0810671068320737 0.418847304378557 -0.190733921869457 0 0 0</pose>
      <must_be_base_link>0</must_be_base_link>
      <velocity_decay>
        <linear>0</linear>
        <angular>0.01</angular>
      </velocity_decay>
      <inertial>
        <mass>0.01</mass>
        <pose>0 0 0 0 0 0</pose>
      </inertial>
      
      <collision name="LeftGripper_collision">
        <pose>-0.537561363166252 -0.418847304378558 -1.72964375101481 0 0 0</pose>
        <geometry>
          <mesh>
            <scale>1 1 1</scale>
            <uri>model://SimSwerveBot4/meshes/LeftGripper_col.STL</uri>
          </mesh>
        </geometry>
        <surface>
        <!--
          <contact>
           <ode>
              <kp>1000.0</kp>
              <kd>1e8</kd>
            </ode>
          </contact>
          <friction>
            <ode>
              <mu>2</mu>
              <mu2>2</mu2>
            </ode>
          </friction>
          -->
        </surface>
      </collision>
      
      <visual name="LeftGripper_visual">
        <pose>-0.537561363166252 -0.418847304378558 -1.72964375101481 0 0 0</pose>
        <material>
          <ambient>0.752941176470588 0.752941176470588 0.752941176470588 1</ambient>
          <diffuse>0.752941176470588 0.752941176470588 0.752941176470588 1</diffuse>
        </material>
        <geometry>
          <mesh>
            <scale>1 1 1</scale>
            <uri>model://SimSwerveBot4/meshes/LeftGripper.STL</uri>
          </mesh>
        </geometry>
      </visual>
    </link>
    <joint name="GripperTwist-LeftGripper" type="revolute">
      <parent>GripperTwist</parent>
      <child>LeftGripper</child>
      <pose>-0.12664725783566 -0.00349102407337348 0.0198663629541476 0 0 0</pose>
      <axis>
        <xyz>0 1 0</xyz>
        <dynamics>
          <damping>0</damping>
          <friction>0</friction>
        </dynamics>
        <limit>
          <upper>0.13</upper>
          <lower>-0.25</lower>
        </limit>
      </axis>
    </joint>
   
    <link name="RightGripper">
      <gravity>1</gravity>
      <self_collide>0</self_collide>
      <pose>0.0839620482191449 0.425397534803131 0.138652543294368 0 0 0</pose>
      <must_be_base_link>0</must_be_base_link>
      <velocity_decay>
        <linear>0</linear>
        <angular>0</angular>
      </velocity_decay>
      <inertial>
        <mass>0.01</mass>
        <pose>0 0 0 0 0 0</pose>
       
      </inertial>
      <!---->
      <collision name="RightGripper_collision">
        <pose>-0.540456304553323 -0.425397534803132 -2.05903021617863 0 0 0</pose>
        <geometry>
          <mesh>
            <scale>1 1 1</scale>
            <uri>model://SimSwerveBot4/meshes/RightGripper_col.STL</uri>
          </mesh>
        </geometry>
        <surface>
        <!--
          <contact>
           <ode>
              <kp>1000.0</kp>
              <kd>1e8</kd>
            </ode>      
          </contact>
          <friction>
            <ode>
              <mu>2</mu>
              <mu2>2</mu2>
            </ode>
          </friction>
          -->
        </surface>
      </collision>
      
      <visual name="RightGripper_visual">
        <pose>-0.540456304553323 -0.425397534803132 -2.05903021617863 0 0 0</pose>
        <material>
          <ambient>0.752941176470588 0.752941176470588 0.752941176470588 1</ambient>
          <diffuse>0.752941176470588 0.752941176470588 0.752941176470588 1</diffuse>
        </material>
        <geometry>
          <mesh>
            <scale>1 1 1</scale>
            <uri>model://SimSwerveBot4/meshes/RightGripper.STL</uri>
          </mesh>
        </geometry>
      </visual>
    </link>
    <joint name="GripperTwist-RightGripper" type="revolute">
      <parent>GripperTwist</parent>
      <child>RightGripper</child>
      <pose>-0.126981660994285 -0.00402853279122511 -0.0174876024108572 0 0 0</pose>
      <axis>
        <xyz>0 -1 0</xyz>
        <dynamics>
          <damping>0</damping>
          <friction>0</friction>
        </dynamics>
         <limit>
          <upper>0.13</upper>
          <lower>-0.25</lower>
        </limit>
      </axis>
    </joint>
     
    <link name="LeftPad">
      <gravity>1</gravity>
      <self_collide>0</self_collide>
      <pose>0.239600029637804 0.424982251188515 -0.154782770122619 0 0 0</pose>
      <must_be_base_link>0</must_be_base_link>
      <velocity_decay>
        <linear>0</linear>
        <angular>0</angular>
      </velocity_decay>
      <inertial>
        <mass>0.01</mass>
        <pose>0 0 0 0 0 0</pose>
      </inertial>
      
      <collision name="LeftPad_collision">
        <pose>-0.696094285971983 -0.424982251188516 -1.76559490276164 0 0 0</pose>
        <geometry>
          <mesh>
            <scale>1 1 1</scale>
            <uri>model://SimSwerveBot4/meshes/LeftPad_col.STL</uri>
          </mesh>
        </geometry>
        <surface>
        <!---->
          <contact>
            <ode>
              <kp>1e3</kp>
              <kd>1e7</kd>
              <min_depth>0.001</min_depth>
            </ode>          
          </contact>
          <torsional>
            <ode>
              <coefficient>1</coefficient>
              <slip>0.1</slip>
            </ode>
          </torsional>
          <friction>
            <ode>
              <mu>4</mu>
              <mu2>4</mu2>
            </ode>
          </friction>
        </surface>
      </collision>
      
      <visual name="LeftPad_visual">
        <pose>-0.696094285971983 -0.424982251188516 -1.76559490276164 0 0 0</pose>
        <material>
          <ambient>0 0.501960784313725 0.501960784313725 1</ambient>
          <diffuse>0 0.501960784313725 0.501960784313725 1</diffuse>
        </material>
        <geometry>
          <mesh>
            <scale>1 1 1</scale>
            <uri>model://SimSwerveBot4/meshes/LeftPad.STL</uri>
          </mesh>
        </geometry>
      </visual>
    </link>
    <joint name="LeftGripper-LeftPad" type="revolute">
      <parent>LeftGripper</parent>
      <child>LeftPad</child>
      <pose>2.70894418008538E-14 8.71525074330748E-15 -4.44089209850063E-15 0 0 0</pose>
      <axis>
        <xyz>0.154458439010382 0.0185508776653356 0.9878251138518</xyz>
        <dynamics>
          <damping>0</damping>
          <friction>0</friction>
        </dynamics>
      </axis>
    </joint>
    
    <link name="RightPad">
      <gravity>1</gravity>
      <self_collide>0</self_collide>
      <pose>0.241878388878302 0.428644634182398 0.0997334452054581 0 0 0</pose>
      <must_be_base_link>0</must_be_base_link>
      <velocity_decay>
        <linear>0</linear>
        <angular>0</angular>
      </velocity_decay>
      <inertial>
        <mass>0.01</mass>
        <pose>0 0 0 0 0 0</pose> 
      </inertial>
      <!-- -->
      <collision name="RightPad_collision">
        <pose>-0.69837264521248 -0.428644634182399 -2.02011111808972 0 0 0</pose>
        <geometry>
          <mesh>
            <scale>1 1 1</scale>
            <uri>model://SimSwerveBot4/meshes/RightPad_col.STL</uri>
          </mesh>
        </geometry>
        <surface>
          <contact>
            <ode>
              <min_depth>0.001</min_depth>
              <kp>1e3</kp>
              <kd>1e7</kd>
            </ode>          
          </contact>
          <torsional>
            <ode>
              <coefficient>1</coefficient>
              <slip>0.1</slip>
            </ode>
          </torsional>
          <friction>
            <ode>
              <mu>4</mu>
              <mu2>4</mu2>
            </ode>
          </friction>
        </surface>
      </collision>
     
      <visual name="RightPad_visual">
        <pose>-0.69837264521248 -0.428644634182399 -2.02011111808972 0 0 0</pose>
        <material>
          <ambient>0 0.501960784313725 0.501960784313725 1</ambient>
          <diffuse>0 0.501960784313725 0.501960784313725 1</diffuse>
        </material>
        <geometry>
          <mesh>
            <scale>1 1 1</scale>
            <uri>model://SimSwerveBot4/meshes/RightPad.STL</uri>
          </mesh>
        </geometry>
      </visual>
    </link>
    <joint name="RightGripper-RightPad" type="revolute">
      <parent>RightGripper</parent>
      <child>RightPad</child>
      <pose>3.11972669919669E-14 1.01585406753202E-14 3.99680288865056E-15 0 0 0</pose>
      <axis>
        <xyz>0.136747414521 -0.00991724477742757 -0.990556304748926</xyz>
        <dynamics>
          <damping>0</damping>
          <friction>0</friction>
        </dynamics>
      </axis>
    </joint>
    
    <plugin name="clock" filename="sim_clock.dll">
      <topic>~/gazebo/frc/simulator/clock</topic>
    </plugin>

    <plugin name="Body_gyro" filename="sim_gyro.dll">
      <link>Body</link>
      <topic>~/gazebo/frc/simulator/gyro/0</topic>
      <units>degrees</units>
      <axis>yaw</axis>
    </plugin>
    
    <plugin name="Frame-FL-drive_motor" filename="sim_motor.dll">
      <joint>FLdrive-FLwheel</joint>
      <topic>~/gazebo/frc/simulator/motor/1</topic>
      <multiplier>25</multiplier>
    </plugin>
    <plugin name="Frame-FL-drive_encoder" filename="sim_encoder.dll">
        <joint>FLdrive-FLwheel</joint>
        <topic>~/gazebo/frc/simulator/encoder/1</topic>
        <multiplier>1</multiplier>
    </plugin> 
    <plugin name="Frame-FL-turn_motor" filename="sim_motor.dll">
        <joint>Body-FLdrive</joint>
        <topic>~/gazebo/frc/simulator/motor/2</topic>
        <multiplier>25</multiplier>
    </plugin>
      <plugin name="Frame-FL-turn_encoder" filename="sim_encoder.dll">
      <joint>Body-FLdrive</joint>
       <topic>~/gazebo/frc/simulator/encoder/2</topic>
      <multiplier>1</multiplier>
    </plugin>
 
    <plugin name="Frame-FR-drive_motor" filename="sim_motor.dll">
        <joint>FRdrive-FRwheel</joint>
        <topic>~/gazebo/frc/simulator/motor/3</topic>
        <multiplier>25</multiplier>
    </plugin>
    <plugin name="Frame-FR-drive_encoder" filename="sim_encoder.dll">
        <joint>FRdrive-FRwheel</joint>
        <topic>~/gazebo/frc/simulator/encoder/3</topic>
        <multiplier>1</multiplier>
    </plugin> 
    <plugin name="Frame-FR-turn_motor" filename="sim_motor.dll">
        <joint>Body-FRdrive</joint>
        <topic>~/gazebo/frc/simulator/motor/4</topic>
        <multiplier>25</multiplier>
    </plugin>
    <plugin name="Frame-FR-turn_encoder" filename="sim_encoder.dll">
      <joint>Body-FRdrive</joint>
       <topic>~/gazebo/frc/simulator/encoder/4</topic>
      <multiplier>1</multiplier>
    </plugin>

    <plugin name="Frame-BL-drive_motor" filename="sim_motor.dll">
        <joint>BLdrive-BLwheel</joint>
        <topic>~/gazebo/frc/simulator/motor/5</topic>
        <multiplier>25</multiplier>
    </plugin>
    <plugin name="Frame-BL-drive_encoder" filename="sim_encoder.dll">
        <joint>BLdrive-BLwheel</joint>
        <topic>~/gazebo/frc/simulator/encoder/5</topic>
        <multiplier>1</multiplier>
    </plugin> 
    <plugin name="Frame-BL-turn_motor" filename="sim_motor.dll">
        <joint>Body-BLdrive</joint>
        <topic>~/gazebo/frc/simulator/motor/6</topic>
        <multiplier>25</multiplier>
    </plugin>
    <plugin name="Frame-BL-turn_encoder" filename="sim_encoder.dll">
        <joint>Body-BLdrive</joint>
        <topic>~/gazebo/frc/simulator/encoder/6</topic>
        <multiplier>1</multiplier>
    </plugin>

    <plugin name="Frame-BR-drive_motor" filename="sim_motor.dll">
        <joint>BRdrive-BRwheel</joint>
        <topic>~/gazebo/frc/simulator/motor/7</topic>
        <multiplier>25</multiplier>
    </plugin>
      <plugin name="Frame-BR-drive_encoder" filename="sim_encoder.dll">
        <joint>BRdrive-BRwheel</joint>
        <topic>~/gazebo/frc/simulator/encoder/7</topic>
        <multiplier>1</multiplier>
    </plugin> 
    <plugin name="Frame-BR-turn_motor" filename="sim_motor.dll">
        <joint>Body-BRdrive</joint>
        <topic>~/gazebo/frc/simulator/motor/8</topic>
        <multiplier>25</multiplier>
    </plugin>
    <plugin name="Frame-BR-turn_encoder" filename="sim_encoder.dll">
        <joint>Body-BRdrive</joint>
        <topic>~/gazebo/frc/simulator/encoder/8</topic>
        <multiplier>1</multiplier>
    </plugin>

    <plugin name="Frame-lower-arm_motor" filename="sim_motor.dll">
        <joint>Body-LowerArm</joint>
        <topic>~/gazebo/frc/simulator/motor/9</topic>
        <multiplier>50</multiplier>
    </plugin>
    <plugin name="Frame-lower-arm_encoder" filename="sim_encoder.dll">
        <joint>Body-LowerArm</joint>
        <topic>~/gazebo/frc/simulator/encoder/9</topic>
        <multiplier>1</multiplier>
    </plugin>

    <plugin name="LowerArm-UpperArm_motor" filename="sim_motor.dll">
        <joint>LowerArm-UpperArm</joint>
        <topic>~/gazebo/frc/simulator/motor/10</topic>
        <multiplier>50</multiplier>
    </plugin>
    <plugin name="LowerArm-UpperArm_encoder" filename="sim_encoder.dll">
        <joint>LowerArm-UpperArm</joint>
        <topic>~/gazebo/frc/simulator/encoder/10</topic>
        <multiplier>1</multiplier>
    </plugin>

    <plugin name="UpperArm-Wrist_motor" filename="sim_motor.dll">
        <joint>UpperArm-GripperRotate</joint>
        <topic>~/gazebo/frc/simulator/motor/11</topic>
        <multiplier>60</multiplier>
    </plugin>
    <plugin name="UpperArm-Wrist_encoder" filename="sim_encoder.dll">
        <joint>UpperArm-GripperRotate</joint>
        <topic>~/gazebo/frc/simulator/encoder/11</topic>
        <multiplier>1</multiplier>
    </plugin>

    <plugin name="GripperRotate-GripperTwist_motor" filename="sim_motor.dll">
        <joint>GripperRotate-GripperTwist</joint>
        <topic>~/gazebo/frc/simulator/motor/12</topic>
        <multiplier>50</multiplier>
    </plugin>
    <plugin name="GripperRotate-GripperTwist_encoder" filename="sim_encoder.dll">
        <joint>GripperRotate-GripperTwist</joint>
        <topic>~/gazebo/frc/simulator/encoder/12</topic>
        <multiplier>1</multiplier>
    </plugin>

    <plugin name="GripperTwist-LeftGripper" filename="sim_piston.dll">
        <joint>GripperTwist-LeftGripper</joint>
        <topic>~/gazebo/frc/simulator/piston/0</topic>
        <forward-force>30</forward-force>
        <reverse-force>20</reverse-force>
    </plugin>

     <plugin name="GripperTwist-RightGripper" filename="sim_piston.dll">
        <joint>GripperTwist-RightGripper</joint>
        <topic>~/gazebo/frc/simulator/piston/0</topic>
        <forward-force>30</forward-force>
        <reverse-force>20</reverse-force>    
      </plugin>

    
  </model>
</sdf>