<?xml version="1.0" encoding="utf-8"?>
<sdf version="1.5">
  <model name="SimBotOneArm">
    <pose>0 0 -1.08924292772216E-15 0 0 0</pose>
    <link name="Body">
      <gravity>1</gravity>
      <self_collide>0</self_collide>
      <pose>0.00985477473838137 0.0248042978731545 0.0167947827619528 0 0 0</pose>
      <must_be_base_link>1</must_be_base_link>
      <velocity_decay>
        <linear>0</linear>
        <angular>0</angular>
      </velocity_decay>
      <inertial>
        <mass>150</mass>
        <pose>0 0 0 0 0 0</pose>
      </inertial>
      <collision name="Body_collision">
        <pose>-0.46634903107256 -0.0248042978731556 -1.91585534725916 0 0 0</pose>
        <geometry>
          <mesh>
            <scale>1 1 1</scale>
            <uri>model://SimBotOneArm/meshes/Body_col.STL</uri>
          </mesh>
        </geometry>
        <surface>
          <contact>
            <ode />
          </contact>
          <friction>
            <ode>
              <mu>0</mu>
              <mu2>0</mu2>
            </ode>
          </friction>
        </surface>
      </collision>
      <visual name="Body_visual">
        <pose>-0.46634903107256 -0.0248042978731556 -1.91585534725916 0 0 0</pose>
        <material>
          <ambient>0.501960784313725 0.501960784313725 0.501960784313725 1</ambient>
          <diffuse>0.501960784313725 0.501960784313725 0.501960784313725 1</diffuse>
        </material>
        <geometry>
          <mesh>
            <scale>1 1 1</scale>
            <uri>model://SimBotOneArm/meshes/Body.STL</uri>
          </mesh>
        </geometry>
      </visual>
    </link>
    <link name="FRdrive">
      <gravity>1</gravity>
      <self_collide>0</self_collide>
      <pose>0.390522917980719 -0.00811354847564088 0.237847957013419 0 0 0</pose>
      <must_be_base_link>0</must_be_base_link>
      <velocity_decay>
        <linear>0</linear>
        <angular>0.01</angular>
      </velocity_decay>
      <inertial>
        <mass>0.0891523549879119</mass>
        <pose>0 0 0 0 0 0</pose>
      </inertial>
      <visual name="FRdrive_visual">
        <pose>-0.847017174314898 0.00811354847563979 -2.13690852151062 0 0 0</pose>
        <material>
          <ambient>0.501960784313725 0.501960784313725 0.501960784313725 1</ambient>
          <diffuse>0.501960784313725 0.501960784313725 0.501960784313725 1</diffuse>
        </material>
        <geometry>
          <mesh>
            <scale>1 1 1</scale>
            <uri>model://SimBotOneArm/meshes/FRdrive.STL</uri>
          </mesh>
        </geometry>
      </visual>
    </link>
    <joint name="Body-FRdrive" type="revolute">
      <parent>Body</parent>
      <child>FRdrive</child>
      <pose>2.08201928131313E-06 5.20417042793042E-18 0.000277042986581044 0 0 0</pose>
      <axis>
        <xyz>-1 0 0</xyz>
        <dynamics>
          <damping>1</damping>
          <friction>1</friction>
        </dynamics>
      </axis>
    </joint>
    <link name="FRwheel">
      <gravity>1</gravity>
      <self_collide>0</self_collide>
      <pose>0.390524894652223 -0.0454407782960001 0.239779131380306 0 0 0</pose>
      <must_be_base_link>0</must_be_base_link>
      <velocity_decay>
        <linear>0</linear>
        <angular>0.002</angular>
      </velocity_decay>
      <inertial>
        <mass>0.123981366006225</mass>
        <pose>0 0 0 0 0 0</pose>
      </inertial>
      <collision name="FRwheel_collision">
        <pose>-0.847019150986402 0.045440778295999 -2.13883969587751 0 0 0</pose>
        <geometry>
          <mesh>
            <scale>1 1 1</scale>
            <uri>model://SimBotOneArm/meshes/FRwheel_col.STL</uri>
          </mesh>
        </geometry>
        <surface>
           <contact>
             <ode>
              <max_vel>0.1</max_vel>
              <soft_cfm>0.8</soft_cfm>
              <soft_erp>0.8</soft_erp>
              <kd>25</kd>
              <kp>1e6</kp>
              <min_depth>0.0001</min_depth>
            </ode>          
          </contact>
          <friction>
            <ode>
              <mu>1</mu>
              <mu2>1</mu2>
            </ode>
          </friction>
        </surface>
      </collision>
      <visual name="FRwheel_visual">
        <pose>-0.847019150986402 0.045440778295999 -2.13883969587751 0 0 0</pose>
        <material>
          <ambient>0 1 0 1</ambient>
          <diffuse>0 1 0 1</diffuse>
        </material>
        <geometry>
          <mesh>
            <scale>1 1 1</scale>
            <uri>model://SimBotOneArm/meshes/FRwheel.STL</uri>
          </mesh>
        </geometry>
      </visual>
    </link>
    <joint name="FRdrive-FRwheel" type="revolute">
      <parent>FRdrive</parent>
      <child>FRwheel</child>
      <pose>1.25638072466794E-05 0.000114295457558686 -9.46325307005225E-08 0 0 0</pose>
      <axis>
        <xyz>1 0 0</xyz>
        <dynamics>
          <damping>1</damping>
          <friction>1</friction>
        </dynamics>
      </axis>
    </joint>
    <link name="FLdrive">
      <gravity>1</gravity>
      <self_collide>0</self_collide>
      <pose>0.390526514220831 -0.00811354846782576 -0.238402046668222 0 0 0</pose>
      <must_be_base_link>0</must_be_base_link>
      <velocity_decay>
        <linear>0</linear>
        <angular>0.01</angular>
      </velocity_decay>
      <inertial>
        <mass>0.0891523549651857</mass>
        <pose>0 0 0 0 0 0</pose>
      </inertial>
      <visual name="FLdrive_visual">
        <pose>-0.84702077055501 0.00811354846782467 -1.66065851782898 0 0 0</pose>
        <material>
          <ambient>0.501960784313725 0.501960784313725 0.501960784313725 1</ambient>
          <diffuse>0.501960784313725 0.501960784313725 0.501960784313725 1</diffuse>
        </material>
        <geometry>
          <mesh>
            <scale>1 1 1</scale>
            <uri>model://SimBotOneArm/meshes/FLdrive.STL</uri>
          </mesh>
        </geometry>
      </visual>
    </link>
    <joint name="Body-FLdrive" type="revolute">
      <parent>Body</parent>
      <child>FLdrive</child>
      <pose>-1.51422083127795E-06 3.46944695195361E-18 0.000277046668222702 0 0 0</pose>
      <axis>
        <xyz>-1 0 0</xyz>
        <dynamics>
          <damping>1</damping>
          <friction>1</friction>
        </dynamics>
      </axis>
    </joint>
    <link name="FLwheel">
      <gravity>1</gravity>
      <self_collide>0</self_collide>
      <pose>0.390532719294217 -0.0453594163528395 -0.237673541862736 0 0 0</pose>
      <must_be_base_link>0</must_be_base_link>
      <velocity_decay>
        <linear>0</linear>
        <angular>0</angular>
      </velocity_decay>
      <inertial>
        <mass>0.413564687541818</mass>
        <pose>0 0 0 0 0 0</pose>
      </inertial>
      <collision name="FLwheel_collision">
        <pose>-0.847026975628395 0.0453594163528384 -1.66138702263447 0 0 0</pose>
        <geometry>
          <mesh>
            <scale>1 1 1</scale>
            <uri>model://SimBotOneArm/meshes/FLwheel_col.STL</uri>
          </mesh>
        </geometry>
        <surface>
           <contact>
             <ode>
              <max_vel>0.1</max_vel>
              <soft_cfm>0.8</soft_cfm>
              <soft_erp>0.8</soft_erp>
              <kd>25</kd>
              <kp>1e6</kp>
              <min_depth>0.001</min_depth>
            </ode>          
          </contact>
          <friction>
            <ode>
              <mu>1</mu>
              <mu2>1</mu2>
            </ode>
          </friction>
        </surface>
      </collision>
      <visual name="FLwheel_visual">
        <pose>-0.847026975628395 0.0453594163528384 -1.66138702263447 0 0 0</pose>
        <material>
          <ambient>0 1 0 1</ambient>
          <diffuse>0 1 0 1</diffuse>
        </material>
        <geometry>
          <mesh>
            <scale>1 1 1</scale>
            <uri>model://SimBotOneArm/meshes/FLwheel.STL</uri>
          </mesh>
        </geometry>
      </visual>
    </link>
    <joint name="FLdrive-FLwheel" type="revolute">
      <parent>FLdrive</parent>
      <child>FLwheel</child>
      <pose>-1.01787932658137E-05 3.29335143966769E-05 -5.54598666990813E-08 0 0 0</pose>
      <axis>
        <xyz>1 0 0</xyz>
        <dynamics>
          <damping>1</damping>
          <friction>1</friction>
        </dynamics>
      </axis>
    </joint>
    <link name="BRdrive">
      <gravity>1</gravity>
      <self_collide>0</self_collide>
      <pose>-0.389817575765436 -0.00811354829345361 0.238402045378659 0 0 0</pose>
      <must_be_base_link>0</must_be_base_link>
      <velocity_decay>
        <linear>0</linear>
        <angular>0.01</angular>
      </velocity_decay>
      <inertial>
        <mass>0.0891523542037304</mass>
        <pose>0 0 0 0 0 0</pose>
      </inertial>
      <visual name="BRdrive_visual">
        <pose>-0.0666766805687427 0.00811354829345252 -2.13746260987586 0 0 0</pose>
        <material>
          <ambient>0.501960784313725 0.501960784313725 0.501960784313725 1</ambient>
          <diffuse>0.501960784313725 0.501960784313725 0.501960784313725 1</diffuse>
        </material>
        <geometry>
          <mesh>
            <scale>1 1 1</scale>
            <uri>model://SimBotOneArm/meshes/BRdrive.STL</uri>
          </mesh>
        </geometry>
      </visual>
    </link>
    <joint name="Body-BRdrive" type="revolute">
      <parent>Body</parent>
      <child>BRdrive</child>
      <pose>-1.68056874268185E-06 0 -0.000277045378659579 0 0 0</pose>
      <axis>
        <xyz>-1 0 0</xyz>
        <dynamics>
          <damping>1</damping>
          <friction>1</friction>
        </dynamics>
      </axis>
    </joint>
    <link name="BRwheel">
      <gravity>1</gravity>
      <self_collide>0</self_collide>
      <pose>-0.389818236008279 -0.0453607471440594 0.237673576041822 0 0 0</pose>
      <must_be_base_link>0</must_be_base_link>
      <velocity_decay>
        <linear>0</linear>
        <angular>0.002</angular>
      </velocity_decay>
      <inertial>
        <mass>0.413564688849332</mass>
        <pose>0 0 0 0 0 0</pose>
      </inertial>
      <collision name="BRwheel_collision">
        <pose>-0.0666760203259 0.0453607471440583 -2.13673414053903 0 0 0</pose>
        <geometry>
          <mesh>
            <scale>1 1 1</scale>
            <uri>model://SimBotOneArm/meshes/BRwheel_col.STL</uri>
          </mesh>
        </geometry>
        <surface>
          <contact>
            <ode>
              <max_vel>0.1</max_vel>
              <soft_cfm>0.8</soft_cfm>
              <soft_erp>0.8</soft_erp>
              <kd>25</kd>
              <kp>1e6</kp>
              <min_depth>0.0001</min_depth>
            </ode>          
          </contact>
          <friction>
            <ode>
              <mu>1</mu>
              <mu2>1</mu2>
            </ode>
          </friction>
        </surface>
      </collision>
      <visual name="BRwheel_visual">
        <pose>-0.0666760203259 0.0453607471440583 -2.13673414053903 0 0 0</pose>
        <material>
          <ambient>0 1 0 1</ambient>
          <diffuse>0 1 0 1</diffuse>
        </material>
        <geometry>
          <mesh>
            <scale>1 1 1</scale>
            <uri>model://SimBotOneArm/meshes/BRwheel.STL</uri>
          </mesh>
        </geometry>
      </visual>
    </link>
    <joint name="BRdrive-BRwheel" type="revolute">
      <parent>BRdrive</parent>
      <child>BRwheel</child>
      <pose>-3.7665044388957E-06 3.42643056162537E-05 2.29141994267934E-08 0 0 0</pose>
      <axis>
        <xyz>-1 0 0</xyz>
        <dynamics>
          <damping>1</damping>
          <friction>1</friction>
        </dynamics>
      </axis>
    </joint>
    <link name="BLdrive">
      <gravity>1</gravity>
      <self_collide>0</self_collide>
      <pose>-0.389815879776734 -0.00717268331806447 -0.237676177415916 0 0 0</pose>
      <must_be_base_link>0</must_be_base_link>
      <velocity_decay>
        <linear>0</linear>
        <angular>0.01</angular>
      </velocity_decay>
      <inertial>
        <mass>0.0869538770297104</mass>
        <pose>0 0 0 0 0 0</pose>
      </inertial>
      <visual name="BLdrive_visual">
        <pose>-0.0666783765574451 0.00717268331806338 -1.66138438708129 0 0 0</pose>
        <material>
          <ambient>0.501960784313725 0.501960784313725 0.501960784313725 1</ambient>
          <diffuse>0.501960784313725 0.501960784313725 0.501960784313725 1</diffuse>
        </material>
        <geometry>
          <mesh>
            <scale>1 1 1</scale>
            <uri>model://SimBotOneArm/meshes/BLdrive.STL</uri>
          </mesh>
        </geometry>
      </visual>
    </link>
    <joint name="Body-BLdrive" type="revolute">
      <parent>Body</parent>
      <child>BLdrive</child>
      <pose>-3.37655744546417E-06 -8.67361737988404E-19 -0.000448822584083075 0 0 0</pose>
      <axis>
        <xyz>-1 0 0</xyz>
        <dynamics>
          <damping>1</damping>
          <friction>1</friction>
        </dynamics>
       </axis>
    </joint>
    <link name="BLwheel">
      <gravity>1</gravity>
      <self_collide>0</self_collide>
      <pose>-0.389819150986403 -0.0454407782960015 -0.239779131380305 0 0 0</pose>
      <must_be_base_link>0</must_be_base_link>
      <velocity_decay>
        <linear>0</linear>
        <angular>0.002</angular>
      </velocity_decay>
      <inertial>
        <mass>0.123981366006226</mass>
        <pose>0 0 0 0 0 0</pose>
      </inertial>
      <collision name="BLwheel_collision">
        <pose>-0.0666751053477762 0.0454407782960004 -1.6592814331169 0 0 0</pose>
        <geometry>
          <mesh>
            <scale>1 1 1</scale>
            <uri>model://SimBotOneArm/meshes/BLwheel_col.STL</uri>
          </mesh>
        </geometry>
        <surface>
           <contact>
             <ode>
              <max_vel>0.1</max_vel>
              <soft_cfm>0.8</soft_cfm>
              <soft_erp>0.8</soft_erp>
              <kd>25</kd>
              <kp>1e6</kp>
              <min_depth>0.0001</min_depth>
            </ode>          
          </contact>
          <friction>
            <ode>
              <mu>1</mu>
              <mu2>1</mu2>
            </ode>
          </friction>
        </surface>
      </collision>
      <visual name="BLwheel_visual">
        <pose>-0.0666751053477762 0.0454407782960004 -1.6592814331169 0 0 0</pose>
        <material>
          <ambient>0 1 0 1</ambient>
          <diffuse>0 1 0 1</diffuse>
        </material>
        <geometry>
          <mesh>
            <scale>1 1 1</scale>
            <uri>model://SimBotOneArm/meshes/BLwheel.STL</uri>
          </mesh>
        </geometry>
      </visual>
    </link>
    <joint name="BLdrive-BLwheel" type="revolute">
      <parent>BLdrive</parent>
      <child>BLwheel</child>
      <pose>-1.25638072461798E-05 0.000114295457558346 9.46325311446117E-08 0 0 0</pose>
      <axis>
        <xyz>-1 0 0</xyz>
        <dynamics>
          <damping>1</damping>
          <friction>1</friction>
        </dynamics>
      </axis>
    </joint>
    <link name="LowerArm">
      <gravity>1</gravity>
      <self_collide>0</self_collide>
      <pose>-0.00683877701198649 0.658190126400442 0.201682058992895 0 0 0</pose>
      <must_be_base_link>0</must_be_base_link>
      <velocity_decay>
        <linear>0</linear>
        <angular>0</angular>
      </velocity_decay>
      <inertial>
        <mass>3.1900657983711</mass>
        <pose>0 0 0 0 0 0</pose>
      </inertial>
      <collision name="LowerArm_collision">
        <pose>-0.449655479322192 -0.658190126400443 -2.1007426234901 0 0 0</pose>
        <geometry>
          <mesh>
            <scale>1 1 1</scale>
            <uri>model://SimBotOneArm/meshes/LowerArm_col.STL</uri>
          </mesh>
        </geometry>
        <surface>
          <contact>
            <ode />
          </contact>
          <friction>
            <ode>
              <mu>0</mu>
              <mu2>0</mu2>
            </ode>
          </friction>
        </surface>
      </collision>
      <visual name="LowerArm_visual">
        <pose>-0.449655479322192 -0.658190126400443 -2.1007426234901 0 0 0</pose>
        <material>
          <ambient>0.250980392156863 0.501960784313725 0.501960784313725 1</ambient>
          <diffuse>0.250980392156863 0.501960784313725 0.501960784313725 1</diffuse>
        </material>
        <geometry>
          <mesh>
            <scale>1 1 1</scale>
            <uri>model://SimBotOneArm/meshes/LowerArm.STL</uri>
          </mesh>
        </geometry>
      </visual>
    </link>
    <joint name="Body-LowerArm" type="revolute">
      <parent>Body</parent>
      <child>LowerArm</child>
      <pose>0.00513152067780792 -0.512140126400443 0 0 0 0</pose>
      <axis>
        <xyz>0 0 1</xyz>
         <dynamics>
          <damping>2</damping>
          <friction>1</friction>
        </dynamics>
         <limit>
         <lower>-1.57</lower>
         <upper>0</upper>
        </limit>
      </axis>
    </joint>
    <link name="UpperArm">
      <gravity>1</gravity>
      <self_collide>0</self_collide>
      <pose>-0.012694648676961 1.24276696311925 0.199362464000009 0 0 0</pose>
      <must_be_base_link>0</must_be_base_link>
      <velocity_decay>
        <linear>0</linear>
        <angular>0</angular>
      </velocity_decay>
      <inertial>
        <mass>0.155731476625825</mass>
        <pose>0 0 0 0 0 0</pose>
      </inertial>
      <collision name="UpperArm_collision">
        <pose>-0.443799607657218 -1.24276696311925 -2.09842302849721 0 0 0</pose>
        <geometry>
          <mesh>
            <scale>1 1 1</scale>
            <uri>model://SimBotOneArm/meshes/UpperArm_col.STL</uri>
          </mesh>
        </geometry>
        <surface>
          <contact>
            <ode />
          </contact>
          <friction>
            <ode>
              <mu>0</mu>
              <mu2>0</mu2>
            </ode>
          </friction>
        </surface>
      </collision>
      <visual name="UpperArm_visual">
        <pose>-0.443799607657218 -1.24276696311925 -2.09842302849721 0 0 0</pose>
        <material>
          <ambient>0.250980392156863 0.501960784313725 0.501960784313725 1</ambient>
          <diffuse>0.250980392156863 0.501960784313725 0.501960784313725 1</diffuse>
        </material>
        <geometry>
          <mesh>
            <scale>1 1 1</scale>
            <uri>model://SimBotOneArm/meshes/UpperArm.STL</uri>
          </mesh>
        </geometry>
      </visual>
    </link>
    <joint name="LowerArm-UpperArm" type="fixed">
      <parent>LowerArm</parent>
      <child>UpperArm</child>
      <pose>1.33226762955019E-15 -7.54951656745106E-15 0 0 4.71238898038469 0</pose>
      <axis>
        <xyz>1 0 0</xyz>
        <dynamics>
          <damping>1</damping>
          <friction>1</friction>
        </dynamics>
      </axis>
    </joint>
    <link name="GripperRotate">
      <gravity>1</gravity>
      <self_collide>0</self_collide>
      <pose>-0.0107347222811323 1.24313024297196 0.0907350565029368 0 0 0</pose>
      <must_be_base_link>0</must_be_base_link>
      <velocity_decay>
        <linear>0</linear>
        <angular>0.05</angular>
      </velocity_decay>
      <inertial>
        <mass>0.16415889155247</mass>
        <pose>0 0 0 0 0 0</pose>
      </inertial>
      <collision name="GripperRotate_collision">
        <pose>-0.445759534053046 -1.24313024297196 -1.98979562100014 0 0 0</pose>
        <geometry>
          <mesh>
            <scale>1 1 1</scale>
            <uri>model://SimBotOneArm/meshes/GripperRotate_col.STL</uri>
          </mesh>
        </geometry>
        <surface>
          <contact>
            <ode />
          </contact>
          <friction>
            <ode>
              <mu>1</mu>
              <mu2>1</mu2>
            </ode>
          </friction>
        </surface>
      </collision>
      <visual name="GripperRotate_visual">
        <pose>-0.445759534053046 -1.24313024297196 -1.98979562100014 0 0 0</pose>
        <material>
          <ambient>0.752941176470588 0.752941176470588 0.752941176470588 1</ambient>
          <diffuse>0.752941176470588 0.752941176470588 0.752941176470588 1</diffuse>
        </material>
        <geometry>
          <mesh>
            <scale>1 1 1</scale>
            <uri>model://SimBotOneArm/meshes/GripperRotate.STL</uri>
          </mesh>
        </geometry>
      </visual>
    </link>
    <joint name="UpperArm-GripperRotate" type="revolute">
      <parent>UpperArm</parent>
      <child>GripperRotate</child>
      <pose>-0.00195992639582859 -0.000363279852706011 0 0 1.5707963267949 0</pose>
      <axis>
        <xyz>-1 0 0</xyz>
        <dynamics>
          <damping>1</damping>
          <friction>1</friction>
        </dynamics>
         <limit>
         <lower>-3</lower>
         <upper>3</upper>
        </limit>  
      </axis>
    </joint>
    <link name="GripperTwist">
      <gravity>1</gravity>
      <self_collide>0</self_collide>
      <pose>0.146048791412694 1.0967249869109 0.0200822184555187 0 0 0</pose>
      <must_be_base_link>0</must_be_base_link>
      <velocity_decay>
        <linear>0</linear>
        <angular>0</angular>
      </velocity_decay>
      <inertial>
        <mass>2.25511392686329</mass>
        <pose>0 0 0 0 0 0</pose>
       </inertial>
      <collision name="GripperTwist_collision">
        <pose>-0.602543047746872 -1.0967249869109 -1.91914278295272 0 0 0</pose>
        <geometry>
          <mesh>
            <scale>1 1 1</scale>
            <uri>model://SimBotOneArm/meshes/GripperTwist_col.STL</uri>
          </mesh>
        </geometry>
        <surface>
          <contact>
            <ode />
          </contact>
          <friction>
            <ode>
              <mu>1</mu>
              <mu2>1</mu2>
            </ode>
          </friction>
        </surface>
      </collision>
      <visual name="GripperTwist_visual">
        <pose>-0.602543047746872 -1.0967249869109 -1.91914278295272 0 0 0</pose>
        <material>
          <ambient>0.752941176470588 0.752941176470588 0.752941176470588 1</ambient>
          <diffuse>0.752941176470588 0.752941176470588 0.752941176470588 1</diffuse>
        </material>
        <geometry>
          <mesh>
            <scale>1 1 1</scale>
            <uri>model://SimBotOneArm/meshes/GripperTwist.STL</uri>
          </mesh>
        </geometry>
      </visual>
      <sensor name="GripperTwistCamera" type="camera">
        <visualize>1</visualize>
        <always_on>1</always_on>
        <pose>0.0205235796459304 0.1 -0.15 -1.57 -0.1 -0.8</pose>
       <camera name="GripperTwistcamera">
          <horizontal_fov>1.5707963267949</horizontal_fov>
          <image>
             <width>640</width>
            <height>480</height>
          </image>
          <clip>
            <near>0.05</near>
            <far>30</far>
          </clip>
        </camera>
         <plugin name="camera1" filename="sim_camera.dll">
          <topic>~/gazebo/frc/simulator/camera/0</topic>
          <port>9000</port>
          <fps>20</fps>
          <enabled>true</enabled>
          <savepath>tmp</savepath>
          <maxframes>1</maxframes>
        </plugin>
      </sensor>
    </link>
    <joint name="GripperRotate-GripperTwist" type="fixed">
      <parent>GripperRotate</parent>
      <child>GripperTwist</child>
      <pose>-0.038351588966394 -0.0753937915180227 0.0266113955059517 0 0 4.71238898038469</pose>
      <axis>
        <xyz>0.887836308761871 0.460159416772162 0</xyz>
        <dynamics>
          <damping>2</damping>
          <friction>1</friction>
        </dynamics>
      </axis>
    </joint>
    <link name="LeftGripper">
      <gravity>1</gravity>
      <self_collide>0</self_collide>
      <pose>0.241320498086195 0.969184291056408 -0.158494078621501 0 0 0</pose>
      <must_be_base_link>0</must_be_base_link>
      <velocity_decay>
        <linear>0</linear>
        <angular>0.1</angular>
      </velocity_decay>
      <inertial>
        <mass>0.1</mass>
        <pose>0 0 0 0 0 0</pose>
      </inertial>
      <collision name="LeftGripper_collision">
        <pose>-0.697814754420374 -0.969184291056409 -1.7405664858757 0 0 0</pose>
        <geometry>
          <mesh>
            <scale>1 1 1</scale>
            <uri>model://SimBotOneArm/meshes/LeftGripper_col.STL</uri>
          </mesh>
        </geometry>
        <surface>
          <contact>
            <ode />
          </contact>
          <friction>
            <ode>
              <mu>1</mu>
              <mu2>1</mu2>
            </ode>
          </friction>
        </surface>
      </collision>
      <visual name="LeftGripper_visual">
        <pose>-0.697814754420374 -0.969184291056409 -1.7405664858757 0 0 0</pose>
        <material>
          <ambient>0.752941176470588 0.752941176470588 0.752941176470588 1</ambient>
          <diffuse>0.752941176470588 0.752941176470588 0.752941176470588 1</diffuse>
        </material>
        <geometry>
          <mesh>
            <scale>1 1 1</scale>
            <uri>model://SimBotOneArm/meshes/LeftGripper.STL</uri>
          </mesh>
        </geometry>
      </visual>
    </link>
    <joint name="GripperTwist-LeftGripper" type="revolute">
      <parent>GripperTwist</parent>
      <child>LeftGripper</child>
      <pose>-0.054185747678801 0.0570231645355036 0.0238046710258071 0 0.0158713592468967 1.59696957940531</pose>
      <axis>
        <xyz>0.585394002287998 -0.810722241994805 -0.00658091332233763</xyz>
        <dynamics>
          <damping>0</damping>
          <friction>0</friction>
        </dynamics>
        <limit>
          <upper>0.3</upper>
          <lower>-0.6</lower>
        </limit>
      </axis>
    </joint>
    <link name="RightGripper">
      <gravity>1</gravity>
      <self_collide>0</self_collide>
      <pose>0.246191175008786 0.971708729210025 0.181958210199892 0 0 0</pose>
      <must_be_base_link>0</must_be_base_link>
      <velocity_decay>
        <linear>0</linear>
        <angular>0</angular>
      </velocity_decay>
      <inertial>
        <mass>0.1</mass>
        <pose>0 0 0 0 0 0</pose>
      </inertial>
      <collision name="RightGripper_collision">
        <pose>-0.702685431342964 -0.971708729210026 -2.0810187746971 0 0 0</pose>
        <geometry>
          <mesh>
            <scale>1 1 1</scale>
            <uri>model://SimBotOneArm/meshes/RightGripper_col.STL</uri>
          </mesh>
        </geometry>
        <surface>
          <contact>
            <ode />
          </contact>
          <friction>
            <ode>
              <mu>0</mu>
              <mu2>0</mu2>
            </ode>
          </friction>
        </surface>
      </collision>
      <visual name="RightGripper_visual">
        <pose>-0.702685431342964 -0.971708729210026 -2.0810187746971 0 0 0</pose>
        <material>
          <ambient>0.752941176470588 0.752941176470588 0.752941176470588 1</ambient>
          <diffuse>0.752941176470588 0.752941176470588 0.752941176470588 1</diffuse>
        </material>
        <geometry>
          <mesh>
            <scale>1 1 1</scale>
            <uri>model://SimBotOneArm/meshes/RightGripper.STL</uri>
          </mesh>
        </geometry>
      </visual>
    </link>
    <joint name="GripperTwist-RightGripper" type="revolute">
      <parent>GripperTwist</parent>
      <child>RightGripper</child>
      <pose>-0.0548566132662593 0.0566754595425552 -0.0230877277876074 0 0.0158713592468967 1.59696957940531</pose>
      <axis>
        <xyz>0.585394002287996 -0.810722241994806 -0.00658091332233764</xyz>
        <dynamics>
          <damping>0</damping>
          <friction>0</friction>
        </dynamics>
        <limit>
          <upper>0</upper>
          <lower>0</lower>
          <effort>1</effort>
        </limit>
      </axis>
    </joint>
    <link name="LeftPad">
      <gravity>1</gravity>
      <self_collide>0</self_collide>
      <pose>0.334045450628088 0.846041003834395 -0.21678381156418 0 0 0</pose>
      <must_be_base_link>0</must_be_base_link>
      <velocity_decay>
        <linear>0</linear>
        <angular>0</angular>
      </velocity_decay>
      <inertial>
        <mass>0.01</mass>
        <pose>0 0 0 0 0 0</pose>
      </inertial>
      <collision name="LeftPad_collision">
        <pose>-0.790539706962267 -0.846041003834396 -1.68227675293302 0 0 0</pose>
        <geometry>
          <mesh>
            <scale>1 1 1</scale>
            <uri>model://SimBotOneArm/meshes/LeftPad_col.STL</uri>
          </mesh>
        </geometry>
        <surface>
          <contact>
            <ode>
              <kp>1e3</kp>
              <kd>1e7</kd>
              <min_depth>0.001</min_depth>
            </ode>          
          </contact>
          <torsional>
            <ode>
              <coefficient>1</coefficient>
              <slip>0</slip>
            </ode>
          </torsional>
          <friction>
            <ode>
              <mu>4</mu>
              <mu2>4</mu2>
            </ode>
          </friction>
        </surface>
      </collision>
      <visual name="LeftPad_visual">
        <pose>-0.790539706962267 -0.846041003834396 -1.68227675293302 0 0 0</pose>
        <material>
          <ambient>0 0.501960784313725 0.501960784313725 1</ambient>
          <diffuse>0 0.501960784313725 0.501960784313725 1</diffuse>
        </material>
        <geometry>
          <mesh>
            <scale>1 1 1</scale>
            <uri>model://SimBotOneArm/meshes/LeftPad.STL</uri>
          </mesh>
        </geometry>
      </visual>
    </link>
    <joint name="LeftGripper-LeftPad" type="revolute">
      <parent>LeftGripper</parent>
      <child>LeftPad</child>
      <pose>-0.00707124173938922 -0.00539133761890198 0.000141142572698261 0 0.0158713592468798 1.59696957940528</pose>
      <axis>
        <xyz>0.585394002288015 -0.810722241994793 -0.00658091332233035</xyz>
        <dynamics>
          <damping>0</damping>
          <friction>0</friction>
        </dynamics>
      </axis>
    </joint>
    <link name="RightPad">
      <gravity>1</gravity>
      <self_collide>0</self_collide>
      <pose>0.340571708024641 0.849423523516375 0.239390956251876 0 0 0</pose>
      <must_be_base_link>0</must_be_base_link>
      <velocity_decay>
        <linear>0</linear>
        <angular>0</angular>
      </velocity_decay>
      <inertial>
        <mass>0.01</mass>
        <pose>0 0 0 0 0 0</pose>
      </inertial>
      <collision name="RightPad_collision">
        <pose>-0.797065964358819 -0.849423523516376 -2.13845152074908 0 0 0</pose>
        <geometry>
          <mesh>
            <scale>1 1 1</scale>
            <uri>model://SimBotOneArm/meshes/RightPad_col.STL</uri>
          </mesh>
        </geometry>
          <contact>
            <ode>
              <min_depth>0.001</min_depth>
              <kp>1e3</kp>
              <kd>1e7</kd>
            </ode>          
          </contact>
          <torsional>
            <ode>
              <coefficient>1</coefficient>
              <slip>0</slip>
            </ode>
          </torsional>
          <friction>
            <ode>
              <mu>4</mu>
              <mu2>4</mu2>
            </ode>
          </friction>
        </surface>
      </collision>
      <visual name="RightPad_visual">
        <pose>-0.797065964358819 -0.849423523516376 -2.13845152074908 0 0 0</pose>
        <material>
          <ambient>0 0.501960784313725 0.501960784313725 1</ambient>
          <diffuse>0 0.501960784313725 0.501960784313725 1</diffuse>
        </material>
        <geometry>
          <mesh>
            <scale>1 1 1</scale>
            <uri>model://SimBotOneArm/meshes/RightPad.STL</uri>
          </mesh>
        </geometry>
      </visual>
    </link>
    <joint name="RightGripper-RightPad" type="revolute">
      <parent>RightGripper</parent>
      <child>RightPad</child>
      <pose>-0.00707123868382553 -0.00539134138354158 0.000141145112782848 0 0.0158713592468729 1.59696957940527</pose>
      <axis>
        <xyz>0.585394002288031 -0.810722241994781 -0.00658091332232724</xyz>
        <dynamics>
          <damping>0</damping>
          <friction>0</friction>
        </dynamics>
      </axis>
    </joint>
    <link name="LeftPad2">
      <gravity>1</gravity>
      <self_collide>0</self_collide>
      <pose>0.267729827818469 0.934037484108341 -0.177919376276616 0 0 0</pose>
      <must_be_base_link>0</must_be_base_link>
      <velocity_decay>
        <linear>0</linear>
        <angular>0</angular>
      </velocity_decay>
      <inertial>
        <mass>0.01</mass>
        <pose>0 0 0 0 0 0</pose>
      </inertial>
      <collision name="LeftPad2_collision">
        <pose>-0.724224084152647 -0.934037484108342 -1.72114118822059 0 0 0</pose>
        <geometry>
          <mesh>
            <scale>1 1 1</scale>
            <uri>model://SimBotOneArm/meshes/LeftPad2_col.STL</uri>
          </mesh>
        </geometry>
        <surface>
          <contact>
            <ode>
              <min_depth>0.001</min_depth>
              <kp>1e3</kp>
              <kd>1e7</kd>
            </ode>          
          </contact>
          <torsional>
            <ode>
              <coefficient>1</coefficient>
              <slip>0</slip>
            </ode>
          </torsional>
          <friction>
            <ode>
              <mu>4</mu>
              <mu2>4</mu2>
            </ode>
          </friction>
        </surface>
      </collision>
      <visual name="LeftPad2_visual">
        <pose>-0.724224084152647 -0.934037484108342 -1.72114118822059 0 0 0</pose>
        <material>
          <ambient>0.250980392156863 0.501960784313725 0.501960784313725 1</ambient>
          <diffuse>0.250980392156863 0.501960784313725 0.501960784313725 1</diffuse>
        </material>
        <geometry>
          <mesh>
            <scale>1 1 1</scale>
            <uri>model://SimBotOneArm/meshes/LeftPad2.STL</uri>
          </mesh>
        </geometry>
      </visual>
    </link>
    <joint name="LeftGripper-LeftPad2" type="revolute">
      <parent>LeftGripper</parent>
      <child>LeftPad2</child>
      <pose>-0.00707123917503549 -0.00539134103551542 0.000141140539531293 0 0.0158713592468895 1.5969695794053</pose>
      <axis>
        <xyz>0.585394002288009 -0.810722241994798 -0.00658091332233447</xyz>
        <dynamics>
          <damping>0</damping>
          <friction>0</friction>
        </dynamics>
      </axis>
    </joint>
    <link name="RightPad2">
      <gravity>1</gravity>
      <self_collide>0</self_collide>
      <pose>0.273152825042775 0.936848188163066 0.201139058060381 0 0 0</pose>
      <must_be_base_link>0</must_be_base_link>
      <velocity_decay>
        <linear>0</linear>
        <angular>0</angular>
      </velocity_decay>
      <inertial>
        <mass>0.01</mass>
        <pose>0 0 0 0 0 0</pose>
      </inertial>
      <collision name="RightPad2_collision">
        <pose>-0.729647081376953 -0.936848188163068 -2.10019962255758 0 0 0</pose>
        <geometry>
          <mesh>
            <scale>1 1 1</scale>
            <uri>model://SimBotOneArm/meshes/RightPad2_col.STL</uri>
          </mesh>
        </geometry>
        <surface>
          <contact>
            <ode>
              <min_depth>0.001</min_depth>
              <kp>1e3</kp>
              <kd>1e7</kd>
            </ode>          
          </contact>
          <torsional>
            <ode>
              <coefficient>1</coefficient>
              <slip>0</slip>
            </ode>
          </torsional>
          <friction>
            <ode>
              <mu>4</mu>
              <mu2>4</mu2>
            </ode>
          </friction>
        </surface>
      </collision>
      <visual name="RightPad2_visual">
        <pose>-0.729647081376953 -0.936848188163068 -2.10019962255758 0 0 0</pose>
        <material>
          <ambient>0.250980392156863 0.501960784313725 0.501960784313725 1</ambient>
          <diffuse>0.250980392156863 0.501960784313725 0.501960784313725 1</diffuse>
        </material>
        <geometry>
          <mesh>
            <scale>1 1 1</scale>
            <uri>model://SimBotOneArm/meshes/RightPad2.STL</uri>
          </mesh>
        </geometry>
      </visual>
    </link>
    <joint name="RightGripper-RightPad2" type="revolute">
      <parent>RightGripper</parent>
      <child>RightPad2</child>
      <pose>-0.00707123836826895 -0.00539134206835934 0.000141141506121656 0 0.0158713592468928 1.5969695794053</pose>
      <axis>
        <xyz>0.585394002288003 -0.810722241994801 -0.00658091332233593</xyz>
        <dynamics>
          <damping>0</damping>
          <friction>0</friction>
        </dynamics>
      </axis>
    </joint>
  </model>
</sdf>