<?xml version="1.0" encoding="utf-8"?>
<sdf version="1.5">
  <model name="SimBot2024">
    <pose>0 0 0.664764464938621 0 0 0</pose>
   
    <link name="Body">
      <gravity>1</gravity>
      <self_collide>0</self_collide>
      <pose>0.912457940108451 0.664764464938621 0.669622619640251 0 0 0</pose>
      <must_be_base_link>1</must_be_base_link>
      <velocity_decay>
        <linear>0</linear>
        <angular>0</angular>
      </velocity_decay>
      <inertial>
        <mass>150</mass>
        <pose>-0.912457940108451 -0.664764464938621 -0.669622619640251 0 0 0</pose>

      </inertial>
      <collision name="Body_collision">
        <pose>0 0 0 0 0 0</pose>
        <geometry>
          <mesh>
            <scale>1 1 1</scale>
            <uri>model://SimBot2024/meshes/Body_col.STL</uri>
          </mesh>
        </geometry>
        <surface>
          <contact>
            <ode />
          </contact>
          <friction>
            <ode>
              <mu>0</mu>
              <mu2>0</mu2>
            </ode>
          </friction>
        </surface>
      </collision>
      <visual name="Body_visual">
        <pose>0 0 0 0 0 0</pose>
        <material>
          <ambient>0.501960784313725 0.501960784313725 0.501960784313725 1</ambient>
          <diffuse>0.501960784313725 0.501960784313725 0.501960784313725 1</diffuse>
        </material>
        <geometry>
          <mesh>
            <scale>1 1 1</scale>
            <uri>model://SimBot2024/meshes/Body.STL</uri>
          </mesh>
        </geometry>
      </visual>
      <sensor name="BodyCamera" type="camera">
        <visualize>1</visualize>
        <always_on>1</always_on>
        <pose>-0.912457940108451 -0.664764464938621 -0.669622619640251 4.7124 0 0.7</pose>
        <camera name="Bodycamera">
          <horizontal_fov>1.22173047639603</horizontal_fov>
          <image>
            <width>320</width>
            <height>240</height>
          </image>
          <clip>
            <near>0.1</near>
            <far>100</far>
          </clip>
        </camera>
        <plugin name="camera1" filename="sim_camera.dll">
          <topic>~/gazebo/frc/simulator/camera/0</topic>
          <port>9000</port>
          <fps>20</fps>
          <enabled>true</enabled>
          <savepath>tmp</savepath>
          <maxframes>1</maxframes>
      </plugin>
      </sensor>
    </link>
    <link name="FRdrive">
      <gravity>1</gravity>
      <self_collide>0</self_collide>
      <pose>0.285104465187053 -0.000891877261577911 0.30432973469854 0 0 0</pose>
      <must_be_base_link>0</must_be_base_link>
      <velocity_decay>
        <linear>0</linear>
        <angular>0.02</angular>
      </velocity_decay>
      <inertial>
        <mass>0.2</mass>
        <pose>0 0 0 0 0 0</pose>
      </inertial>
      <visual name="FRdrive_visual">
        <pose>0.627353474921398 0.665656342200199 0.36529288494171 0 0 0</pose>
        <material>
          <ambient>0.501960784313725 0.501960784313725 0.501960784313725 1</ambient>
          <diffuse>0.501960784313725 0.501960784313725 0.501960784313725 1</diffuse>
        </material>
        <geometry>
          <mesh>
            <scale>1 1 1</scale>
            <uri>model://SimBot2024/meshes/FRdrive.STL</uri>
          </mesh>
        </geometry>
      </visual>
    </link>
    <joint name="Body-FRdrive" type="revolute">
      <parent>Body</parent>
      <child>FRdrive</child>
      <pose>-4.59233142036108E-06 -1.11022302462516E-16 -0.000609234698539962 0 0 4.71238898038469</pose>
      <axis>
        <xyz>-1 0 0</xyz>
        <dynamics>
          <damping>2</damping>
          <friction>1</friction>
        </dynamics>
      </axis>
    </joint>
    <link name="FRwheel">
      <gravity>1</gravity>
      <self_collide>0</self_collide>
      <pose>0.285099767507856 -0.0422657782960008 0.305374631380306 0 0 0</pose>
      <must_be_base_link>0</must_be_base_link>
      <velocity_decay>
        <linear>0</linear>
        <angular>0.002</angular>
      </velocity_decay>
      <inertial>
        <mass>0.123981366006225</mass>
        <pose>0 0 0 0 0 0</pose>
      </inertial>
      <collision name="FRwheel_collision">
        <pose>0.627358172600595 0.707030243234621 0.364247988259944 0 0 0</pose>
        <geometry>
          <mesh>
            <scale>1 1 1</scale>
            <uri>model://SimBot2024/meshes/FRwheel_col.STL</uri>
          </mesh>
        </geometry>
         <surface>
          <contact>
             <ode>
              <max_vel>0.1</max_vel>
              <soft_cfm>0.8</soft_cfm>
              <soft_erp>0.8</soft_erp>
              <kd>25</kd>
              <kp>1e6</kp>
              <min_depth>0.0001</min_depth>
            </ode>          
          </contact>
          <friction>
            <ode>
              <mu>1</mu>
              <mu2>1</mu2>
            </ode>
          </friction>         
        </surface>
      </collision>
      <visual name="FRwheel_visual">
        <pose>0.627358172600595 0.707030243234621 0.364247988259944 0 0 0</pose>
        <material>
          <ambient>0 1 0 1</ambient>
          <diffuse>0 1 0 1</diffuse>
        </material>
        <geometry>
          <mesh>
            <scale>1 1 1</scale>
            <uri>model://SimBot2024/meshes/FRwheel.STL</uri>
          </mesh>
        </geometry>
      </visual>
    </link>
    <joint name="FRdrive-FRwheel" type="revolute">
      <parent>FRdrive</parent>
      <child>FRwheel</child>
      <pose>1.25638072462353E-05 0.000114295457558033 -9.46325307005225E-08 0 4.7199209919262 6.28318530717959</pose>
      <axis>
        <xyz>-1 0 0</xyz>
        <dynamics>
          <damping>1</damping>
          <friction>1</friction>
        </dynamics>
      </axis>
    </joint>
    <link name="FLdrive">
      <gravity>1</gravity>
      <self_collide>0</self_collide>
      <pose>0.285096556835301 -0.000891877254056483 -0.292125757014884 0 0 0</pose>
      <must_be_base_link>0</must_be_base_link>
      <velocity_decay>
        <linear>0</linear>
        <angular>0.02</angular>
      </velocity_decay>
      <inertial>
        <mass>0.2</mass>
        <pose>0 0 0 0 0 0</pose>
      </inertial>
      <visual name="FLdrive_visual">
        <pose>0.62736138327315 0.665656342192677 0.961748376655134 0 0 0</pose>
        <material>
          <ambient>0.501960784313725 0.501960784313725 0.501960784313725 1</ambient>
          <diffuse>0.501960784313725 0.501960784313725 0.501960784313725 1</diffuse>
        </material>
        <geometry>
          <mesh>
            <scale>1 1 1</scale>
            <uri>model://SimBot2024/meshes/FLdrive.STL</uri>
          </mesh>
        </geometry>
      </visual>
    </link>
    <joint name="Body-FLdrive" type="revolute">
      <parent>Body</parent>
      <child>FLdrive</child>
      <pose>3.3160203279925E-06 0 -0.000609242985113667 0 0 4.71238898038469</pose>
      <axis>
        <xyz>-1 0 0</xyz>
        <dynamics>
          <damping>2</damping>
          <friction>1</friction>
        </dynamics>
      </axis>
    </joint>
    <link name="FLwheel">
      <gravity>1</gravity>
      <self_collide>0</self_collide>
      <pose>0.285124814005293 -0.0422613391768113 -0.29108075611794 0 0 0</pose>
      <must_be_base_link>0</must_be_base_link>
      <velocity_decay>
        <linear>0</linear>
        <angular>0.002</angular>
      </velocity_decay>
      <inertial>
        <mass>0.123981363237597</mass>
        <pose>0 0 0 0 0 0</pose>
      </inertial>
      <collision name="FLwheel_collision">
        <pose>0.627333126103158 0.707025804115432 0.960703375758191 0 0 0</pose>
        <geometry>
          <mesh>
            <scale>1 1 1</scale>
            <uri>model://SimBot2024/meshes/FLwheel_col.STL</uri>
          </mesh>
        </geometry>
        <surface>
          <contact>
             <ode>
              <max_vel>0.1</max_vel>
              <soft_cfm>0.8</soft_cfm>
              <soft_erp>0.8</soft_erp>
              <kd>25</kd>
              <kp>1e6</kp>
              <min_depth>0.001</min_depth>
            </ode>          
          </contact>
          <friction>
            <ode>
              <mu>1</mu>
              <mu2>1</mu2>
            </ode>
          </friction>          
        </surface>
      </collision>
      <visual name="FLwheel_visual">
        <pose>0.627333126103158 0.707025804115432 0.960703375758191 0 0 0</pose>
        <material>
          <ambient>0 1 0 1</ambient>
          <diffuse>0 1 0 1</diffuse>
        </material>
        <geometry>
          <mesh>
            <scale>1 1 1</scale>
            <uri>model://SimBot2024/meshes/FLwheel.STL</uri>
          </mesh>
        </geometry>
      </visual>
    </link>
    <joint name="FLdrive-FLwheel" type="revolute">
      <parent>FLdrive</parent>
      <child>FLwheel</child>
      <pose>-3.39534051447821E-05 0.000109856338369019 -1.84997502095108E-07 0 4.71783749638596 5.40646336552239E-16</pose>
      <axis>
        <xyz>-1 0 0</xyz>
        <dynamics>
          <damping>2</damping>
          <friction>1</friction>
        </dynamics>
      </axis>
    </joint>
    <link name="BRdrive">
      <gravity>1</gravity>
      <self_collide>0</self_collide>
      <pose>-0.292738710749348 -0.000891875992105717 0.303111257451075 0 0 0</pose>
      <must_be_base_link>0</must_be_base_link>
      <velocity_decay>
        <linear>0</linear>
        <angular>0.02</angular>
      </velocity_decay>
      <inertial>
        <mass>0.2</mass>
        <pose>0 0 0 0 0 0</pose>
      </inertial>
      <visual name="BRdrive_visual">
        <pose>1.2051966508578 0.665656340930726 0.366511362189176 0 0 0</pose>
        <material>
          <ambient>0.501960784313725 0.501960784313725 0.501960784313725 1</ambient>
          <diffuse>0.501960784313725 0.501960784313725 0.501960784313725 1</diffuse>
        </material>
        <geometry>
          <mesh>
            <scale>1 1 1</scale>
            <uri>model://SimBot2024/meshes/BRdrive.STL</uri>
          </mesh>
        </geometry>
      </visual>
    </link>
    <joint name="Body-BRdrive" type="revolute">
      <parent>Body</parent>
      <child>BRdrive</child>
      <pose>3.7107493495725E-06 1.11022302462516E-16 0.000609242548921973 0 0 4.71238898038469</pose>
      <axis>
        <xyz>-1 0 0</xyz>
        <dynamics>
          <damping>2</damping>
          <friction>1</friction>
        </dynamics>
      </axis>
    </joint>
    <link name="BRwheel">
      <gravity>1</gravity>
      <self_collide>0</self_collide>
      <pose>-0.29273249879448 -0.042265778296819 0.302066370684938 0 0 0</pose>
      <must_be_base_link>0</must_be_base_link>
      <velocity_decay>
        <linear>0</linear>
        <angular>0.002</angular>
      </velocity_decay>
      <inertial>
        <mass>0.123981364545111</mass>
        <pose>0 0 0 0 0 0</pose>
      </inertial>
      <collision name="BRwheel_collision">
        <pose>1.20519043890293 0.70703024323544 0.367556248955313 0 0 0</pose>
        <geometry>
          <mesh>
            <scale>1 1 1</scale>
            <uri>model://SimBot2024/meshes/BRwheel_col.STL</uri>
          </mesh>
        </geometry>
        <surface>
          <contact>
            <ode>
              <max_vel>0.1</max_vel>
              <soft_cfm>0.8</soft_cfm>
              <soft_erp>0.8</soft_erp>
              <kd>25</kd>
              <kp>1e6</kp>
              <min_depth>0.0001</min_depth>
            </ode>          
          </contact>
          <friction>
            <ode>
              <mu>1</mu>
              <mu2>1</mu2>
            </ode>
          </friction>
        </surface>
      </collision>
      <visual name="BRwheel_visual">
        <pose>1.20519043890293 0.70703024323544 0.367556248955313 0 0 0</pose>
        <material>
          <ambient>0 1 0 1</ambient>
          <diffuse>0 1 0 1</diffuse>
        </material>
        <geometry>
          <mesh>
            <scale>1 1 1</scale>
            <uri>model://SimBot2024/meshes/BRwheel.STL</uri>
          </mesh>
        </geometry>
      </visual>
    </link>
    <joint name="BRdrive-BRwheel" type="revolute">
      <parent>BRdrive</parent>
      <child>BRwheel</child>
      <pose>-1.256393041138E-05 0.000114295458376379 7.64349053494762E-08 0 1.56471272398399 3.14159265358979</pose>
      <axis>
        <xyz>1 0 0</xyz>
        <dynamics>
          <damping>2</damping>
          <friction>1</friction>
        </dynamics>
      </axis>
    </joint>
    <link name="BLdrive">
      <gravity>1</gravity>
      <self_collide>0</self_collide>
      <pose>-0.292739593177212 -0.000891875993563773 -0.293344236536098 0 0 0</pose>
      <must_be_base_link>0</must_be_base_link>
      <velocity_decay>
        <linear>0</linear>
        <angular>0.02</angular>
      </velocity_decay>
      <inertial>
        <mass>0.2</mass>
        <pose>0 0 0 0 0 0</pose>
      </inertial>
      <visual name="BLdrive_visual">
        <pose>1.20519753328566 0.665656340932185 0.962966856176349 0 0 0</pose>
        <material>
          <ambient>0.501960784313725 0.501960784313725 0.501960784313725 1</ambient>
          <diffuse>0.501960784313725 0.501960784313725 0.501960784313725 1</diffuse>
        </material>
        <geometry>
          <mesh>
            <scale>1 1 1</scale>
            <uri>model://SimBot2024/meshes/BLdrive.STL</uri>
          </mesh>
        </geometry>
      </visual>
    </link>
    <joint name="Body-BLdrive" type="revolute">
      <parent>Body</parent>
      <child>BLdrive</child>
      <pose>4.59317720657992E-06 3.33066907387547E-16 0.000609236536125213 0 6.28318530717956 4.71238898038472</pose>
      <axis>
        <xyz>-1 0 0</xyz>
        <dynamics>
          <damping>2</damping>
          <friction>1</friction>
        </dynamics>
      </axis>
    </joint>
    <link name="BLwheel">
      <gravity>1</gravity>
      <self_collide>0</self_collide>
      <pose>-0.292734894652229 -0.042265778296026 -0.294389131380278 0 0 0</pose>
      <must_be_base_link>0</must_be_base_link>
      <velocity_decay>
        <linear>0</linear>
        <angular>0.002</angular>
      </velocity_decay>
      <inertial>
        <mass>0.123981366006225</mass>
        <pose>0 0 0 0 0 0</pose>
      </inertial>
      <collision name="BLwheel_collision">
        <pose>1.20519283476068 0.707030243234647 0.964011751020529 0 0 0</pose>
        <geometry>
          <mesh>
            <scale>1 1 1</scale>
            <uri>model://SimBot2024/meshes/BLwheel_col.STL</uri>
          </mesh>
        </geometry>
        <surface>
          <contact>
             <ode>
              <max_vel>0.1</max_vel>
              <soft_cfm>0.8</soft_cfm>
              <soft_erp>0.8</soft_erp>
              <kd>25</kd>
              <kp>1e6</kp>
              <min_depth>0.0001</min_depth>
            </ode>          
          </contact>
          <friction>
            <ode>
              <mu>1</mu>
              <mu2>1</mu2>
            </ode>
          </friction>         
        </surface>
      </collision>
      <visual name="BLwheel_visual">
        <pose>1.20519283476068 0.707030243234647 0.964011751020529 0 0 0</pose>
        <material>
          <ambient>0 1 0 1</ambient>
          <diffuse>0 1 0 1</diffuse>
        </material>
        <geometry>
          <mesh>
            <scale>1 1 1</scale>
            <uri>model://SimBot2024/meshes/BLwheel.STL</uri>
          </mesh>
        </geometry>
      </visual>
    </link>
    <joint name="BLdrive-BLwheel" type="revolute">
      <parent>BLdrive</parent>
      <child>BLwheel</child>
      <pose>-1.25638072465684E-05 0.000114295457558478 9.46325305895002E-08 0 1.56326431525336 3.14159265358982</pose>
      <axis>
        <xyz>1 0 0</xyz>
        <dynamics>
          <damping>1</damping>
          <friction>1</friction>
        </dynamics>
      </axis>
    </joint>
    <link name="gyro">
      <gravity>1</gravity>
      <self_collide>0</self_collide>
      <pose>0.00239033409729017 0.00999999999999934 0.00725534380777826 0 0 0</pose>
      <must_be_base_link>0</must_be_base_link>
      <inertial>
        <mass>0.0149162507870566</mass>
        <pose>0 0 0 0 0 0</pose>
      </inertial>
      <visual name="gyro_visual">
        <pose>0.910067606011161 0.654764464938621 0.662367275832473 0 0 0</pose>
        <material>
          <ambient>0 0 0.501960784313725 1</ambient>
          <diffuse>0 0 0.501960784313725 1</diffuse>
        </material>
        <geometry>
          <mesh>
            <scale>1 1 1</scale>
            <uri>model://SimBot2024/meshes/gyro.STL</uri>
          </mesh>
        </geometry>
      </visual>
    </link>
    <joint name="Body-gyro" type="fixed">
      <parent>Body</parent>
      <child>gyro</child>
      <pose>-0.0237573955480299 0.292474543733779 0.00156542555178252 0 0 0</pose>
      <axis>
        <xyz>0 1 0</xyz>
      </axis>
    </joint>
    <link name="CircuitBoard">
      <gravity>1</gravity>
      <self_collide>0</self_collide>
      <pose>0 -0.00317499999999993 0 0 0 0</pose>
      <must_be_base_link>0</must_be_base_link>
      <velocity_decay>
        <linear>0</linear>
        <angular>0</angular>
      </velocity_decay>
      <inertial>
        <mass>0.1</mass>
        <pose>0 0 0 0 0 0</pose>
      </inertial>
      <collision name="CircuitBoard_collision">
        <pose>0.912457940108451 0.667939464938621 0.669622619640251 0 0 0</pose>
        <geometry>
          <mesh>
            <scale>1 1 1</scale>
            <uri>model://SimBot2024/meshes/CircuitBoard_col.STL</uri>
          </mesh>
        </geometry>
        <surface>
          <contact>
            <ode />
          </contact>
          <friction>
            <ode>
              <mu>0</mu>
              <mu2>0</mu2>
            </ode>
          </friction>
        </surface>
      </collision>
      <visual name="CircuitBoard_visual">
        <pose>0.912457940108451 0.667939464938621 0.669622619640251 0 0 0</pose>
        <material>
          <ambient>0 0.250980392156863 1 0.5</ambient>
          <diffuse>0 0.250980392156863 1 0.5</diffuse>
        </material>
        <geometry>
          <mesh>
            <scale>1 1 1</scale>
            <uri>model://SimBot2024/meshes/CircuitBoard.STL</uri>
          </mesh>
        </geometry>
      </visual>
    </link>
    <joint name="Body-CircuitBoard" type="fixed">
      <parent>Body</parent>
      <child>CircuitBoard</child>
      <pose>-0.0213670614507397 0.2924745437338 0.00882076935956078 0 0 0</pose>
      <axis>
        <xyz>0 1 0</xyz>
      </axis>
    </joint>
    <link name="Bumpers">
      <gravity>1</gravity>
      <self_collide>0</self_collide>
      <pose>-0.00829312000370586 0.015 0.00476250000000045 0 0 0</pose>
      <must_be_base_link>0</must_be_base_link>
      <velocity_decay>
        <linear>0</linear>
        <angular>0</angular>
      </velocity_decay>
      <inertial>
        <mass>1</mass>
        <pose>0 0 0 0 0 0</pose>
      </inertial>
      <collision name="Bumpers_collision">
        <pose>0.911816732685752 0.648630566736356 0.655169025032963 0 0 0</pose>
        <geometry>
          <mesh>
            <scale>1 1 1</scale>
            <uri>model://SimBot2024/meshes/Bumpers.STL</uri>
          </mesh>
        </geometry>
        <surface>
          <contact>
            <ode />
          </contact>
          <friction>
            <ode>
              <mu>0</mu>
              <mu2>0</mu2>
            </ode>
          </friction>
        </surface>
      </collision>
      
      <visual name="Bumpers_visual">
        <pose>0.911816732685752 0.648630566736356 0.655169025032963 0 0 0</pose>
        <material>
          <ambient>0 0 1 1</ambient>
          <diffuse>0 0 1 1</diffuse>
        </material>
        <geometry>
          <mesh>
            <scale>1 1 1</scale>
            <uri>model://SimBot2024/meshes/Bumpers.STL</uri>
          </mesh>
        </geometry>
      </visual>
    </link>
    <joint name="Body-Bumpers" type="fixed">
      <parent>Body</parent>
      <child>Bumpers</child>
      <pose>1.11022302462516E-15 0.063499999999874 0.364902750000056 0 0 0</pose>
      <axis>
        <xyz>1 0 0</xyz>
      </axis>
    </joint>
   <plugin name="clock" filename="sim_clock.dll">
      <topic>~/gazebo/frc/simulator/clock</topic>
    </plugin>
    <plugin name="Body_gyro" filename="sim_gyro.dll">
      <link>Body</link>
      <topic>~/gazebo/frc/simulator/gyro/0</topic>
      <units>degrees</units>
      <axis>yaw</axis>
    </plugin>
    <plugin name="Frame-FL-drive_motor" filename="sim_motor.dll">
      <joint>FLdrive-FLwheel</joint>
      <topic>~/gazebo/frc/simulator/motor/1</topic>
      <multiplier>25</multiplier>
    </plugin>
    <plugin name="Frame-FL-drive_encoder" filename="sim_encoder.dll">
        <joint>FLdrive-FLwheel</joint>
        <topic>~/gazebo/frc/simulator/encoder/1</topic>
        <multiplier>1</multiplier>
    </plugin> 
    <plugin name="Frame-FL-turn_motor" filename="sim_motor.dll">
        <joint>Body-FLdrive</joint>
        <topic>~/gazebo/frc/simulator/motor/2</topic>
        <multiplier>25</multiplier>
    </plugin>
      <plugin name="Frame-FL-turn_encoder" filename="sim_encoder.dll">
      <joint>Body-FLdrive</joint>
       <topic>~/gazebo/frc/simulator/encoder/2</topic>
      <multiplier>1</multiplier>
    </plugin>
 
    <plugin name="Frame-FR-drive_motor" filename="sim_motor.dll">
        <joint>FRdrive-FRwheel</joint>
        <topic>~/gazebo/frc/simulator/motor/3</topic>
        <multiplier>25</multiplier>
    </plugin>
    <plugin name="Frame-FR-drive_encoder" filename="sim_encoder.dll">
        <joint>FRdrive-FRwheel</joint>
        <topic>~/gazebo/frc/simulator/encoder/3</topic>
        <multiplier>1</multiplier>
    </plugin> 
    <plugin name="Frame-FR-turn_motor" filename="sim_motor.dll">
        <joint>Body-FRdrive</joint>
        <topic>~/gazebo/frc/simulator/motor/4</topic>
        <multiplier>25</multiplier>
    </plugin>
    <plugin name="Frame-FR-turn_encoder" filename="sim_encoder.dll">
      <joint>Body-FRdrive</joint>
       <topic>~/gazebo/frc/simulator/encoder/4</topic>
      <multiplier>1</multiplier>
    </plugin>

    <plugin name="Frame-BL-drive_motor" filename="sim_motor.dll">
        <joint>BLdrive-BLwheel</joint>
        <topic>~/gazebo/frc/simulator/motor/5</topic>
        <multiplier>25</multiplier>
    </plugin>
    <plugin name="Frame-BL-drive_encoder" filename="sim_encoder.dll">
        <joint>BLdrive-BLwheel</joint>
        <topic>~/gazebo/frc/simulator/encoder/5</topic>
        <multiplier>1</multiplier>
    </plugin> 
    <plugin name="Frame-BL-turn_motor" filename="sim_motor.dll">
        <joint>Body-BLdrive</joint>
        <topic>~/gazebo/frc/simulator/motor/6</topic>
        <multiplier>25</multiplier>
    </plugin>
    <plugin name="Frame-BL-turn_encoder" filename="sim_encoder.dll">
        <joint>Body-BLdrive</joint>
        <topic>~/gazebo/frc/simulator/encoder/6</topic>
        <multiplier>1</multiplier>
    </plugin>

    <plugin name="Frame-BR-drive_motor" filename="sim_motor.dll">
        <joint>BRdrive-BRwheel</joint>
        <topic>~/gazebo/frc/simulator/motor/7</topic>
        <multiplier>25</multiplier>
    </plugin>
      <plugin name="Frame-BR-drive_encoder" filename="sim_encoder.dll">
        <joint>BRdrive-BRwheel</joint>
        <topic>~/gazebo/frc/simulator/encoder/7</topic>
        <multiplier>1</multiplier>
    </plugin> 
    <plugin name="Frame-BR-turn_motor" filename="sim_motor.dll">
        <joint>Body-BRdrive</joint>
        <topic>~/gazebo/frc/simulator/motor/8</topic>
        <multiplier>25</multiplier>
    </plugin>
    <plugin name="Frame-BR-turn_encoder" filename="sim_encoder.dll">
        <joint>Body-BRdrive</joint>
        <topic>~/gazebo/frc/simulator/encoder/8</topic>
        <multiplier>1</multiplier>
    </plugin>
  </model>
</sdf>