<?xml version="1.0" encoding="utf-8"?>
<sdf version="1.5">
  <model name="CompBot">
    <pose>0 0 0.04699 0 0 0</pose>
    
    <link name="Body">
      <gravity>1</gravity>
      <self_collide>0</self_collide>
      <pose>-0.0237029953602895 1.63376267480753E-05 0.0384753884025163 1.5707963267949 0 1.5707963267949</pose>
      <must_be_base_link>1</must_be_base_link>
      <velocity_decay>
        <linear>0</linear>
        <angular>0</angular>
      </velocity_decay>
      <inertial>
        <mass>150</mass>
        <pose>0 0 0 0 0 0</pose>
      </inertial>
      <!--
      <collision name="Body_collision">
        <pose>0.351434396726782 -0.0206931095382913 0.254969445688298 0 0 0</pose>
        <geometry>
          <mesh>
            <scale>1 1 1</scale>
            <uri>model://CompBot/meshes/Body_col.STL</uri>
          </mesh>
        </geometry>
        <surface>
          <contact>
            <ode />
          </contact>
          <friction>
            <ode>
              <mu>0</mu>
              <mu2>0</mu2>
            </ode>
          </friction>
        </surface>
      </collision>
      -->
      <visual name="Body_visual">
        <pose>0.351434396726782 -0.0206931095382913 0.254969445688298 0 0 0</pose>
        <material>
          <ambient>0.752941176470588 0.752941176470588 0.752941176470588 1</ambient>
          <diffuse>0.752941176470588 0.752941176470588 0.752941176470588 1</diffuse>
        </material>
        <geometry>
          <mesh>
            <scale>1 1 1</scale>
            <uri>model://CompBot/meshes/Body.STL</uri>
          </mesh>
        </geometry>
      </visual>
    </link>
    <link name="FLdrive">
      <gravity>1</gravity>
      <self_collide>0</self_collide>
      <pose>0.30797762346829 0.308455549680306 0.0459904553533026 1.5707963267949 0 1.5707963267949</pose>
      <must_be_base_link>0</must_be_base_link>
      <velocity_decay>
        <linear>0</linear>
        <angular>0.02</angular>
      </velocity_decay>
      <inertial>
        <mass>0.2</mass>
        <pose>0 0 0 0 0 0</pose>
              </inertial>
      
      <visual name="FLdrive_visual">
        <pose>0.0429951846732238 -0.0282081764890776 -0.0767111731402816 0 0 0</pose>
        <material>
          <ambient>0.752941176470588 0.752941176470588 0.752941176470588 1</ambient>
          <diffuse>0.752941176470588 0.752941176470588 0.752941176470588 1</diffuse>
        </material>
        <geometry>
          <mesh>
            <scale>1 1 1</scale>
            <uri>model://CompBot/meshes/FLdrive.STL</uri>
          </mesh>
        </geometry>
      </visual>
    </link>
    <joint name="Body-FLdrive" type="revolute">
      <parent>Body</parent>
      <child>FLdrive</child>
      <pose>-0.000480549680306634 0 -2.62346811480407E-06 0 0 0</pose>
      <axis>
        <xyz>0 1 0</xyz>
        <dynamics>
          <damping>10</damping>
          <friction>1</friction>
        </dynamics>
              </axis>
    </joint>
    <link name="FRdrive">
      <gravity>1</gravity>
      <self_collide>0</self_collide>
      <pose>0.307971385826406 -0.307494457110629 0.0459904555733764 1.5707963267949 0 1.5707963267949</pose>
      <must_be_base_link>0</must_be_base_link>
      <velocity_decay>
        <linear>0</linear>
        <angular>0.02</angular>
      </velocity_decay>
      <inertial>
        <mass>0.0814304850393228</mass>
        <pose>0 0 0 0 0 0</pose>
              </inertial>
      
      <visual name="FRdrive_visual">
        <pose>0.658945191464159 -0.0282081767091513 -0.0767049354983975 0 0 0</pose>
        <material>
          <ambient>0.752941176470588 0.752941176470588 0.752941176470588 1</ambient>
          <diffuse>0.752941176470588 0.752941176470588 0.752941176470588 1</diffuse>
        </material>
        <geometry>
          <mesh>
            <scale>1 1 1</scale>
            <uri>model://CompBot/meshes/FRdrive.STL</uri>
          </mesh>
        </geometry>
      </visual>
    </link>
    <joint name="Body-FRdrive" type="revolute">
      <parent>Body</parent>
      <child>FRdrive</child>
      <pose>-0.000480542889371494 -2.42861286636753E-17 3.61417376947004E-06 0 0 0</pose>
      <axis>
        <xyz>0 1 0</xyz>
        <dynamics>
          <damping>10</damping>
          <friction>1</friction>
        </dynamics>
              </axis>
    </joint>
    <link name="BLdrive">
      <gravity>1</gravity>
      <self_collide>0</self_collide>
      <pose>-0.307061275306404 0.307494456747135 0.045990455343827 1.5707963267949 0 1.5707963267949</pose>
      <must_be_base_link>0</must_be_base_link>
      <velocity_decay>
        <linear>0</linear>
        <angular>0.02</angular>
      </velocity_decay>
      <inertial>
        <mass>0.2</mass>
        <pose>0 0 0 0 0 0</pose>
              </inertial>
      
      <visual name="BLdrive_visual">
        <pose>0.0439562776063957 -0.0282081764796021 0.538327725634413 0 0 0</pose>
        <material>
          <ambient>0.752941176470588 0.752941176470588 0.752941176470588 1</ambient>
          <diffuse>0.752941176470588 0.752941176470588 0.752941176470588 1</diffuse>
        </material>
        <geometry>
          <mesh>
            <scale>1 1 1</scale>
            <uri>model://CompBot/meshes/BLdrive.STL</uri>
          </mesh>
        </geometry>
      </visual>
    </link>
    <joint name="Body-BLdrive" type="revolute">
      <parent>Body</parent>
      <child>BLdrive</child>
      <pose>0.000480543252869871 -1.73472347597681E-17 -3.61436787332803E-06 0 0 0</pose>
      <axis>
        <xyz>0 1 0</xyz>
        <dynamics>
          <damping>10</damping>
          <friction>1</friction>
        </dynamics>
              </axis>
    </joint>
    <link name="BRdrive">
      <gravity>1</gravity>
      <self_collide>0</self_collide>
      <pose>-0.307972081852506 -0.308455547621338 0.0459904555751103 1.5707963267949 0 1.5707963267949</pose>
      <must_be_base_link>0</must_be_base_link>
      <velocity_decay>
        <linear>0</linear>
        <angular>0.02</angular>
      </velocity_decay>
      <inertial>
        <mass>0.123981363237599</mass>
        <pose>0 0 0 0 0 0</pose>
              </inertial>
      
      <visual name="BRdrive_visual">
        <pose>0.659906281974868 -0.0282081767108854 0.539238532180514 0 0 0</pose>
        <material>
          <ambient>0.752941176470588 0.752941176470588 0.752941176470588 1</ambient>
          <diffuse>0.752941176470588 0.752941176470588 0.752941176470588 1</diffuse>
        </material>
        <geometry>
          <mesh>
            <scale>1 1 1</scale>
            <uri>model://CompBot/meshes/BRdrive.STL</uri>
          </mesh>
        </geometry>
      </visual>
    </link>
    <joint name="Body-BRdrive" type="revolute">
      <parent>Body</parent>
      <child>BRdrive</child>
      <pose>0.000480547621342753 4.16333634234434E-17 -2.91814749442398E-06 0 0 0</pose>
      <axis>
        <xyz>0 1 0</xyz>
        <dynamics>
          <damping>10</damping>
          <friction>1</friction>
        </dynamics>
              </axis>
    </joint>
    <link name="FLwheel">
      <gravity>1</gravity>
      <self_collide>0</self_collide>
      <pose>0.307999941130778 0.306320756122001 0.00536366086022772 1.5707963267949 0 1.5707963267949</pose>
      <must_be_base_link>0</must_be_base_link>
      <velocity_decay>
        <linear>0</linear>
        <angular>0.002</angular>
      </velocity_decay>
      <inertial>
        <mass>0.2</mass>
        <pose>0 0 0 0 0 0</pose>
      </inertial>
      <collision name="FLwheel_collision">
        <pose>0.0451299782315297 0.0124186180039973 -0.0767334908027693 0 0 0</pose>
        <geometry>
          <mesh>
            <scale>1 1 1</scale>
            <uri>model://CompBot/meshes/FLwheel_col.STL</uri>
          </mesh>
        </geometry>
        <surface>
          <contact>
            <ode>
              <max_vel>0.1</max_vel>
              <soft_cfm>0.8</soft_cfm>
              <soft_erp>0.8</soft_erp>
              <kd>25</kd>
              <kp>1e6</kp>
              <min_depth>0.0001</min_depth>
            </ode>          
          </contact>
          <friction>
            <ode>
              <mu>1</mu>
              <mu2>1</mu2>
            </ode>
          </friction>
        </surface>
      </collision>
      <visual name="FLwheel_visual">
        <pose>0.0451299782315297 0.0124186180039973 -0.0767334908027693 0 0 0</pose>
        <material>
          <ambient>0 1 0 1</ambient>
          <diffuse>0 1 0 1</diffuse>
        </material>
        <geometry>
          <mesh>
            <scale>1 1 1</scale>
            <uri>model://CompBot/meshes/FLwheel.STL</uri>
          </mesh>
        </geometry>
      </visual>
    </link>
    <joint name="FLdrive-FLwheel" type="revolute">
      <parent>FLdrive</parent>
      <child>FLwheel</child>
      <pose>1.84993443445858E-07 0.000109856301326414 -3.39533860826829E-05 0 0 0</pose>
      <axis>
        <xyz>1 0 0</xyz>
        <dynamics>
          <damping>0</damping>
          <friction>0</friction>
        </dynamics>
      </axis>
    </joint>
    <link name="FRwheel">
      <gravity>1</gravity>
      <self_collide>0</self_collide>
      <pose>0.307974894650058 -0.309629131373644 0.00535922177115607 1.5707963267949 0 1.5707963267949</pose>
      <must_be_base_link>0</must_be_base_link>
      <velocity_decay>
        <linear>0</linear>
        <angular>0.002</angular>
      </velocity_decay>
      <inertial>
        <mass>0.123981365764209</mass>
        <pose>0 0 0 0 0 0</pose>
      </inertial>
      <collision name="FRwheel_collision">
        <pose>0.661079865727175 0.012423057093069 -0.0767084443220492 0 0 0</pose>
        <geometry>
          <mesh>
            <scale>1 1 1</scale>
            <uri>model://CompBot/meshes/FRwheel_col.STL</uri>
          </mesh>
        </geometry>
        <surface>
          <contact>
            <ode>
              <max_vel>0.1</max_vel>
              <soft_cfm>0.8</soft_cfm>
              <soft_erp>0.8</soft_erp>
              <kd>25</kd>
              <kp>1e6</kp>
              <min_depth>0.0001</min_depth>
            </ode>          
          </contact>
          <friction>
            <ode>
              <mu>1</mu>
              <mu2>1</mu2>
            </ode>
          </friction>
        </surface>
      </collision>
      <visual name="FRwheel_visual">
        <pose>0.661079865727175 0.012423057093069 -0.0767084443220492 0 0 0</pose>
        <material>
          <ambient>0 1 0 1</ambient>
          <diffuse>0 1 0 1</diffuse>
        </material>
        <geometry>
          <mesh>
            <scale>1 1 1</scale>
            <uri>model://CompBot/meshes/FRwheel.STL</uri>
          </mesh>
        </geometry>
      </visual>
    </link>
    <joint name="FRdrive-FRwheel" type="revolute">
      <parent>FRdrive</parent>
      <child>FRwheel</child>
      <pose>9.46258693623747E-08 0.000114295390402161 1.25638095872516E-05 0 0 0</pose>
      <axis>
        <xyz>1 0 0</xyz>
        <dynamics>
          <damping>0</damping>
          <friction>0</friction>
        </dynamics>
      </axis>
    </joint>
    <link name="BLwheel">
      <gravity>1</gravity>
      <self_collide>0</self_collide>
      <pose>-0.307064784323681 0.309629131376358 0.0053592217457117 1.5707963267949 0 1.5707963267949</pose>
      <must_be_base_link>0</must_be_base_link>
      <velocity_decay>
        <linear>0</linear>
        <angular>0.002</angular>
      </velocity_decay>
      <inertial>
        <mass>0.2</mass>
        <pose>0 0 0 0 0 0</pose>
      </inertial>
      <collision name="BLwheel_collision">
        <pose>0.041821602977172 0.0124230571185132 0.538331234651689 0 0 0</pose>
        <geometry>
          <mesh>
            <scale>1 1 1</scale>
            <uri>model://CompBot/meshes/BLwheel_col.STL</uri>
          </mesh>
        </geometry>
        <surface>
          <contact>
            <ode>
              <max_vel>0.1</max_vel>
              <soft_cfm>0.8</soft_cfm>
              <soft_erp>0.8</soft_erp>
              <kd>25</kd>
              <kp>1e6</kp>
              <min_depth>0.0001</min_depth>
            </ode>          
          </contact>
          <friction>
            <ode>
              <mu>1</mu>
              <mu2>1</mu2>
            </ode>
          </friction>
        </surface>
      </collision>
      <visual name="BLwheel_visual">
        <pose>0.041821602977172 0.0124230571185132 0.538331234651689 0 0 0</pose>
        <material>
          <ambient>0 1 0 1</ambient>
          <diffuse>0 1 0 1</diffuse>
        </material>
        <geometry>
          <mesh>
            <scale>1 1 1</scale>
            <uri>model://CompBot/meshes/BLwheel.STL</uri>
          </mesh>
        </geometry>
      </visual>
    </link>
    <joint name="BLdrive-BLwheel" type="revolute">
      <parent>BLdrive</parent>
      <child>BLwheel</child>
      <pose>-9.46285789310553E-08 0.00011429541584666 -1.25638100663128E-05 0 0 0</pose>
      <axis>
        <xyz>0.99997163453517 -5.23364362502435E-16 -0.00753194032504285</xyz>
        <dynamics>
          <damping>0</damping>
          <friction>0</friction>
        </dynamics>
      </axis>
    </joint>
    <link name="BRwheel">
      <gravity>1</gravity>
      <self_collide>0</self_collide>
      <pose>-0.30797249879215 -0.306320870691601 0.00535922177033808 1.5707963267949 0 1.5707963267949</pose>
      <must_be_base_link>0</must_be_base_link>
      <velocity_decay>
        <linear>0</linear>
        <angular>0.002</angular>
      </velocity_decay>
      <inertial>
        <mass>0.123981364303097</mass>
        <pose>0 0 0 0 0 0</pose>
      </inertial>
      <collision name="BRwheel_collision">
        <pose>0.657771605045132 0.0124230570938868 0.539238949120159 0 0 0</pose>
        <geometry>
          <mesh>
            <scale>1 1 1</scale>
            <uri>model://CompBot/meshes/BRwheel_col.STL</uri>
          </mesh>
        </geometry>
        <surface>
          <contact>
            <ode>
              <max_vel>0.1</max_vel>
              <soft_cfm>0.8</soft_cfm>
              <soft_erp>0.8</soft_erp>
              <kd>25</kd>
              <kp>1e6</kp>
              <min_depth>0.0001</min_depth>
            </ode>          
          </contact>
          <friction>
            <ode>
              <mu>1</mu>
              <mu2>1</mu2>
            </ode>
          </friction>
        </surface>
      </collision>
      <visual name="BRwheel_visual">
        <pose>0.657771605045132 0.0124230570938868 0.539238949120159 0 0 0</pose>
        <material>
          <ambient>0 1 0 1</ambient>
          <diffuse>0 1 0 1</diffuse>
        </material>
        <geometry>
          <mesh>
            <scale>1 1 1</scale>
            <uri>model://CompBot/meshes/BRwheel.STL</uri>
          </mesh>
        </geometry>
      </visual>
    </link>
    <joint name="BRdrive-BRwheel" type="revolute">
      <parent>BRdrive</parent>
      <child>BRwheel</child>
      <pose>-7.64282406251482E-08 0.000114295391220261 -1.25639327421823E-05 0 0 0</pose>
      <axis>
        <xyz>0.999981494945493 5.471689450125E-16 -0.00608356528504267</xyz>
        <dynamics>
          <damping>0</damping>
          <friction>0</friction>
        </dynamics>
      </axis>
    </joint>
    <link name="Arm">
      <gravity>1</gravity>
      <self_collide>0</self_collide>
      <pose>0.0968953204761955 0.00931954357825204 0.60410719159625 1.5707963267949 0 1.5707963267949</pose>
      <must_be_base_link>0</must_be_base_link>
      <velocity_decay>
        <linear>0</linear>
        <angular>0.0</angular>
      </velocity_decay>
      <inertial>
        <mass>0.5</mass>
        <pose>0 0 0 0 0 0</pose>
              </inertial>
      <collision name="Arm_collision">
        <pose>0.342131190775278 -0.586324912732025 0.134371129851813 0 0 0</pose>
        <geometry>
          <mesh>
            <scale>1 1 1</scale>
            <uri>model://CompBot/meshes/Arm_col.STL</uri>
          </mesh>
        </geometry>
        <surface>
          <contact>
            <ode />
          </contact>
          <friction>
            <ode>
              <mu>0</mu>
              <mu2>0</mu2>
            </ode>
          </friction>
        </surface>
      </collision>
      <visual name="Arm_visual">
        <pose>0.342131190775278 -0.586324912732025 0.134371129851813 0 0 0</pose>
        <material>
          <ambient>0.752941176470588 0.752941176470588 0.752941176470588 1</ambient>
          <diffuse>0.752941176470588 0.752941176470588 0.752941176470588 1</diffuse>
        </material>
        <geometry>
          <mesh>
            <scale>1 1 1</scale>
            <uri>model://CompBot/meshes/Arm.STL</uri>
          </mesh>
        </geometry>
      </visual>
      <sensor name="ArmCamera" type="camera">
        <visualize>1</visualize>
        <always_on>1</always_on>
        
        <!--<pose>0.0 0.29 0.0 0 1.7 1.57</pose>-->
       <!--<pose>0.0 0.29 0.0 0 1.57 1.57</pose>-->

       <pose>0.02 0.0 0.0 0 1.57 1.57</pose>

        <!--<pose>0.0 0.29 0.0 0 1.9 1.5707963267949</pose>-->
        <camera name="Armcamera">
          <horizontal_fov>0.7</horizontal_fov>
          <image>
            <width>640</width>
            <height>480</height>
          </image>
          <clip>
            <near>0.1</near>
            <far>100</far>
          </clip>
        </camera>
        <plugin name="camera1" filename="sim_camera.dll">
          <topic>~/gazebo/frc/simulator/camera/0</topic>
          <port>9000</port>
          <fps>20</fps>
          <enabled>true</enabled>
          <savepath>tmp</savepath>
          <maxframes>5</maxframes>
      </plugin>
      </sensor>
    </link>
    <joint name="Body-Arm" type="revolute">
      <parent>Body</parent>
      <child>Arm</child>
      <pose>2.77555756156289E-16 -0.482557191596254 -0.291499416138689 0 0 0</pose>
      <axis>
        <xyz>-1 0 0</xyz>
        <dynamics>
          <damping>100.0</damping>
          <friction>0.5</friction>
        </dynamics>
        <limit>
          <upper>0.8</upper>
          <lower>-1.1</lower>
        </limit>
      </axis>
    </joint>
    <link name="TopShootWheels">
      <gravity>1</gravity>
      <self_collide>0</self_collide>
      <pose>0.0460576027304715 0.00950414360974239 0.821679124275062 1.5707963267949 0 1.5707963267949</pose>
      <must_be_base_link>0</must_be_base_link>
      <velocity_decay>
        <linear>0</linear>
        <angular>0.000</angular>
      </velocity_decay>
      <inertial>
        <mass>0.629822998132586</mass>
        <pose>0 0 0 0 0 0</pose>
        
      </inertial>
      <collision name="TopShootWheels_collision">
        <pose>0.341946590743788 -0.803896845410837 0.185208847597537 0 0 0</pose>
        <geometry>
          <mesh>
            <scale>1 1 1</scale>
            <uri>model://CompBot/meshes/TopShootWheels_col.STL</uri>
          </mesh>
        </geometry>
        <surface>
          <contact>
            <ode>
              <max_vel>0.1</max_vel>
              <soft_cfm>0.8</soft_cfm>
              <soft_erp>0.8</soft_erp>
              <kd>25</kd>
              <kp>1e6</kp>
              <min_depth>0.0001</min_depth>
            </ode>          
          </contact>
          <friction>
            <ode>
              <mu>1</mu>
              <mu2>1</mu2>
            </ode>
          </friction>
        </surface>
      </collision>
      <visual name="TopShootWheels_visual">
        <pose>0.341946590743788 -0.803896845410837 0.185208847597537 0 0 0</pose>
        <material>
          <ambient>0 0.5 0 1</ambient>
          <diffuse>0 0.5 0 1</diffuse>
        </material>
        <geometry>
          <mesh>
            <scale>1 1 1</scale>
            <uri>model://CompBot/meshes/TopShootWheels.STL</uri>
          </mesh>
        </geometry>
      </visual>
    </link>
    <joint name="Arm-TopShootWheels" type="revolute">
      <parent>Arm</parent>
      <child>TopShootWheels</child>
      <pose>-1.11022302462516E-16 -1.4432899320127E-15 1.19348975147204E-15 0 0 0</pose>
      <axis>
        <xyz>1 0 0</xyz>
        <dynamics>
          <damping>2.0</damping>
          <friction>0</friction>
        </dynamics>        
      </axis>
    </joint>
    <link name="BotShootWheels">
      <gravity>1</gravity>
      <self_collide>0</self_collide>
      <pose>0.0459457308553526 0.0118720527751893 0.720079185866204 1.5707963267949 0 1.5707963267949</pose>
      <must_be_base_link>0</must_be_base_link>
      <velocity_decay>
        <linear>0</linear>
        <angular>0.000</angular>
      </velocity_decay>
      <inertial>
        <mass>0.1</mass>
        <pose>0 0 0 0 0 0</pose>
        
      </inertial>
      <collision name="BotShootWheels_collision">
        <pose>0.339578681578341 -0.702296907001979 0.185320719472656 0 0 0</pose>
        <geometry>
          <mesh>
            <scale>1 1 1</scale>
            <uri>model://CompBot/meshes/BotShootWheels_col.STL</uri>
          </mesh>
        </geometry>
        <surface>
          <contact>
            <ode>
              <max_vel>0.1</max_vel>
              <soft_cfm>0.8</soft_cfm>
              <soft_erp>0.8</soft_erp>
              <kd>25</kd>
              <kp>1e6</kp>
              <min_depth>0.0001</min_depth>
            </ode>          
          </contact>
          <friction>
            <ode>
              <mu>1</mu>
              <mu2>1</mu2>
            </ode>
          </friction>
        </surface>
      </collision>
      <visual name="BotShootWheels_visual">
        <pose>0.339578681578341 -0.702296907001979 0.185320719472656 0 0 0</pose>
        <material>
          <ambient>0 0.5 0 1</ambient>
          <diffuse>0 0.5 0 1</diffuse>
        </material>
        <geometry>
          <mesh>
            <scale>1 1 1</scale>
            <uri>model://CompBot/meshes/BotShootWheels.STL</uri>
          </mesh>
        </geometry>
      </visual>
      <sensor name="Shooter_contact" type="contact">
        <always_on>1</always_on>
        <contact>
          <collision>BotShootWheels_collision</collision>
        </contact>
        <plugin name="Shoot_contact" filename="sim_contact.dll">
          <topic>~/gazebo/frc/simulator/contact/1</topic>
        </plugin>
      </sensor>
    </link>
    <joint name="Arm-BotShootWheels" type="revolute">
      <parent>Arm</parent>
      <child>BotShootWheels</child>
      <pose>5.55111512312578E-17 -1.33226762955019E-15 1.02695629777827E-15 0 0 0</pose>
      <axis>
        <xyz>-1 0 0</xyz>
        <dynamics>
          <damping>2.0</damping>
          <friction>0.0</friction>
        </dynamics>      
      </axis>
    </joint>
    <link name="PickupTop">
      <gravity>1</gravity>
      <self_collide>0</self_collide>
      <pose>0.325370806308249 0.00959083891817836 0.815038370446376 1.5707963267949 0 1.5707963267949</pose>
      <must_be_base_link>0</must_be_base_link>
      <velocity_decay>
        <linear>0</linear>
        <angular>0.002</angular>
      </velocity_decay>
      <inertial>
        <mass>0.01</mass>
        <pose>0 0 0 0 0 0</pose>
      </inertial>
      <collision name="PickupTop_collision">
        <pose>0.341859895435352 -0.79725609158215 -0.0941043559802404 0 0 0</pose>
        <geometry>
          <mesh>
            <scale>1 1 1</scale>
            <uri>model://CompBot/meshes/PickupTop_col.STL</uri>
          </mesh>
        </geometry>
        <surface>
          <contact>
            <ode>
              <max_vel>0.1</max_vel>
              <soft_cfm>0.8</soft_cfm>
              <soft_erp>0.8</soft_erp>
              <kd>25</kd>
              <kp>1e6</kp>
              <min_depth>0.0001</min_depth>
            </ode> 
          </contact>
          <friction>
            <ode>
              <mu>4</mu>
              <mu2>4</mu2>
            </ode>
          </friction>
        </surface>
      </collision>
      <visual name="PickupTop_visual">
        <pose>0.341859895435352 -0.79725609158215 -0.0941043559802404 0 0 0</pose>
        <material>
          <ambient>0 1 0 1</ambient>
          <diffuse>0 1 0 1</diffuse>
        </material>
        <geometry>
          <mesh>
            <scale>1 1 1</scale>
            <uri>model://CompBot/meshes/PickupTop.STL</uri>
          </mesh>
        </geometry>
      </visual>
       <sensor name="Intake_contact" type="contact">
        <always_on>1</always_on>
        <contact>
          <collision>PickupTop_collision</collision>
        </contact>
        <plugin name="intake_contact" filename="sim_contact.dll">
          <topic>~/gazebo/frc/simulator/contact/0</topic>
        </plugin>
      </sensor>
    </link>
    <joint name="Arm-PickupTop" type="revolute">
      <parent>Arm</parent>
      <child>PickupTop</child>
      <pose>-1.11022302462516E-16 -1.68105137270391E-05 7.46668675341566E-06 0 0 0</pose>
      <axis>
        <xyz>1 0 0</xyz>
        <dynamics>
          <damping>0.3</damping>
          <friction>0.1</friction>
        </dynamics>     
      </axis>
    </joint>
    <link name="PickupBot">
      <gravity>1</gravity>
      <self_collide>0</self_collide>
      <pose>0.325284319821121 0.00909578225203628 0.726103645441941 1.5707963267949 0 1.5707963267949</pose>
      <must_be_base_link>0</must_be_base_link>
      <velocity_decay>
        <linear>0</linear>
        <angular>0.002</angular>
      </velocity_decay>
      <inertial>
        <mass>0.01</mass>
        <pose>0 0 0 0 0 0</pose>
      </inertial>
      <collision name="PickupBot_collision">
        <pose>0.342354952101494 -0.708321366577716 -0.0940178694931124 0 0 0</pose>
        <geometry>
          <mesh>
            <scale>1 1 1</scale>
            <uri>model://CompBot/meshes/PickupBot_col.STL</uri>
          </mesh>
        </geometry>
        <surface>
          <contact>
            <ode>
              <max_vel>0.1</max_vel>
              <soft_cfm>0.8</soft_cfm>
              <soft_erp>0.8</soft_erp>
              <kd>25</kd>
              <kp>1e6</kp>
              <min_depth>0.0001</min_depth>
            </ode>          
          </contact>
          <friction>
            <ode>
              <mu>4</mu>
              <mu2>4</mu2>
            </ode>
          </friction>
        </surface>
      </collision>
      <visual name="PickupBot_visual">
        <pose>0.342354952101494 -0.708321366577716 -0.0940178694931124 0 0 0</pose>
        <material>
          <ambient>0 1 0 1</ambient>
          <diffuse>0 1 0 1</diffuse>
        </material>
        <geometry>
          <mesh>
            <scale>1 1 1</scale>
            <uri>model://CompBot/meshes/PickupBot.STL</uri>
          </mesh>
        </geometry>
      </visual>
     
    </link>
    <joint name="Arm-PickupBot" type="revolute">
      <parent>Arm</parent>
      <child>PickupBot</child>
      <pose>-5.55111512312578E-17 1.79683829570898E-05 -3.93471684784208E-06 0 0 0</pose>
      <axis>
        <xyz>-1 0 0</xyz>
        <dynamics>
          <damping>0.3</damping>
          <friction>0.1</friction>
        </dynamics>
        
      </axis>
    </joint>
    <link name="MidRollersTop">
      <gravity>1</gravity>
      <self_collide>0</self_collide>
      <pose>0.183350586503084 0.0159049411881834 0.815187970776111 1.5707963267949 0 1.5707963267949</pose>
      <must_be_base_link>0</must_be_base_link>
      <velocity_decay>
        <linear>0</linear>
        <angular>0.001</angular>
      </velocity_decay>
      <inertial>
        <mass>0.01</mass>
        <pose>0 0 0 0 0 0</pose>
              </inertial>
      <collision name="MidRollersTop_collision">
        <pose>0.335545793165347 -0.797405691911886 0.0479158638249241 0 0 0</pose>
        <geometry>
          <mesh>
            <scale>1 1 1</scale>
            <uri>model://CompBot/meshes/MidRollersTop_col.STL</uri>
          </mesh>
        </geometry>
        <surface>
          <contact>
            <ode>
              <max_vel>0.1</max_vel>
              <soft_cfm>0.8</soft_cfm>
              <soft_erp>0.8</soft_erp>
              <kd>25</kd>
              <kp>1e6</kp>
              <min_depth>0.0001</min_depth>
            </ode>          
          </contact>
          <friction>
            <ode>
              <mu>1</mu>
              <mu2>1</mu2>
            </ode>
          </friction>
        </surface>
      </collision>
      <visual name="MidRollersTop_visual">
        <pose>0.335545793165347 -0.797405691911886 0.0479158638249241 0 0 0</pose>
        <material>
          <ambient>0 0.5 0.2 1</ambient>
          <diffuse>0 0.5 0.2 1</diffuse>
        </material>
        <geometry>
          <mesh>
            <scale>1 1 1</scale>
            <uri>model://CompBot/meshes/MidRollersTop.STL</uri>
          </mesh>
        </geometry>
      </visual>
    </link>
    <joint name="Arm-MidRollersTop" type="revolute">
      <parent>Arm</parent>
      <child>MidRollersTop</child>
      <pose>-1.66533453693773E-16 -1.00335465836876E-05 8.75890639987636E-06 0 0 0</pose>
      <axis>
        <xyz>1 0 0</xyz>
        <dynamics>
          <damping>1</damping>
          <friction>0</friction>
        </dynamics>    
      </axis>
    </joint>
    <link name="MidRollersBot">
      <gravity>1</gravity>
      <self_collide>0</self_collide>
      <pose>0.183255228507182 0.0116524295626112 0.726289763540617 1.5707963267949 0 1.5707963267949</pose>
      <must_be_base_link>0</must_be_base_link>
      <velocity_decay>
        <linear>0</linear>
        <angular>0</angular>
      </velocity_decay>
      <inertial>
        <mass>0.01</mass>
        <pose>0 0 0 0 0 0</pose>
              </inertial>
      <collision name="MidRollersBot_collision">
        <pose>0.339798304790919 -0.708507484676392 0.048011221820826 0 0 0</pose>
        <geometry>
          <mesh>
            <scale>1 1 1</scale>
            <uri>model://CompBot/meshes/MidRollersBot_col.STL</uri>
          </mesh>
        </geometry>
        <surface>
          <contact>
            <ode>
              <max_vel>0.1</max_vel>
              <soft_cfm>0.8</soft_cfm>
              <soft_erp>0.8</soft_erp>
              <kd>25</kd>
              <kp>1e6</kp>
              <min_depth>0.0001</min_depth>
            </ode>          
          </contact>
          <friction>
            <ode>
              <mu>1</mu>
              <mu2>1</mu2>
            </ode>
          </friction>
        </surface>
      </collision>
      <visual name="MidRollersBot_visual">
        <pose>0.339798304790919 -0.708507484676392 0.048011221820826 0 0 0</pose>
        <material>
          <ambient>0 0.5 0.2 1</ambient>
          <diffuse>0 0.5 0.2 1</diffuse>
        </material>
        <geometry>
          <mesh>
            <scale>1 1 1</scale>
            <uri>model://CompBot/meshes/MidRollersBot.STL</uri>
          </mesh>
        </geometry>
      </visual>
      
      
    </link>
    <joint name="Arm-MidRollersBot" type="revolute">
      <parent>Arm</parent>
      <child>MidRollersBot</child>
      <pose>5.55111512312578E-17 -1.17724188397617E-05 6.22901157191352E-06 0 0 0</pose>
      <axis>
        <xyz>-1 0 0</xyz>
        <dynamics>
          <damping>1</damping>
          <friction>0</friction>
        </dynamics>
        
      </axis>
    </joint>
    <link name="Bumpers">
      <gravity>1</gravity>
      <self_collide>0</self_collide>
      <pose>8.77908856722343E-14 -1.09196115062882E-05 0.0634999999999998 1.5707963267949 0 1.5707963267949</pose>
      <must_be_base_link>0</must_be_base_link>
      <velocity_decay>
        <linear>0</linear>
        <angular>0</angular>
      </velocity_decay>
      <inertial>
        <mass>0.5</mass>
        <pose>0 0 0 0 0 0</pose>
       
      </inertial>
      <collision name="Bumpers_collision">
        <pose>0.351461653965037 -0.0457177211357748 0.231266450327921 0 0 0</pose>
        <geometry>
          <mesh>
            <scale>1 1 1</scale>
            <uri>model://CompBot/meshes/Bumpers_col.STL</uri>
          </mesh>
        </geometry>
        <surface>
          <contact>
            <ode />
          </contact>
          <friction>
            <ode>
              <mu>0</mu>
              <mu2>0</mu2>
            </ode>
          </friction>
        </surface>
      </collision>
      <visual name="Bumpers_visual">
        <pose>0.351461653965037 -0.0457177211357748 0.231266450327921 0 0 0</pose>
        <material>
          <ambient>0 0 1 1</ambient>
          <diffuse>0 0 1 1</diffuse>
        </material>
        <geometry>
          <mesh>
            <scale>1 1 1</scale>
            <uri>model://CompBot/meshes/Bumpers.STL</uri>
          </mesh>
        </geometry>
      </visual>
    </link>
    <joint name="Body-Bumpers" type="fixed">
      <parent>Body</parent>
      <child>Bumpers</child>
      <pose>0.374660919611507 -0.012700000000004 -1.66533453693773E-16 0 0 0</pose>
      <axis>
        <xyz>0 0 -1</xyz>
        <dynamics>
          <damping>0</damping>
          <friction>0</friction>
        </dynamics>
        <limit>
          <upper>0</upper>
          <lower>0</lower>
          <effort>1</effort>
        </limit>
      </axis>
    </joint>
  
  <plugin name="clock" filename="sim_clock.dll">
      <topic>~/gazebo/frc/simulator/clock</topic>
    </plugin>
    <plugin name="Body_gyro" filename="sim_gyro.dll">
      <link>Body</link>
      <topic>~/gazebo/frc/simulator/gyro/0</topic>
      <units>degrees</units>
      <axis>yaw</axis>
    </plugin>
     <plugin name="Arm_gyro" filename="sim_gyro.dll">
      <link>Arm</link>
      <topic>~/gazebo/frc/simulator/gyro/1</topic>
      <units>degrees</units>
      <axis>roll</axis>
      <num_axis>3</num_axis>
    </plugin>

    <plugin name="Body-FL-drive_motor" filename="sim_motor.dll">
      <joint>FLdrive-FLwheel</joint>
      <topic>~/gazebo/frc/simulator/motor/1</topic>
      <multiplier>25</multiplier>
    </plugin>
    <plugin name="Body-FL-drive_encoder" filename="sim_encoder.dll">
        <joint>FLdrive-FLwheel</joint>
        <topic>~/gazebo/frc/simulator/encoder/1</topic>
        <multiplier>1</multiplier>
    </plugin> 
    <plugin name="Body-FL-turn_motor" filename="sim_motor.dll">
        <joint>Body-FLdrive</joint>
        <topic>~/gazebo/frc/simulator/motor/2</topic>
        <multiplier>25</multiplier>
    </plugin>
    <plugin name="Body-FL-turn_encoder" filename="sim_encoder.dll">
      <joint>Body-FLdrive</joint>
       <topic>~/gazebo/frc/simulator/encoder/2</topic>
      <multiplier>1</multiplier>
    </plugin>
 
    <plugin name="Body-FR-drive_motor" filename="sim_motor.dll">
        <joint>FRdrive-FRwheel</joint>
        <topic>~/gazebo/frc/simulator/motor/3</topic>
        <multiplier>25</multiplier>
    </plugin>
    <plugin name="Body-FR-drive_encoder" filename="sim_encoder.dll">
        <joint>FRdrive-FRwheel</joint>
        <topic>~/gazebo/frc/simulator/encoder/3</topic>
        <multiplier>1</multiplier>
    </plugin> 
    <plugin name="Body-FR-turn_motor" filename="sim_motor.dll">
        <joint>Body-FRdrive</joint>
        <topic>~/gazebo/frc/simulator/motor/4</topic>
        <multiplier>25</multiplier>
    </plugin>
    <plugin name="Body-FR-turn_encoder" filename="sim_encoder.dll">
      <joint>Body-FRdrive</joint>
       <topic>~/gazebo/frc/simulator/encoder/4</topic>
      <multiplier>1</multiplier>
    </plugin>

    <plugin name="Body-BL-drive_motor" filename="sim_motor.dll">
        <joint>BLdrive-BLwheel</joint>
        <topic>~/gazebo/frc/simulator/motor/5</topic>
        <multiplier>25</multiplier>
    </plugin>
    <plugin name="Body-BL-drive_encoder" filename="sim_encoder.dll">
        <joint>BLdrive-BLwheel</joint>
        <topic>~/gazebo/frc/simulator/encoder/5</topic>
        <multiplier>1</multiplier>
    </plugin> 
    <plugin name="Body-BL-turn_motor" filename="sim_motor.dll">
        <joint>Body-BLdrive</joint>
        <topic>~/gazebo/frc/simulator/motor/6</topic>
        <multiplier>25</multiplier>
    </plugin>
    <plugin name="Body-BL-turn_encoder" filename="sim_encoder.dll">
        <joint>Body-BLdrive</joint>
        <topic>~/gazebo/frc/simulator/encoder/6</topic>
        <multiplier>1</multiplier>
    </plugin>

    <plugin name="Body-BR-drive_motor" filename="sim_motor.dll">
        <joint>BRdrive-BRwheel</joint>
        <topic>~/gazebo/frc/simulator/motor/7</topic>
        <multiplier>25</multiplier>
    </plugin>
      <plugin name="Body-BR-drive_encoder" filename="sim_encoder.dll">
        <joint>BRdrive-BRwheel</joint>
        <topic>~/gazebo/frc/simulator/encoder/7</topic>
        <multiplier>1</multiplier>
    </plugin> 
    <plugin name="Body-BR-turn_motor" filename="sim_motor.dll">
        <joint>Body-BRdrive</joint>
        <topic>~/gazebo/frc/simulator/motor/8</topic>
        <multiplier>25</multiplier>
    </plugin>
    <plugin name="Body-BR-turn_encoder" filename="sim_encoder.dll">
        <joint>Body-BRdrive</joint>
        <topic>~/gazebo/frc/simulator/encoder/8</topic>
        <multiplier>1</multiplier>
    </plugin>

    <plugin name="Arm_motor" filename="sim_motor.dll">
        <joint>Body-Arm</joint>
        <topic>~/gazebo/frc/simulator/motor/9</topic>
        <multiplier>50</multiplier>
    </plugin>
    <plugin name="Arm_encoder" filename="sim_encoder.dll">
        <joint>Body-Arm</joint>
        <topic>~/gazebo/frc/simulator/encoder/9</topic>
        <multiplier>1</multiplier>
    </plugin>

    <plugin name="intake_motor" filename="sim_motor.dll">
        <joint>Arm-PickupTop</joint>
        <topic>~/gazebo/frc/simulator/motor/10</topic>
        <multiplier>50</multiplier>
    </plugin>

    <plugin name="intake_motor" filename="sim_motor.dll">
        <joint>Arm-PickupBot</joint>
        <topic>~/gazebo/frc/simulator/motor/10</topic>
        <multiplier>50</multiplier>
    </plugin>

     <plugin name="shooter_motor" filename="sim_motor.dll">
        <joint>Arm-TopShootWheels</joint>
        <topic>~/gazebo/frc/simulator/motor/11</topic>
        <multiplier>100</multiplier>
    </plugin>

    <plugin name="shooter_motor" filename="sim_motor.dll">
        <joint>Arm-BotShootWheels</joint>
        <topic>~/gazebo/frc/simulator/motor/11</topic>
        <multiplier>100</multiplier>
    </plugin>

     <plugin name="Shooterencoder" filename="sim_encoder.dll">
        <joint>Arm-TopShootWheels</joint>
        <topic>~/gazebo/frc/simulator/encoder/11</topic>
    </plugin>
<!--
    <plugin name="pusher_motor" filename="sim_motor.dll">
        <joint>Arm-MidRollersTop</joint>
        <topic>~/gazebo/frc/simulator/motor/12</topic>
        <multiplier>50</multiplier>
    </plugin>

    <plugin name="pusher_motor" filename="sim_motor.dll">
        <joint>Arm-MidRollersBot</joint>
        <topic>~/gazebo/frc/simulator/motor/12</topic>
        <multiplier>50</multiplier>
    </plugin>
-->
    <plugin name="Arm_llimit" filename="sim_limitswitch.dll">
      <joint>Body-Arm</joint>
      <topic>~/gazebo/frc/simulator/switch/2</topic>
      <units>radians</units>
      <low>-0.9</low>
      <high>2</high>
    </plugin>
</model>
</sdf>