<?xml version="1.0" encoding="utf-8"?>
<sdf version="1.5">
  <model name="CompBot2">
    <pose>0 0 0.04699 0 0 0</pose>
    
    <link name="Body">
      <gravity>1</gravity>
      <self_collide>0</self_collide>
      <pose>-0.0240421506857467 -0.0115168248329588 0.0384756490139345 1.5707963267949 0 1.5707963267949</pose>
      <must_be_base_link>1</must_be_base_link>
      <velocity_decay>
        <linear>0</linear>
        <angular>0</angular>
      </velocity_decay>
      <inertial>
        <mass>150</mass>
        <pose>0 0 0 0 0 0</pose>
              </inertial>
      <collision name="Body_collision">
        <pose>0.362967559186486 -0.0206933701497099 0.254398490688035 0 0 0</pose>
        <geometry>
          <mesh>
            <scale>1 1 1</scale>
            <uri>model://CompBot/meshes/Body_col.STL</uri>
          </mesh>
        </geometry>
        <surface>
          <contact>
            <ode />
          </contact>
          <friction>
            <ode>
              <mu>0</mu>
              <mu2>0</mu2>
            </ode>
          </friction>
        </surface>
      </collision>
      <visual name="Body_visual">
        <pose>0.362967559186486 -0.0206933701497099 0.254398490688035 0 0 0</pose>
        <material>
          <ambient>0.752941176470588 0.752941176470588 0.752941176470588 1</ambient>
          <diffuse>0.752941176470588 0.752941176470588 0.752941176470588 1</diffuse>
        </material>
        <geometry>
          <mesh>
            <scale>1 1 1</scale>
            <uri>model://CompBot/meshes/Body.STL</uri>
          </mesh>
        </geometry>
      </visual>
    </link>
    <link name="FLdrive">
      <gravity>1</gravity>
      <self_collide>0</self_collide>
      <pose>0.30706751314257 0.308455549680304 0.0459904553533022 1.5707963267949 0 1.5707963267949</pose>
      <must_be_base_link>0</must_be_base_link>
      <velocity_decay>
        <linear>0</linear>
        <angular>0.02</angular>
      </velocity_decay>
      <inertial>
        <mass>0.2</mass>
        <pose>0 0 0 0 0 0</pose>
              </inertial>
      
      <visual name="FLdrive_visual">
        <pose>0.0429951846732238 -0.0282081764890775 -0.0767111731402816 0 0 0</pose>
        <material>
          <ambient>0.752941176470588 0.752941176470588 0.752941176470588 1</ambient>
          <diffuse>0.752941176470588 0.752941176470588 0.752941176470588 1</diffuse>
        </material>
        <geometry>
          <mesh>
            <scale>1 1 1</scale>
            <uri>model://CompBot/meshes/FLdrive.STL</uri>
          </mesh>
        </geometry>
      </visual>
    </link>
    <joint name="Body-FLdrive" type="revolute">
      <parent>Body</parent>
      <child>FLdrive</child>
      <pose>-0.000480549680306641 -1.73472347597681E-17 -2.62346811480407E-06 0 0 4.71238898038469</pose>
      <axis>
        <xyz>-1 0 0</xyz>
        <dynamics>
          <damping>2</damping>
          <friction>1</friction>
        </dynamics>
              </axis>
    </joint>
    <link name="FRdrive">
      <gravity>1</gravity>
      <self_collide>0</self_collide>
      <pose>0.30706127445237 -0.328843214809227 0.0459904540447738 1.5707963267949 0 1.5707963267949</pose>
      <must_be_base_link>0</must_be_base_link>
      <velocity_decay>
        <linear>0</linear>
        <angular>0.02</angular>
      </velocity_decay>
      <inertial>
        <mass>0.0814304850393228</mass>
        <pose>0 0 0 0 0 0</pose>
              </inertial>
      
      <visual name="FRdrive_visual">
        <pose>0.680293949162755 -0.0282081751805492 -0.0767049344500819 0 0 0</pose>
        <material>
          <ambient>0.752941176470588 0.752941176470588 0.752941176470588 1</ambient>
          <diffuse>0.752941176470588 0.752941176470588 0.752941176470588 1</diffuse>
        </material>
        <geometry>
          <mesh>
            <scale>1 1 1</scale>
            <uri>model://CompBot/meshes/FRdrive.STL</uri>
          </mesh>
        </geometry>
      </visual>
    </link>
    <joint name="Body-FRdrive" type="revolute">
      <parent>Body</parent>
      <child>FRdrive</child>
      <pose>-0.000480545103756058 3.46944695195361E-18 3.61522208874865E-06 0 6.28318530717959 4.71238898038469</pose>
      <axis>
        <xyz>-1 0 0</xyz>
        <dynamics>
          <damping>2</damping>
          <friction>1</friction>
        </dynamics>
      </axis>
    </joint>
    <link name="BLdrive">
      <gravity>1</gravity>
      <self_collide>0</self_collide>
      <pose>-0.30797138582623 0.307494457110633 0.0459904555733718 1.5707963267949 0 1.5707963267949</pose>
      <must_be_base_link>0</must_be_base_link>
      <velocity_decay>
        <linear>0</linear>
        <angular>0.02</angular>
      </velocity_decay>
      <inertial>
        <mass>0.2</mass>
        <pose>0 0 0 0 0 0</pose>
              </inertial>
      
      <visual name="BLdrive_visual">
        <pose>0.0439562772428945 -0.0282081767091473 0.538327725828519 0 0 0</pose>
        <material>
          <ambient>0.752941176470588 0.752941176470588 0.752941176470588 1</ambient>
          <diffuse>0.752941176470588 0.752941176470588 0.752941176470588 1</diffuse>
        </material>
        <geometry>
          <mesh>
            <scale>1 1 1</scale>
            <uri>model://CompBot/meshes/BLdrive.STL</uri>
          </mesh>
        </geometry>
      </visual>
    </link>
    <joint name="Body-BLdrive" type="revolute">
      <parent>Body</parent>
      <child>BLdrive</child>
      <pose>0.000480542889371591 0 -3.61417376959494E-06 0 2.11147054026647E-16 4.71238898038469</pose>
      <axis>
        <xyz>-1 0 0</xyz>
        <dynamics>
          <damping>2</damping>
          <friction>1</friction>
        </dynamics>
              </axis>
    </joint>
    <link name="BRdrive">
      <gravity>1</gravity>
      <self_collide>0</self_collide>
      <pose>-0.308882191132753 -0.329804309750062 0.0459904540467044 1.5707963267949 0 1.5707963267949</pose>
      <must_be_base_link>0</must_be_base_link>
      <velocity_decay>
        <linear>0</linear>
        <angular>0.02</angular>
      </velocity_decay>
      <inertial>
        <mass>0.123981363237599</mass>
        <pose>0 0 0 0 0 0</pose>
              </inertial>
      
      <visual name="BRdrive_visual">
        <pose>0.68125504410359 -0.0282081751824799 0.539238531135041 0 0 0</pose>
        <material>
          <ambient>0.752941176470588 0.752941176470588 0.752941176470588 1</ambient>
          <diffuse>0.752941176470588 0.752941176470588 0.752941176470588 1</diffuse>
        </material>
        <geometry>
          <mesh>
            <scale>1 1 1</scale>
            <uri>model://CompBot/meshes/BRdrive.STL</uri>
          </mesh>
        </geometry>
      </visual>
    </link>
    <joint name="Body-BRdrive" type="revolute">
      <parent>Body</parent>
      <child>BRdrive</child>
      <pose>0.000480549837083788 3.46944695195361E-18 -2.91919297701337E-06 0 3.46944695195361E-16 4.71238898038469</pose>
      <axis>
        <xyz>-1 0 0</xyz>
        <dynamics>
          <damping>2</damping>
          <friction>1</friction>
        </dynamics>
     </axis>
    </joint>
    <link name="FLwheel">
      <gravity>1</gravity>
      <self_collide>0</self_collide>
      <pose>0.307089830824119 0.306320756117939 0.00536366082318432 1.5707963267949 0 1.5707963267949</pose>
      <must_be_base_link>0</must_be_base_link>
      <velocity_decay>
        <linear>0</linear>
        <angular>0.002</angular>
      </velocity_decay>
      <inertial>
        <mass>0.2</mass>
        <pose>0 0 0 0 0 0</pose>
              </inertial>
      <collision name="FLwheel_collision">
        <pose>0.045129978235588 0.0124186180410403 -0.0767334908218308 0 0 0</pose>
        <geometry>
          <mesh>
            <scale>1 1 1</scale>
            <uri>model://CompBot/meshes/FLwheel_col.STL</uri>
          </mesh>
        </geometry>
        <surface>
          <contact>
            <ode>
              <max_vel>0.1</max_vel>
              <soft_cfm>0.8</soft_cfm>
              <soft_erp>0.8</soft_erp>
              <kd>25</kd>
              <kp>1e6</kp>
              <min_depth>0.0001</min_depth>
            </ode>          
          </contact>
          <friction>
            <ode>
              <mu>1</mu>
              <mu2>1</mu2>
            </ode>
          </friction>
        </surface>
      </collision>
      <visual name="FLwheel_visual">
        <pose>0.045129978235588 0.0124186180410403 -0.0767334908218308 0 0 0</pose>
        <material>
          <ambient>0.501960784313725 0.501960784313725 0.501960784313725 1</ambient>
          <diffuse>0.501960784313725 0.501960784313725 0.501960784313725 1</diffuse>
        </material>
        <geometry>
          <mesh>
            <scale>1 1 1</scale>
            <uri>model://CompBot/meshes/FLwheel.STL</uri>
          </mesh>
        </geometry>
      </visual>
    </link>
    <joint name="FLdrive-FLwheel" type="revolute">
      <parent>FLdrive</parent>
      <child>FLwheel</child>
      <pose>1.84997501866124E-07 0.000109856338369409 -3.39534051441853E-05 0 0 0</pose>
      <axis>
        <xyz>1 0 0</xyz>
        <dynamics>
          <damping>0</damping>
          <friction>0</friction>
        </dynamics>
              </axis>
    </joint>
    <link name="FRwheel">
      <gravity>1</gravity>
      <self_collide>0</self_collide>
      <pose>0.307064784326682 -0.330977891293289 0.00535922170399944 1.5707963267949 0 1.5707963267949</pose>
      <must_be_base_link>0</must_be_base_link>
      <velocity_decay>
        <linear>0</linear>
        <angular>0.002</angular>
      </velocity_decay>
      <inertial>
        <mass>0.123981366006225</mass>
        <pose>0 0 0 0 0 0</pose>
              </inertial>
      <collision name="FRwheel_collision">
        <pose>0.682428625646816 0.0124230571602252 -0.076708444324394 0 0 0</pose>
        <geometry>
          <mesh>
            <scale>1 1 1</scale>
            <uri>model://CompBot/meshes/FRwheel_col.STL</uri>
          </mesh>
        </geometry>
        <surface>
          <contact>
            <ode>
              <max_vel>0.1</max_vel>
              <soft_cfm>0.8</soft_cfm>
              <soft_erp>0.8</soft_erp>
              <kd>25</kd>
              <kp>1e6</kp>
              <min_depth>0.0001</min_depth>
            </ode>          
          </contact>
          <friction>
            <ode>
              <mu>1</mu>
              <mu2>1</mu2>
            </ode>
          </friction>
        </surface>
      </collision>
      <visual name="FRwheel_visual">
        <pose>0.682428625646816 0.0124230571602252 -0.076708444324394 0 0 0</pose>
        <material>
          <ambient>0 1 0 1</ambient>
          <diffuse>0 1 0 1</diffuse>
        </material>
        <geometry>
          <mesh>
            <scale>1 1 1</scale>
            <uri>model://CompBot/meshes/FRwheel.STL</uri>
          </mesh>
        </geometry>
      </visual>
    </link>
    <joint name="FRdrive-FRwheel" type="revolute">
      <parent>FRdrive</parent>
      <child>FRwheel</child>
      <pose>-0.0242488382472968 0.000114295457559203 1.25638072394074E-05 0 0 0</pose>
      <axis>
        <xyz>1 0 0</xyz>
        <dynamics>
          <damping>2</damping>
          <friction>1</friction>
        </dynamics>
              </axis>
    </joint>
    <link name="BLwheel">
      <gravity>1</gravity>
      <self_collide>0</self_collide>
      <pose>-0.307974894652223 0.30962913138031 0.00535922170399523 1.5707963267949 0 1.5707963267949</pose>
      <must_be_base_link>0</must_be_base_link>
      <velocity_decay>
        <linear>0</linear>
        <angular>0</angular>
      </velocity_decay>
      <inertial>
        <mass>0.2</mass>
        <pose>0 0 0 0 0 0</pose>
              </inertial>
      <collision name="BLwheel_collision">
        <pose>0.0418216029732173 0.0124230571602293 0.538331234654511 0 0 0</pose>
        <geometry>
          <mesh>
            <scale>1 1 1</scale>
            <uri>model://CompBot/meshes/BLwheel_col.STL</uri>
          </mesh>
        </geometry>
        <surface>
          <contact>
            <ode>
              <max_vel>0.1</max_vel>
              <soft_cfm>0.8</soft_cfm>
              <soft_erp>0.8</soft_erp>
              <kd>25</kd>
              <kp>1e6</kp>
              <min_depth>0.0001</min_depth>
            </ode>          
          </contact>
          <friction>
            <ode>
              <mu>1</mu>
              <mu2>1</mu2>
            </ode>
          </friction>
        </surface>
      </collision>
      <visual name="BLwheel_visual">
        <pose>0.0418216029732173 0.0124230571602293 0.538331234654511 0 0 0</pose>
        <material>
          <ambient>0.501960784313725 0.501960784313725 0.501960784313725 1</ambient>
          <diffuse>0.501960784313725 0.501960784313725 0.501960784313725 1</diffuse>
        </material>
        <geometry>
          <mesh>
            <scale>1 1 1</scale>
            <uri>model://CompBot/meshes/BLwheel.STL</uri>
          </mesh>
        </geometry>
      </visual>
    </link>
    <joint name="BLdrive-BLwheel" type="revolute">
      <parent>BLdrive</parent>
      <child>BLwheel</child>
      <pose>0.000114433137145625 0.000114295457558453 -1.3426448042142E-05 0 0 0</pose>
      <axis>
        <xyz>0.99997163453517 -5.23364362502435E-16 -0.00753194032504285</xyz>
        <dynamics>
          <damping>2</damping>
          <friction>1</friction>
        </dynamics>
              </axis>
    </joint>
    <link name="BRwheel">
      <gravity>1</gravity>
      <self_collide>0</self_collide>
      <pose>-0.308882609120212 -0.32766963059792 0.00535922170317728 1.5707963267949 0 1.5707963267949</pose>
      <must_be_base_link>0</must_be_base_link>
      <velocity_decay>
        <linear>0</linear>
        <angular>0</angular>
      </velocity_decay>
      <inertial>
        <mass>0.123981364545113</mass>
        <pose>0 0 0 0 0 0</pose>
              </inertial>
      <collision name="BRwheel_collision">
        <pose>0.679120364951447 0.0124230571610472 0.5392389491225 0 0 0</pose>
        <geometry>
          <mesh>
            <scale>1 1 1</scale>
            <uri>model://CompBot/meshes/BRwheel_col.STL</uri>
          </mesh>
        </geometry>
        <surface>
          <contact>
            <ode>
              <max_vel>0.1</max_vel>
              <soft_cfm>0.8</soft_cfm>
              <soft_erp>0.8</soft_erp>
              <kd>25</kd>
              <kp>1e6</kp>
              <min_depth>0.0001</min_depth>
            </ode>          
          </contact>
          <friction>
            <ode>
              <mu>1</mu>
              <mu2>1</mu2>
            </ode>
          </friction>
        </surface>
      </collision>
      <visual name="BRwheel_visual">
        <pose>0.679120364951447 0.0124230571610472 0.5392389491225 0 0 0</pose>
        <material>
          <ambient>0 1 0 1</ambient>
          <diffuse>0 1 0 1</diffuse>
        </material>
        <geometry>
          <mesh>
            <scale>1 1 1</scale>
            <uri>model://CompBot/meshes/BRwheel.STL</uri>
          </mesh>
        </geometry>
      </visual>
    </link>
    <joint name="BRdrive-BRwheel" type="revolute">
      <parent>BRdrive</parent>
      <child>BRwheel</child>
      <pose>-0.0241611432290119 0.000114295458376401 0.000134424216811202 0 0 0</pose>
      <axis>
        <xyz>0.999981494945493 5.471689450125E-16 -0.00608356528504267</xyz>
        <dynamics>
          <damping>1</damping>
          <friction>1</friction>
        </dynamics>
              </axis>
    </joint>
    <link name="Arm">
      <gravity>1</gravity>
      <self_collide>0</self_collide>
      <pose>0.0968953204761871 -0.00135483637824102 0.60410719159625 1.5707963267949 0 1.5707963267949</pose>
      <must_be_base_link>0</must_be_base_link>
      <velocity_decay>
        <linear>0</linear>
        <angular>0</angular>
      </velocity_decay>
      <inertial>
        <mass>0.5</mass>
        <pose>0 0 0 0 0 0</pose>
      </inertial>
       <collision name="Arm_collision">
        <pose>0.352805570731768 -0.586324912732025 0.133461019526101 0 0 0</pose>
        <geometry>
          <mesh>
            <scale>1 1 1</scale>
            <uri>model://CompBot/meshes/Arm_col.STL</uri>
          </mesh>
        </geometry>
        <surface>
          <contact>
            <ode />
          </contact>
          <friction>
            <ode>
              <mu>0</mu>
              <mu2>0</mu2>
            </ode>
          </friction>
        </surface>
      </collision>
      
      <visual name="Arm_visual">
        <pose>0.352805570731768 -0.586324912732025 0.133461019526101 0 0 0</pose>
        <material>
          <ambient>0.752941176470588 0.752941176470588 0.752941176470588 1</ambient>
          <diffuse>0.752941176470588 0.752941176470588 0.752941176470588 1</diffuse>
        </material>
        <geometry>
          <mesh>
            <scale>1 1 1</scale>
            <uri>model://CompBot/meshes/Arm.STL</uri>
          </mesh>
        </geometry>
      </visual>
      <sensor name="ArmCamera" type="camera">
        <visualize>0</visualize>
        <always_on>1</always_on>
        
        <!--<pose>0 0.7 0.1 0 1.5 1.5707963267949</pose>-->
        <pose>0.0 0.29 0.0 0 1.57 1.5707963267949</pose>
        <camera name="Armcamera">
          <horizontal_fov>0.7</horizontal_fov>
          <image>
            <width>640</width>
            <height>480</height>
          </image>
          <clip>
            <near>0.1</near>
            <far>100</far>
          </clip>
        </camera>
        <plugin name="camera1" filename="sim_camera.dll">
          <topic>~/gazebo/frc/simulator/camera/0</topic>
          <port>9000</port>
          <fps>20</fps>
          <enabled>true</enabled>
          <savepath>tmp</savepath>
          <maxframes>5</maxframes>
      </plugin>
      </sensor>
    </link>
    <joint name="Body-Arm" type="revolute">
      <parent>Body</parent>
      <child>Arm</child>
      <pose>-0.0121244664399145 -0.482557191596254 -0.291499416138689 0 0 3.14159265358979</pose>
      <axis>
        <xyz>1 0 0</xyz>
        <dynamics>
          <damping>12.0</damping>
          <friction>1.0</friction>
        </dynamics>
        <limit>
          <upper>0.8</upper>
          <lower>-1.1</lower>
                  </limit>
      </axis>
    </joint>
    <link name="TopShootWheels">
      <gravity>1</gravity>
      <self_collide>0</self_collide>
      <pose>0.0460576027304631 -0.00117023634675095 0.821679124275062 1.5707963267949 0 1.5707963267949</pose>
      <must_be_base_link>0</must_be_base_link>
      <velocity_decay>
        <linear>0</linear>
        <angular>0</angular>
      </velocity_decay>
      <inertial>
        <mass>0.629822998132586</mass>
        <pose>0 0 0 0 0 0</pose>
        
      </inertial>
      <collision name="TopShootWheels_collision">
        <pose>0.352620970700278 -0.803896845410837 0.184298737271825 0 0 0</pose>
        <geometry>
          <mesh>
            <scale>1 1 1</scale>
            <uri>model://CompBot/meshes/TopShootWheels_col.STL</uri>
          </mesh>
        </geometry>
        <surface>
          <contact>
            <ode>
              <max_vel>0.1</max_vel>
              <soft_cfm>0.8</soft_cfm>
              <soft_erp>0.8</soft_erp>
              <kd>25</kd>
              <kp>1e6</kp>
              <min_depth>0.0001</min_depth>
            </ode>          
          </contact>
          <friction>
            <ode>
              <mu>1</mu>
              <mu2>1</mu2>
            </ode>
          </friction>
        </surface>
      </collision>
      <visual name="TopShootWheels_visual">
        <pose>0.352620970700278 -0.803896845410837 0.184298737271825 0 0 0</pose>
        <material>
          <ambient>0 0.5 0 1</ambient>
          <diffuse>0 0.5 0 1</diffuse>
        </material>
        <geometry>
          <mesh>
            <scale>1 1 1</scale>
            <uri>model://CompBot/meshes/TopShootWheels.STL</uri>
          </mesh>
        </geometry>
      </visual>
    </link>
    <joint name="Arm-TopShootWheels" type="revolute">
      <parent>Arm</parent>
      <child>TopShootWheels</child>
      <pose>0 -1.55431223447522E-15 1.22124532708767E-15 0 6.28318530717958 3.14159265358979</pose>
      <axis>
        <xyz>-1 0 0</xyz>
        <dynamics>
          <damping>2</damping>
          <friction>0</friction>
        </dynamics>
        
      </axis>
    </joint>
    <link name="BotShootWheels">
      <gravity>1</gravity>
      <self_collide>0</self_collide>
      <pose>0.045945730855344 0.00119767281869604 0.720079185866204 1.5707963267949 0 1.5707963267949</pose>
      <must_be_base_link>0</must_be_base_link>
      <velocity_decay>
        <linear>0</linear>
        <angular>0</angular>
      </velocity_decay>
      <inertial>
        <mass>0.1</mass>
        <pose>0 0 0 0 0 0</pose>
        
      </inertial>
      <collision name="BotShootWheels_collision">
        <pose>0.350253061534831 -0.702296907001979 0.184410609146944 0 0 0</pose>
        <geometry>
          <mesh>
            <scale>1 1 1</scale>
            <uri>model://CompBot/meshes/BotShootWheels_col.STL</uri>
          </mesh>
        </geometry>
        <surface>
          <contact>
            <ode>
              <max_vel>0.1</max_vel>
              <soft_cfm>0.8</soft_cfm>
              <soft_erp>0.8</soft_erp>
              <kd>25</kd>
              <kp>1e6</kp>
              <min_depth>0.0001</min_depth>
            </ode>          
          </contact>
          <friction>
            <ode>
              <mu>1</mu>
              <mu2>1</mu2>
            </ode>
          </friction>
        </surface>
      </collision>
      <visual name="BotShootWheels_visual">
        <pose>0.350253061534831 -0.702296907001979 0.184410609146944 0 0 0</pose>
        <material>
          <ambient>0 0.5 0 1</ambient>
          <diffuse>0 0.5 0 1</diffuse>
        </material>
        <geometry>
          <mesh>
            <scale>1 1 1</scale>
            <uri>model://CompBot/meshes/BotShootWheels.STL</uri>
          </mesh>
        </geometry>
      </visual>
    </link>
    <joint name="Arm-BotShootWheels" type="revolute">
      <parent>Arm</parent>
      <child>BotShootWheels</child>
      <pose>0 -1.4432899320127E-15 1.19348975147204E-15 0 6.28318530717958 3.14159265358979</pose>
      <axis>
        <xyz>1 0 0</xyz>
        <dynamics>
          <damping>2</damping>
          <friction>0</friction>
        </dynamics>
        
      </axis>
    </joint>
    <link name="PickupTop">
      <gravity>1</gravity>
      <self_collide>0</self_collide>
      <pose>0.32537080630824 -0.00108354103831498 0.815038370446375 1.5707963267949 0 1.5707963267949</pose>
      <must_be_base_link>0</must_be_base_link>
      <velocity_decay>
        <linear>0</linear>
        <angular>0</angular>
      </velocity_decay>
      <inertial>
        <mass>0.01</mass>
        <pose>0 0 0 0 0 0</pose>
              </inertial>
      <collision name="PickupTop_collision">
        <pose>0.352534275391842 -0.79725609158215 -0.0950144663059523 0 0 0</pose>
        <geometry>
          <mesh>
            <scale>1 1 1</scale>
            <uri>model://CompBot/meshes/PickupTop_col.STL</uri>
          </mesh>
        </geometry>
        <surface>
          <contact>
            <ode>
              <max_vel>0.1</max_vel>
              <soft_cfm>0.8</soft_cfm>
              <soft_erp>0.8</soft_erp>
              <kd>25</kd>
              <kp>1e6</kp>
              <min_depth>0.0001</min_depth>
            </ode>          
          </contact>
          <friction>
            <ode>
              <mu>1</mu>
              <mu2>1</mu2>
            </ode>
          </friction>
        </surface>
      </collision>
      <visual name="PickupTop_visual">
        <pose>0.352534275391842 -0.79725609158215 -0.0950144663059523 0 0 0</pose>
        <material>
          <ambient>0 1 0 1</ambient>
          <diffuse>0 1 0 1</diffuse>
        </material>
        <geometry>
          <mesh>
            <scale>1 1 1</scale>
            <uri>model://CompBot/meshes/PickupTop.STL</uri>
          </mesh>
        </geometry>
      </visual>
    </link>
    <joint name="Arm-PickupTop" type="revolute">
      <parent>Arm</parent>
      <child>PickupTop</child>
      <pose>0 -1.68105137269281E-05 7.46668675344342E-06 0 6.28318530717958 3.14159265358979</pose>
      <axis>
        <xyz>-1 0 0</xyz>
        <dynamics>
          <damping>1</damping>
          <friction>0</friction>
        </dynamics>
        
      </axis>
    </joint>
    <link name="PickupBot">
      <gravity>1</gravity>
      <self_collide>0</self_collide>
      <pose>0.325284319821112 -0.00157859770445706 0.726103645441941 1.5707963267949 0 1.5707963267949</pose>
      <must_be_base_link>0</must_be_base_link>
      <velocity_decay>
        <linear>0</linear>
        <angular>0</angular>
      </velocity_decay>
      <inertial>
        <mass>0.01</mass>
        <pose>0 0 0 0 0 0</pose>
              </inertial>
      <collision name="PickupBot_collision">
        <pose>0.353029332057984 -0.708321366577716 -0.0949279798188243 0 0 0</pose>
        <geometry>
          <mesh>
            <scale>1 1 1</scale>
            <uri>model://CompBot/meshes/PickupBot_col.STL</uri>
          </mesh>
        </geometry>
        <surface>
          <contact>
            <ode>
              <max_vel>0.1</max_vel>
              <soft_cfm>0.8</soft_cfm>
              <soft_erp>0.8</soft_erp>
              <kd>25</kd>
              <kp>1e6</kp>
              <min_depth>0.0001</min_depth>
            </ode>          
          </contact>
          <friction>
            <ode>
              <mu>1</mu>
              <mu2>1</mu2>
            </ode>
          </friction>
        </surface>
      </collision>
      <visual name="PickupBot_visual">
        <pose>0.353029332057984 -0.708321366577716 -0.0949279798188243 0 0 0</pose>
        <material>
          <ambient>0 1 0 1</ambient>
          <diffuse>0 1 0 1</diffuse>
        </material>
        <geometry>
          <mesh>
            <scale>1 1 1</scale>
            <uri>model://CompBot/meshes/PickupBot.STL</uri>
          </mesh>
        </geometry>
      </visual>
    </link>
    <joint name="Arm-PickupBot" type="revolute">
      <parent>Arm</parent>
      <child>PickupBot</child>
      <pose>5.55111512312578E-17 1.79683829570898E-05 -3.93471684780045E-06 0 6.28318530717958 3.14159265358979</pose>
      <axis>
        <xyz>1 0 0</xyz>
        <dynamics>
          <damping>1</damping>
          <friction>0</friction>
        </dynamics>
        
      </axis>
    </joint>
    <link name="MidRollersTop">
      <gravity>1</gravity>
      <self_collide>0</self_collide>
      <pose>0.18335058650393 0.00523056122855137 0.81518797077711 1.5707963267949 0 1.5707963267949</pose>
      <must_be_base_link>0</must_be_base_link>
      <velocity_decay>
        <linear>0</linear>
        <angular>0</angular>
      </velocity_decay>
      <inertial>
        <mass>0.01</mass>
        <pose>0 0 0 0 0 0</pose>
              </inertial>
      <collision name="MidRollersTop_collision">
        <pose>0.346220173124976 -0.797405691912885 0.0470057534983583 0 0 0</pose>
        <geometry>
          <mesh>
            <scale>1 1 1</scale>
            <uri>model://CompBot/meshes/MidRollersTop_col.STL</uri>
          </mesh>
        </geometry>
        <surface>
          <contact>
            <ode>
              <max_vel>0.1</max_vel>
              <soft_cfm>0.8</soft_cfm>
              <soft_erp>0.8</soft_erp>
              <kd>25</kd>
              <kp>1e6</kp>
              <min_depth>0.0001</min_depth>
            </ode>          
          </contact>
          <friction>
            <ode>
              <mu>1</mu>
              <mu2>1</mu2>
            </ode>
          </friction>
        </surface>
      </collision>
      <visual name="MidRollersTop_visual">
        <pose>0.346220173124976 -0.797405691912885 0.0470057534983583 0 0 0</pose>
        <material>
          <ambient>0 0.5 0.2 1</ambient>
          <diffuse>0 0.5 0.2 1</diffuse>
        </material>
        <geometry>
          <mesh>
            <scale>1 1 1</scale>
            <uri>model://CompBot/meshes/MidRollersTop.STL</uri>
          </mesh>
        </geometry>
      </visual>
    </link>
    <joint name="Arm-MidRollersTop" type="revolute">
      <parent>Arm</parent>
      <child>MidRollersTop</child>
      <pose>0 -1.00335475828883E-05 8.75890554602465E-06 0 6.28318530717958 3.14159265358979</pose>
      <axis>
        <xyz>-1 0 0</xyz>
        <dynamics>
          <damping>1</damping>
          <friction>0</friction>
        </dynamics>
        
      </axis>
    </joint>
    <link name="MidRollersBot">
      <gravity>1</gravity>
      <self_collide>0</self_collide>
      <pose>0.183255228506357 0.000978049615793564 0.726289763540079 1.5707963267949 0 1.5707963267949</pose>
      <must_be_base_link>0</must_be_base_link>
      <velocity_decay>
        <linear>0</linear>
        <angular>0</angular>
      </velocity_decay>
      <inertial>
        <mass>0.01</mass>
        <pose>0 0 0 0 0 0</pose>
              </inertial>
      <collision name="MidRollersBot_collision">
        <pose>0.350472684737734 -0.708507484675855 0.0471011114959307 0 0 0</pose>
        <geometry>
          <mesh>
            <scale>1 1 1</scale>
            <uri>model://CompBot/meshes/MidRollersBot_col.STL</uri>
          </mesh>
        </geometry>
        <surface>
          <contact>
            <ode>
              <max_vel>0.1</max_vel>
              <soft_cfm>0.8</soft_cfm>
              <soft_erp>0.8</soft_erp>
              <kd>25</kd>
              <kp>1e6</kp>
              <min_depth>0.0001</min_depth>
            </ode>          
          </contact>
          <friction>
            <ode>
              <mu>1</mu>
              <mu2>1</mu2>
            </ode>
          </friction>
        </surface>
      </collision>
      <visual name="MidRollersBot_visual">
        <pose>0.350472684737734 -0.708507484675855 0.0471011114959307 0 0 0</pose>
        <material>
          <ambient>0 0.5 0.2 1</ambient>
          <diffuse>0 0.5 0.2 1</diffuse>
        </material>
        <geometry>
          <mesh>
            <scale>1 1 1</scale>
            <uri>model://CompBot/meshes/MidRollersBot.STL</uri>
          </mesh>
        </geometry>
      </visual>
    </link>
    <joint name="Arm-MidRollersBot" type="revolute">
      <parent>Arm</parent>
      <child>MidRollersBot</child>
      <pose>1.11022302462516E-16 -1.17724183026358E-05 6.22901238853807E-06 0 6.28318530717958 3.14159265358979</pose>
      <axis>
        <xyz>1 0 0</xyz>
        <dynamics>
          <damping>1</damping>
          <friction>0</friction>
        </dynamics>
        
      </axis>
    </joint>

    <plugin name="clock" filename="sim_clock.dll">
      <topic>~/gazebo/frc/simulator/clock</topic>
    </plugin>
    <plugin name="Body_gyro" filename="sim_gyro.dll">
      <link>Body</link>
      <topic>~/gazebo/frc/simulator/gyro/0</topic>
      <units>degrees</units>
      <axis>yaw</axis>
    </plugin>

    <plugin name="Body-FL-drive_motor" filename="sim_motor.dll">
      <joint>FLdrive-FLwheel</joint>
      <topic>~/gazebo/frc/simulator/motor/1</topic>
      <multiplier>25</multiplier>
    </plugin>
    <plugin name="Body-FL-drive_encoder" filename="sim_encoder.dll">
        <joint>FLdrive-FLwheel</joint>
        <topic>~/gazebo/frc/simulator/encoder/1</topic>
        <multiplier>1</multiplier>
    </plugin> 
    <plugin name="Body-FL-turn_motor" filename="sim_motor.dll">
        <joint>Body-FLdrive</joint>
        <topic>~/gazebo/frc/simulator/motor/2</topic>
        <multiplier>25</multiplier>
    </plugin>
    <plugin name="Body-FL-turn_encoder" filename="sim_encoder.dll">
      <joint>Body-FLdrive</joint>
       <topic>~/gazebo/frc/simulator/encoder/2</topic>
      <multiplier>1</multiplier>
    </plugin>
 
    <plugin name="Body-FR-drive_motor" filename="sim_motor.dll">
        <joint>FRdrive-FRwheel</joint>
        <topic>~/gazebo/frc/simulator/motor/3</topic>
        <multiplier>25</multiplier>
    </plugin>
    <plugin name="Body-FR-drive_encoder" filename="sim_encoder.dll">
        <joint>FRdrive-FRwheel</joint>
        <topic>~/gazebo/frc/simulator/encoder/3</topic>
        <multiplier>1</multiplier>
    </plugin> 
    <plugin name="Body-FR-turn_motor" filename="sim_motor.dll">
        <joint>Body-FRdrive</joint>
        <topic>~/gazebo/frc/simulator/motor/4</topic>
        <multiplier>25</multiplier>
    </plugin>
    <plugin name="Body-FR-turn_encoder" filename="sim_encoder.dll">
      <joint>Body-FRdrive</joint>
       <topic>~/gazebo/frc/simulator/encoder/4</topic>
      <multiplier>1</multiplier>
    </plugin>

    <plugin name="Body-BL-drive_motor" filename="sim_motor.dll">
        <joint>BLdrive-BLwheel</joint>
        <topic>~/gazebo/frc/simulator/motor/5</topic>
        <multiplier>25</multiplier>
    </plugin>
    <plugin name="Body-BL-drive_encoder" filename="sim_encoder.dll">
        <joint>BLdrive-BLwheel</joint>
        <topic>~/gazebo/frc/simulator/encoder/5</topic>
        <multiplier>1</multiplier>
    </plugin> 
    <plugin name="Body-BL-turn_motor" filename="sim_motor.dll">
        <joint>Body-BLdrive</joint>
        <topic>~/gazebo/frc/simulator/motor/6</topic>
        <multiplier>25</multiplier>
    </plugin>
    <plugin name="Body-BL-turn_encoder" filename="sim_encoder.dll">
        <joint>Body-BLdrive</joint>
        <topic>~/gazebo/frc/simulator/encoder/6</topic>
        <multiplier>1</multiplier>
    </plugin>

    <plugin name="Body-BR-drive_motor" filename="sim_motor.dll">
        <joint>BRdrive-BRwheel</joint>
        <topic>~/gazebo/frc/simulator/motor/7</topic>
        <multiplier>25</multiplier>
    </plugin>
      <plugin name="Body-BR-drive_encoder" filename="sim_encoder.dll">
        <joint>BRdrive-BRwheel</joint>
        <topic>~/gazebo/frc/simulator/encoder/7</topic>
        <multiplier>1</multiplier>
    </plugin> 
    <plugin name="Body-BR-turn_motor" filename="sim_motor.dll">
        <joint>Body-BRdrive</joint>
        <topic>~/gazebo/frc/simulator/motor/8</topic>
        <multiplier>25</multiplier>
    </plugin>
    <plugin name="Body-BR-turn_encoder" filename="sim_encoder.dll">
        <joint>Body-BRdrive</joint>
        <topic>~/gazebo/frc/simulator/encoder/8</topic>
        <multiplier>1</multiplier>
    </plugin>

    <plugin name="Arm_motor" filename="sim_motor.dll">
        <joint>Body-Arm</joint>
        <topic>~/gazebo/frc/simulator/motor/9</topic>
        <multiplier>50</multiplier>
    </plugin>
    <plugin name="Arm_encoder" filename="sim_encoder.dll">
        <joint>Body-Arm</joint>
        <topic>~/gazebo/frc/simulator/encoder/9</topic>
        <multiplier>1</multiplier>
    </plugin>

    <plugin name="intake_motor" filename="sim_motor.dll">
        <joint>Arm-PickupTop</joint>
        <topic>~/gazebo/frc/simulator/motor/10</topic>
        <multiplier>50</multiplier>
    </plugin>

    <plugin name="intake_motor" filename="sim_motor.dll">
        <joint>Arm-PickupBot</joint>
        <topic>~/gazebo/frc/simulator/motor/10</topic>
        <multiplier>50</multiplier>
    </plugin>

     <plugin name="shooter_motor" filename="sim_motor.dll">
        <joint>Arm-TopShootWheels</joint>
        <topic>~/gazebo/frc/simulator/motor/11</topic>
        <multiplier>100</multiplier>
    </plugin>

    <plugin name="shooter_motor" filename="sim_motor.dll">
        <joint>Arm-BotShootWheels</joint>
        <topic>~/gazebo/frc/simulator/motor/11</topic>
        <multiplier>100</multiplier>
    </plugin>

     <plugin name="Shooterencoder" filename="sim_encoder.dll">
        <joint>Arm-TopShootWheels</joint>
        <topic>~/gazebo/frc/simulator/encoder/11</topic>
    </plugin>

    <plugin name="pusher_motor" filename="sim_motor.dll">
        <joint>Arm-MidRollersTop</joint>
        <topic>~/gazebo/frc/simulator/motor/12</topic>
        <multiplier>50</multiplier>
    </plugin>

    <plugin name="pusher_motor" filename="sim_motor.dll">
        <joint>Arm-MidRollersBot</joint>
        <topic>~/gazebo/frc/simulator/motor/12</topic>
        <multiplier>50</multiplier>
    </plugin>

    <plugin name="Arm_llimit" filename="sim_limitswitch.dll">
      <joint>Body-Arm</joint>
      <topic>~/gazebo/frc/simulator/switch/2</topic>
      <units>radians</units>
      <low>-0.9</low>
      <high>2</high>
    </plugin>
  </model>
</sdf>