<sdf version='1.7'>
  <world name='default'>
    <light name='sun' type='directional'>
      <cast_shadows>1</cast_shadows>
      <pose>0 0 10 0 -0 0</pose>
      <diffuse>0.8 0.8 0.8 1</diffuse>
      <specular>0.2 0.2 0.2 1</specular>
      <attenuation>
        <range>1000</range>
        <constant>0.9</constant>
        <linear>0.01</linear>
        <quadratic>0.001</quadratic>
      </attenuation>
      <direction>-0.5 0.1 -0.9</direction>
      <spot>
        <inner_angle>0</inner_angle>
        <outer_angle>0</outer_angle>
        <falloff>0</falloff>
      </spot>
    </light>
    <model name='ground_plane'>
      <static>1</static>
      <link name='link'>
        <collision name='collision'>
          <geometry>
            <plane>
              <normal>0 0 1</normal>
              <size>100 100</size>
            </plane>
          </geometry>
          <surface>
            <contact>
              <collide_bitmask>65535</collide_bitmask>
              <ode/>
            </contact>
            <friction>
              <ode>
                <mu>100</mu>
                <mu2>50</mu2>
              </ode>
              <torsional>
                <ode/>
              </torsional>
            </friction>
            <bounce/>
          </surface>
          <max_contacts>10</max_contacts>
        </collision>
        <visual name='visual'>
          <cast_shadows>0</cast_shadows>
          <geometry>
            <plane>
              <normal>0 0 1</normal>
              <size>100 100</size>
            </plane>
          </geometry>
          <material>
            <script>
              <uri>file://media/materials/scripts/gazebo.material</uri>
              <name>Gazebo/Grey</name>
            </script>
          </material>
        </visual>
        <self_collide>0</self_collide>
        <enable_wind>0</enable_wind>
        <kinematic>0</kinematic>
      </link>
    </model>
    <model name='2016-Robot'>
      <pose>0 0 0 0 -0 0</pose>
      <link name='TopFrame'>
        <gravity>1</gravity>
        <self_collide>0</self_collide>
        <pose>-0.535308 0.079389 -0.40987 0 -0 0</pose>
        <must_be_base_link>1</must_be_base_link>
        <velocity_decay>
          <linear>0</linear>
          <angular>0</angular>
        </velocity_decay>
        <inertial>
          <mass>13.8297</mass>
          <pose>0 0 0 0 -0 0</pose>
          <inertia>
            <ixx>0.313059</ixx>
            <ixy>0.0778786</ixy>
            <ixz>0.0746279</ixz>
            <iyy>0.983339</iyy>
            <iyz>0.00643566</iyz>
            <izz>0.739761</izz>
          </inertia>
        </inertial>
        <collision name='TopFrame_collision'>
          <pose>0.40835 -0.148138 -0.030953 0 -0 0</pose>
          <geometry>
            <mesh>
              <scale>1 1 1</scale>
              <uri>model://2016-Robot/meshes/TopFrame_col.STL</uri>
            </mesh>
          </geometry>
          <surface>
            <contact>
              <ode/>
            </contact>
            <friction>
              <ode>
                <mu>1</mu>
                <mu2>1</mu2>
              </ode>
              <torsional>
                <ode/>
              </torsional>
            </friction>
            <bounce/>
          </surface>
          <max_contacts>10</max_contacts>
        </collision>
        <visual name='TopFrame_visual'>
          <pose>0.40835 -0.148138 -0.030953 0 -0 0</pose>
          <material>
            <ambient>0 0 1 1</ambient>
            <diffuse>0 0 1 1</diffuse>
          </material>
          <geometry>
            <mesh>
              <scale>1 1 1</scale>
              <uri>model://2016-Robot/meshes/TopFrame.STL</uri>
            </mesh>
          </geometry>
        </visual>
        <sensor name='TopFrameUltrasonic' type='sonar'>
          <always_on>1</always_on>
          <visualize>1</visualize>
          <pose>0.378134 0.093995 -0.083943 2.86033 -0 3.14159</pose>
          <sonar>
            <min>0.05</min>
            <max>7</max>
            <radius>0.05</radius>
          </sonar>
        </sensor>
        <enable_wind>0</enable_wind>
        <kinematic>0</kinematic>
      </link>
      <link name='LeftFrame'>
        <gravity>1</gravity>
        <self_collide>0</self_collide>
        <pose>-0.61845 0.063143 -0.127837 0 -0 0</pose>
        <must_be_base_link>0</must_be_base_link>
        <velocity_decay>
          <linear>0</linear>
          <angular>0</angular>
        </velocity_decay>
        <inertial>
          <mass>9.85785</mass>
          <pose>0 0 0 0 -0 0</pose>
          <inertia>
            <ixx>0.0471972</ixx>
            <ixy>0.007664</ixy>
            <ixz>0.0465517</ixz>
            <iyy>0.223821</iyy>
            <iyz>0.000454312</iyz>
            <izz>0.191819</izz>
          </inertia>
        </inertial>
        <collision name='LeftFrame_collision'>
          <pose>0.491493 -0.131892 -0.312986 0 -0 0</pose>
          <geometry>
            <mesh>
              <scale>1 1 1</scale>
              <uri>model://2016-Robot/meshes/LeftFrame_col.STL</uri>
            </mesh>
          </geometry>
          <surface>
            <contact>
              <ode/>
            </contact>
            <friction>
              <ode>
                <mu>0</mu>
                <mu2>0</mu2>
              </ode>
              <torsional>
                <ode/>
              </torsional>
            </friction>
            <bounce/>
          </surface>
          <max_contacts>10</max_contacts>
        </collision>
        <visual name='LeftFrame_visual'>
          <pose>0.491493 -0.131892 -0.312986 0 -0 0</pose>
          <material>
            <ambient>0 1 0 1</ambient>
            <diffuse>0 1 0 1</diffuse>
          </material>
          <geometry>
            <mesh>
              <scale>1 1 1</scale>
              <uri>model://2016-Robot/meshes/LeftFrame.STL</uri>
            </mesh>
          </geometry>
        </visual>
        <enable_wind>0</enable_wind>
        <kinematic>0</kinematic>
      </link>
      <joint name='TopFrame-LeftFrame' type='revolute'>
        <parent>TopFrame</parent>
        <child>LeftFrame</child>
        <pose>0.239026 -0.012827 0.108787 0 -0 0</pose>
        <axis>
          <xyz>0 0 -1</xyz>
          <dynamics>
            <damping>1</damping>
            <friction>2</friction>
            <spring_reference>0</spring_reference>
            <spring_stiffness>0</spring_stiffness>
          </dynamics>
          <limit>
            <upper>0.05</upper>
            <lower>-0.05</lower>
            <effort>1</effort>
          </limit>
        </axis>
      </joint>
      <link name='L1Wheel'>
        <gravity>1</gravity>
        <self_collide>0</self_collide>
        <pose>-0.683804 0.067805 0.042014 0 -0 0</pose>
        <must_be_base_link>0</must_be_base_link>
        <velocity_decay>
          <linear>0</linear>
          <angular>0</angular>
        </velocity_decay>
        <inertial>
          <mass>0.56309</mass>
          <pose>0 0 0 0 -0 0</pose>
          <inertia>
            <ixx>0.00128474</ixx>
            <ixy>8.45307e-08</ixy>
            <ixz>5.92558e-08</ixz>
            <iyy>0.00128284</iyy>
            <iyz>4.61663e-07</iyz>
            <izz>0.00217023</izz>
          </inertia>
        </inertial>
        <collision name='L1Wheel_collision'>
          <pose>0.556847 -0.136554 -0.482836 0 -0 0</pose>
          <geometry>
            <mesh>
              <scale>1 1 1</scale>
              <uri>model://2016-Robot/meshes/L1Wheel_col.STL</uri>
            </mesh>
          </geometry>
          <surface>
            <contact>
              <ode/>
            </contact>
            <friction>
              <ode>
                <mu>2</mu>
                <mu2>2</mu2>
              </ode>
              <torsional>
                <ode/>
              </torsional>
            </friction>
            <bounce/>
          </surface>
          <max_contacts>10</max_contacts>
        </collision>
        <visual name='L1Wheel_visual'>
          <pose>0.556847 -0.136554 -0.482836 0 -0 0</pose>
          <material>
            <ambient>0.501961 0.501961 0.501961 1</ambient>
            <diffuse>0.501961 0.501961 0.501961 1</diffuse>
          </material>
          <geometry>
            <mesh>
              <scale>1 1 1</scale>
              <uri>model://2016-Robot/meshes/L1Wheel.STL</uri>
            </mesh>
          </geometry>
        </visual>
        <enable_wind>0</enable_wind>
        <kinematic>0</kinematic>
      </link>
      <joint name='LeftFrame-L1Wheel' type='revolute'>
        <parent>LeftFrame</parent>
        <child>L1Wheel</child>
        <pose>-5e-06 -0.001262 -0.002802 3.14159 -1.57079 3.14159</pose>
        <axis>
          <xyz>1 0 0</xyz>
          <dynamics>
            <damping>1</damping>
            <friction>1</friction>
            <spring_reference>0</spring_reference>
            <spring_stiffness>0</spring_stiffness>
          </dynamics>
          <limit>
            <effort>40</effort>
            <lower>-1e+16</lower>
            <upper>1e+16</upper>
          </limit>
        </axis>
      </joint>
      <link name='L2Wheel'>
        <gravity>1</gravity>
        <self_collide>0</self_collide>
        <pose>-0.481243 0.044541 0.042014 0 -0 0</pose>
        <must_be_base_link>0</must_be_base_link>
        <velocity_decay>
          <linear>0</linear>
          <angular>0</angular>
        </velocity_decay>
        <inertial>
          <mass>0.56309</mass>
          <pose>0 0 0 0 -0 0</pose>
          <inertia>
            <ixx>0.00128356</ixx>
            <ixy>9.23396e-07</ixy>
            <ixz>3.42107e-07</ixz>
            <iyy>0.00128402</iyy>
            <iyz>3.1533e-07</iyz>
            <izz>0.00217023</izz>
          </inertia>
        </inertial>
        <collision name='L2Wheel_collision'>
          <pose>0.354286 -0.11329 -0.482836 0 -0 0</pose>
          <geometry>
            <mesh>
              <scale>1 1 1</scale>
              <uri>model://2016-Robot/meshes/L2Wheel_col.STL</uri>
            </mesh>
          </geometry>
          <surface>
            <contact>
              <ode/>
            </contact>
            <friction>
              <ode>
                <mu>2</mu>
                <mu2>2</mu2>
              </ode>
              <torsional>
                <ode/>
              </torsional>
            </friction>
            <bounce/>
          </surface>
          <max_contacts>10</max_contacts>
        </collision>
        <visual name='L2Wheel_visual'>
          <pose>0.354286 -0.11329 -0.482836 0 -0 0</pose>
          <material>
            <ambient>0.501961 0.501961 0.501961 1</ambient>
            <diffuse>0.501961 0.501961 0.501961 1</diffuse>
          </material>
          <geometry>
            <mesh>
              <scale>1 1 1</scale>
              <uri>model://2016-Robot/meshes/L2Wheel.STL</uri>
            </mesh>
          </geometry>
        </visual>
        <enable_wind>0</enable_wind>
        <kinematic>0</kinematic>
      </link>
      <joint name='LeftFrame-L2Wheel' type='revolute'>
        <parent>LeftFrame</parent>
        <child>L2Wheel</child>
        <pose>-0.001032 -0.000726 -0.002802 3.14159 -1.57079 3.14159</pose>
        <axis>
          <xyz>1 0 -0</xyz>
          <dynamics>
            <damping>1</damping>
            <friction>1</friction>
            <spring_reference>0</spring_reference>
            <spring_stiffness>0</spring_stiffness>
          </dynamics>
          <limit>
            <effort>40</effort>
            <lower>-1e+16</lower>
            <upper>1e+16</upper>
          </limit>
        </axis>
      </joint>
      <link name='L3Wheel'>
        <gravity>1</gravity>
        <self_collide>0</self_collide>
        <pose>-0.278177 0.037167 0.042014 0 -0 0</pose>
        <must_be_base_link>0</must_be_base_link>
        <velocity_decay>
          <linear>0</linear>
          <angular>0</angular>
        </velocity_decay>
        <inertial>
          <mass>0.56309</mass>
          <pose>0 0 0 0 -0 0</pose>
          <inertia>
            <ixx>0.00128356</ixx>
            <ixy>9.23397e-07</ixy>
            <ixz>3.42107e-07</ixz>
            <iyy>0.00128402</iyy>
            <iyz>3.1533e-07</iyz>
            <izz>0.00217023</izz>
          </inertia>
        </inertial>
        <collision name='L3Wheel_collision'>
          <pose>0.15122 -0.105916 -0.482836 0 -0 0</pose>
          <geometry>
            <mesh>
              <scale>1 1 1</scale>
              <uri>model://2016-Robot/meshes/L3Wheel_col.STL</uri>
            </mesh>
          </geometry>
          <surface>
            <contact>
              <ode/>
            </contact>
            <friction>
              <ode>
                <mu>2</mu>
                <mu2>2</mu2>
              </ode>
              <torsional>
                <ode/>
              </torsional>
            </friction>
            <bounce/>
          </surface>
          <max_contacts>10</max_contacts>
        </collision>
        <visual name='L3Wheel_visual'>
          <pose>0.15122 -0.105916 -0.482836 0 -0 0</pose>
          <material>
            <ambient>0.501961 0.501961 0.501961 1</ambient>
            <diffuse>0.501961 0.501961 0.501961 1</diffuse>
          </material>
          <geometry>
            <mesh>
              <scale>1 1 1</scale>
              <uri>model://2016-Robot/meshes/L3Wheel.STL</uri>
            </mesh>
          </geometry>
        </visual>
        <enable_wind>0</enable_wind>
        <kinematic>0</kinematic>
      </link>
      <joint name='LeftFrame-L3Wheel' type='revolute'>
        <parent>LeftFrame</parent>
        <child>L3Wheel</child>
        <pose>-0.001032 -0.000726 -0.002802 3.14159 -1.57079 3.14159</pose>
        <axis>
          <xyz>1 0 -0</xyz>
          <dynamics>
            <damping>1</damping>
            <friction>1</friction>
            <spring_reference>0</spring_reference>
            <spring_stiffness>0</spring_stiffness>
          </dynamics>
          <limit>
            <effort>40</effort>
            <lower>-1e+16</lower>
            <upper>1e+16</upper>
          </limit>
        </axis>
      </joint>
      <link name='L4Wheel'>
        <gravity>1</gravity>
        <self_collide>0</self_collide>
        <pose>-0.074671 0.045632 0.042014 0 -0 0</pose>
        <must_be_base_link>0</must_be_base_link>
        <velocity_decay>
          <linear>0</linear>
          <angular>0</angular>
        </velocity_decay>
        <inertial>
          <mass>0.56309</mass>
          <pose>0 0 0 0 -0 0</pose>
          <inertia>
            <ixx>0.00128327</ixx>
            <ixy>7.94198e-07</ixy>
            <ixz>4.26489e-07</ixz>
            <iyy>0.00128432</iyy>
            <iyz>1.85964e-07</iyz>
            <izz>0.00217023</izz>
          </inertia>
        </inertial>
        <collision name='L4Wheel_collision'>
          <pose>-0.052287 -0.114381 -0.482836 0 -0 0</pose>
          <geometry>
            <mesh>
              <scale>1 1 1</scale>
              <uri>model://2016-Robot/meshes/L4Wheel_col.STL</uri>
            </mesh>
          </geometry>
          <surface>
            <contact>
              <ode/>
            </contact>
            <friction>
              <ode>
                <mu>2</mu>
                <mu2>2</mu2>
              </ode>
              <torsional>
                <ode/>
              </torsional>
            </friction>
            <bounce/>
          </surface>
          <max_contacts>10</max_contacts>
        </collision>
        <visual name='L4Wheel_visual'>
          <pose>-0.052287 -0.114381 -0.482836 0 -0 0</pose>
          <material>
            <ambient>0.501961 0.501961 0.501961 1</ambient>
            <diffuse>0.501961 0.501961 0.501961 1</diffuse>
          </material>
          <geometry>
            <mesh>
              <scale>1 1 1</scale>
              <uri>model://2016-Robot/meshes/L4Wheel.STL</uri>
            </mesh>
          </geometry>
        </visual>
        <enable_wind>0</enable_wind>
        <kinematic>0</kinematic>
      </link>
      <joint name='LeftFrame-L4Wheel' type='revolute'>
        <parent>LeftFrame</parent>
        <child>L4Wheel</child>
        <pose>0.001081 -0.000652 -0.002802 3.14159 -1.57079 3.14159</pose>
        <axis>
          <xyz>1 0 0</xyz>
          <dynamics>
            <damping>1</damping>
            <friction>1</friction>
            <spring_reference>0</spring_reference>
            <spring_stiffness>0</spring_stiffness>
          </dynamics>
          <limit>
            <effort>40</effort>
            <lower>-1e+16</lower>
            <upper>1e+16</upper>
          </limit>
        </axis>
      </joint>
      <link name='R1Wheel'>
        <gravity>1</gravity>
        <self_collide>0</self_collide>
        <pose>-0.674628 0.055829 -0.584939 0 -0 0</pose>
        <must_be_base_link>0</must_be_base_link>
        <velocity_decay>
          <linear>0</linear>
          <angular>0</angular>
        </velocity_decay>
        <inertial>
          <mass>0.56309</mass>
          <pose>0 0 0 0 -0 0</pose>
          <inertia>
            <ixx>0.0012832</ixx>
            <ixy>7.48042e-07</ixy>
            <ixz>4.00452e-07</ixz>
            <iyy>0.00128438</iyy>
            <iyz>2.36873e-07</iyz>
            <izz>0.00217023</izz>
          </inertia>
        </inertial>
        <collision name='R1Wheel_collision'>
          <pose>0.547671 -0.124578 0.144116 0 -0 0</pose>
          <geometry>
            <mesh>
              <scale>1 1 1</scale>
              <uri>model://2016-Robot/meshes/R1Wheel_col.STL</uri>
            </mesh>
          </geometry>
          <surface>
            <contact>
              <ode/>
            </contact>
            <friction>
              <ode>
                <mu>2</mu>
                <mu2>2</mu2>
              </ode>
              <torsional>
                <ode/>
              </torsional>
            </friction>
            <bounce/>
          </surface>
          <max_contacts>10</max_contacts>
        </collision>
        <visual name='R1Wheel_visual'>
          <pose>0.547671 -0.124578 0.144116 0 -0 0</pose>
          <material>
            <ambient>0.501961 0.501961 0.501961 1</ambient>
            <diffuse>0.501961 0.501961 0.501961 1</diffuse>
          </material>
          <geometry>
            <mesh>
              <scale>1 1 1</scale>
              <uri>model://2016-Robot/meshes/R1Wheel.STL</uri>
            </mesh>
          </geometry>
        </visual>
        <enable_wind>0</enable_wind>
        <kinematic>0</kinematic>
      </link>
      <joint name='TopFrame-R1Wheel' type='revolute'>
        <parent>TopFrame</parent>
        <child>R1Wheel</child>
        <pose>-0.001161 0.000494 0.002802 3.14159 -1.57079 3.14159</pose>
        <axis>
          <xyz>1 0 0</xyz>
          <dynamics>
            <damping>1</damping>
            <friction>1</friction>
            <spring_reference>0</spring_reference>
            <spring_stiffness>0</spring_stiffness>
          </dynamics>
          <limit>
            <effort>40</effort>
            <lower>-1e+16</lower>
            <upper>1e+16</upper>
          </limit>
        </axis>
      </joint>
      <link name='R2Wheel'>
        <gravity>1</gravity>
        <self_collide>0</self_collide>
        <pose>-0.471504 0.039915 -0.584939 0 -0 0</pose>
        <must_be_base_link>0</must_be_base_link>
        <velocity_decay>
          <linear>0</linear>
          <angular>0</angular>
        </velocity_decay>
        <inertial>
          <mass>0.56309</mass>
          <pose>0 0 0 0 -0 0</pose>
          <inertia>
            <ixx>0.00128474</ixx>
            <ixy>8.06254e-08</ixy>
            <ixz>1.89056e-08</ixz>
            <iyy>0.00128284</iyy>
            <iyz>4.65066e-07</iyz>
            <izz>0.00217023</izz>
          </inertia>
        </inertial>
        <collision name='R2Wheel_collision'>
          <pose>0.344546 -0.108664 0.144116 0 -0 0</pose>
          <geometry>
            <mesh>
              <scale>1 1 1</scale>
              <uri>model://2016-Robot/meshes/R2Wheel_col.STL</uri>
            </mesh>
          </geometry>
          <surface>
            <contact>
              <ode/>
            </contact>
            <friction>
              <ode>
                <mu>2</mu>
                <mu2>2</mu2>
              </ode>
              <torsional>
                <ode/>
              </torsional>
            </friction>
            <bounce/>
          </surface>
          <max_contacts>10</max_contacts>
        </collision>
        <visual name='R2Wheel_visual'>
          <pose>0.344546 -0.108664 0.144116 0 -0 0</pose>
          <material>
            <ambient>0.501961 0.501961 0.501961 1</ambient>
            <diffuse>0.501961 0.501961 0.501961 1</diffuse>
          </material>
          <geometry>
            <mesh>
              <scale>1 1 1</scale>
              <uri>model://2016-Robot/meshes/R2Wheel.STL</uri>
            </mesh>
          </geometry>
        </visual>
        <enable_wind>0</enable_wind>
        <kinematic>0</kinematic>
      </link>
      <joint name='TopFrame-R2Wheel' type='revolute'>
        <parent>TopFrame</parent>
        <child>R2Wheel</child>
        <pose>-0.000115 0.001257 0.002802 3.14159 -1.57079 3.14159</pose>
        <axis>
          <xyz>1 0 -0</xyz>
          <dynamics>
            <damping>1</damping>
            <friction>1</friction>
            <spring_reference>0</spring_reference>
            <spring_stiffness>0</spring_stiffness>
          </dynamics>
          <limit>
            <effort>40</effort>
            <lower>-1e+16</lower>
            <upper>1e+16</upper>
          </limit>
        </axis>
      </joint>
      <link name='R3Wheel'>
        <gravity>1</gravity>
        <self_collide>0</self_collide>
        <pose>-0.268299 0.039915 -0.584939 0 -0 0</pose>
        <must_be_base_link>0</must_be_base_link>
        <velocity_decay>
          <linear>0</linear>
          <angular>0</angular>
        </velocity_decay>
        <inertial>
          <mass>0.56309</mass>
          <pose>0 0 0 0 -0 0</pose>
          <inertia>
            <ixx>0.00128472</ixx>
            <ixy>1.86161e-07</ixy>
            <ixz>7.21305e-09</ixz>
            <iyy>0.00128286</iyy>
            <iyz>4.65394e-07</iyz>
            <izz>0.00217023</izz>
          </inertia>
        </inertial>
        <collision name='R3Wheel_collision'>
          <pose>0.141342 -0.108663 0.144116 0 -0 0</pose>
          <geometry>
            <mesh>
              <scale>1 1 1</scale>
              <uri>model://2016-Robot/meshes/R3Wheel_col.STL</uri>
            </mesh>
          </geometry>
          <surface>
            <contact>
              <ode/>
            </contact>
            <friction>
              <ode>
                <mu>2</mu>
                <mu2>2</mu2>
              </ode>
              <torsional>
                <ode/>
              </torsional>
            </friction>
            <bounce/>
          </surface>
          <max_contacts>10</max_contacts>
        </collision>
        <visual name='R3Wheel_visual'>
          <pose>0.141342 -0.108663 0.144116 0 -0 0</pose>
          <material>
            <ambient>0.501961 0.501961 0.501961 1</ambient>
            <diffuse>0.501961 0.501961 0.501961 1</diffuse>
          </material>
          <geometry>
            <mesh>
              <scale>1 1 1</scale>
              <uri>model://2016-Robot/meshes/R3Wheel.STL</uri>
            </mesh>
          </geometry>
        </visual>
        <enable_wind>0</enable_wind>
        <kinematic>0</kinematic>
      </link>
      <joint name='TopFrame-R3Wheel' type='revolute'>
        <parent>TopFrame</parent>
        <child>R3Wheel</child>
        <pose>-0.000185 0.001248 0.002802 3.14159 -1.57079 3.14159</pose>
        <axis>
          <xyz>1 0 -0</xyz>
          <dynamics>
            <damping>1</damping>
            <friction>1</friction>
            <spring_reference>0</spring_reference>
            <spring_stiffness>0</spring_stiffness>
          </dynamics>
          <limit>
            <effort>40</effort>
            <lower>-1e+16</lower>
            <upper>1e+16</upper>
          </limit>
        </axis>
      </joint>
      <link name='R4Wheel'>
        <gravity>1</gravity>
        <self_collide>0</self_collide>
        <pose>-0.065099 0.05579 -0.584939 0 -0 0</pose>
        <must_be_base_link>0</must_be_base_link>
        <velocity_decay>
          <linear>0</linear>
          <angular>0</angular>
        </velocity_decay>
        <inertial>
          <mass>0.56309</mass>
          <pose>0 0 0 0 -0 0</pose>
          <inertia>
            <ixx>0.00128472</ixx>
            <ixy>1.86161e-07</ixy>
            <ixz>7.21303e-09</ixz>
            <iyy>0.00128286</iyy>
            <iyz>4.65394e-07</iyz>
            <izz>0.00217023</izz>
          </inertia>
        </inertial>
        <collision name='R4Wheel_collision'>
          <pose>-0.061858 -0.124538 0.144116 0 -0 0</pose>
          <geometry>
            <mesh>
              <scale>1 1 1</scale>
              <uri>model://2016-Robot/meshes/R4Wheel_col.STL</uri>
            </mesh>
          </geometry>
          <surface>
            <contact>
              <ode/>
            </contact>
            <friction>
              <ode>
                <mu>2</mu>
                <mu2>2</mu2>
              </ode>
              <torsional>
                <ode/>
              </torsional>
            </friction>
            <bounce/>
          </surface>
          <max_contacts>10</max_contacts>
        </collision>
        <visual name='R4Wheel_visual'>
          <pose>-0.061858 -0.124538 0.144116 0 -0 0</pose>
          <material>
            <ambient>0.501961 0.501961 0.501961 1</ambient>
            <diffuse>0.501961 0.501961 0.501961 1</diffuse>
          </material>
          <geometry>
            <mesh>
              <scale>1 1 1</scale>
              <uri>model://2016-Robot/meshes/R4Wheel.STL</uri>
            </mesh>
          </geometry>
        </visual>
        <enable_wind>0</enable_wind>
        <kinematic>0</kinematic>
      </link>
      <joint name='TopFrame-R4Wheel' type='revolute'>
        <parent>TopFrame</parent>
        <child>R4Wheel</child>
        <pose>-0.000185 0.001248 0.002802 3.14159 -1.57079 3.14159</pose>
        <axis>
          <xyz>1 0 -0</xyz>
          <dynamics>
            <damping>1</damping>
            <friction>1</friction>
            <spring_reference>0</spring_reference>
            <spring_stiffness>0</spring_stiffness>
          </dynamics>
          <limit>
            <effort>40</effort>
            <lower>-1e+16</lower>
            <upper>1e+16</upper>
          </limit>
        </axis>
      </joint>
      <link name='Shooter'>
        <gravity>1</gravity>
        <self_collide>0</self_collide>
        <pose>-0.34031 0.103955 -0.307805 0 -0 0</pose>
        <must_be_base_link>0</must_be_base_link>
        <velocity_decay>
          <linear>0</linear>
          <angular>0</angular>
        </velocity_decay>
        <inertial>
          <mass>6.6474</mass>
          <pose>0 0 0 0 -0 0</pose>
          <inertia>
            <ixx>0.171657</ixx>
            <ixy>0.00116502</ixy>
            <ixz>0.0375602</ixz>
            <iyy>0.206254</iyy>
            <iyz>0.00368475</iyz>
            <izz>0.0699035</izz>
          </inertia>
        </inertial>
        <collision name='Shooter_collision'>
          <pose>0.213353 -0.172704 -0.133017 0 -0 0</pose>
          <geometry>
            <mesh>
              <scale>1 1 1</scale>
              <uri>model://2016-Robot/meshes/Shooter_col.STL</uri>
            </mesh>
          </geometry>
          <surface>
            <contact>
              <ode/>
            </contact>
            <friction>
              <ode>
                <mu>0.2</mu>
                <mu2>0.2</mu2>
              </ode>
              <torsional>
                <ode/>
              </torsional>
            </friction>
            <bounce/>
          </surface>
          <max_contacts>10</max_contacts>
        </collision>
        <visual name='Shooter_visual'>
          <pose>0.213353 -0.172704 -0.133017 0 -0 0</pose>
          <material>
            <ambient>0 0.501961 0.501961 1</ambient>
            <diffuse>0 0.501961 0.501961 1</diffuse>
          </material>
          <geometry>
            <mesh>
              <scale>1 1 1</scale>
              <uri>model://2016-Robot/meshes/Shooter.STL</uri>
            </mesh>
          </geometry>
        </visual>
        <sensor name='ShooterCamera' type='camera'>
          <visualize>1</visualize>
          <always_on>1</always_on>
          <update_rate>100</update_rate>
          <pose>-0.124207 0.103145 -0.122065 1.5708 -0 3.14159</pose>
          <camera name='Shootercamera'>
            <horizontal_fov>1.0472</horizontal_fov>
            <image>
              <width>320</width>
              <height>240</height>
            </image>
            <clip>
              <near>0.1</near>
              <far>100</far>
            </clip>
          </camera>
        </sensor>
        <enable_wind>0</enable_wind>
        <kinematic>0</kinematic>
      </link>
      <joint name='TopFrame-Shooter' type='revolute'>
        <parent>TopFrame</parent>
        <child>Shooter</child>
        <pose>0.127842 0.048255 -0.21884 0 -0 0</pose>
        <axis>
          <xyz>0 0 -1</xyz>
          <dynamics>
            <damping>1</damping>
            <friction>1</friction>
            <spring_reference>0</spring_reference>
            <spring_stiffness>0</spring_stiffness>
          </dynamics>
          <limit>
            <upper>1.3</upper>
            <lower>-0.05</lower>
            <effort>30</effort>
          </limit>
        </axis>
      </joint>
      <link name='PushWheel'>
        <gravity>1</gravity>
        <self_collide>0</self_collide>
        <pose>-0.212547 0.150899 -0.428966 0 -0 0</pose>
        <must_be_base_link>0</must_be_base_link>
        <velocity_decay>
          <linear>0</linear>
          <angular>0</angular>
        </velocity_decay>
        <inertial>
          <mass>0.596238</mass>
          <pose>0 0 0 0 -0 0</pose>
          <inertia>
            <ixx>0.000669968</ixx>
            <ixy>2.05741e-05</ixy>
            <ixz>4.46929e-07</ixz>
            <iyy>0.00125126</iyy>
            <iyz>1.21436e-07</iyz>
            <izz>0.000668908</izz>
          </inertia>
        </inertial>
        <collision name='PushWheel_collision'>
          <pose>0.08559 -0.219648 -0.011857 0 -0 0</pose>
          <geometry>
            <mesh>
              <scale>1 1 1</scale>
              <uri>model://2016-Robot/meshes/PushWheel_col.STL</uri>
            </mesh>
          </geometry>
          <surface>
            <contact>
              <ode/>
            </contact>
            <friction>
              <ode>
                <mu>2</mu>
                <mu2>2</mu2>
              </ode>
              <torsional>
                <ode/>
              </torsional>
            </friction>
            <bounce/>
          </surface>
          <max_contacts>10</max_contacts>
        </collision>
        <visual name='PushWheel_visual'>
          <pose>0.08559 -0.219648 -0.011857 0 -0 0</pose>
          <material>
            <ambient>0.501961 0.501961 0.501961 1</ambient>
            <diffuse>0.501961 0.501961 0.501961 1</diffuse>
          </material>
          <geometry>
            <mesh>
              <scale>1 1 1</scale>
              <uri>model://2016-Robot/meshes/PushWheel.STL</uri>
            </mesh>
          </geometry>
        </visual>
        <enable_wind>0</enable_wind>
        <kinematic>0</kinematic>
      </link>
      <joint name='Shooter-PushWheel' type='revolute'>
        <parent>Shooter</parent>
        <child>PushWheel</child>
        <pose>2.9e-05 -0.000101 2.3e-05 0 0 -1.5708</pose>
        <axis>
          <xyz>0.999388 -0.034988 -0</xyz>
          <dynamics>
            <damping>1</damping>
            <friction>1</friction>
            <spring_reference>0</spring_reference>
            <spring_stiffness>0</spring_stiffness>
          </dynamics>
          <limit>
            <effort>50</effort>
            <lower>-1e+16</lower>
            <upper>1e+16</upper>
          </limit>
        </axis>
      </joint>
      <link name='LeftFW'>
        <gravity>1</gravity>
        <self_collide>0</self_collide>
        <pose>-0.415611 0.158012 -0.111454 0 -0 0</pose>
        <must_be_base_link>0</must_be_base_link>
        <velocity_decay>
          <linear>0</linear>
          <angular>0</angular>
        </velocity_decay>
        <inertial>
          <mass>1.80417</mass>
          <pose>0 0 0 0 -0 0</pose>
          <inertia>
            <ixx>0.00209273</ixx>
            <ixy>6.40454e-05</ixy>
            <ixz>7.13508e-07</ixz>
            <iyy>0.0039091</iyy>
            <iyz>1.76726e-07</iyz>
            <izz>0.00208954</izz>
          </inertia>
        </inertial>
        <collision name='LeftFW_collision'>
          <pose>0.288654 -0.226761 -0.329368 0 -0 0</pose>
          <geometry>
            <mesh>
              <scale>1 1 1</scale>
              <uri>model://2016-Robot/meshes/LeftFW_col.STL</uri>
            </mesh>
          </geometry>
          <surface>
            <contact>
              <ode/>
            </contact>
            <friction>
              <ode>
                <mu>1</mu>
                <mu2>1</mu2>
              </ode>
              <torsional>
                <ode/>
              </torsional>
            </friction>
            <bounce/>
          </surface>
          <max_contacts>10</max_contacts>
        </collision>
        <visual name='LeftFW_visual'>
          <pose>0.288654 -0.226761 -0.329368 0 -0 0</pose>
          <material>
            <ambient>0.501961 0.25098 0.25098 1</ambient>
            <diffuse>0.501961 0.25098 0.25098 1</diffuse>
          </material>
          <geometry>
            <mesh>
              <scale>1 1 1</scale>
              <uri>model://2016-Robot/meshes/LeftFW.STL</uri>
            </mesh>
          </geometry>
        </visual>
        <enable_wind>0</enable_wind>
        <kinematic>0</kinematic>
      </link>
      <joint name='Shooter-LeftFW' type='revolute'>
        <parent>Shooter</parent>
        <child>LeftFW</child>
        <pose>1.7e-05 -0.000105 1.1e-05 0 -0 0</pose>
        <axis>
          <xyz>0.034988 0.999388 0</xyz>
          <dynamics>
            <damping>0.1</damping>
            <friction>0.1</friction>
            <spring_reference>0</spring_reference>
            <spring_stiffness>0</spring_stiffness>
          </dynamics>
          <limit>
            <effort>800</effort>
            <lower>-1e+16</lower>
            <upper>1e+16</upper>
          </limit>
        </axis>
      </joint>
      <link name='RightFW'>
        <gravity>1</gravity>
        <self_collide>0</self_collide>
        <pose>-0.415611 0.158012 -0.428954 0 -0 0</pose>
        <must_be_base_link>0</must_be_base_link>
        <velocity_decay>
          <linear>0</linear>
          <angular>0</angular>
        </velocity_decay>
        <inertial>
          <mass>1.80417</mass>
          <pose>0 0 0 0 -0 0</pose>
          <inertia>
            <ixx>0.00209273</ixx>
            <ixy>6.40454e-05</ixy>
            <ixz>7.13508e-07</ixz>
            <iyy>0.0039091</iyy>
            <iyz>1.76726e-07</iyz>
            <izz>0.00208954</izz>
          </inertia>
        </inertial>
        <collision name='RightFW_collision'>
          <pose>0.288654 -0.226761 -0.011868 0 -0 0</pose>
          <geometry>
            <mesh>
              <scale>1 1 1</scale>
              <uri>model://2016-Robot/meshes/RightFW_col.STL</uri>
            </mesh>
          </geometry>
          <surface>
            <contact>
              <ode/>
            </contact>
            <friction>
              <ode>
                <mu>1</mu>
                <mu2>1</mu2>
              </ode>
              <torsional>
                <ode/>
              </torsional>
            </friction>
            <bounce/>
          </surface>
          <max_contacts>10</max_contacts>
        </collision>
        <visual name='RightFW_visual'>
          <pose>0.288654 -0.226761 -0.011868 0 -0 0</pose>
          <material>
            <ambient>0.501961 0.25098 0.25098 1</ambient>
            <diffuse>0.501961 0.25098 0.25098 1</diffuse>
          </material>
          <geometry>
            <mesh>
              <scale>1 1 1</scale>
              <uri>model://2016-Robot/meshes/RightFW.STL</uri>
            </mesh>
          </geometry>
        </visual>
        <enable_wind>0</enable_wind>
        <kinematic>0</kinematic>
      </link>
      <joint name='Shooter-RightFW' type='revolute'>
        <parent>Shooter</parent>
        <child>RightFW</child>
        <pose>1.7e-05 -0.000105 1.1e-05 0 0 -1.5708</pose>
        <axis>
          <xyz>0.999388 -0.034988 -0</xyz>
          <dynamics>
            <damping>0.1</damping>
            <friction>0.1</friction>
            <spring_reference>0</spring_reference>
            <spring_stiffness>0</spring_stiffness>
          </dynamics>
          <limit>
            <effort>800</effort>
            <lower>-1e+16</lower>
            <upper>1e+16</upper>
          </limit>
        </axis>
      </joint>
      <link name='Gate'>
        <gravity>1</gravity>
        <self_collide>0</self_collide>
        <pose>-0.281727 0.208591 -0.196709 0 -0 0</pose>
        <must_be_base_link>0</must_be_base_link>
        <velocity_decay>
          <linear>0</linear>
          <angular>0</angular>
        </velocity_decay>
        <inertial>
          <mass>0.973575</mass>
          <pose>0 0 0 0 -0 0</pose>
          <inertia>
            <ixx>0.015346</ixx>
            <ixy>0.000252256</ixy>
            <ixz>0.00153103</ixz>
            <iyy>0.0152469</iyy>
            <iyz>0.00179957</iyz>
            <izz>0.000731699</izz>
          </inertia>
        </inertial>
        <collision name='Gate_collision'>
          <pose>0.15477 -0.27734 -0.244113 0 -0 0</pose>
          <geometry>
            <mesh>
              <scale>1 1 1</scale>
              <uri>model://2016-Robot/meshes/Gate_col.STL</uri>
            </mesh>
          </geometry>
          <surface>
            <contact>
              <ode/>
            </contact>
            <friction>
              <ode>
                <mu>2</mu>
                <mu2>2</mu2>
              </ode>
              <torsional>
                <ode/>
              </torsional>
            </friction>
            <bounce/>
          </surface>
          <max_contacts>10</max_contacts>
        </collision>
        <visual name='Gate_visual'>
          <pose>0.15477 -0.27734 -0.244113 0 -0 0</pose>
          <material>
            <ambient>0.501961 0.501961 0.501961 1</ambient>
            <diffuse>0.501961 0.501961 0.501961 1</diffuse>
          </material>
          <geometry>
            <mesh>
              <scale>1 1 1</scale>
              <uri>model://2016-Robot/meshes/Gate.STL</uri>
            </mesh>
          </geometry>
        </visual>
        <enable_wind>0</enable_wind>
        <kinematic>0</kinematic>
      </link>
      <joint name='Shooter-Gate' type='revolute'>
        <parent>Shooter</parent>
        <child>Gate</child>
        <pose>-0.006621 -0.04588 0.080132 0 -0 1.5708</pose>
        <axis>
          <xyz>0.999388 -0.034988 -0</xyz>
          <dynamics>
            <damping>1</damping>
            <friction>1</friction>
            <spring_reference>0</spring_reference>
            <spring_stiffness>0</spring_stiffness>
          </dynamics>
          <limit>
            <upper>1.5</upper>
            <lower>0</lower>
            <effort>30</effort>
          </limit>
        </axis>
      </joint>
      <link name='LoaderArms'>
        <gravity>1</gravity>
        <self_collide>0</self_collide>
        <pose>-0.042984 0.202131 -0.28017 0 -0 0</pose>
        <must_be_base_link>0</must_be_base_link>
        <velocity_decay>
          <linear>0</linear>
          <angular>0</angular>
        </velocity_decay>
        <inertial>
          <mass>0.746692</mass>
          <pose>0 0 0 0 -0 0</pose>
          <inertia>
            <ixx>0.0555147</ixx>
            <ixy>0.0068512</ixy>
            <ixz>0.000672797</ixz>
            <iyy>0.0943017</iyy>
            <iyz>0.000133469</iyz>
            <izz>0.0437458</izz>
          </inertia>
        </inertial>
        <collision name='LoaderArms_collision'>
          <pose>-0.083973 -0.27088 -0.160652 0 -0 0</pose>
          <geometry>
            <mesh>
              <scale>1 1 1</scale>
              <uri>model://2016-Robot/meshes/LoaderArms_col.STL</uri>
            </mesh>
          </geometry>
          <surface>
            <contact>
              <ode/>
            </contact>
            <friction>
              <ode>
                <mu>0</mu>
                <mu2>0</mu2>
              </ode>
              <torsional>
                <ode/>
              </torsional>
            </friction>
            <bounce/>
          </surface>
          <max_contacts>10</max_contacts>
        </collision>
        <visual name='LoaderArms_visual'>
          <pose>-0.083973 -0.27088 -0.160652 0 -0 0</pose>
          <material>
            <ambient>0.501961 0.501961 0.501961 1</ambient>
            <diffuse>0.501961 0.501961 0.501961 1</diffuse>
          </material>
          <geometry>
            <mesh>
              <scale>1 1 1</scale>
              <uri>model://2016-Robot/meshes/LoaderArms.STL</uri>
            </mesh>
          </geometry>
        </visual>
        <sensor name='LoaderArmsCamera' type='camera'>
          <visualize>0</visualize>
          <always_on>1</always_on>
          <pose>0.200907 0.032306 -0.296092 -1.5708 -0 0</pose>
          <camera name='LoaderArmscamera'>
            <horizontal_fov>1.5708</horizontal_fov>
            <image>
              <width>320</width>
              <height>240</height>
            </image>
            <clip>
              <near>0.1</near>
              <far>100</far>
            </clip>
          </camera>
        </sensor>
        <enable_wind>0</enable_wind>
        <kinematic>0</kinematic>
      </link>
      <joint name='TopFrame-LoaderArms' type='revolute'>
        <parent>TopFrame</parent>
        <child>LoaderArms</child>
        <pose>-0.421386 0.029319 0.263025 3.14159 -1.57079 3.14159</pose>
        <axis>
          <xyz>1 0 -0</xyz>
          <dynamics>
            <damping>1</damping>
            <friction>1</friction>
            <spring_reference>0</spring_reference>
            <spring_stiffness>0</spring_stiffness>
          </dynamics>
          <limit>
            <upper>1.5</upper>
            <lower>0</lower>
            <effort>30</effort>
          </limit>
        </axis>
      </joint>
      <link name='Roller1'>
        <gravity>1</gravity>
        <self_collide>0</self_collide>
        <pose>0.119822 0.234437 -0.271446 0 -0 0</pose>
        <must_be_base_link>0</must_be_base_link>
        <velocity_decay>
          <linear>0</linear>
          <angular>0</angular>
        </velocity_decay>
        <inertial>
          <mass>0.526942</mass>
          <pose>0 0 0 0 -0 0</pose>
          <inertia>
            <ixx>0.011581</ixx>
            <ixy>5.59773e-37</ixy>
            <ixz>1.06935e-19</ixz>
            <iyy>0.011581</iyy>
            <iyz>1.63085e-35</iyz>
            <izz>0.000242427</izz>
          </inertia>
        </inertial>
        <collision name='Roller1_collision'>
          <pose>-0.24678 -0.303186 -0.169376 0 -0 0</pose>
          <geometry>
            <mesh>
              <scale>1 1 1</scale>
              <uri>model://2016-Robot/meshes/Roller1_col.STL</uri>
            </mesh>
          </geometry>
          <surface>
            <contact>
              <ode/>
            </contact>
            <friction>
              <ode>
                <mu>2</mu>
                <mu2>2</mu2>
              </ode>
              <torsional>
                <ode/>
              </torsional>
            </friction>
            <bounce/>
          </surface>
          <max_contacts>10</max_contacts>
        </collision>
        <visual name='Roller1_visual'>
          <pose>-0.24678 -0.303186 -0.169376 0 -0 0</pose>
          <material>
            <ambient>0 0.752941 0.501961 1</ambient>
            <diffuse>0 0.752941 0.501961 1</diffuse>
          </material>
          <geometry>
            <mesh>
              <scale>1 1 1</scale>
              <uri>model://2016-Robot/meshes/Roller1.STL</uri>
            </mesh>
          </geometry>
        </visual>
        <enable_wind>0</enable_wind>
        <kinematic>0</kinematic>
      </link>
      <joint name='LoaderArms-Roller1' type='revolute'>
        <parent>LoaderArms</parent>
        <child>Roller1</child>
        <pose>-0 -0 0.29129 3.14159 1.57079 3.14159</pose>
        <axis>
          <xyz>1 0 -0</xyz>
          <dynamics>
            <damping>0.2</damping>
            <friction>0.1</friction>
            <spring_reference>0</spring_reference>
            <spring_stiffness>0</spring_stiffness>
          </dynamics>
          <limit>
            <effort>30</effort>
            <lower>-1e+16</lower>
            <upper>1e+16</upper>
          </limit>
        </axis>
      </joint>
      <link name='Roller2'>
        <gravity>1</gravity>
        <self_collide>0</self_collide>
        <pose>0.172174 0.182618 -0.274629 0 -0 0</pose>
        <must_be_base_link>0</must_be_base_link>
        <velocity_decay>
          <linear>0</linear>
          <angular>0</angular>
        </velocity_decay>
        <inertial>
          <mass>0.413223</mass>
          <pose>0 0 0 0 -0 0</pose>
          <inertia>
            <ixx>0.0111058</ixx>
            <ixy>1.0829e-36</ixy>
            <ixz>5.75067e-21</ixz>
            <iyy>0.0111058</iyy>
            <iyz>2.28507e-35</iyz>
            <izz>0.000211202</izz>
          </inertia>
        </inertial>
        <collision name='Roller2_collision'>
          <pose>-0.299131 -0.251367 -0.166194 0 -0 0</pose>
          <geometry>
            <mesh>
              <scale>1 1 1</scale>
              <uri>model://2016-Robot/meshes/Roller2_col.STL</uri>
            </mesh>
          </geometry>
          <surface>
            <contact>
              <ode/>
            </contact>
            <friction>
              <ode>
                <mu>2</mu>
                <mu2>2</mu2>
              </ode>
              <torsional>
                <ode/>
              </torsional>
            </friction>
            <bounce/>
          </surface>
          <max_contacts>10</max_contacts>
        </collision>
        <visual name='Roller2_visual'>
          <pose>-0.299131 -0.251367 -0.166194 0 -0 0</pose>
          <material>
            <ambient>0 0.752941 0.501961 1</ambient>
            <diffuse>0 0.752941 0.501961 1</diffuse>
          </material>
          <geometry>
            <mesh>
              <scale>1 1 1</scale>
              <uri>model://2016-Robot/meshes/Roller2.STL</uri>
            </mesh>
          </geometry>
        </visual>
        <enable_wind>0</enable_wind>
        <kinematic>0</kinematic>
      </link>
      <joint name='LoaderArms-Roller2' type='revolute'>
        <parent>LoaderArms</parent>
        <child>Roller2</child>
        <pose>0 -0 0.294472 3.14159 1.57079 3.14159</pose>
        <axis>
          <xyz>1 0 -0</xyz>
          <dynamics>
            <damping>0.2</damping>
            <friction>0.1</friction>
            <spring_reference>0</spring_reference>
            <spring_stiffness>0</spring_stiffness>
          </dynamics>
          <limit>
            <effort>30</effort>
            <lower>-1e+16</lower>
            <upper>1e+16</upper>
          </limit>
        </axis>
      </joint>
      <link name='Roller3'>
        <gravity>1</gravity>
        <self_collide>0</self_collide>
        <pose>0.220914 0.134373 -0.274629 0 -0 0</pose>
        <must_be_base_link>0</must_be_base_link>
        <velocity_decay>
          <linear>0</linear>
          <angular>0</angular>
        </velocity_decay>
        <inertial>
          <mass>0.413223</mass>
          <pose>0 0 0 0 -0 0</pose>
          <inertia>
            <ixx>0.0111058</ixx>
            <ixy>1.0829e-36</ixy>
            <ixz>5.75067e-21</ixz>
            <iyy>0.0111058</iyy>
            <iyz>2.28507e-35</iyz>
            <izz>0.000211202</izz>
          </inertia>
        </inertial>
        <collision name='Roller3_collision'>
          <pose>-0.347871 -0.203122 -0.166194 0 -0 0</pose>
          <geometry>
            <mesh>
              <scale>1 1 1</scale>
              <uri>model://2016-Robot/meshes/Roller3_col.STL</uri>
            </mesh>
          </geometry>
          <surface>
            <contact>
              <ode/>
            </contact>
            <friction>
              <ode>
                <mu>2</mu>
                <mu2>2</mu2>
              </ode>
              <torsional>
                <ode/>
              </torsional>
            </friction>
            <bounce/>
          </surface>
          <max_contacts>10</max_contacts>
        </collision>
        <visual name='Roller3_visual'>
          <pose>-0.347871 -0.203122 -0.166194 0 -0 0</pose>
          <material>
            <ambient>0 0.752941 0.501961 1</ambient>
            <diffuse>0 0.752941 0.501961 1</diffuse>
          </material>
          <geometry>
            <mesh>
              <scale>1 1 1</scale>
              <uri>model://2016-Robot/meshes/Roller3.STL</uri>
            </mesh>
          </geometry>
        </visual>
        <enable_wind>0</enable_wind>
        <kinematic>0</kinematic>
      </link>
      <joint name='LoaderArms-Roller3' type='revolute'>
        <parent>LoaderArms</parent>
        <child>Roller3</child>
        <pose>0 0 0.294472 3.14159 1.57079 3.14159</pose>
        <axis>
          <xyz>1 0 -0</xyz>
          <dynamics>
            <damping>0.2</damping>
            <friction>0.1</friction>
            <spring_reference>0</spring_reference>
            <spring_stiffness>0</spring_stiffness>
          </dynamics>
          <limit>
            <effort>30</effort>
            <lower>-1e+16</lower>
            <upper>1e+16</upper>
          </limit>
        </axis>
      </joint>
      <link name='Roller4'>
        <gravity>1</gravity>
        <self_collide>0</self_collide>
        <pose>0.269655 0.086129 -0.274629 0 -0 0</pose>
        <must_be_base_link>0</must_be_base_link>
        <velocity_decay>
          <linear>0</linear>
          <angular>0</angular>
        </velocity_decay>
        <inertial>
          <mass>0.413223</mass>
          <pose>0 0 0 0 -0 0</pose>
          <inertia>
            <ixx>0.0111058</ixx>
            <ixy>1.0829e-36</ixy>
            <ixz>5.75067e-21</ixz>
            <iyy>0.0111058</iyy>
            <iyz>2.28507e-35</iyz>
            <izz>0.000211202</izz>
          </inertia>
        </inertial>
        <collision name='Roller4_collision'>
          <pose>-0.396612 -0.154878 -0.166194 0 -0 0</pose>
          <geometry>
            <mesh>
              <scale>1 1 1</scale>
              <uri>model://2016-Robot/meshes/Roller4_col.STL</uri>
            </mesh>
          </geometry>
          <surface>
            <contact>
              <ode/>
            </contact>
            <friction>
              <ode>
                <mu>2</mu>
                <mu2>2</mu2>
              </ode>
              <torsional>
                <ode/>
              </torsional>
            </friction>
            <bounce/>
          </surface>
          <max_contacts>10</max_contacts>
        </collision>
        <visual name='Roller4_visual'>
          <pose>-0.396612 -0.154878 -0.166194 0 -0 0</pose>
          <material>
            <ambient>0 0.752941 0.501961 1</ambient>
            <diffuse>0 0.752941 0.501961 1</diffuse>
          </material>
          <geometry>
            <mesh>
              <scale>1 1 1</scale>
              <uri>model://2016-Robot/meshes/Roller4.STL</uri>
            </mesh>
          </geometry>
        </visual>
        <enable_wind>0</enable_wind>
        <kinematic>0</kinematic>
      </link>
      <joint name='LoaderArms-Roller4' type='revolute'>
        <parent>LoaderArms</parent>
        <child>Roller4</child>
        <pose>0 0 0.294472 3.14159 1.57079 3.14159</pose>
        <axis>
          <xyz>1 0 -0</xyz>
          <dynamics>
            <damping>0.2</damping>
            <friction>0.1</friction>
            <spring_reference>0</spring_reference>
            <spring_stiffness>0</spring_stiffness>
          </dynamics>
          <limit>
            <effort>30</effort>
            <lower>-1e+16</lower>
            <upper>1e+16</upper>
          </limit>
        </axis>
      </joint>
      <link name='Roller5'>
        <gravity>1</gravity>
        <self_collide>0</self_collide>
        <pose>0.318396 0.037884 -0.274629 0 -0 0</pose>
        <must_be_base_link>0</must_be_base_link>
        <velocity_decay>
          <linear>0</linear>
          <angular>0</angular>
        </velocity_decay>
        <inertial>
          <mass>0.413223</mass>
          <pose>0 0 0 0 -0 0</pose>
          <inertia>
            <ixx>0.0111058</ixx>
            <ixy>1.0829e-36</ixy>
            <ixz>5.75067e-21</ixz>
            <iyy>0.0111058</iyy>
            <iyz>2.28507e-35</iyz>
            <izz>0.000211202</izz>
          </inertia>
        </inertial>
        <collision name='Roller5_collision'>
          <pose>-0.445353 -0.106633 -0.166194 0 -0 0</pose>
          <geometry>
            <mesh>
              <scale>1 1 1</scale>
              <uri>model://2016-Robot/meshes/Roller5_col.STL</uri>
            </mesh>
          </geometry>
          <surface>
            <contact>
              <ode/>
            </contact>
            <friction>
              <ode>
                <mu>2</mu>
                <mu2>2</mu2>
              </ode>
              <torsional>
                <ode/>
              </torsional>
            </friction>
            <bounce/>
          </surface>
          <max_contacts>10</max_contacts>
        </collision>
        <visual name='Roller5_visual'>
          <pose>-0.445353 -0.106633 -0.166194 0 -0 0</pose>
          <material>
            <ambient>0 0.752941 0.501961 1</ambient>
            <diffuse>0 0.752941 0.501961 1</diffuse>
          </material>
          <geometry>
            <mesh>
              <scale>1 1 1</scale>
              <uri>model://2016-Robot/meshes/Roller5.STL</uri>
            </mesh>
          </geometry>
        </visual>
        <enable_wind>0</enable_wind>
        <kinematic>0</kinematic>
      </link>
      <joint name='LoaderArms-Roller5' type='revolute'>
        <parent>LoaderArms</parent>
        <child>Roller5</child>
        <pose>-0 -0 0.294472 3.14159 1.57079 3.14159</pose>
        <axis>
          <xyz>1 0 -0</xyz>
          <dynamics>
            <damping>0.2</damping>
            <friction>0.1</friction>
            <spring_reference>0</spring_reference>
            <spring_stiffness>0</spring_stiffness>
          </dynamics>
          <limit>
            <effort>30</effort>
            <lower>-1e+16</lower>
            <upper>1e+16</upper>
          </limit>
        </axis>
      </joint>
    </model>
    <gravity>0 0 -9.8</gravity>
    <magnetic_field>6e-06 2.3e-05 -4.2e-05</magnetic_field>
    <atmosphere type='adiabatic'/>
    <physics type='ode'>
      <max_step_size>0.001</max_step_size>
      <real_time_factor>1</real_time_factor>
      <real_time_update_rate>1000</real_time_update_rate>
    </physics>
    <scene>
      <ambient>0.4 0.4 0.4 1</ambient>
      <background>0.7 0.7 0.7 1</background>
      <shadows>1</shadows>
    </scene>
    <wind/>
    <spherical_coordinates>
      <surface_model>EARTH_WGS84</surface_model>
      <latitude_deg>0</latitude_deg>
      <longitude_deg>0</longitude_deg>
      <elevation>0</elevation>
      <heading_deg>0</heading_deg>
    </spherical_coordinates>
    <state world_name='default'>
      <sim_time>26 560000000</sim_time>
      <real_time>51 17589200</real_time>
      <wall_time>1699026353 267875500</wall_time>
      <iterations>26560</iterations>
      <model name='2016-Robot'>
        <pose>-0.0319 0.030353 0.061388 1.56347 -0.000218 0.028882</pose>
        <scale>1 1 1</scale>
        <link name='Gate'>
          <pose>-0.32785 0.220244 0.264843 1.56237 -0.049672 0.102066</pose>
          <velocity>-0.00031 -0.000907 -0.005841 0.004417 0.00788 -0.001481</velocity>
          <acceleration>-0.139724 -0.283418 -10.1187 -0.068957 1.0369 0.920149</acceleration>
          <wrench>-0.136032 -0.275928 -9.85127 0 -0 0</wrench>
        </link>
        <link name='L1Wheel'>
          <pose>-0.71471 -0.031018 0.114116 1.56344 -0.04039 0.029177</pose>
          <velocity>-0.00114 0.000331 -0.008035 0.011093 0.002319 -0.00138</velocity>
          <acceleration>0.083279 0.044152 -10.7764 -1.38942 -0.70983 -2.9147</acceleration>
          <wrench>0.046894 0.024861 -6.06809 0 -0 0</wrench>
        </link>
        <link name='L2Wheel'>
          <pose>-0.51139 -0.025239 0.101129 1.56341 -0.124802 0.0298</pose>
          <velocity>-0.001268 -0.000107 -0.010079 0.004975 0.002141 -0.00152</velocity>
          <acceleration>-0.207844 -0.233126 -15.1206 -2.86631 0.714858 2.84462</acceleration>
          <wrench>-0.117035 -0.131271 -8.51425 0 -0 0</wrench>
        </link>
        <link name='L3Wheel'>
          <pose>-0.308145 -0.019349 0.103737 1.56346 0.07631 0.028321</pose>
          <velocity>-0.001121 -0.000183 -0.006069 0.00221 0.002063 -0.001432</velocity>
          <acceleration>0.063338 0.105726 -7.81466 -2.63635 -1.13818 0.089936</acceleration>
          <wrench>0.035665 0.059533 -4.40036 0 -0 0</wrench>
        </link>
        <link name='L4Wheel'>
          <pose>-0.105448 -0.013355 0.122624 1.56348 0.029816 0.028662</pose>
          <velocity>-0.001128 -0.000521 -0.006028 0.002696 0.002079 -0.001426</velocity>
          <acceleration>0.067265 0.154234 -8.11024 -1.80168 -0.832459 0.108953</acceleration>
          <wrench>0.037876 0.086848 -4.56679 0 -0 0</wrench>
        </link>
        <link name='LeftFW'>
          <pose>-0.450655 0.130837 0.20832 1.56352 -0.050275 0.025316</pose>
          <velocity>-0.0009 -0.000477 -0.005235 0.00447 0.008193 -0.001483</velocity>
          <acceleration>0.016475 -0.172298 -10.636 -0.960716 1.53291 -3.08565</acceleration>
          <wrench>0.029724 -0.310855 -19.1892 0 -0 0</wrench>
        </link>
        <link name='LeftFrame'>
          <pose>-0.654148 0.140638 0.111492 1.56344 -0.050222 0.029249</pose>
          <velocity>-0.000909 0.000277 -0.006243 0.01113 0.002319 -0.00138</velocity>
          <acceleration>0.046206 0.090427 -8.65465 0.167976 0.25231 0.346637</acceleration>
          <wrench>0.455495 0.891414 -85.3163 0 -0 0</wrench>
        </link>
        <link name='LoaderArms'>
          <pose>-0.083043 0.310637 0.261446 1.56347 -0.000215 0.028882</pose>
          <velocity>-0.000504 -0.001318 -0.00535 0.004954 -5.7e-05 -0.001365</velocity>
          <acceleration>0.064525 -0.418583 -9.45855 2.85294 0.2203 -2.958</acceleration>
          <wrench>0.04818 -0.312553 -7.06263 0 -0 0</wrench>
        </link>
        <link name='PushWheel'>
          <pose>-0.256744 0.454097 0.209089 1.56346 -0.050246 0.029228</pose>
          <velocity>-0.000411 -0.000761 -0.005359 0.004483 0.008148 -0.001482</velocity>
          <acceleration>0.009663 -0.152394 -9.37473 2.20201 1.447 0.053685</acceleration>
          <wrench>0.005762 -0.090863 -5.58957 0 -0 0</wrench>
        </link>
        <link name='R1Wheel'>
          <pose>-0.723093 0.595963 0.11299 1.56336 -0.173118 0.03016</pose>
          <velocity>-0.000325 0.000349 -0.004914 0.003954 0.000902 -0.001295</velocity>
          <acceleration>-0.108992 0.038177 -10.1402 0.841134 -0.22612 0.51225</acceleration>
          <wrench>-0.061372 0.021497 -5.70984 0 -0 0</wrench>
        </link>
        <link name='R2Wheel'>
          <pose>-0.519942 0.601713 0.096949 1.56342 -0.137805 0.029892</pose>
          <velocity>-0.000477 0.000244 -0.007053 0.001223 0.000827 -0.000817</velocity>
          <acceleration>-0.451918 0.389724 -13.9993 -0.34913 0.648573 2.38533</acceleration>
          <wrench>-0.25447 0.219449 -7.88287 0 -0 0</wrench>
        </link>
        <link name='R3Wheel'>
          <pose>-0.317037 0.607576 0.096949 1.56349 0.034819 0.028623</pose>
          <velocity>-0.000454 -0.00024 -0.00448 0.000326 0.000802 -0.000645</velocity>
          <acceleration>-0.422959 0.016878 -8.85283 -2.36229 0.692134 1.83893</acceleration>
          <wrench>-0.238164 0.009504 -4.98494 0 -0 0</wrench>
        </link>
        <link name='R4Wheel'>
          <pose>-0.113898 0.61356 0.112873 1.56347 0.009192 0.028813</pose>
          <velocity>-0.000279 -0.00045 -0.004973 0.004729 0.000924 -0.001368</velocity>
          <acceleration>-0.061414 0.182406 -9.55098 2.28584 -0.157129 0.238938</acceleration>
          <wrench>-0.034582 0.102711 -5.37806 0 -0 0</wrench>
        </link>
        <link name='RightFW'>
          <pose>-0.459823 0.448196 0.205995 1.56352 -0.050272 0.025588</pose>
          <velocity>-0.000459 -0.000448 -0.003749 0.004596 0.008116 -0.00148</velocity>
          <acceleration>-0.011094 -0.155232 -9.95929 2.42462 1.33337 0.048494</acceleration>
          <wrench>-0.020015 -0.280065 -17.9683 0 -0 0</wrench>
        </link>
        <link name='Roller1'>
          <pose>0.079934 0.306854 0.293847 1.56347 0.01615 0.028762</pose>
          <velocity>-0.000464 -0.001707 -0.004857 0.004552 -6.5e-05 -0.001342</velocity>
          <acceleration>0.2115 -0.516305 -8.7538 2.9836 1.49687 2.63781</acceleration>
          <wrench>0.111448 -0.272063 -4.61275 0 -0 0</wrench>
        </link>
        <link name='Roller2'>
          <pose>0.132193 0.311168 0.242018 1.56347 0.012483 0.028789</pose>
          <velocity>-0.000455 -0.001529 -0.004941 0.004657 -6.3e-05 -0.001364</velocity>
          <acceleration>0.129979 -0.380664 -9.03336 -0.4272 -1.42153 -0.619075</acceleration>
          <wrench>0.05371 -0.157299 -3.73279 0 -0 0</wrench>
        </link>
        <link name='Roller3'>
          <pose>0.180934 0.312223 0.193786 1.56347 0.009063 0.028814</pose>
          <velocity>-0.000458 -0.00136 -0.005003 0.004698 -6.2e-05 -0.001375</velocity>
          <acceleration>0.037883 -0.249477 -9.24668 -0.386169 -0.521628 -0.625754</acceleration>
          <wrench>0.015654 -0.10309 -3.82094 0 -0 0</wrench>
        </link>
        <link name='Roller4'>
          <pose>0.229675 0.313277 0.145553 1.56347 0.00532 0.028841</pose>
          <velocity>-0.000474 -0.001189 -0.005079 0.004742 -6.2e-05 -0.001386</velocity>
          <acceleration>-0.084555 -0.113562 -9.4929 -0.33683 0.467306 -0.633072</acceleration>
          <wrench>-0.03494 -0.046926 -3.92268 0 -0 0</wrench>
        </link>
        <link name='Roller5'>
          <pose>0.278416 0.314332 0.09732 1.56347 0.00166 0.028868</pose>
          <velocity>-0.000501 -0.001014 -0.005165 0.004792 -6.2e-05 -0.001396</velocity>
          <acceleration>-0.233084 0.028725 -9.76481 -0.275373 1.46813 -0.640463</acceleration>
          <wrench>-0.096315 0.01187 -4.03504 0 -0 0</wrench>
        </link>
        <link name='Shooter'>
          <pose>-0.378426 0.328983 0.156676 1.56346 -0.050246 0.029249</pose>
          <velocity>-0.001024 -0.000346 -0.004911 0.004474 0.008152 -0.001482</velocity>
          <acceleration>0.150778 -0.039366 -9.94667 2.91061 0.688722 -0.99627</acceleration>
          <wrench>1.00228 -0.261681 -66.1195 0 -0 0</wrench>
        </link>
        <link name='TopFrame'>
          <pose>-0.578853 0.425163 0.137655 1.56347 -0.000218 0.028882</pose>
          <velocity>-0.000532 6.4e-05 -0.005691 0.005237 0.000937 -0.001407</velocity>
          <acceleration>-0.061445 0.058924 -10.2771 1.90005 0.141547 0.129657</acceleration>
          <wrench>-0.849762 0.814906 -142.129 0 -0 0</wrench>
        </link>
      </model>
      <model name='ground_plane'>
        <pose>0 0 0 0 -0 0</pose>
        <scale>1 1 1</scale>
        <link name='link'>
          <pose>0 0 0 0 -0 0</pose>
          <velocity>0 0 0 0 -0 0</velocity>
          <acceleration>0 0 0 0 -0 0</acceleration>
          <wrench>0 0 0 0 -0 0</wrench>
        </link>
      </model>
      <light name='sun'>
        <pose>0 0 10 0 -0 0</pose>
      </light>
    </state>
    <gui fullscreen='0'>
      <camera name='user_camera'>
        <pose>1.10588 1.57578 1.28063 0 0.523642 -2.31099</pose>
        <view_controller>orbit</view_controller>
        <projection_type>perspective</projection_type>
      </camera>
    </gui>
  </world>
</sdf>
