<sdf version='1.7'>
  <world name='default'>
    <gui fullscreen='0'>
      <camera name='user_camera'>
        <pose>-2.22275 -7.38671 4.38955 0 0.829797 2.0002</pose>
        <view_controller>orbit</view_controller>
        <projection_type>perspective</projection_type>
      </camera>
    </gui>
    <light name='sun' type='directional'>
      <cast_shadows>1</cast_shadows>
      <pose>0 0 10 0 -0 0</pose>
      <diffuse>0.8 0.8 0.8 1</diffuse>
      <specular>0.2 0.2 0.2 1</specular>
      <attenuation>
        <range>1000</range>
        <constant>0.9</constant>
        <linear>0.01</linear>
        <quadratic>0.001</quadratic>
      </attenuation>
      <direction>-0.5 0.1 -0.9</direction>
      <spot>
        <inner_angle>0</inner_angle>
        <outer_angle>0</outer_angle>
        <falloff>0</falloff>
      </spot>
    </light>
    <model name='ground_plane'>
      <static>1</static>
      <link name='link'>
        <collision name='collision'>
          <geometry>
            <plane>
              <normal>0 0 1</normal>
              <size>100 100</size>
            </plane>
          </geometry>
          <surface>
            <contact>
              <collide_bitmask>65535</collide_bitmask>
              <ode/>
            </contact>
            <friction>
              <ode>
                <mu>100</mu>
                <mu2>50</mu2>
              </ode>
              <torsional>
                <ode/>
              </torsional>
            </friction>
            <bounce/>
          </surface>
          <max_contacts>10</max_contacts>
        </collision>
        <visual name='visual'>
          <cast_shadows>0</cast_shadows>
          <geometry>
            <plane>
              <normal>0 0 1</normal>
              <size>100 100</size>
            </plane>
          </geometry>
          <material>
            <script>
              <uri>file://media/materials/scripts/gazebo.material</uri>
              <name>Gazebo/Grey</name>
            </script>
          </material>
        </visual>
        <self_collide>0</self_collide>
        <enable_wind>0</enable_wind>
        <kinematic>0</kinematic>
      </link>
    </model>
    <model name='SimBot2019'>
      <pose>-6.09985 -5.027 0.329301 0 -0 3.1415</pose>
      <link name='Frame'>
        <gravity>1</gravity>
        <self_collide>0</self_collide>
        <pose>-0.4064 0 0 -1.5708 0 1.5708</pose>
        <must_be_base_link>1</must_be_base_link>
        <velocity_decay>
          <linear>0</linear>
          <angular>0</angular>
        </velocity_decay>
        <inertial>
          <mass>150</mass>
          <pose>0 0 -0.1 0 -0 0</pose>
          <inertia>
            <ixx>1</ixx>
            <ixy>0</ixy>
            <ixz>0</ixz>
            <iyy>1</iyy>
            <iyz>0</iyz>
            <izz>1</izz>
          </inertia>
        </inertial>
        <collision name='Frame_collision'>
          <pose>0 0 0 0 -0 0</pose>
          <geometry>
            <mesh>
              <scale>1 1 1</scale>
              <uri>model://SimBot2019/meshes/Frame_col.STL</uri>
            </mesh>
          </geometry>
          <surface>
            <contact>
              <ode>
                <max_vel>0</max_vel>
              </ode>
            </contact>
            <friction>
              <ode>
                <mu>1</mu>
                <mu2>1</mu2>
              </ode>
              <torsional>
                <ode/>
              </torsional>
            </friction>
            <bounce/>
          </surface>
          <max_contacts>10</max_contacts>
        </collision>
        <visual name='Frame_visual'>
          <pose>0 0 0 0 -0 0</pose>
          <material>
            <ambient>0.501961 0.501961 0.501961 1</ambient>
            <diffuse>0.501961 0.501961 0.501961 1</diffuse>
          </material>
          <geometry>
            <mesh>
              <scale>1 1 1</scale>
              <uri>model://SimBot2019/meshes/Frame.STL</uri>
            </mesh>
          </geometry>
        </visual>
        <sensor name='FrameCamera' type='camera'>
          <visualize>0</visualize>
          <always_on>1</always_on>
          <update_rate>20</update_rate>
          <pose>0 -0.05 0.25 1.57079 -1.57079 -0.001593</pose>
          <camera name='Framecamera'>
            <horizontal_fov>1.5708</horizontal_fov>
            <image>
              <width>320</width>
              <height>240</height>
            </image>
            <clip>
              <near>0.05</near>
              <far>50</far>
            </clip>
          </camera>
          <plugin name='camera' filename='sim_camera.dll'>
            <topic>~/gazebo/frc/simulator/camera/1</topic>
            <port>9001</port>
            <fps>20</fps>
            <enabled>1</enabled>
            <savepath>tmp</savepath>
            <maxframes>0</maxframes>
            <video>back.avi</video>
          </plugin>
        </sensor>
        <enable_wind>0</enable_wind>
        <kinematic>0</kinematic>
      </link>
      <link name='R1Wheel'>
        <gravity>1</gravity>
        <self_collide>0</self_collide>
        <pose>-0.673098 0.303263 0.001695 -1.5708 0 1.5708</pose>
        <must_be_base_link>0</must_be_base_link>
        <velocity_decay>
          <linear>0</linear>
          <angular>0.002</angular>
        </velocity_decay>
        <inertial>
          <mass>0.255325</mass>
          <pose>0 0 0 0 -0 0</pose>
          <inertia>
            <ixx>1</ixx>
            <ixy>0</ixy>
            <ixz>0</ixz>
            <iyy>1</iyy>
            <iyz>0</iyz>
            <izz>1</izz>
          </inertia>
        </inertial>
        <collision name='R1Wheel_collision'>
          <pose>-0.303263 0.001695 -0.266698 0 -0 0</pose>
          <geometry>
            <mesh>
              <scale>1 1 1</scale>
              <uri>model://SimBot2019/meshes/R1Wheel.STL</uri>
            </mesh>
          </geometry>
          <surface>
            <contact>
              <ode>
                <kp>1e+07</kp>
                <kd>25</kd>
              </ode>
            </contact>
            <friction>
              <ode>
                <mu>1</mu>
                <mu2>1</mu2>
              </ode>
              <torsional>
                <ode/>
              </torsional>
            </friction>
            <bounce/>
          </surface>
          <max_contacts>10</max_contacts>
        </collision>
        <visual name='R1Wheel_visual'>
          <pose>-0.303263 0.001695 -0.266698 0 -0 0</pose>
          <material>
            <ambient>0.501961 0.501961 0.501961 1</ambient>
            <diffuse>0.501961 0.501961 0.501961 1</diffuse>
          </material>
          <geometry>
            <mesh>
              <scale>1 1 1</scale>
              <uri>model://SimBot2019/meshes/R1Wheel.STL</uri>
            </mesh>
          </geometry>
        </visual>
        <enable_wind>0</enable_wind>
        <kinematic>0</kinematic>
      </link>
      <joint name='Frame-R1Wheel' type='revolute'>
        <parent>Frame</parent>
        <child>R1Wheel</child>
        <pose>0 4.4e-05 -3e-06 0 -0 0</pose>
        <axis>
          <xyz>-1 0 0</xyz>
          <dynamics>
            <damping>1</damping>
            <friction>1</friction>
            <spring_reference>0</spring_reference>
            <spring_stiffness>0</spring_stiffness>
          </dynamics>
          <limit>
            <effort>50</effort>
            <lower>-1e+16</lower>
            <upper>1e+16</upper>
          </limit>
        </axis>
      </joint>
      <link name='R2Wheel'>
        <gravity>1</gravity>
        <self_collide>0</self_collide>
        <pose>-0.405313 0.303263 -0.003858 -1.5708 0 1.5708</pose>
        <must_be_base_link>0</must_be_base_link>
        <velocity_decay>
          <linear>0</linear>
          <angular>0.002</angular>
        </velocity_decay>
        <inertial>
          <mass>0.255325</mass>
          <pose>0 0 0 0 -0 0</pose>
          <inertia>
            <ixx>1</ixx>
            <ixy>0</ixy>
            <ixz>0</ixz>
            <iyy>1</iyy>
            <iyz>0</iyz>
            <izz>1</izz>
          </inertia>
        </inertial>
        <collision name='R2Wheel_collision'>
          <pose>-0.303263 -0.003858 0.001087 0 -0 0</pose>
          <geometry>
            <mesh>
              <scale>1 1 1</scale>
              <uri>model://SimBot2019/meshes/R2Wheel.STL</uri>
            </mesh>
          </geometry>
          <surface>
            <contact>
              <ode>
                <kp>1e+07</kp>
                <kd>25</kd>
              </ode>
            </contact>
            <friction>
              <ode>
                <mu>1</mu>
                <mu2>1</mu2>
              </ode>
              <torsional>
                <ode/>
              </torsional>
            </friction>
            <bounce/>
          </surface>
          <max_contacts>10</max_contacts>
        </collision>
        <visual name='R2Wheel_visual'>
          <pose>-0.303263 -0.003858 0.001087 0 -0 0</pose>
          <material>
            <ambient>0.501961 0.501961 0.501961 1</ambient>
            <diffuse>0.501961 0.501961 0.501961 1</diffuse>
          </material>
          <geometry>
            <mesh>
              <scale>1 1 1</scale>
              <uri>model://SimBot2019/meshes/R2Wheel.STL</uri>
            </mesh>
          </geometry>
        </visual>
        <enable_wind>0</enable_wind>
        <kinematic>0</kinematic>
      </link>
      <joint name='Frame-R2Wheel' type='revolute'>
        <parent>Frame</parent>
        <child>R2Wheel</child>
        <pose>0 4.4e-05 -7e-06 0 -0 0</pose>
        <axis>
          <xyz>-1 0 0</xyz>
          <dynamics>
            <damping>1</damping>
            <friction>1</friction>
            <spring_reference>0</spring_reference>
            <spring_stiffness>0</spring_stiffness>
          </dynamics>
          <limit>
            <effort>50</effort>
            <lower>-1e+16</lower>
            <upper>1e+16</upper>
          </limit>
        </axis>
      </joint>
      <link name='R3Wheel'>
        <gravity>1</gravity>
        <self_collide>0</self_collide>
        <pose>-0.139701 0.303199 0.001695 -1.5708 0 1.5708</pose>
        <must_be_base_link>0</must_be_base_link>
        <velocity_decay>
          <linear>0</linear>
          <angular>0.002</angular>
        </velocity_decay>
        <inertial>
          <mass>0.255325</mass>
          <pose>0 0 0 0 -0 0</pose>
          <inertia>
            <ixx>1</ixx>
            <ixy>0</ixy>
            <ixz>0</ixz>
            <iyy>1</iyy>
            <iyz>0</iyz>
            <izz>1</izz>
          </inertia>
        </inertial>
        <collision name='R3Wheel_collision'>
          <pose>-0.303199 0.001695 0.266699 0 -0 0</pose>
          <geometry>
            <mesh>
              <scale>1 1 1</scale>
              <uri>model://SimBot2019/meshes/R3Wheel.STL</uri>
            </mesh>
          </geometry>
          <surface>
            <contact>
              <ode>
                <kp>1e+07</kp>
                <kd>25</kd>
              </ode>
            </contact>
            <friction>
              <ode>
                <mu>1</mu>
                <mu2>1</mu2>
              </ode>
              <torsional>
                <ode/>
              </torsional>
            </friction>
            <bounce/>
          </surface>
          <max_contacts>10</max_contacts>
        </collision>
        <visual name='R3Wheel_visual'>
          <pose>-0.303199 0.001695 0.266699 0 -0 0</pose>
          <material>
            <ambient>0.501961 0.501961 0.501961 1</ambient>
            <diffuse>0.501961 0.501961 0.501961 1</diffuse>
          </material>
          <geometry>
            <mesh>
              <scale>1 1 1</scale>
              <uri>model://SimBot2019/meshes/R3Wheel.STL</uri>
            </mesh>
          </geometry>
        </visual>
        <enable_wind>0</enable_wind>
        <kinematic>0</kinematic>
      </link>
      <joint name='Frame-R3Wheel' type='revolute'>
        <parent>Frame</parent>
        <child>R3Wheel</child>
        <pose>0 4.4e-05 4e-06 0 -0 0</pose>
        <axis>
          <xyz>-1 0 0</xyz>
          <dynamics>
            <damping>1</damping>
            <friction>1</friction>
            <spring_reference>0</spring_reference>
            <spring_stiffness>0</spring_stiffness>
          </dynamics>
          <limit>
            <effort>50</effort>
            <lower>-1e+16</lower>
            <upper>1e+16</upper>
          </limit>
        </axis>
      </joint>
      <link name='L1Wheel'>
        <gravity>1</gravity>
        <self_collide>0</self_collide>
        <pose>-0.673097 -0.303263 0.001695 -1.5708 0 1.5708</pose>
        <must_be_base_link>0</must_be_base_link>
        <velocity_decay>
          <linear>0</linear>
          <angular>0.002</angular>
        </velocity_decay>
        <inertial>
          <mass>0.255325</mass>
          <pose>0 0 0 0 -0 0</pose>
          <inertia>
            <ixx>1</ixx>
            <ixy>0</ixy>
            <ixz>0</ixz>
            <iyy>1</iyy>
            <iyz>0</iyz>
            <izz>1</izz>
          </inertia>
        </inertial>
        <collision name='L1Wheel_collision'>
          <pose>0.303263 0.001695 -0.266697 0 -0 0</pose>
          <geometry>
            <mesh>
              <scale>1 1 1</scale>
              <uri>model://SimBot2019/meshes/L1Wheel.STL</uri>
            </mesh>
          </geometry>
          <surface>
            <contact>
              <ode>
                <kp>1e+07</kp>
                <kd>25</kd>
              </ode>
            </contact>
            <friction>
              <ode>
                <mu>1</mu>
                <mu2>1</mu2>
              </ode>
              <torsional>
                <ode/>
              </torsional>
            </friction>
            <bounce/>
          </surface>
          <max_contacts>10</max_contacts>
        </collision>
        <visual name='L1Wheel_visual'>
          <pose>0.303263 0.001695 -0.266697 0 -0 0</pose>
          <material>
            <ambient>0.501961 0.501961 0.501961 1</ambient>
            <diffuse>0.501961 0.501961 0.501961 1</diffuse>
          </material>
          <geometry>
            <mesh>
              <scale>1 1 1</scale>
              <uri>model://SimBot2019/meshes/L1Wheel.STL</uri>
            </mesh>
          </geometry>
        </visual>
        <enable_wind>0</enable_wind>
        <kinematic>0</kinematic>
      </link>
      <joint name='Frame-L1Wheel' type='revolute'>
        <parent>Frame</parent>
        <child>L1Wheel</child>
        <pose>0 4.4e-05 -1e-06 0 -0 0</pose>
        <axis>
          <xyz>-1 0 0</xyz>
          <dynamics>
            <damping>1</damping>
            <friction>1</friction>
            <spring_reference>0</spring_reference>
            <spring_stiffness>0</spring_stiffness>
          </dynamics>
          <limit>
            <effort>50</effort>
            <lower>-1e+16</lower>
            <upper>1e+16</upper>
          </limit>
        </axis>
      </joint>
      <link name='L2Wheel'>
        <gravity>1</gravity>
        <self_collide>0</self_collide>
        <pose>-0.406431 -0.303369 -0.003683 -1.5708 0 1.5708</pose>
        <must_be_base_link>0</must_be_base_link>
        <velocity_decay>
          <linear>0</linear>
          <angular>0.002</angular>
        </velocity_decay>
        <inertial>
          <mass>0.255325</mass>
          <pose>0 0 0 0 -0 0</pose>
          <inertia>
            <ixx>1</ixx>
            <ixy>0</ixy>
            <ixz>0</ixz>
            <iyy>1</iyy>
            <iyz>0</iyz>
            <izz>1</izz>
          </inertia>
        </inertial>
        <collision name='L2Wheel_collision'>
          <pose>0.303369 -0.003683 -3.1e-05 0 -0 0</pose>
          <geometry>
            <mesh>
              <scale>1 1 1</scale>
              <uri>model://SimBot2019/meshes/L2Wheel.STL</uri>
            </mesh>
          </geometry>
          <surface>
            <contact>
              <ode>
                <kp>1e+07</kp>
                <kd>25</kd>
              </ode>
            </contact>
            <friction>
              <ode>
                <mu>1</mu>
                <mu2>1</mu2>
              </ode>
              <torsional>
                <ode/>
              </torsional>
            </friction>
            <bounce/>
          </surface>
          <max_contacts>10</max_contacts>
        </collision>
        <visual name='L2Wheel_visual'>
          <pose>0.303369 -0.003683 -3.1e-05 0 -0 0</pose>
          <material>
            <ambient>0.501961 0.501961 0.501961 1</ambient>
            <diffuse>0.501961 0.501961 0.501961 1</diffuse>
          </material>
          <geometry>
            <mesh>
              <scale>1 1 1</scale>
              <uri>model://SimBot2019/meshes/L2Wheel.STL</uri>
            </mesh>
          </geometry>
        </visual>
        <enable_wind>0</enable_wind>
        <kinematic>0</kinematic>
      </link>
      <joint name='Frame-L2Wheel' type='revolute'>
        <parent>Frame</parent>
        <child>L2Wheel</child>
        <pose>0 4.1e-05 1.7e-05 0 -0 0</pose>
        <axis>
          <xyz>-1 0 0</xyz>
          <dynamics>
            <damping>1</damping>
            <friction>1</friction>
            <spring_reference>0</spring_reference>
            <spring_stiffness>0</spring_stiffness>
          </dynamics>
          <limit>
            <effort>50</effort>
            <lower>-1e+16</lower>
            <upper>1e+16</upper>
          </limit>
        </axis>
      </joint>
      <link name='L3Wheel'>
        <gravity>1</gravity>
        <self_collide>0</self_collide>
        <pose>-0.139685 -0.303263 0.001691 -1.5708 0 1.5708</pose>
        <must_be_base_link>0</must_be_base_link>
        <velocity_decay>
          <linear>0</linear>
          <angular>0.002</angular>
        </velocity_decay>
        <inertial>
          <mass>0.255325</mass>
          <pose>0 0 0 0 -0 0</pose>
          <inertia>
            <ixx>1</ixx>
            <ixy>0</ixy>
            <ixz>0</ixz>
            <iyy>1</iyy>
            <iyz>0</iyz>
            <izz>1</izz>
          </inertia>
        </inertial>
        <collision name='L3Wheel_collision'>
          <pose>0.303263 0.001691 0.266715 0 -0 0</pose>
          <geometry>
            <mesh>
              <scale>1 1 1</scale>
              <uri>model://SimBot2019/meshes/L3Wheel.STL</uri>
            </mesh>
          </geometry>
          <surface>
            <contact>
              <ode>
                <kp>1e+07</kp>
                <kd>25</kd>
              </ode>
            </contact>
            <friction>
              <ode>
                <mu>1</mu>
                <mu2>1</mu2>
              </ode>
              <torsional>
                <ode/>
              </torsional>
            </friction>
            <bounce/>
          </surface>
          <max_contacts>10</max_contacts>
        </collision>
        <visual name='L3Wheel_visual'>
          <pose>0.303263 0.001691 0.266715 0 -0 0</pose>
          <material>
            <ambient>0.501961 0.501961 0.501961 1</ambient>
            <diffuse>0.501961 0.501961 0.501961 1</diffuse>
          </material>
          <geometry>
            <mesh>
              <scale>1 1 1</scale>
              <uri>model://SimBot2019/meshes/L3Wheel.STL</uri>
            </mesh>
          </geometry>
        </visual>
        <enable_wind>0</enable_wind>
        <kinematic>0</kinematic>
      </link>
      <joint name='Frame-L3Wheel' type='revolute'>
        <parent>Frame</parent>
        <child>L3Wheel</child>
        <pose>0 4e-05 2e-05 0 -0 0</pose>
        <axis>
          <xyz>-1 0 0</xyz>
          <dynamics>
            <damping>1</damping>
            <friction>1</friction>
            <spring_reference>0</spring_reference>
            <spring_stiffness>0</spring_stiffness>
          </dynamics>
          <limit>
            <effort>50</effort>
            <lower>-1e+16</lower>
            <upper>1e+16</upper>
          </limit>
        </axis>
      </joint>
      <link name='Bumpers'>
        <gravity>1</gravity>
        <self_collide>0</self_collide>
        <pose>-0.4 0.021 0 -1.5708 0 1.5708</pose>
        <must_be_base_link>0</must_be_base_link>
        <velocity_decay>
          <linear>0</linear>
          <angular>0</angular>
        </velocity_decay>
        <inertial>
          <mass>0.413208</mass>
          <pose>0 0 0 0 -0 0</pose>
          <inertia>
            <ixx>1</ixx>
            <ixy>0</ixy>
            <ixz>0</ixz>
            <iyy>1</iyy>
            <iyz>0</iyz>
            <izz>1</izz>
          </inertia>
        </inertial>
        <collision name='Bumpers_collision'>
          <pose>-0.02 -0.02 -0.003185 0 -0 0</pose>
          <geometry>
            <mesh>
              <scale>1 1 1</scale>
              <uri>model://SimBot2019/meshes/Bumpers.STL</uri>
            </mesh>
          </geometry>
          <surface>
            <contact>
              <ode>
                <kp>1e+07</kp>
                <kd>25</kd>
              </ode>
            </contact>
            <friction>
              <ode>
                <mu>0.1</mu>
                <mu2>0.1</mu2>
              </ode>
              <torsional>
                <ode/>
              </torsional>
            </friction>
            <bounce/>
          </surface>
          <max_contacts>10</max_contacts>
        </collision>
        <visual name='Bumpers_visual'>
          <pose>-0.02 -0.02 -0.003185 0 -0 0</pose>
          <material>
            <ambient>1 0 0 1</ambient>
            <diffuse>1 0 0 1</diffuse>
          </material>
          <geometry>
            <mesh>
              <scale>1 1 1</scale>
              <uri>model://SimBot2019/meshes/Bumpers.STL</uri>
            </mesh>
          </geometry>
        </visual>
        <enable_wind>0</enable_wind>
        <kinematic>0</kinematic>
      </link>
      <joint name='Frame-Bumpers' type='fixed'>
        <parent>Frame</parent>
        <child>Bumpers</child>
        <pose>0.1905 -0 0.377815 0 -0 0</pose>
      </joint>
      <plugin name='clock' filename='sim_clock.dll'>
        <topic>~/gazebo/frc/simulator/clock</topic>
      </plugin>
      <plugin name='Body_gyro' filename='sim_gyro.dll'>
        <link>Frame</link>
        <topic>~/gazebo/frc/simulator/gyro/0</topic>
        <units>degrees</units>
        <axis>yaw</axis>
      </plugin>
      <plugin name='Frame-R1Wheel_motor' filename='sim_motor.dll'>
        <joint>Frame-R1Wheel</joint>
        <topic>~/gazebo/frc/simulator/motor/1</topic>
        <multiplier>30</multiplier>
      </plugin>
      <plugin name='Frame-R2Wheel_motor' filename='sim_motor.dll'>
        <joint>Frame-R2Wheel</joint>
        <topic>~/gazebo/frc/simulator/motor/1</topic>
        <multiplier>30</multiplier>
      </plugin>
      <plugin name='Frame-R3Wheel_motor' filename='sim_motor.dll'>
        <joint>Frame-R3Wheel</joint>
        <topic>~/gazebo/frc/simulator/motor/1</topic>
        <multiplier>30</multiplier>
      </plugin>
      <plugin name='Body-RightWheel_encoder' filename='sim_encoder.dll'>
        <joint>Frame-R2Wheel</joint>
        <topic>~/gazebo/frc/simulator/encoder/1</topic>
        <units>degrees</units>
      </plugin>
      <plugin name='Frame-L1Wheel_motor' filename='sim_motor.dll'>
        <joint>Frame-L1Wheel</joint>
        <topic>~/gazebo/frc/simulator/motor/2</topic>
        <multiplier>30</multiplier>
      </plugin>
      <plugin name='Frame-L2Wheel_motor' filename='sim_motor.dll'>
        <joint>Frame-L2Wheel</joint>
        <topic>~/gazebo/frc/simulator/motor/2</topic>
        <multiplier>30</multiplier>
      </plugin>
      <plugin name='Frame-L3Wheel_motor' filename='sim_motor.dll'>
        <joint>Frame-L3Wheel</joint>
        <topic>~/gazebo/frc/simulator/motor/2</topic>
        <multiplier>30</multiplier>
      </plugin>
      <plugin name='Body-LeftWheel_encoder' filename='sim_encoder.dll'>
        <joint>Frame-L2Wheel</joint>
        <topic>~/gazebo/frc/simulator/encoder/2</topic>
        <units>degrees</units>
      </plugin>
      <frame name='PegClimber::__model__' attached_to='PegClimber::FramePlate'>
        <pose relative_to='__model__'>-0.534 0.3 0.02 0 -0 0</pose>
      </frame>
      <link name='PegClimber::FramePlate'>
        <gravity>1</gravity>
        <self_collide>0</self_collide>
        <pose relative_to='PegClimber::__model__'>0 -0 0.005 0 -0 0</pose>
        <must_be_base_link>1</must_be_base_link>
        <velocity_decay>
          <linear>0</linear>
          <angular>0</angular>
        </velocity_decay>
        <inertial>
          <mass>0.0424596</mass>
          <pose>0 0 0 0 -0 0</pose>
          <inertia>
            <ixx>0</ixx>
            <ixy>0</ixy>
            <ixz>0</ixz>
            <iyy>0</iyy>
            <iyz>0</iyz>
            <izz>0</izz>
          </inertia>
        </inertial>
        <collision name='FramePlate_collision'>
          <pose>-0.012125 -0.032122 -0.043458 0 -0 0</pose>
          <geometry>
            <mesh>
              <scale>1 1 1</scale>
              <uri>model://PegClimber/meshes/FramePlate_col.STL</uri>
            </mesh>
          </geometry>
          <surface>
            <contact>
              <ode/>
            </contact>
            <friction>
              <ode>
                <mu>0</mu>
                <mu2>0</mu2>
              </ode>
              <torsional>
                <ode/>
              </torsional>
            </friction>
            <bounce/>
          </surface>
          <max_contacts>10</max_contacts>
        </collision>
        <visual name='FramePlate_visual'>
          <pose>-0.012125 -0.032122 -0.043458 0 -0 0</pose>
          <material>
            <ambient>0.752941 0.752941 0.752941 1</ambient>
            <diffuse>0.752941 0.752941 0.752941 1</diffuse>
          </material>
          <geometry>
            <mesh>
              <scale>1 1 1</scale>
              <uri>model://PegClimber/meshes/FramePlate.STL</uri>
            </mesh>
          </geometry>
        </visual>
        <enable_wind>0</enable_wind>
        <kinematic>0</kinematic>
      </link>
      <link name='PegClimber::PegPiston'>
        <gravity>1</gravity>
        <self_collide>0</self_collide>
        <pose relative_to='PegClimber::__model__'>0.000379 0.000346 0.099505 0 -0 0</pose>
        <must_be_base_link>0</must_be_base_link>
        <velocity_decay>
          <linear>0</linear>
          <angular>0</angular>
        </velocity_decay>
        <inertial>
          <mass>0.438198</mass>
          <pose>0 0 0 0 -0 0</pose>
          <inertia>
            <ixx>0</ixx>
            <ixy>0</ixy>
            <ixz>0</ixz>
            <iyy>0</iyy>
            <iyz>0</iyz>
            <izz>0</izz>
          </inertia>
        </inertial>
        <collision name='PegPiston_collision'>
          <pose>-0.012504 -0.032468 -0.137963 0 -0 0</pose>
          <geometry>
            <mesh>
              <scale>1 1 1</scale>
              <uri>model://PegClimber/meshes/Piston_col.STL</uri>
            </mesh>
          </geometry>
          <surface>
            <contact>
              <ode/>
            </contact>
            <friction>
              <ode>
                <mu>0</mu>
                <mu2>0</mu2>
              </ode>
              <torsional>
                <ode/>
              </torsional>
            </friction>
            <bounce/>
          </surface>
          <max_contacts>10</max_contacts>
        </collision>
        <visual name='PegPiston_visual'>
          <pose>-0.012504 -0.032468 -0.137963 0 -0 0</pose>
          <material>
            <ambient>0.25098 0.501961 0.501961 1</ambient>
            <diffuse>0.25098 0.501961 0.501961 1</diffuse>
          </material>
          <geometry>
            <mesh>
              <scale>1 1 1</scale>
              <uri>model://PegClimber/meshes/Piston.STL</uri>
            </mesh>
          </geometry>
        </visual>
        <enable_wind>0</enable_wind>
        <kinematic>0</kinematic>
      </link>
      <joint name='PegClimber::FramePlate-PegPiston' type='prismatic'>
        <parent>PegClimber::FramePlate</parent>
        <child>PegClimber::PegPiston</child>
        <pose>-0.000379 -0.000346 0 0 -0 0</pose>
        <axis>
          <xyz>0 0 -1</xyz>
          <dynamics>
            <damping>1</damping>
            <friction>1</friction>
            <spring_reference>0</spring_reference>
            <spring_stiffness>0</spring_stiffness>
          </dynamics>
          <limit>
            <upper>0.15</upper>
            <lower>0</lower>
            <effort>500</effort>
          </limit>
        </axis>
      </joint>
      <plugin name='Frame-FrontClimber_motor' filename='sim_piston.dll'>
        <joint>PegClimber::FramePlate-PegPiston</joint>
        <topic>~/gazebo/frc/simulator/piston/4</topic>
        <forward-force>400</forward-force>
        <reverse-force>400</reverse-force>
      </plugin>
      <joint name='Frame-FrontLeg1' type='fixed'>
        <parent>Frame</parent>
        <child>PegClimber::FramePlate</child>
      </joint>
      <frame name='PegClimber1::__model__' attached_to='PegClimber1::FramePlate'>
        <pose relative_to='__model__'>-0.534 -0.291 0.02 0 -0 0</pose>
      </frame>
      <link name='PegClimber1::FramePlate'>
        <gravity>1</gravity>
        <self_collide>0</self_collide>
        <pose relative_to='PegClimber1::__model__'>0 -0 0.005 0 -0 0</pose>
        <must_be_base_link>1</must_be_base_link>
        <velocity_decay>
          <linear>0</linear>
          <angular>0</angular>
        </velocity_decay>
        <inertial>
          <mass>0.0424596</mass>
          <pose>0 0 0 0 -0 0</pose>
          <inertia>
            <ixx>0</ixx>
            <ixy>0</ixy>
            <ixz>0</ixz>
            <iyy>0</iyy>
            <iyz>0</iyz>
            <izz>0</izz>
          </inertia>
        </inertial>
        <collision name='FramePlate_collision'>
          <pose>-0.012125 -0.032122 -0.043458 0 -0 0</pose>
          <geometry>
            <mesh>
              <scale>1 1 1</scale>
              <uri>model://PegClimber/meshes/FramePlate_col.STL</uri>
            </mesh>
          </geometry>
          <surface>
            <contact>
              <ode/>
            </contact>
            <friction>
              <ode>
                <mu>0</mu>
                <mu2>0</mu2>
              </ode>
              <torsional>
                <ode/>
              </torsional>
            </friction>
            <bounce/>
          </surface>
          <max_contacts>10</max_contacts>
        </collision>
        <visual name='FramePlate_visual'>
          <pose>-0.012125 -0.032122 -0.043458 0 -0 0</pose>
          <material>
            <ambient>0.752941 0.752941 0.752941 1</ambient>
            <diffuse>0.752941 0.752941 0.752941 1</diffuse>
          </material>
          <geometry>
            <mesh>
              <scale>1 1 1</scale>
              <uri>model://PegClimber/meshes/FramePlate.STL</uri>
            </mesh>
          </geometry>
        </visual>
        <enable_wind>0</enable_wind>
        <kinematic>0</kinematic>
      </link>
      <link name='PegClimber1::PegPiston'>
        <gravity>1</gravity>
        <self_collide>0</self_collide>
        <pose relative_to='PegClimber1::__model__'>0.000379 0.000346 0.099505 0 -0 0</pose>
        <must_be_base_link>0</must_be_base_link>
        <velocity_decay>
          <linear>0</linear>
          <angular>0</angular>
        </velocity_decay>
        <inertial>
          <mass>0.438198</mass>
          <pose>0 0 0 0 -0 0</pose>
          <inertia>
            <ixx>0</ixx>
            <ixy>0</ixy>
            <ixz>0</ixz>
            <iyy>0</iyy>
            <iyz>0</iyz>
            <izz>0</izz>
          </inertia>
        </inertial>
        <collision name='PegPiston_collision'>
          <pose>-0.012504 -0.032468 -0.137963 0 -0 0</pose>
          <geometry>
            <mesh>
              <scale>1 1 1</scale>
              <uri>model://PegClimber/meshes/Piston_col.STL</uri>
            </mesh>
          </geometry>
          <surface>
            <contact>
              <ode/>
            </contact>
            <friction>
              <ode>
                <mu>0</mu>
                <mu2>0</mu2>
              </ode>
              <torsional>
                <ode/>
              </torsional>
            </friction>
            <bounce/>
          </surface>
          <max_contacts>10</max_contacts>
        </collision>
        <visual name='PegPiston_visual'>
          <pose>-0.012504 -0.032468 -0.137963 0 -0 0</pose>
          <material>
            <ambient>0.25098 0.501961 0.501961 1</ambient>
            <diffuse>0.25098 0.501961 0.501961 1</diffuse>
          </material>
          <geometry>
            <mesh>
              <scale>1 1 1</scale>
              <uri>model://PegClimber/meshes/Piston.STL</uri>
            </mesh>
          </geometry>
        </visual>
        <enable_wind>0</enable_wind>
        <kinematic>0</kinematic>
      </link>
      <joint name='PegClimber1::FramePlate-PegPiston' type='prismatic'>
        <parent>PegClimber1::FramePlate</parent>
        <child>PegClimber1::PegPiston</child>
        <pose>-0.000379 -0.000346 0 0 -0 0</pose>
        <axis>
          <xyz>0 0 -1</xyz>
          <dynamics>
            <damping>1</damping>
            <friction>1</friction>
            <spring_reference>0</spring_reference>
            <spring_stiffness>0</spring_stiffness>
          </dynamics>
          <limit>
            <upper>0.15</upper>
            <lower>0</lower>
            <effort>500</effort>
          </limit>
        </axis>
      </joint>
      <plugin name='Frame-FrontClimber_motor' filename='sim_piston.dll'>
        <joint>PegClimber1::FramePlate-PegPiston</joint>
        <topic>~/gazebo/frc/simulator/piston/4</topic>
        <forward-force>400</forward-force>
        <reverse-force>400</reverse-force>
      </plugin>
      <joint name='Frame-FrontLeg2' type='fixed'>
        <parent>Frame</parent>
        <child>PegClimber1::FramePlate</child>
      </joint>
      <frame name='PegClimber2::__model__' attached_to='PegClimber2::FramePlate'>
        <pose relative_to='__model__'>-0.01 0 0.02 0 -0 0</pose>
      </frame>
      <link name='PegClimber2::FramePlate'>
        <gravity>1</gravity>
        <self_collide>0</self_collide>
        <pose relative_to='PegClimber2::__model__'>0 -0 0.005 0 -0 0</pose>
        <must_be_base_link>1</must_be_base_link>
        <velocity_decay>
          <linear>0</linear>
          <angular>0</angular>
        </velocity_decay>
        <inertial>
          <mass>0.0424596</mass>
          <pose>0 0 0 0 -0 0</pose>
          <inertia>
            <ixx>0</ixx>
            <ixy>0</ixy>
            <ixz>0</ixz>
            <iyy>0</iyy>
            <iyz>0</iyz>
            <izz>0</izz>
          </inertia>
        </inertial>
        <collision name='FramePlate_collision'>
          <pose>-0.012125 -0.032122 -0.043458 0 -0 0</pose>
          <geometry>
            <mesh>
              <scale>1 1 1</scale>
              <uri>model://PegClimber2/meshes/FramePlate_col.STL</uri>
            </mesh>
          </geometry>
          <surface>
            <contact>
              <ode/>
            </contact>
            <friction>
              <ode>
                <mu>0</mu>
                <mu2>0</mu2>
              </ode>
              <torsional>
                <ode/>
              </torsional>
            </friction>
            <bounce/>
          </surface>
          <max_contacts>10</max_contacts>
        </collision>
        <visual name='FramePlate_visual'>
          <pose>-0.012125 -0.032122 -0.043458 0 -0 0</pose>
          <material>
            <ambient>0.752941 0.752941 0.752941 1</ambient>
            <diffuse>0.752941 0.752941 0.752941 1</diffuse>
          </material>
          <geometry>
            <mesh>
              <scale>1 1 1</scale>
              <uri>model://PegClimber2/meshes/FramePlate.STL</uri>
            </mesh>
          </geometry>
        </visual>
        <enable_wind>0</enable_wind>
        <kinematic>0</kinematic>
      </link>
      <link name='PegClimber2::PegPiston2'>
        <gravity>1</gravity>
        <self_collide>0</self_collide>
        <pose relative_to='PegClimber2::__model__'>0.000379 0.000346 0.099505 0 -0 0</pose>
        <must_be_base_link>0</must_be_base_link>
        <velocity_decay>
          <linear>0</linear>
          <angular>0</angular>
        </velocity_decay>
        <inertial>
          <mass>0.438198</mass>
          <pose>0 0 0 0 -0 0</pose>
          <inertia>
            <ixx>0</ixx>
            <ixy>0</ixy>
            <ixz>0</ixz>
            <iyy>0</iyy>
            <iyz>0</iyz>
            <izz>0</izz>
          </inertia>
        </inertial>
        <collision name='Piston_collision'>
          <pose>-0.012504 -0.032468 -0.137963 0 -0 0</pose>
          <geometry>
            <mesh>
              <scale>1 1 1</scale>
              <uri>model://PegClimber2/meshes/Piston_col.STL</uri>
            </mesh>
          </geometry>
          <surface>
            <contact>
              <ode/>
            </contact>
            <friction>
              <ode>
                <mu>0</mu>
                <mu2>0</mu2>
              </ode>
              <torsional>
                <ode/>
              </torsional>
            </friction>
            <bounce/>
          </surface>
          <max_contacts>10</max_contacts>
        </collision>
        <visual name='Piston_visual'>
          <pose>-0.012504 -0.032468 -0.137963 0 -0 0</pose>
          <material>
            <ambient>0.25098 0.501961 0.501961 1</ambient>
            <diffuse>0.25098 0.501961 0.501961 1</diffuse>
          </material>
          <geometry>
            <mesh>
              <scale>1 1 1</scale>
              <uri>model://PegClimber2/meshes/Piston.STL</uri>
            </mesh>
          </geometry>
        </visual>
        <enable_wind>0</enable_wind>
        <kinematic>0</kinematic>
      </link>
      <joint name='PegClimber2::FramePlate-PegPiston2' type='prismatic'>
        <parent>PegClimber2::FramePlate</parent>
        <child>PegClimber2::PegPiston2</child>
        <pose>-0.000379 -0.000346 0 0 -0 0</pose>
        <axis>
          <xyz>0 0 -1</xyz>
          <dynamics>
            <damping>1</damping>
            <friction>1</friction>
            <spring_reference>0</spring_reference>
            <spring_stiffness>0</spring_stiffness>
          </dynamics>
          <limit>
            <upper>0.2</upper>
            <lower>0</lower>
          </limit>
        </axis>
      </joint>
      <plugin name='Frame-FrontClimber_motor' filename='sim_piston.dll'>
        <joint>PegClimber2::FramePlate-PegPiston2</joint>
        <topic>~/gazebo/frc/simulator/piston/5</topic>
        <forward-force>600</forward-force>
        <reverse-force>600</reverse-force>
      </plugin>
      <joint name='Frame-BackLeg' type='fixed'>
        <parent>Frame</parent>
        <child>PegClimber2::FramePlate</child>
      </joint>
      <model name='Elevator'>
        <pose>-0.66 -0.265 0.03 3.14159 -0.003567 3.14159</pose>
        <link name='FrameBase'>
          <gravity>1</gravity>
          <self_collide>0</self_collide>
          <pose>-0.069233 0.266711 -0.01355 -1.5708 0 0</pose>
          <must_be_base_link>0</must_be_base_link>
          <velocity_decay>
            <linear>0</linear>
            <angular>0</angular>
          </velocity_decay>
          <inertial>
            <mass>0.967597</mass>
            <pose>0 0 0 0 -0 0</pose>
            <inertia>
              <ixx>0.00430893</ixx>
              <ixy>8.21392e-06</ixy>
              <ixz>2.89565e-07</ixz>
              <iyy>0.0187849</iyy>
              <iyz>1.69755e-08</iyz>
              <izz>0.0144998</izz>
            </inertia>
          </inertial>
          <collision name='FrameBase_collision'>
            <pose>0.031133 -0.00085 -1.1e-05 0 -0 0</pose>
            <geometry>
              <mesh>
                <scale>1 1 1</scale>
                <uri>model://Elevator/meshes/FrameBase_col.STL</uri>
              </mesh>
            </geometry>
            <surface>
              <contact>
                <ode>
                  <max_vel>0</max_vel>
                </ode>
              </contact>
              <friction>
                <ode>
                  <mu>0</mu>
                  <mu2>0</mu2>
                </ode>
                <torsional>
                  <ode/>
                </torsional>
              </friction>
              <bounce/>
            </surface>
            <max_contacts>10</max_contacts>
          </collision>
          <visual name='FrameBase_visual'>
            <pose>0.031133 -0.00085 -1.1e-05 0 -0 0</pose>
            <material>
              <ambient>0.701961 0.701961 0.701961 1</ambient>
              <diffuse>0.501961 0.501961 0.501961 1</diffuse>
            </material>
            <geometry>
              <mesh>
                <scale>1 1 1</scale>
                <uri>model://Elevator/meshes/FrameBase.STL</uri>
              </mesh>
            </geometry>
          </visual>
          <enable_wind>0</enable_wind>
          <kinematic>0</kinematic>
        </link>
        <link name='ElevatorBase'>
          <gravity>1</gravity>
          <self_collide>0</self_collide>
          <pose>-0.048922 0.266697 -0.597377 -1.5708 0 0</pose>
          <must_be_base_link>0</must_be_base_link>
          <velocity_decay>
            <linear>0</linear>
            <angular>0</angular>
          </velocity_decay>
          <inertial>
            <mass>6.13721</mass>
            <pose>0 0 0 0 -0 0</pose>
            <inertia>
              <ixx>0.794501</ixx>
              <ixy>0.0150648</ixy>
              <ixz>3.30956e-06</ixz>
              <iyy>0.25856</iyy>
              <iyz>4.88227e-05</iyz>
              <izz>0.542914</izz>
            </inertia>
          </inertial>
          <collision name='ElevatorBase_collision'>
            <pose>0.010822 -0.584677 3e-06 0 -0 0</pose>
            <geometry>
              <mesh>
                <scale>1 1 1</scale>
                <uri>model://Elevator/meshes/ElevatorBase_col.STL</uri>
              </mesh>
            </geometry>
            <surface>
              <contact>
                <ode>
                  <max_vel>0</max_vel>
                </ode>
              </contact>
              <friction>
                <ode>
                  <mu>0</mu>
                  <mu2>0</mu2>
                </ode>
                <torsional>
                  <ode/>
                </torsional>
              </friction>
              <bounce/>
            </surface>
            <max_contacts>10</max_contacts>
          </collision>
          <visual name='ElevatorBase_visual'>
            <pose>0.010822 -0.584677 3e-06 0 -0 0</pose>
            <material>
              <ambient>0.701961 0.701961 0.701961 1</ambient>
              <diffuse>0.501961 0.501961 0.501961 1</diffuse>
            </material>
            <geometry>
              <mesh>
                <scale>1 1 1</scale>
                <uri>model://Elevator/meshes/ElevatorBase.STL</uri>
              </mesh>
            </geometry>
          </visual>
          <enable_wind>0</enable_wind>
          <kinematic>0</kinematic>
        </link>
        <joint name='FrameBase-ElevatorBase' type='revolute'>
          <parent>FrameBase</parent>
          <child>ElevatorBase</child>
          <pose>-0.039673 -0.568802 0 0 -0 0</pose>
          <axis>
            <xyz>0 0 1</xyz>
            <dynamics>
              <damping>1</damping>
              <friction>1</friction>
              <spring_reference>0</spring_reference>
              <spring_stiffness>0</spring_stiffness>
            </dynamics>
            <limit>
              <upper>0.6</upper>
              <lower>0</lower>
            </limit>
          </axis>
        </joint>
        <link name='Stage1'>
          <gravity>1</gravity>
          <self_collide>0</self_collide>
          <pose>-0.044951 0.268157 -0.614138 -1.5708 0 0</pose>
          <must_be_base_link>0</must_be_base_link>
          <velocity_decay>
            <linear>0</linear>
            <angular>0</angular>
          </velocity_decay>
          <inertial>
            <mass>5.14333</mass>
            <pose>0 0 0 0 -0 0</pose>
            <inertia>
              <ixx>0.481772</ixx>
              <ixy>0.0174063</ixy>
              <ixz>0.00037574</ixz>
              <iyy>0.106616</iyy>
              <iyz>0.00366235</iyz>
              <izz>0.379693</izz>
            </inertia>
          </inertial>
          <collision name='Stage1_collision'>
            <pose>0.006851 -0.601438 -0.001457 0 -0 0</pose>
            <geometry>
              <mesh>
                <scale>1 1 1</scale>
                <uri>model://Elevator/meshes/Stage1_col.STL</uri>
              </mesh>
            </geometry>
            <surface>
              <contact>
                <ode>
                  <max_vel>0</max_vel>
                </ode>
              </contact>
              <friction>
                <ode>
                  <mu>1</mu>
                  <mu2>1</mu2>
                </ode>
                <torsional>
                  <ode/>
                </torsional>
              </friction>
              <bounce/>
            </surface>
            <max_contacts>10</max_contacts>
          </collision>
          <visual name='Stage1_visual'>
            <pose>0.006851 -0.601438 -0.001457 0 -0 0</pose>
            <material>
              <ambient>0.701961 0.701961 0.701961 1</ambient>
              <diffuse>0.501961 0.501961 0.501961 1</diffuse>
            </material>
            <geometry>
              <mesh>
                <scale>1 1 1</scale>
                <uri>model://Elevator/meshes/Stage1.STL</uri>
              </mesh>
            </geometry>
          </visual>
          <enable_wind>0</enable_wind>
          <kinematic>0</kinematic>
        </link>
        <joint name='ElevatorBase-Stage1' type='prismatic'>
          <parent>ElevatorBase</parent>
          <child>Stage1</child>
          <pose>0.006851 -0 0.230369 0 -0 -1.5708</pose>
          <axis>
            <xyz>-1 0 0</xyz>
            <dynamics>
              <damping>40</damping>
              <friction>1</friction>
              <spring_reference>0</spring_reference>
              <spring_stiffness>0</spring_stiffness>
            </dynamics>
            <limit>
              <upper>0.85</upper>
              <lower>0</lower>
              <effort>500</effort>
            </limit>
          </axis>
        </joint>
        <link name='Stage2'>
          <gravity>1</gravity>
          <self_collide>0</self_collide>
          <pose>-0.0381 0.266705 -0.630865 -1.5708 0 0</pose>
          <must_be_base_link>0</must_be_base_link>
          <velocity_decay>
            <linear>0</linear>
            <angular>0</angular>
          </velocity_decay>
          <inertial>
            <mass>4.28523</mass>
            <pose>0 0 0 0 -0 0</pose>
            <inertia>
              <ixx>0.17601</ixx>
              <ixy>2.36116e-09</ixy>
              <ixz>5.79863e-13</ixz>
              <iyy>0.0234279</iyy>
              <iyz>9.4653e-06</iyz>
              <izz>0.152582</izz>
            </inertia>
          </inertial>
          <collision name='Stage2_collision'>
            <pose>0 -0.618165 -5e-06 0 -0 0</pose>
            <geometry>
              <mesh>
                <scale>1 1 1</scale>
                <uri>model://Elevator/meshes/Stage2_col.STL</uri>
              </mesh>
            </geometry>
            <surface>
              <contact>
                <ode>
                  <max_vel>0</max_vel>
                </ode>
              </contact>
              <friction>
                <ode>
                  <mu>1</mu>
                  <mu2>1</mu2>
                </ode>
                <torsional>
                  <ode/>
                </torsional>
              </friction>
              <bounce/>
            </surface>
            <max_contacts>10</max_contacts>
          </collision>
          <visual name='Stage2_visual'>
            <pose>0 -0.618165 -5e-06 0 -0 0</pose>
            <material>
              <ambient>0.701961 0.701961 0.701961 1</ambient>
              <diffuse>0.501961 0.501961 0.501961 1</diffuse>
            </material>
            <geometry>
              <mesh>
                <scale>1 1 1</scale>
                <uri>model://Elevator/meshes/Stage2.STL</uri>
              </mesh>
            </geometry>
          </visual>
          <enable_wind>0</enable_wind>
          <kinematic>0</kinematic>
        </link>
        <joint name='Stage1-Stage2' type='prismatic'>
          <parent>Stage1</parent>
          <child>Stage2</child>
          <pose>0 -0 0.231821 0 -0 1.5708</pose>
          <axis>
            <xyz>1 0 0</xyz>
            <dynamics>
              <damping>40</damping>
              <friction>1</friction>
              <spring_reference>0</spring_reference>
              <spring_stiffness>0</spring_stiffness>
            </dynamics>
            <limit>
              <upper>0.95</upper>
              <lower>0</lower>
              <effort>200</effort>
            </limit>
          </axis>
        </joint>
        <link name='Carriage'>
          <gravity>1</gravity>
          <self_collide>0</self_collide>
          <pose>-0.0381 0.2667 -0.281063 -1.5708 0 0</pose>
          <must_be_base_link>0</must_be_base_link>
          <velocity_decay>
            <linear>0</linear>
            <angular>0</angular>
          </velocity_decay>
          <inertial>
            <mass>0.1</mass>
            <pose>0 0 0 0 -0 0</pose>
            <inertia>
              <ixx>0</ixx>
              <ixy>0</ixy>
              <ixz>0</ixz>
              <iyy>0</iyy>
              <iyz>0</iyz>
              <izz>0</izz>
            </inertia>
          </inertial>
          <collision name='Carriage_collision'>
            <pose>-0 -0.268363 -0 0 -0 0</pose>
            <geometry>
              <mesh>
                <scale>1 1 1</scale>
                <uri>model://Elevator/meshes/Carriage_col.STL</uri>
              </mesh>
            </geometry>
            <surface>
              <contact>
                <ode>
                  <max_vel>0</max_vel>
                </ode>
              </contact>
              <friction>
                <ode>
                  <mu>0</mu>
                  <mu2>0</mu2>
                </ode>
                <torsional>
                  <ode/>
                </torsional>
              </friction>
              <bounce/>
            </surface>
            <max_contacts>10</max_contacts>
          </collision>
          <visual name='Carriage_visual'>
            <pose>-0 -0.268363 -0 0 -0 0</pose>
            <material>
              <ambient>0.25098 0.501961 0.501961 1</ambient>
              <diffuse>0.25098 0.501961 0.501961 1</diffuse>
            </material>
            <geometry>
              <mesh>
                <scale>1 1 1</scale>
                <uri>model://Elevator/meshes/Carriage.STL</uri>
              </mesh>
            </geometry>
          </visual>
          <sensor name='CarriageCamera' type='camera'>
            <visualize>0</visualize>
            <always_on>1</always_on>
            <update_rate>10</update_rate>
            <pose>0.0381 0 -0 -1.57079 0.001593 -0.001593</pose>
            <camera name='Carriagecamera'>
              <horizontal_fov>1.5708</horizontal_fov>
              <image>
                <width>320</width>
                <height>240</height>
              </image>
              <clip>
                <near>0.05</near>
                <far>50</far>
              </clip>
            </camera>
            <plugin name='camera2' filename='sim_camera.dll'>
              <topic>~/gazebo/frc/simulator/camera/2</topic>
              <port>9002</port>
              <fps>20</fps>
              <enabled>1</enabled>
              <savepath>tmp</savepath>
              <maxframes>0</maxframes>
              <video>back.avi</video>
            </plugin>
          </sensor>
          <enable_wind>0</enable_wind>
          <kinematic>0</kinematic>
        </link>
        <joint name='Stage2-Carriage' type='prismatic'>
          <parent>Stage2</parent>
          <child>Carriage</child>
          <pose>-0 -0 0.231826 0 -0 1.5708</pose>
          <axis>
            <xyz>1 0 0</xyz>
            <dynamics>
              <damping>40</damping>
              <friction>1</friction>
              <spring_reference>0</spring_reference>
              <spring_stiffness>0</spring_stiffness>
            </dynamics>
            <limit>
              <upper>0.75</upper>
              <lower>0</lower>
              <effort>100</effort>
            </limit>
          </axis>
        </joint>
        <link name='TilterBaseArm'>
          <gravity>1</gravity>
          <self_collide>0</self_collide>
          <pose>-0.39609 0.261767 -0.206919 -1.5708 0 0</pose>
          <must_be_base_link>0</must_be_base_link>
          <velocity_decay>
            <linear>0</linear>
            <angular>0</angular>
          </velocity_decay>
          <inertial>
            <mass>0.414124</mass>
            <pose>0 0 0 0 -0 0</pose>
            <inertia>
              <ixx>0.0131141</ixx>
              <ixy>0.00161299</ixy>
              <ixz>0.000129718</ixz>
              <iyy>0.0131182</iyy>
              <iyz>0.000129552</iyz>
              <izz>0.00322598</izz>
            </inertia>
          </inertial>
          <collision name='TilterBaseArm_collision'>
            <pose>0.35799 -0.194219 0.004933 0 -0 0</pose>
            <geometry>
              <mesh>
                <scale>1 1 1</scale>
                <uri>model://Elevator/meshes/TilterBaseArm_col.STL</uri>
              </mesh>
            </geometry>
            <surface>
              <contact>
                <ode>
                  <max_vel>0</max_vel>
                </ode>
              </contact>
              <friction>
                <ode>
                  <mu>0</mu>
                  <mu2>0</mu2>
                </ode>
                <torsional>
                  <ode/>
                </torsional>
              </friction>
              <bounce/>
            </surface>
            <max_contacts>10</max_contacts>
          </collision>
          <visual name='TilterBaseArm_visual'>
            <pose>0.35799 -0.194219 0.004933 0 -0 0</pose>
            <material>
              <ambient>0.701961 0.701961 0.701961 1</ambient>
              <diffuse>0.501961 0.501961 0.501961 1</diffuse>
            </material>
            <geometry>
              <mesh>
                <scale>1 1 1</scale>
                <uri>model://Elevator/meshes/TilterBaseArm.STL</uri>
              </mesh>
            </geometry>
          </visual>
          <enable_wind>0</enable_wind>
          <kinematic>0</kinematic>
        </link>
        <joint name='FrameBase-TilterBaseArm' type='revolute'>
          <parent>FrameBase</parent>
          <child>TilterBaseArm</child>
          <pose>-0.18811 -0.187869 0 0 -0 0</pose>
          <axis>
            <xyz>0 0 -1</xyz>
            <dynamics>
              <damping>1</damping>
              <friction>1</friction>
              <spring_reference>0</spring_reference>
              <spring_stiffness>0</spring_stiffness>
            </dynamics>
            <limit>
              <upper>1</upper>
              <lower>-1</lower>
            </limit>
          </axis>
        </joint>
        <joint name='TilterEleArm-TilterBaseArm' type='revolute'>
          <parent>TilterEleArm</parent>
          <child>TilterBaseArm</child>
          <pose>0.063498 0.063417 -0 0 -0 0</pose>
          <axis>
            <xyz expressed_in='__model__'>0 1 0</xyz>
            <dynamics>
              <damping>1</damping>
              <friction>1</friction>
              <spring_reference>0</spring_reference>
              <spring_stiffness>0</spring_stiffness>
            </dynamics>
            <limit>
              <upper>1.25</upper>
              <lower>0</lower>
            </limit>
          </axis>
        </joint>
        <link name='TilterEleArm'>
          <gravity>1</gravity>
          <self_collide>0</self_collide>
          <pose>-0.185346 0.2667 -0.369993 -1.5708 0 0</pose>
          <must_be_base_link>0</must_be_base_link>
          <velocity_decay>
            <linear>0</linear>
            <angular>0</angular>
          </velocity_decay>
          <inertial>
            <mass>0.514276</mass>
            <pose>0 0 0 0 -0 0</pose>
            <inertia>
              <ixx>0.159756</ixx>
              <ixy>0</ixy>
              <ixz>0</ixz>
              <iyy>0.159756</iyy>
              <iyz>0</iyz>
              <izz>0</izz>
            </inertia>
          </inertial>
          <collision name='TilterEleArm_collision'>
            <pose>0.147246 -0.357293 0 0 -0 0</pose>
            <geometry>
              <mesh>
                <scale>1 1 1</scale>
                <uri>model://Elevator/meshes/TilterEleArm_col.STL</uri>
              </mesh>
            </geometry>
            <surface>
              <contact>
                <ode>
                  <max_vel>0</max_vel>
                </ode>
              </contact>
              <friction>
                <ode>
                  <mu>0</mu>
                  <mu2>0</mu2>
                </ode>
                <torsional>
                  <ode/>
                </torsional>
              </friction>
              <bounce/>
            </surface>
            <max_contacts>10</max_contacts>
          </collision>
          <visual name='TilterEleArm_visual'>
            <pose>0.147246 -0.357293 0 0 -0 0</pose>
            <material>
              <ambient>0.701961 0.701961 0.701961 1</ambient>
              <diffuse>0.501961 0.501961 0.501961 1</diffuse>
            </material>
            <geometry>
              <mesh>
                <scale>1 1 1</scale>
                <uri>model://Elevator/meshes/TilterEleArm.STL</uri>
              </mesh>
            </geometry>
          </visual>
          <enable_wind>0</enable_wind>
          <kinematic>0</kinematic>
        </link>
        <joint name='ElevatorBase-TilterEleArm' type='revolute'>
          <parent>ElevatorBase</parent>
          <child>TilterEleArm</child>
          <pose>0.147246 0.099657 0 0 -0 0</pose>
          <axis>
            <xyz>0 0 1</xyz>
            <dynamics>
              <damping>1</damping>
              <friction>1</friction>
              <spring_reference>0</spring_reference>
              <spring_stiffness>0</spring_stiffness>
            </dynamics>
            <limit>
              <upper>3</upper>
              <lower>-3</lower>
              <effort>100</effort>
            </limit>
          </axis>
        </joint>
        <plugin name='TilterEleArm-TilterBaseArm_piston' filename='sim_piston.dll'>
          <joint>TilterEleArm-TilterBaseArm</joint>
          <topic>~/gazebo/frc/simulator/piston/3</topic>
          <forward-force>50</forward-force>
          <reverse-force>50</reverse-force>
        </plugin>
        <plugin name='ElevatorBase-Stage1_motor' filename='sim_motor.dll'>
          <joint>ElevatorBase-Stage1</joint>
          <topic>~/gazebo/frc/simulator/motor/7</topic>
          <multiplier>200</multiplier>
        </plugin>
        <plugin name='ElevatorBase-Stage1_encoder' filename='sim_encoder.dll'>
          <joint>ElevatorBase-Stage1</joint>
          <topic>~/gazebo/frc/simulator/encoder/7</topic>
          <multiplier>6.28</multiplier>
        </plugin>
        <plugin name='Stage1-Stage2_motor' filename='sim_motor.dll'>
          <joint>Stage1-Stage2</joint>
          <topic>~/gazebo/frc/simulator/motor/8</topic>
          <multiplier>100</multiplier>
        </plugin>
        <plugin name='Stage1-Stage2_encoder' filename='sim_encoder.dll'>
          <joint>Stage1-Stage2</joint>
          <topic>~/gazebo/frc/simulator/encoder/8</topic>
          <multiplier>6.28</multiplier>
        </plugin>
        <plugin name='Stage2-Carriage_motor' filename='sim_motor.dll'>
          <joint>Stage2-Carriage</joint>
          <topic>~/gazebo/frc/simulator/motor/9</topic>
          <multiplier>50</multiplier>
        </plugin>
        <plugin name='Stage2-Carriage_encoder' filename='sim_encoder.dll'>
          <joint>Stage2-Carriage</joint>
          <topic>~/gazebo/frc/simulator/encoder/9</topic>
          <multiplier>6.28</multiplier>
        </plugin>
        <joint name='model1-model2' type='fixed'>
          <parent>Frame</parent>
          <child>FrameBase</child>
        </joint>
        <model name='Grabber2'>
          <pose>-0.01 0.267 -0.25 0 -0 0</pose>
          <link name='BasePlate'>
            <gravity>1</gravity>
            <self_collide>0</self_collide>
            <pose>0.03941 -0.006692 0.182263 -1.5708 -0 -1.5708</pose>
            <velocity_decay>
              <linear>0</linear>
              <angular>0</angular>
            </velocity_decay>
            <inertial>
              <mass>0.1</mass>
              <pose>0 0 0 0 -0 0</pose>
              <inertia>
                <ixx>1</ixx>
                <ixy>0</ixy>
                <ixz>0</ixz>
                <iyy>1</iyy>
                <iyz>0</iyz>
                <izz>1</izz>
              </inertia>
            </inertial>
            <collision name='BasePlate_collision'>
              <pose>-0.006692 -0.020937 -0.006811 0 -0 0</pose>
              <geometry>
                <mesh>
                  <scale>1 1 1</scale>
                  <uri>model://Grabber2/meshes/BasePlate_col.STL</uri>
                </mesh>
              </geometry>
              <surface>
                <contact>
                  <ode/>
                </contact>
                <friction>
                  <ode>
                    <mu>0</mu>
                    <mu2>0</mu2>
                  </ode>
                  <torsional>
                    <ode/>
                  </torsional>
                </friction>
                <bounce/>
              </surface>
              <max_contacts>10</max_contacts>
            </collision>
            <visual name='BasePlate_visual'>
              <pose>-0.006692 -0.020937 -0.006811 0 -0 0</pose>
              <material>
                <ambient>0.752941 0.752941 0.752941 1</ambient>
                <diffuse>0.752941 0.752941 0.752941 1</diffuse>
              </material>
              <geometry>
                <mesh>
                  <scale>1 1 1</scale>
                  <uri>model://Grabber2/meshes/BasePlate.STL</uri>
                </mesh>
              </geometry>
            </visual>
            <enable_wind>0</enable_wind>
            <kinematic>0</kinematic>
          </link>
          <link name='Piston'>
            <gravity>1</gravity>
            <self_collide>0</self_collide>
            <pose>0.142017 0 0.202178 -1.5708 -0 -1.5708</pose>
            <must_be_base_link>0</must_be_base_link>
            <velocity_decay>
              <linear>0</linear>
              <angular>0</angular>
            </velocity_decay>
            <inertial>
              <mass>0.01</mass>
              <pose>0 0 0 0 -0 0</pose>
              <inertia>
                <ixx>1</ixx>
                <ixy>0</ixy>
                <ixz>0</ixz>
                <iyy>1</iyy>
                <iyz>0</iyz>
                <izz>1</izz>
              </inertia>
            </inertial>
            <collision name='Piston_collision'>
              <pose>0 -0.001022 -0.109418 0 -0 0</pose>
              <geometry>
                <mesh>
                  <scale>1 1 1</scale>
                  <uri>model://Grabber2/meshes/Piston_col.STL</uri>
                </mesh>
              </geometry>
              <surface>
                <contact>
                  <ode/>
                </contact>
                <friction>
                  <ode>
                    <mu>0</mu>
                    <mu2>0</mu2>
                  </ode>
                  <torsional>
                    <ode/>
                  </torsional>
                </friction>
                <bounce/>
              </surface>
              <max_contacts>10</max_contacts>
            </collision>
            <visual name='Piston_visual'>
              <pose>0 -0.001022 -0.109418 0 -0 0</pose>
              <material>
                <ambient>0.501961 0.501961 0.501961 1</ambient>
                <diffuse>0.501961 0.501961 0.501961 1</diffuse>
              </material>
              <geometry>
                <mesh>
                  <scale>1 1 1</scale>
                  <uri>model://Grabber2/meshes/Piston.STL</uri>
                </mesh>
              </geometry>
            </visual>
            <enable_wind>0</enable_wind>
            <kinematic>0</kinematic>
          </link>
          <joint name='BasePlate-Piston' type='prismatic'>
            <parent>BasePlate</parent>
            <child>Piston</child>
            <pose>0 -0.001022 -0.028113 3.14159 -1.57079 3.14159</pose>
            <axis>
              <xyz>1 0 -0</xyz>
              <dynamics>
                <damping>0.1</damping>
                <friction>0.1</friction>
                <spring_reference>0</spring_reference>
                <spring_stiffness>0</spring_stiffness>
              </dynamics>
              <limit>
                <upper>0</upper>
                <lower>-1.5</lower>
              </limit>
            </axis>
          </joint>
          <link name='PistonTop'>
            <gravity>1</gravity>
            <self_collide>0</self_collide>
            <pose>0.107212 -0 0.109409 -1.5708 -0 -1.5708</pose>
            <must_be_base_link>0</must_be_base_link>
            <velocity_decay>
              <linear>0</linear>
              <angular>0</angular>
            </velocity_decay>
            <inertial>
              <mass>0.01</mass>
              <pose>0 0 0 0 -0 0</pose>
              <inertia>
                <ixx>1</ixx>
                <ixy>0</ixy>
                <ixz>0</ixz>
                <iyy>1</iyy>
                <iyz>0</iyz>
                <izz>1</izz>
              </inertia>
            </inertial>
            <collision name='PistonTop_collision'>
              <pose>-0 -0.093791 -0.074613 0 -0 0</pose>
              <geometry>
                <mesh>
                  <scale>1 1 1</scale>
                  <uri>model://Grabber2/meshes/PistonTop_col.STL</uri>
                </mesh>
              </geometry>
              <surface>
                <contact>
                  <ode/>
                </contact>
                <friction>
                  <ode>
                    <mu>0</mu>
                    <mu2>0</mu2>
                  </ode>
                  <torsional>
                    <ode/>
                  </torsional>
                </friction>
                <bounce/>
              </surface>
              <max_contacts>10</max_contacts>
            </collision>
            <visual name='PistonTop_visual'>
              <pose>-0 -0.093791 -0.074613 0 -0 0</pose>
              <material>
                <ambient>0.501961 0.501961 0.501961 1</ambient>
                <diffuse>0.501961 0.501961 0.501961 1</diffuse>
              </material>
              <geometry>
                <mesh>
                  <scale>1 1 1</scale>
                  <uri>model://Grabber2/meshes/PistonTop.STL</uri>
                </mesh>
              </geometry>
            </visual>
            <enable_wind>0</enable_wind>
            <kinematic>0</kinematic>
          </link>
          <joint name='Piston-PistonTop' type='revolute'>
            <parent>Piston</parent>
            <child>PistonTop</child>
            <pose>-0 -0.021083 0 0 -0 0</pose>
            <axis>
              <xyz>-1 0 0</xyz>
              <dynamics>
                <damping>0.9</damping>
                <friction>0.1</friction>
                <spring_reference>0</spring_reference>
                <spring_stiffness>0</spring_stiffness>
              </dynamics>
              <limit>
                <upper>0</upper>
                <lower>-1.7</lower>
              </limit>
            </axis>
          </joint>
          <joint name='TopArmIn-PistonTop' type='revolute'>
            <parent>TopArmIn</parent>
            <child>PistonTop</child>
            <pose>-0 0.021083 0 0 -0 0</pose>
            <axis>
              <xyz>-1 0 0</xyz>
              <dynamics>
                <damping>0.9</damping>
                <friction>0.1</friction>
                <spring_reference>0</spring_reference>
                <spring_stiffness>0</spring_stiffness>
              </dynamics>
              <limit>
                <upper>0</upper>
                <lower>-0.8</lower>
              </limit>
            </axis>
          </joint>
          <link name='PistonLeft'>
            <gravity>1</gravity>
            <self_collide>0</self_collide>
            <pose>0.107212 -0.081225 0.250095 -1.5708 -0 -1.5708</pose>
            <must_be_base_link>0</must_be_base_link>
            <velocity_decay>
              <linear>0</linear>
              <angular>0</angular>
            </velocity_decay>
            <inertial>
              <mass>0.01</mass>
              <pose>0 0 0 0 -0 0</pose>
              <inertia>
                <ixx>1</ixx>
                <ixy>0</ixy>
                <ixz>0</ixz>
                <iyy>1</iyy>
                <iyz>0</iyz>
                <izz>1</izz>
              </inertia>
            </inertial>
            <collision name='PistonLeft_collision'>
              <pose>-0.081225 0.046895 -0.074613 0 -0 0</pose>
              <geometry>
                <mesh>
                  <scale>1 1 1</scale>
                  <uri>model://Grabber2/meshes/PistonLeft_col.STL</uri>
                </mesh>
              </geometry>
              <surface>
                <contact>
                  <ode/>
                </contact>
                <friction>
                  <ode>
                    <mu>0</mu>
                    <mu2>0</mu2>
                  </ode>
                  <torsional>
                    <ode/>
                  </torsional>
                </friction>
                <bounce/>
              </surface>
              <max_contacts>10</max_contacts>
            </collision>
            <visual name='PistonLeft_visual'>
              <pose>-0.081225 0.046895 -0.074613 0 -0 0</pose>
              <material>
                <ambient>0.501961 0.501961 0.501961 1</ambient>
                <diffuse>0.501961 0.501961 0.501961 1</diffuse>
              </material>
              <geometry>
                <mesh>
                  <scale>1 1 1</scale>
                  <uri>model://Grabber2/meshes/PistonLeft.STL</uri>
                </mesh>
              </geometry>
            </visual>
            <enable_wind>0</enable_wind>
            <kinematic>0</kinematic>
          </link>
          <joint name='Piston-PistonLeft' type='revolute'>
            <parent>Piston</parent>
            <child>PistonLeft</child>
            <pose>-0.018259 0.010542 0 0 -0 0</pose>
            <axis>
              <xyz>-0.5 -0.866025 0</xyz>
              <dynamics>
                <damping>0.9</damping>
                <friction>0.1</friction>
                <spring_reference>0</spring_reference>
                <spring_stiffness>0</spring_stiffness>
              </dynamics>
              <limit>
                <upper>1.7</upper>
                <lower>0</lower>
              </limit>
            </axis>
          </joint>
          <joint name='LeftArmIn-PistonLeft' type='revolute'>
            <parent>LeftArmIn</parent>
            <child>PistonLeft</child>
            <pose>0.018259 -0.010542 -0 0 -0 0</pose>
            <axis>
              <xyz>-0.5 -0.866025 0</xyz>
              <dynamics>
                <damping>0.9</damping>
                <friction>0.1</friction>
                <spring_reference>0</spring_reference>
                <spring_stiffness>0</spring_stiffness>
              </dynamics>
              <limit>
                <upper>0.8</upper>
                <lower>0</lower>
              </limit>
            </axis>
          </joint>
          <link name='PistonRight'>
            <gravity>1</gravity>
            <self_collide>0</self_collide>
            <pose>0.107212 0.081225 0.250095 -1.5708 -0 -1.5708</pose>
            <must_be_base_link>0</must_be_base_link>
            <velocity_decay>
              <linear>0</linear>
              <angular>0</angular>
            </velocity_decay>
            <inertial>
              <mass>0.01</mass>
              <pose>0 0 0 0 -0 0</pose>
              <inertia>
                <ixx>1</ixx>
                <ixy>0</ixy>
                <ixz>0</ixz>
                <iyy>1</iyy>
                <iyz>0</iyz>
                <izz>1</izz>
              </inertia>
            </inertial>
            <collision name='PistonRight_collision'>
              <pose>0.081225 0.046895 -0.074613 0 -0 0</pose>
              <geometry>
                <mesh>
                  <scale>1 1 1</scale>
                  <uri>model://Grabber2/meshes/PistonRight_col.STL</uri>
                </mesh>
              </geometry>
              <surface>
                <contact>
                  <ode/>
                </contact>
                <friction>
                  <ode>
                    <mu>0</mu>
                    <mu2>0</mu2>
                  </ode>
                  <torsional>
                    <ode/>
                  </torsional>
                </friction>
                <bounce/>
              </surface>
              <max_contacts>10</max_contacts>
            </collision>
            <visual name='PistonRight_visual'>
              <pose>0.081225 0.046895 -0.074613 0 -0 0</pose>
              <material>
                <ambient>0.501961 0.501961 0.501961 1</ambient>
                <diffuse>0.501961 0.501961 0.501961 1</diffuse>
              </material>
              <geometry>
                <mesh>
                  <scale>1 1 1</scale>
                  <uri>model://Grabber2/meshes/PistonRight.STL</uri>
                </mesh>
              </geometry>
            </visual>
            <enable_wind>0</enable_wind>
            <kinematic>0</kinematic>
          </link>
          <joint name='Piston-PistonRight' type='revolute'>
            <parent>Piston</parent>
            <child>PistonRight</child>
            <pose>0.018259 0.010542 -0 0 -0 1.5708</pose>
            <axis>
              <xyz>-0.866025 -0.5 0</xyz>
              <dynamics>
                <damping>0.9</damping>
                <friction>0.1</friction>
                <spring_reference>0</spring_reference>
                <spring_stiffness>0</spring_stiffness>
              </dynamics>
              <limit>
                <upper>0</upper>
                <lower>-1.7</lower>
              </limit>
            </axis>
          </joint>
          <joint name='RightArmIn-PistonRight' type='revolute'>
            <parent>RightArmIn</parent>
            <child>PistonRight</child>
            <pose>-0.018259 -0.010542 0 0 0 -1.5708</pose>
            <axis>
              <xyz>0.866025 0.5 -0</xyz>
              <dynamics>
                <damping>0.9</damping>
                <friction>0.1</friction>
                <spring_reference>0</spring_reference>
                <spring_stiffness>0</spring_stiffness>
              </dynamics>
              <limit>
                <upper>0</upper>
                <lower>-0.8</lower>
              </limit>
            </axis>
          </joint>
          <link name='TopArmOut'>
            <gravity>1</gravity>
            <self_collide>0</self_collide>
            <pose>0.121621 -0 0.033994 -1.5708 -0 -1.5708</pose>
            <must_be_base_link>0</must_be_base_link>
            <velocity_decay>
              <linear>0</linear>
              <angular>0</angular>
            </velocity_decay>
            <inertial>
              <mass>0.01</mass>
              <pose>0 0 0 0 -0 0</pose>
              <inertia>
                <ixx>1</ixx>
                <ixy>0</ixy>
                <ixz>0</ixz>
                <iyy>1</iyy>
                <iyz>0</iyz>
                <izz>1</izz>
              </inertia>
            </inertial>
            <collision name='TopArmOut_collision'>
              <pose>-0 -0.169206 -0.089022 0 -0 0</pose>
              <geometry>
                <mesh>
                  <scale>1 1 1</scale>
                  <uri>model://Grabber2/meshes/TopArmOut_col.STL</uri>
                </mesh>
              </geometry>
              <surface>
                <contact>
                  <ode/>
                </contact>
                <friction>
                  <ode>
                    <mu>0</mu>
                    <mu2>0</mu2>
                  </ode>
                  <torsional>
                    <ode/>
                  </torsional>
                </friction>
                <bounce/>
              </surface>
              <max_contacts>10</max_contacts>
            </collision>
            <visual name='TopArmOut_visual'>
              <pose>-0 -0.169206 -0.089022 0 -0 0</pose>
              <material>
                <ambient>0.25098 0.501961 0.501961 1</ambient>
                <diffuse>0.25098 0.501961 0.501961 1</diffuse>
              </material>
              <geometry>
                <mesh>
                  <scale>1 1 1</scale>
                  <uri>model://Grabber2/meshes/TopArmOut.STL</uri>
                </mesh>
              </geometry>
            </visual>
            <enable_wind>0</enable_wind>
            <kinematic>0</kinematic>
          </link>
          <joint name='BasePlate-TopArmOut' type='revolute'>
            <parent>BasePlate</parent>
            <child>TopArmOut</child>
            <pose>0 -0.038396 -0.069972 0 -0 3.14159</pose>
            <axis>
              <xyz>1 0 0</xyz>
              <dynamics>
                <damping>0.9</damping>
                <friction>0.1</friction>
                <spring_reference>0</spring_reference>
                <spring_stiffness>0</spring_stiffness>
              </dynamics>
              <limit>
                <upper>0</upper>
                <lower>-0.9</lower>
              </limit>
            </axis>
          </joint>
          <link name='RightArmOut'>
            <gravity>1</gravity>
            <self_collide>0</self_collide>
            <pose>0.121621 0.146536 0.287803 -1.5708 -0 -1.5708</pose>
            <must_be_base_link>0</must_be_base_link>
            <velocity_decay>
              <linear>0</linear>
              <angular>0</angular>
            </velocity_decay>
            <inertial>
              <mass>0.01</mass>
              <pose>0 0 0 0 -0 0</pose>
              <inertia>
                <ixx>1</ixx>
                <ixy>0</ixy>
                <ixz>0</ixz>
                <iyy>1</iyy>
                <iyz>0</iyz>
                <izz>1</izz>
              </inertia>
            </inertial>
            <collision name='RightArmOut_collision'>
              <pose>0.146536 0.084603 -0.089022 0 -0 0</pose>
              <geometry>
                <mesh>
                  <scale>1 1 1</scale>
                  <uri>model://Grabber2/meshes/RightArmOut_col.STL</uri>
                </mesh>
              </geometry>
              <surface>
                <contact>
                  <ode/>
                </contact>
                <friction>
                  <ode>
                    <mu>0</mu>
                    <mu2>0</mu2>
                  </ode>
                  <torsional>
                    <ode/>
                  </torsional>
                </friction>
                <bounce/>
              </surface>
              <max_contacts>10</max_contacts>
            </collision>
            <visual name='RightArmOut_visual'>
              <pose>0.146536 0.084603 -0.089022 0 -0 0</pose>
              <material>
                <ambient>0.25098 0.501961 0.501961 1</ambient>
                <diffuse>0.25098 0.501961 0.501961 1</diffuse>
              </material>
              <geometry>
                <mesh>
                  <scale>1 1 1</scale>
                  <uri>model://Grabber2/meshes/RightArmOut.STL</uri>
                </mesh>
              </geometry>
            </visual>
            <enable_wind>0</enable_wind>
            <kinematic>0</kinematic>
          </link>
          <joint name='BasePlate-RightArmOut' type='revolute'>
            <parent>BasePlate</parent>
            <child>RightArmOut</child>
            <pose>0.033252 0.019198 -0.069972 0 -0 -1.5708</pose>
            <axis>
              <xyz>0.866025 0.5 0</xyz>
              <dynamics>
                <damping>0.9</damping>
                <friction>0.1</friction>
                <spring_reference>0</spring_reference>
                <spring_stiffness>0</spring_stiffness>
              </dynamics>
              <limit>
                <upper>0</upper>
                <lower>-0.9</lower>
              </limit>
            </axis>
          </joint>
          <link name='LeftArmOut'>
            <gravity>1</gravity>
            <self_collide>0</self_collide>
            <pose>0.121621 -0.146536 0.287803 -1.5708 -0 -1.5708</pose>
            <must_be_base_link>0</must_be_base_link>
            <velocity_decay>
              <linear>0</linear>
              <angular>0</angular>
            </velocity_decay>
            <inertial>
              <mass>0.01</mass>
              <pose>0 0 0 0 -0 0</pose>
              <inertia>
                <ixx>1</ixx>
                <ixy>0</ixy>
                <ixz>0</ixz>
                <iyy>1</iyy>
                <iyz>0</iyz>
                <izz>1</izz>
              </inertia>
            </inertial>
            <collision name='LeftArmOut_collision'>
              <pose>-0.146536 0.084603 -0.089022 0 -0 0</pose>
              <geometry>
                <mesh>
                  <scale>1 1 1</scale>
                  <uri>model://Grabber2/meshes/LeftArmOut_col.STL</uri>
                </mesh>
              </geometry>
              <surface>
                <contact>
                  <ode/>
                </contact>
                <friction>
                  <ode>
                    <mu>0</mu>
                    <mu2>0</mu2>
                  </ode>
                  <torsional>
                    <ode/>
                  </torsional>
                </friction>
                <bounce/>
              </surface>
              <max_contacts>10</max_contacts>
            </collision>
            <visual name='LeftArmOut_visual'>
              <pose>-0.146536 0.084603 -0.089022 0 -0 0</pose>
              <material>
                <ambient>0.25098 0.501961 0.501961 1</ambient>
                <diffuse>0.25098 0.501961 0.501961 1</diffuse>
              </material>
              <geometry>
                <mesh>
                  <scale>1 1 1</scale>
                  <uri>model://Grabber2/meshes/LeftArmOut.STL</uri>
                </mesh>
              </geometry>
            </visual>
            <enable_wind>0</enable_wind>
            <kinematic>0</kinematic>
          </link>
          <joint name='BasePlate-LeftArmOut' type='revolute'>
            <parent>BasePlate</parent>
            <child>LeftArmOut</child>
            <pose>-0.033252 0.019198 -0.069972 0 -0 1.5708</pose>
            <axis>
              <xyz>-0.866025 0.5 0</xyz>
              <dynamics>
                <damping>0.9</damping>
                <friction>0.1</friction>
                <spring_reference>0</spring_reference>
                <spring_stiffness>0</spring_stiffness>
              </dynamics>
              <limit>
                <upper>0.9</upper>
                <lower>0</lower>
              </limit>
            </axis>
          </joint>
          <link name='TopGrabber'>
            <gravity>1</gravity>
            <self_collide>0</self_collide>
            <pose>0.303415 0.00055 0.01211 -1.5708 -0 -1.5708</pose>
            <must_be_base_link>0</must_be_base_link>
            <velocity_decay>
              <linear>0</linear>
              <angular>0</angular>
            </velocity_decay>
            <inertial>
              <mass>0.01</mass>
              <pose>0 -0 -0 0 -0 0</pose>
              <inertia>
                <ixx>1</ixx>
                <ixy>0</ixy>
                <ixz>0</ixz>
                <iyy>1</iyy>
                <iyz>0</iyz>
                <izz>1</izz>
              </inertia>
            </inertial>
            <collision name='TopGrabber_collision'>
              <pose>0.00055 -0.19109 -0.270816 0 -0 0</pose>
              <geometry>
                <mesh>
                  <scale>1 1 1</scale>
                  <uri>model://Grabber2/meshes/TopGrabber_col.STL</uri>
                </mesh>
              </geometry>
              <surface>
                <contact>
                  <ode/>
                </contact>
                <friction>
                  <ode>
                    <mu>1</mu>
                    <mu2>1</mu2>
                  </ode>
                  <torsional>
                    <ode/>
                  </torsional>
                </friction>
                <bounce/>
              </surface>
              <max_contacts>10</max_contacts>
            </collision>
            <visual name='TopGrabber_visual'>
              <pose>0.00055 -0.19109 -0.270816 0 -0 0</pose>
              <material>
                <ambient>0 0.25098 0.25098 1</ambient>
                <diffuse>0 0.25098 0.25098 1</diffuse>
              </material>
              <geometry>
                <mesh>
                  <scale>1 1 1</scale>
                  <uri>model://Grabber2/meshes/TopGrabber.STL</uri>
                </mesh>
              </geometry>
            </visual>
            <enable_wind>0</enable_wind>
            <kinematic>0</kinematic>
          </link>
          <joint name='TopArmOut-TopGrabber' type='revolute'>
            <parent>TopArmOut</parent>
            <child>TopGrabber</child>
            <pose>0 0.01651 -0.109929 0 -0 0</pose>
            <axis>
              <xyz>-1 0 0</xyz>
              <dynamics>
                <damping>0.9</damping>
                <friction>0.1</friction>
                <spring_reference>0</spring_reference>
                <spring_stiffness>0</spring_stiffness>
              </dynamics>
              <limit>
                <upper>0.9</upper>
                <lower>0</lower>
              </limit>
            </axis>
          </joint>
          <joint name='TopArmIn-TopGrabber' type='revolute'>
            <parent>TopArmIn</parent>
            <child>TopGrabber</child>
            <pose>0 -0.01651 -0.109929 0 -0 0</pose>
            <axis>
              <xyz>-1 0 0</xyz>
              <dynamics>
                <damping>0.9</damping>
                <friction>0.1</friction>
                <spring_reference>0</spring_reference>
                <spring_stiffness>0</spring_stiffness>
              </dynamics>
              <limit>
                <upper>0.9</upper>
                <lower>0</lower>
              </limit>
            </axis>
          </joint>
          <link name='RightGrabber'>
            <gravity>1</gravity>
            <self_collide>0</self_collide>
            <pose>0.303415 0.165214 0.299222 -1.5708 -0 -1.5708</pose>
            <velocity_decay>
              <linear>0</linear>
              <angular>0</angular>
            </velocity_decay>
            <inertial>
              <mass>0.01</mass>
              <pose>0 -0 0 0 -0 0</pose>
              <inertia>
                <ixx>1</ixx>
                <ixy>0</ixy>
                <ixz>0</ixz>
                <iyy>1</iyy>
                <iyz>0</iyz>
                <izz>1</izz>
              </inertia>
            </inertial>
            <collision name='RightGrabber_collision'>
              <pose>0.165214 0.096022 -0.270816 0 -0 0</pose>
              <geometry>
                <mesh>
                  <scale>1 1 1</scale>
                  <uri>model://Grabber2/meshes/RightGrabber_col.STL</uri>
                </mesh>
              </geometry>
              <surface>
                <contact>
                  <ode/>
                </contact>
                <friction>
                  <ode>
                    <mu>1</mu>
                    <mu2>1</mu2>
                  </ode>
                  <torsional>
                    <ode/>
                  </torsional>
                </friction>
                <bounce/>
              </surface>
              <max_contacts>10</max_contacts>
            </collision>
            <visual name='RightGrabber_visual'>
              <pose>0.165214 0.096022 -0.270816 0 -0 0</pose>
              <material>
                <ambient>0 0.25098 0.25098 1</ambient>
                <diffuse>0 0.25098 0.25098 1</diffuse>
              </material>
              <geometry>
                <mesh>
                  <scale>1 1 1</scale>
                  <uri>model://Grabber2/meshes/RightGrabber.STL</uri>
                </mesh>
              </geometry>
            </visual>
            <enable_wind>0</enable_wind>
            <kinematic>0</kinematic>
          </link>
          <joint name='RightArmOut-RightGrabber' type='revolute'>
            <parent>RightArmOut</parent>
            <child>RightGrabber</child>
            <pose>-0.014298 -0.008255 -0.109929 0 -0 -1.5708</pose>
            <axis>
              <xyz>0.866025 0.5 0</xyz>
              <dynamics>
                <damping>0.9</damping>
                <friction>0.1</friction>
                <spring_reference>0</spring_reference>
                <spring_stiffness>0</spring_stiffness>
              </dynamics>
              <limit>
                <upper>0.9</upper>
                <lower>0</lower>
              </limit>
            </axis>
          </joint>
          <joint name='RightArmIn-RightGrabber' type='revolute'>
            <parent>RightArmIn</parent>
            <child>RightGrabber</child>
            <pose>0.014298 0.008255 -0.109929 0 -0 -1.5708</pose>
            <axis>
              <xyz>0.866025 0.5 0</xyz>
              <dynamics>
                <damping>0.9</damping>
                <friction>0.1</friction>
                <spring_reference>0</spring_reference>
                <spring_stiffness>0</spring_stiffness>
              </dynamics>
              <limit>
                <upper>0.9</upper>
                <lower>0</lower>
              </limit>
            </axis>
          </joint>
          <link name='LeftGrabber'>
            <gravity>1</gravity>
            <self_collide>0</self_collide>
            <pose>0.303415 -0.165764 0.298269 -1.5708 -0 -1.5708</pose>
            <velocity_decay>
              <linear>0</linear>
              <angular>0</angular>
            </velocity_decay>
            <inertial>
              <mass>0.01</mass>
              <pose>0 -0 -0 0 -0 0</pose>
              <inertia>
                <ixx>1</ixx>
                <ixy>0</ixy>
                <ixz>0</ixz>
                <iyy>1</iyy>
                <iyz>0</iyz>
                <izz>1</izz>
              </inertia>
            </inertial>
            <collision name='LeftGrabber_collision'>
              <pose>-0.165764 0.095069 -0.270816 0 -0 0</pose>
              <geometry>
                <mesh>
                  <scale>1 1 1</scale>
                  <uri>model://Grabber2/meshes/LeftGrabber_col.STL</uri>
                </mesh>
              </geometry>
              <surface>
                <contact>
                  <ode/>
                </contact>
                <friction>
                  <ode>
                    <mu>1</mu>
                    <mu2>1</mu2>
                  </ode>
                  <torsional>
                    <ode/>
                  </torsional>
                </friction>
                <bounce/>
              </surface>
              <max_contacts>10</max_contacts>
            </collision>
            <visual name='LeftGrabber_visual'>
              <pose>-0.165764 0.095069 -0.270816 0 -0 0</pose>
              <material>
                <ambient>0 0.25098 0.25098 1</ambient>
                <diffuse>0 0.25098 0.25098 1</diffuse>
              </material>
              <geometry>
                <mesh>
                  <scale>1 1 1</scale>
                  <uri>model://Grabber2/meshes/LeftGrabber.STL</uri>
                </mesh>
              </geometry>
            </visual>
            <enable_wind>0</enable_wind>
            <kinematic>0</kinematic>
          </link>
          <joint name='LeftArmOut-LeftGrabber' type='revolute'>
            <parent>LeftArmOut</parent>
            <child>LeftGrabber</child>
            <pose>0.014298 -0.008255 -0.109929 0 -0 0</pose>
            <axis>
              <xyz>-0.5 -0.866025 0</xyz>
              <dynamics>
                <damping>0.9</damping>
                <friction>0.1</friction>
                <spring_reference>0</spring_reference>
                <spring_stiffness>0</spring_stiffness>
              </dynamics>
              <limit>
                <upper>0</upper>
                <lower>-0.9</lower>
              </limit>
            </axis>
          </joint>
          <joint name='LeftArmIn-LeftGrabber' type='revolute'>
            <parent>LeftArmIn</parent>
            <child>LeftGrabber</child>
            <pose>-0.014298 0.008255 -0.109929 0 -0 0</pose>
            <axis>
              <xyz>-0.5 -0.866025 0</xyz>
              <dynamics>
                <damping>0.9</damping>
                <friction>0.1</friction>
                <spring_reference>0</spring_reference>
                <spring_stiffness>0</spring_stiffness>
              </dynamics>
              <limit>
                <upper>0</upper>
                <lower>-0.9</lower>
              </limit>
            </axis>
          </joint>
          <link name='TopWheel'>
            <gravity>1</gravity>
            <self_collide>0</self_collide>
            <pose>0.406211 0.028669 0.01211 -1.5708 -0 -1.5708</pose>
            <must_be_base_link>0</must_be_base_link>
            <velocity_decay>
              <linear>0</linear>
              <angular>0</angular>
            </velocity_decay>
            <inertial>
              <mass>0.00457804</mass>
              <pose>0 0 0 0 -0 0</pose>
              <inertia>
                <ixx>1</ixx>
                <ixy>0</ixy>
                <ixz>0</ixz>
                <iyy>1</iyy>
                <iyz>0</iyz>
                <izz>1</izz>
              </inertia>
            </inertial>
            <collision name='TopWheel_collision'>
              <pose>0.028669 -0.19109 -0.373612 0 -0 0</pose>
              <geometry>
                <mesh>
                  <scale>1 1 1</scale>
                  <uri>model://Grabber2/meshes/TopWheel_col.STL</uri>
                </mesh>
              </geometry>
              <surface>
                <contact>
                  <ode/>
                </contact>
                <friction>
                  <ode>
                    <mu>1</mu>
                    <mu2>1</mu2>
                  </ode>
                  <torsional>
                    <ode/>
                  </torsional>
                </friction>
                <bounce/>
              </surface>
              <max_contacts>10</max_contacts>
            </collision>
            <visual name='TopWheel_visual'>
              <pose>0.028669 -0.19109 -0.373612 0 -0 0</pose>
              <material>
                <ambient>0 0 1 1</ambient>
                <diffuse>0 0 1 1</diffuse>
              </material>
              <geometry>
                <mesh>
                  <scale>1 1 1</scale>
                  <uri>model://Grabber2/meshes/TopWheel.STL</uri>
                </mesh>
              </geometry>
            </visual>
            <enable_wind>0</enable_wind>
            <kinematic>0</kinematic>
          </link>
          <joint name='TopGrabber-TopWheel' type='revolute'>
            <parent>TopGrabber</parent>
            <child>TopWheel</child>
            <pose>0 -0 0 0 -0 0</pose>
            <axis>
              <xyz>-1 0 0</xyz>
              <dynamics>
                <damping>1</damping>
                <friction>0</friction>
                <spring_reference>0</spring_reference>
                <spring_stiffness>0</spring_stiffness>
              </dynamics>
              <limit>
                <lower>-1e+16</lower>
                <upper>1e+16</upper>
              </limit>
            </axis>
          </joint>
          <link name='RightWheel'>
            <gravity>1</gravity>
            <self_collide>0</self_collide>
            <pose>0.406211 0.151155 0.323573 -1.5708 -0 -1.5708</pose>
            <must_be_base_link>0</must_be_base_link>
            <velocity_decay>
              <linear>0</linear>
              <angular>0</angular>
            </velocity_decay>
            <inertial>
              <mass>0.00457804</mass>
              <pose>0 0 0 0 -0 0</pose>
              <inertia>
                <ixx>1</ixx>
                <ixy>0</ixy>
                <ixz>0</ixz>
                <iyy>1</iyy>
                <iyz>0</iyz>
                <izz>1</izz>
              </inertia>
            </inertial>
            <collision name='RightWheel_collision'>
              <pose>0.151155 0.120373 -0.373612 0 -0 0</pose>
              <geometry>
                <mesh>
                  <scale>1 1 1</scale>
                  <uri>model://Grabber2/meshes/RightWheel_col.STL</uri>
                </mesh>
              </geometry>
              <surface>
                <contact>
                  <ode/>
                </contact>
                <friction>
                  <ode>
                    <mu>1</mu>
                    <mu2>1</mu2>
                  </ode>
                  <torsional>
                    <ode/>
                  </torsional>
                </friction>
                <bounce/>
              </surface>
              <max_contacts>10</max_contacts>
            </collision>
            <visual name='RightWheel_visual'>
              <pose>0.151155 0.120373 -0.373612 0 -0 0</pose>
              <material>
                <ambient>0 0 1 1</ambient>
                <diffuse>0 0 1 1</diffuse>
              </material>
              <geometry>
                <mesh>
                  <scale>1 1 1</scale>
                  <uri>model://Grabber2/meshes/RightWheel.STL</uri>
                </mesh>
              </geometry>
            </visual>
            <enable_wind>0</enable_wind>
            <kinematic>0</kinematic>
          </link>
          <joint name='RightGrabber-RightWheel' type='revolute'>
            <parent>RightGrabber</parent>
            <child>RightWheel</child>
            <pose>0 0 -0 0 -0 1.5708</pose>
            <axis>
              <xyz>0.866025 0.5 -0</xyz>
              <dynamics>
                <damping>1</damping>
                <friction>0</friction>
                <spring_reference>0</spring_reference>
                <spring_stiffness>0</spring_stiffness>
              </dynamics>
              <limit>
                <lower>-1e+16</lower>
                <upper>1e+16</upper>
              </limit>
            </axis>
          </joint>
          <link name='LeftWheel'>
            <gravity>1</gravity>
            <self_collide>0</self_collide>
            <pose>0.406211 -0.179823 0.273917 -1.5708 -0 -1.5708</pose>
            <must_be_base_link>0</must_be_base_link>
            <velocity_decay>
              <linear>0</linear>
              <angular>0</angular>
            </velocity_decay>
            <inertial>
              <mass>0.00457804</mass>
              <pose>0 0 0 0 -0 0</pose>
              <inertia>
                <ixx>1</ixx>
                <ixy>0</ixy>
                <ixz>0</ixz>
                <iyy>1</iyy>
                <iyz>0</iyz>
                <izz>1</izz>
              </inertia>
            </inertial>
            <collision name='LeftWheel_collision'>
              <pose>-0.179823 0.070717 -0.373612 0 -0 0</pose>
              <geometry>
                <mesh>
                  <scale>1 1 1</scale>
                  <uri>model://Grabber2/meshes/LeftWheel_col.STL</uri>
                </mesh>
              </geometry>
              <surface>
                <contact>
                  <ode/>
                </contact>
                <friction>
                  <ode>
                    <mu>1</mu>
                    <mu2>1</mu2>
                  </ode>
                  <torsional>
                    <ode/>
                  </torsional>
                </friction>
                <bounce/>
              </surface>
              <max_contacts>10</max_contacts>
            </collision>
            <visual name='LeftWheel_visual'>
              <pose>-0.179823 0.070717 -0.373612 0 -0 0</pose>
              <material>
                <ambient>0 0 1 1</ambient>
                <diffuse>0 0 1 1</diffuse>
              </material>
              <geometry>
                <mesh>
                  <scale>1 1 1</scale>
                  <uri>model://Grabber2/meshes/LeftWheel.STL</uri>
                </mesh>
              </geometry>
            </visual>
            <enable_wind>0</enable_wind>
            <kinematic>0</kinematic>
          </link>
          <joint name='LeftGrabber-LeftWheel' type='revolute'>
            <parent>LeftGrabber</parent>
            <child>LeftWheel</child>
            <pose>-0 -0 0 0 0 -1.5708</pose>
            <axis>
              <xyz>0.866025 -0.5 -0</xyz>
              <dynamics>
                <damping>1</damping>
                <friction>0</friction>
                <spring_reference>0</spring_reference>
                <spring_stiffness>0</spring_stiffness>
              </dynamics>
              <limit>
                <lower>-1e+16</lower>
                <upper>1e+16</upper>
              </limit>
            </axis>
          </joint>
          <link name='TopArmIn'>
            <gravity>1</gravity>
            <self_collide>0</self_collide>
            <pose>0.122051 -0 0.067808 -1.5708 -0 -1.5708</pose>
            <must_be_base_link>0</must_be_base_link>
            <velocity_decay>
              <linear>0</linear>
              <angular>0</angular>
            </velocity_decay>
            <inertial>
              <mass>0.01</mass>
              <pose>0 0 0 0 -0 0</pose>
              <inertia>
                <ixx>1</ixx>
                <ixy>0</ixy>
                <ixz>0</ixz>
                <iyy>1</iyy>
                <iyz>0</iyz>
                <izz>1</izz>
              </inertia>
            </inertial>
            <collision name='TopArmIn_collision'>
              <pose>-0 -0.135392 -0.089452 0 -0 0</pose>
              <geometry>
                <mesh>
                  <scale>1 1 1</scale>
                  <uri>model://Grabber2/meshes/TopArmIn_col.STL</uri>
                </mesh>
              </geometry>
              <surface>
                <contact>
                  <ode/>
                </contact>
                <friction>
                  <ode>
                    <mu>0</mu>
                    <mu2>0</mu2>
                  </ode>
                  <torsional>
                    <ode/>
                  </torsional>
                </friction>
                <bounce/>
              </surface>
              <max_contacts>10</max_contacts>
            </collision>
            <visual name='TopArmIn_visual'>
              <pose>-0 -0.135392 -0.089452 0 -0 0</pose>
              <material>
                <ambient>0.25098 0.501961 0.501961 1</ambient>
                <diffuse>0.25098 0.501961 0.501961 1</diffuse>
              </material>
              <geometry>
                <mesh>
                  <scale>1 1 1</scale>
                  <uri>model://Grabber2/meshes/TopArmIn.STL</uri>
                </mesh>
              </geometry>
            </visual>
            <enable_wind>0</enable_wind>
            <kinematic>0</kinematic>
          </link>
          <joint name='BasePlate-TopArmIn' type='revolute'>
            <parent>BasePlate</parent>
            <child>TopArmIn</child>
            <pose>-0 -0.037602 -0.070402 0 -0 3.14159</pose>
            <axis>
              <xyz>1 0 0</xyz>
              <dynamics>
                <damping>0.9</damping>
                <friction>0.1</friction>
                <spring_reference>0</spring_reference>
                <spring_stiffness>0</spring_stiffness>
              </dynamics>
              <limit>
                <upper>0</upper>
                <lower>-0.9</lower>
              </limit>
            </axis>
          </joint>
          <link name='LeftArmIn'>
            <gravity>1</gravity>
            <self_collide>0</self_collide>
            <pose>0.122051 -0.117253 0.270896 -1.5708 -0 -1.5708</pose>
            <must_be_base_link>0</must_be_base_link>
            <velocity_decay>
              <linear>0</linear>
              <angular>0</angular>
            </velocity_decay>
            <inertial>
              <mass>0.01</mass>
              <pose>0 0 0 0 -0 0</pose>
              <inertia>
                <ixx>1</ixx>
                <ixy>0</ixy>
                <ixz>0</ixz>
                <iyy>1</iyy>
                <iyz>0</iyz>
                <izz>1</izz>
              </inertia>
            </inertial>
            <collision name='LeftArmIn_collision'>
              <pose>-0.117253 0.067696 -0.089452 0 -0 0</pose>
              <geometry>
                <mesh>
                  <scale>1 1 1</scale>
                  <uri>model://Grabber2/meshes/LeftArmIn_col.STL</uri>
                </mesh>
              </geometry>
              <surface>
                <contact>
                  <ode/>
                </contact>
                <friction>
                  <ode>
                    <mu>0</mu>
                    <mu2>0</mu2>
                  </ode>
                  <torsional>
                    <ode/>
                  </torsional>
                </friction>
                <bounce/>
              </surface>
              <max_contacts>10</max_contacts>
            </collision>
            <visual name='LeftArmIn_visual'>
              <pose>-0.117253 0.067696 -0.089452 0 -0 0</pose>
              <material>
                <ambient>0.25098 0.501961 0.501961 1</ambient>
                <diffuse>0.25098 0.501961 0.501961 1</diffuse>
              </material>
              <geometry>
                <mesh>
                  <scale>1 1 1</scale>
                  <uri>model://Grabber2/meshes/LeftArmIn.STL</uri>
                </mesh>
              </geometry>
            </visual>
            <enable_wind>0</enable_wind>
            <kinematic>0</kinematic>
          </link>
          <joint name='BasePlate-LeftArmIn' type='revolute'>
            <parent>BasePlate</parent>
            <child>LeftArmIn</child>
            <pose>-0.032565 0.018801 -0.070402 0 -0 1.5708</pose>
            <axis>
              <xyz>-0.866025 0.5 0</xyz>
              <dynamics>
                <damping>0.9</damping>
                <friction>0.1</friction>
                <spring_reference>0</spring_reference>
                <spring_stiffness>0</spring_stiffness>
              </dynamics>
              <limit>
                <upper>0.9</upper>
                <lower>0</lower>
              </limit>
            </axis>
          </joint>
          <link name='RightArmIn'>
            <gravity>1</gravity>
            <self_collide>0</self_collide>
            <pose>0.122051 0.117253 0.270896 -1.5708 -0 -1.5708</pose>
            <must_be_base_link>0</must_be_base_link>
            <velocity_decay>
              <linear>0</linear>
              <angular>0</angular>
            </velocity_decay>
            <inertial>
              <mass>0.01</mass>
              <pose>0 0 0 0 -0 0</pose>
              <inertia>
                <ixx>1</ixx>
                <ixy>0</ixy>
                <ixz>0</ixz>
                <iyy>1</iyy>
                <iyz>0</iyz>
                <izz>1</izz>
              </inertia>
            </inertial>
            <collision name='RightArmIn_collision'>
              <pose>0.117253 0.067696 -0.089452 0 -0 0</pose>
              <geometry>
                <mesh>
                  <scale>1 1 1</scale>
                  <uri>model://Grabber2/meshes/RightArmIn_col.STL</uri>
                </mesh>
              </geometry>
              <surface>
                <contact>
                  <ode/>
                </contact>
                <friction>
                  <ode>
                    <mu>0</mu>
                    <mu2>0</mu2>
                  </ode>
                  <torsional>
                    <ode/>
                  </torsional>
                </friction>
                <bounce/>
              </surface>
              <max_contacts>10</max_contacts>
            </collision>
            <visual name='RightArmIn_visual'>
              <pose>0.117253 0.067696 -0.089452 0 -0 0</pose>
              <material>
                <ambient>0.25098 0.501961 0.501961 1</ambient>
                <diffuse>0.25098 0.501961 0.501961 1</diffuse>
              </material>
              <geometry>
                <mesh>
                  <scale>1 1 1</scale>
                  <uri>model://Grabber2/meshes/RightArmIn.STL</uri>
                </mesh>
              </geometry>
            </visual>
            <enable_wind>0</enable_wind>
            <kinematic>0</kinematic>
          </link>
          <joint name='BasePlate-RightArmIn' type='revolute'>
            <parent>BasePlate</parent>
            <child>RightArmIn</child>
            <pose>0.032565 0.018801 -0.070402 0 -0 -1.5708</pose>
            <axis>
              <xyz>0.866025 0.5 0</xyz>
              <dynamics>
                <damping>0.9</damping>
                <friction>0.1</friction>
                <spring_reference>0</spring_reference>
                <spring_stiffness>0</spring_stiffness>
              </dynamics>
              <limit>
                <upper>0</upper>
                <lower>-0.9</lower>
              </limit>
            </axis>
          </joint>
          <plugin name='BasePlate-Piston_piston' filename='sim_piston.dll'>
            <joint>BasePlate-Piston</joint>
            <topic>~/gazebo/frc/simulator/piston/2</topic>
            <forward-force>400</forward-force>
            <reverse-force>400</reverse-force>
          </plugin>
          <plugin name='RightWheelMotor' filename='sim_motor.dll'>
            <joint>RightGrabber-RightWheel</joint>
            <topic>~/gazebo/frc/simulator/motor/6</topic>
            <multiplier>10</multiplier>
          </plugin>
          <plugin name='LeftWheelMotor' filename='sim_motor.dll'>
            <joint>LeftGrabber-LeftWheel</joint>
            <topic>~/gazebo/frc/simulator/motor/6</topic>
            <multiplier>10</multiplier>
          </plugin>
          <plugin name='TopWheelMotor' filename='sim_motor.dll'>
            <joint>TopGrabber-TopWheel</joint>
            <topic>~/gazebo/frc/simulator/motor/6</topic>
            <multiplier>10</multiplier>
          </plugin>
          <joint name='grabber-elevator' type='revolute'>
            <parent>Carriage</parent>
            <child>BasePlate</child>
            <pose>0 0.15 -0.05 0 -0 0</pose>
            <axis>
              <xyz>-1 0 0</xyz>
              <dynamics>
                <damping>1</damping>
                <friction>1</friction>
                <spring_reference>0</spring_reference>
                <spring_stiffness>0</spring_stiffness>
              </dynamics>
              <limit>
                <upper>1.3</upper>
                <lower>0</lower>
              </limit>
            </axis>
          </joint>
          <plugin name='grabber-elevator_piston' filename='sim_piston.dll'>
            <joint>grabber-elevator</joint>
            <topic>~/gazebo/frc/simulator/piston/1</topic>
            <forward-force>50</forward-force>
            <reverse-force>50</reverse-force>
          </plugin>
        </model>
      </model>
    </model>
    <model name='Platform2'>
      <pose>-3.9286 -3.8364 0.000104 -3.14 -2e-06 -0.000627</pose>
      <static>1</static>
      <link name='Platform2'>
        <gravity>1</gravity>
        <self_collide>0</self_collide>
        <pose>-1.24298 2e-05 -0.189223 -1.5708 -0 3.14159</pose>
        <must_be_base_link>1</must_be_base_link>
        <velocity_decay>
          <linear>0</linear>
          <angular>0</angular>
        </velocity_decay>
        <inertial>
          <mass>129.621</mass>
          <pose>0 0 0 0 -0 0</pose>
          <inertia>
            <ixx>0.317774</ixx>
            <ixy>2.23656</ixy>
            <ixz>0.000291577</ixz>
            <iyy>15.7413</iyy>
            <iyz>4.14277e-05</iyz>
            <izz>16.0591</izz>
          </inertia>
        </inertial>
        <collision name='Platform_collision'>
          <pose>0.507913 -0.189223 0.384851 0 -0 0</pose>
          <geometry>
            <mesh>
              <scale>1 1 1</scale>
              <uri>model://Platform2/meshes/Platform_col.STL</uri>
            </mesh>
          </geometry>
          <surface>
            <contact>
              <ode/>
            </contact>
            <friction>
              <ode>
                <mu>1</mu>
                <mu2>1</mu2>
              </ode>
              <torsional>
                <ode/>
              </torsional>
            </friction>
            <bounce/>
          </surface>
          <max_contacts>10</max_contacts>
        </collision>
        <visual name='Platform_visual'>
          <pose>0.507913 -0.189223 0.384851 0 -0 0</pose>
          <material>
            <ambient>0.6 0.6 0.6 1</ambient>
            <diffuse>0.6 0.6 0.6 1</diffuse>
          </material>
          <geometry>
            <mesh>
              <scale>1 1 1</scale>
              <uri>model://Platform2/meshes/Platform.STL</uri>
            </mesh>
          </geometry>
        </visual>
        <enable_wind>0</enable_wind>
        <kinematic>0</kinematic>
      </link>
    </model>
    <model name='2019-Field-3'>
      <pose>13.2 -3.861 4.5797 1.57 -0 0</pose>
      <static>1</static>
      <link name='All'>
        <gravity>1</gravity>
        <self_collide>0</self_collide>
        <pose>-11.2776 -4.572 -0 0 -0 0</pose>
        <must_be_base_link>1</must_be_base_link>
        <velocity_decay>
          <linear>0</linear>
          <angular>0</angular>
        </velocity_decay>
        <inertial>
          <mass>1000</mass>
          <pose>1000 100 100 0 -0 0</pose>
          <inertia>
            <ixx>100</ixx>
            <ixy>100</ixy>
            <ixz>100</ixz>
            <iyy>100</iyy>
            <iyz>100</iyz>
            <izz>100</izz>
          </inertia>
        </inertial>
        <collision name='All_collision'>
          <pose>0 0 0 0 -0 0</pose>
          <geometry>
            <mesh>
              <scale>1 1 1</scale>
              <uri>model://2019-Field-3/meshes/All_col.STL</uri>
            </mesh>
          </geometry>
          <surface>
            <contact>
              <ode/>
            </contact>
            <friction>
              <ode>
                <mu>1</mu>
                <mu2>1</mu2>
              </ode>
              <torsional>
                <ode/>
              </torsional>
            </friction>
            <bounce/>
          </surface>
          <max_contacts>10</max_contacts>
        </collision>
        <visual name='All_visual'>
          <pose>0 0 0 0 -0 0</pose>
          <material>
            <ambient>0.5 0.5 0.5 1</ambient>
            <diffuse>0.5 0.5 0.5 1</diffuse>
          </material>
          <geometry>
            <mesh>
              <scale>1 1 1</scale>
              <uri>model://2019-Field-3/meshes/All.STL</uri>
            </mesh>
          </geometry>
        </visual>
        <enable_wind>0</enable_wind>
        <kinematic>0</kinematic>
      </link>
    </model>
    <model name='TapePatterns'>
      <pose>13.2 -3.85 4.5797 1.57 -0 0</pose>
      <static>1</static>
      <link name='All'>
        <gravity>1</gravity>
        <self_collide>0</self_collide>
        <pose>-11.2776 -4.572 -0 0 -0 0</pose>
        <must_be_base_link>1</must_be_base_link>
        <visual name='All_visual'>
          <pose>0 0 0 0 -0 0</pose>
          <material>
            <ambient>1 1 1 1</ambient>
            <diffuse>1 1 1 1</diffuse>
            <emissive>0.2 0.2 0.2 1</emissive>
          </material>
          <geometry>
            <mesh>
              <scale>1 1 1</scale>
              <uri>model://TapePatterns/meshes/All.STL</uri>
            </mesh>
          </geometry>
        </visual>
        <enable_wind>0</enable_wind>
        <kinematic>0</kinematic>
      </link>
    </model>
    <gravity>0 0 -9.8</gravity>
    <magnetic_field>6e-06 2.3e-05 -4.2e-05</magnetic_field>
    <atmosphere type='adiabatic'/>
    <physics type='ode'>
      <max_step_size>0.001</max_step_size>
      <real_time_factor>1</real_time_factor>
      <real_time_update_rate>1000</real_time_update_rate>
    </physics>
    <scene>
      <ambient>0.4 0.4 0.4 1</ambient>
      <background>0.7 0.7 0.7 1</background>
      <shadows>1</shadows>
    </scene>
    <wind/>
    <spherical_coordinates>
      <surface_model>EARTH_WGS84</surface_model>
      <latitude_deg>0</latitude_deg>
      <longitude_deg>0</longitude_deg>
      <elevation>0</elevation>
      <heading_deg>0</heading_deg>
    </spherical_coordinates>
    <state world_name='default'>
      <sim_time>36 425000000</sim_time>
      <real_time>72 958456800</real_time>
      <wall_time>1698687423 44085200</wall_time>
      <iterations>36425</iterations>
      <model name='2019-Field-3'>
        <pose>13.2 -3.861 4.5797 1.57 -0 0</pose>
        <scale>1 1 1</scale>
        <link name='All'>
          <pose>1.9224 -3.86464 0.007701 1.57 -0 0</pose>
          <velocity>0 0 0 0 -0 0</velocity>
          <acceleration>0 0 0 0 -0 0</acceleration>
          <wrench>0 0 0 0 -0 0</wrench>
        </link>
      </model>
      <model name='HatchPlate'>
        <pose>-5.44295 -5.03551 0.864861 0.021942 -0.246755 -0.040213</pose>
        <scale>1 1 1</scale>
        <link name='Black'>
          <pose>-5.44301 -5.0355 0.864851 1.40885 -0.188949 0.762808</pose>
          <velocity>0.113374 0.00016 0.041379 0.012368 -0.023775 0.003197</velocity>
          <acceleration>31.7271 -22.8376 -50.383 0 -0 0</acceleration>
          <wrench>0.451414 -0.324934 -0.71685 0 -0 0</wrench>
        </link>
        <link name='SolidBody'>
          <pose>-5.44142 -5.03544 0.858863 1.40958 -0.188882 0.763211</pose>
          <velocity>0.103742 0.000689 0.038072 0.013874 -0.023688 0.002635</velocity>
          <acceleration>31.221 -22.5915 -51.9087 1.80774 0.594977 -2.72453</acceleration>
          <wrench>10.4992 -7.59724 -17.4562 0 -0 0</wrench>
        </link>
        <link name='Yellow'>
          <pose>-5.44301 -5.0355 0.864851 1.40957 -0.188885 0.76321</pose>
          <velocity>0.113423 0.000358 0.041339 0.011883 -0.024057 0.002956</velocity>
          <acceleration>31.7802 -22.7845 -50.2827 0 -0 0</acceleration>
          <wrench>1.20437 -0.863462 -1.90556 0 -0 0</wrench>
        </link>
      </model>
      <model name='Platform2'>
        <pose>-3.9286 -3.8364 0.000104 -3.14 -2e-06 -0.000627</pose>
        <scale>1 1 1</scale>
        <link name='Platform2'>
          <pose>-5.17158 -3.83594 0.189324 1.5692 2e-06 3.14097</pose>
          <velocity>0 0 0 0 -0 0</velocity>
          <acceleration>0 0 0 0 -0 0</acceleration>
          <wrench>0 0 0 0 -0 0</wrench>
        </link>
      </model>
      <model name='SimBot2019'>
        <pose>-6.0917 -5.02692 0.323897 -0.001583 0.019913 3.13376</pose>
        <scale>1 1 1</scale>
        <link name='Bumpers'>
          <pose>-5.69195 -5.05105 0.331828 -1.55089 0.001583 -1.5786</pose>
          <velocity>-5.5e-05 -6e-05 -0.001208 -0.000133 0.00075 -9.1e-05</velocity>
          <acceleration>0.087882 -0.005507 -0.888035 -1.22813 1.34409 -3.11817</acceleration>
          <wrench>0.036314 -0.002275 -0.366943 0 -0 0</wrench>
        </link>
        <link name='Frame'>
          <pose>-5.68539 -5.0301 0.331989 -1.55089 0.001583 -1.5786</pose>
          <velocity>-5.2e-05 -6.5e-05 -0.00128 0.000399 0.001114 -0.000119</velocity>
          <acceleration>0.083304 -0.00727 -0.719903 0.022694 0.529558 3.1211</acceleration>
          <wrench>12.4955 -1.09056 -107.985 0 -0 0</wrench>
        </link>
        <link name='L1Wheel'>
          <pose>-5.41641 -4.72894 0.339477 -1.68974 0.001596 -1.5786</pose>
          <velocity>-1.4e-05 -8.7e-05 -0.00157 -0.000596 0.001519 -0.000113</velocity>
          <acceleration>0.093874 -0.011099 -0.857311 1.49216 0.977896 0.021523</acceleration>
          <wrench>0.023968 -0.002834 -0.218893 0 -0 0</wrench>
        </link>
        <link name='L2Wheel'>
          <pose>-5.68292 -4.72677 0.328859 -1.69199 0.001595 -1.5786</pose>
          <velocity>0.000134 6e-05 -0.002796 -0.00053 0.001315 -0.00011</velocity>
          <acceleration>0.083033 -0.165356 0.03204 1.62671 0.817864 0.021956</acceleration>
          <wrench>0.0212 -0.04222 0.008181 0 -0 0</wrench>
        </link>
        <link name='L3Wheel'>
          <pose>-5.94971 -4.72478 0.328906 -1.56483 0.001589 -1.5786</pose>
          <velocity>9.3e-05 3.5e-05 -0.002042 -0.000304 0.000915 -0.000102</velocity>
          <acceleration>0.061206 -0.176826 0.093854 1.7386 0.602832 0.02582</acceleration>
          <wrench>0.015627 -0.045148 0.023963 0 -0 0</wrench>
        </link>
        <link name='PegClimber1::FramePlate'>
          <pose>-5.55605 -4.74015 0.35998 -0.001583 0.019911 3.13376</pose>
          <velocity>-5.6e-05 -1.9e-05 -0.001098 3.1e-05 0.000868 -8.2e-05</velocity>
          <acceleration>0.030707 0.090475 -0.327673 0 -0 0</acceleration>
          <wrench>0.001304 0.003842 -0.013913 0 -0 0</wrench>
        </link>
        <link name='PegClimber1::PegPiston'>
          <pose>-5.55831 -4.74062 0.45446 -0.001583 0.019912 3.13376</pose>
          <velocity>4.4e-05 -4e-05 -0.001176 6.4e-05 0.000889 -8.1e-05</velocity>
          <acceleration>0.25319 -0.181568 -0.378798 0 -0 0</acceleration>
          <wrench>0.110947 -0.079563 -0.165989 0 -0 0</wrench>
        </link>
        <link name='PegClimber2::FramePlate'>
          <pose>-6.0822 -5.02703 0.349088 -0.001584 0.019912 3.13376</pose>
          <velocity>-9.4e-05 3.4e-05 -0.000674 0.000168 0.000961 -7.6e-05</velocity>
          <acceleration>0.015488 0.093028 0.176315 0 -0 0</acceleration>
          <wrench>0.000658 0.00395 0.007486 0 -0 0</wrench>
        </link>
        <link name='PegClimber2::PegPiston2'>
          <pose>-6.08446 -5.02751 0.443567 -0.001584 0.019912 3.13376</pose>
          <velocity>1.7e-05 -4e-06 -0.000737 0.000203 0.000983 -7.4e-05</velocity>
          <acceleration>0.253785 -0.208299 0.099377 0 -0 0</acceleration>
          <wrench>0.111208 -0.091276 0.043547 0 -0 0</wrench>
        </link>
        <link name='PegClimber::FramePlate'>
          <pose>-5.56066 -5.33113 0.359045 -0.001583 0.019911 3.13376</pose>
          <velocity>-0.000125 -2.2e-05 -0.000778 -0.000101 0.000774 -8.9e-05</velocity>
          <acceleration>0.039014 0.092779 -0.844437 0 -0 0</acceleration>
          <wrench>0.001657 0.003939 -0.035854 0 -0 0</wrench>
        </link>
        <link name='PegClimber::PegPiston'>
          <pose>-5.56292 -5.33161 0.453524 -0.001583 0.019911 3.13376</pose>
          <velocity>-3e-05 -2.9e-05 -0.000935 -7e-05 0.000795 -8.7e-05</velocity>
          <acceleration>0.247912 -0.146801 -1.10341 0 -0 0</acceleration>
          <wrench>0.108634 -0.064328 -0.483514 0 -0 0</wrench>
        </link>
        <link name='R1Wheel'>
          <pose>-5.42115 -5.33545 0.338514 -1.65198 0.001583 -1.5786</pose>
          <velocity>-7.9e-05 -9.9e-05 -0.001749 0.000432 0.000577 -0.000119</velocity>
          <acceleration>0.100902 -0.043669 -2.72568 -3.05147 0.973549 -0.022567</acceleration>
          <wrench>0.025763 -0.01115 -0.695935 0 -0 0</wrench>
        </link>
        <link name='R2Wheel'>
          <pose>-5.68876 -5.33332 0.327764 -1.71349 0.001583 -1.5786</pose>
          <velocity>0.000259 -3.6e-05 -0.015156 0.000579 0.002552 -0.000116</velocity>
          <acceleration>0.231686 -0.315624 -25.4883 0.352436 0.845222 3.11486</acceleration>
          <wrench>0.059155 -0.080587 -6.50779 0 -0 0</wrench>
        </link>
        <link name='R3Wheel'>
          <pose>-5.95443 -5.33118 0.327896 -1.45526 0.001597 -1.5786</pose>
          <velocity>0.000118 8e-05 0.000632 -0.000812 0.001158 -0.000111</velocity>
          <acceleration>0.069354 -0.120035 0.938268 1.16763 0.683209 0.021046</acceleration>
          <wrench>0.017708 -0.030648 0.239563 0 -0 0</wrench>
        </link>
        <model name='Elevator'>
          <pose>-5.43982 -4.76206 0.359301 3.14159 -0.003567 -9.5e-05</pose>
          <scale>1 1 1</scale>
          <link name='Carriage'>
            <pose>-5.60386 -5.03291 0.637585 1.57262 -0.522049 -0.008716</pose>
            <velocity>-0.040833 -0.00162 0.071599 0.001405 0.005065 0.000418</velocity>
            <acceleration>-41.3473 0.036971 70.7684 0 -0 0</acceleration>
            <wrench>-4.13473 0.003697 7.07684 0 -0 0</wrench>
          </link>
          <link name='ElevatorBase'>
            <pose>-5.77095 -5.03204 0.906338 1.57261 -0.522025 -0.008713</pose>
            <velocity>0.002042 -0.000642 0.000438 0.001887 0.006745 0.000396</velocity>
            <acceleration>-0.804442 0.393574 2.33773 0.487757 0.571168 -0.628373</acceleration>
            <wrench>-4.93703 2.41545 14.3471 0 -0 0</wrench>
          </link>
          <link name='FrameBase'>
            <pose>-5.50202 -5.03332 0.378956 1.57237 -0.023724 -0.007843</pose>
            <velocity>-0.001879 0.000377 -0.000532 0.002266 -0.020554 0.00047</velocity>
            <acceleration>-0.480609 0.32564 2.88067 1.13587 0.670138 -0.508458</acceleration>
            <wrench>-0.465036 0.315089 2.78732 0 -0 0</wrench>
          </link>
          <link name='Stage1'>
            <pose>-5.77588 -5.03349 0.922843 1.57261 -0.522029 -0.008712</pose>
            <velocity>0.002164 -0.000683 0.000363 0.001995 0.00649 0.000391</velocity>
            <acceleration>-0.712272 0.398136 2.24546 0.60738 0.379312 -0.825853</acceleration>
            <wrench>-3.66345 2.04774 11.5491 0 -0 0</wrench>
          </link>
          <link name='Stage2'>
            <pose>-5.77827 -5.03204 0.940759 1.57261 -0.522031 -0.008713</pose>
            <velocity>0.002293 -0.000703 0.000287 0.002229 0.006326 0.0003</velocity>
            <acceleration>-0.610301 0.409671 2.14737 -1.25185 0.230418 1.45069</acceleration>
            <wrench>-2.61528 1.75554 9.202 0 -0 0</wrench>
          </link>
          <link name='TilterBaseArm'>
            <pose>-6.0383 -5.0246 0.637254 1.57323 -0.86555 -0.009641</pose>
            <velocity>0.004591 -0.000255 -0.009273 0.002622 0.079455 0.001806</velocity>
            <acceleration>-1.5477 0.627274 -12.0892 -0.360312 -1.42693 2.1656</acceleration>
            <wrench>-0.640939 0.259769 -5.00643 0 -0 0</wrench>
          </link>
          <link name='TilterEleArm'>
            <pose>-5.87172 -5.03103 0.763865 1.57249 0.384408 -0.00717</pose>
            <velocity>0.003754 -0.000376 -0.003961 0.00171 -0.027841 0.000358</velocity>
            <acceleration>-1.44601 0.479093 -3.5442 -2.77155 1.27077 -2.01206</acceleration>
            <wrench>-0.743648 0.246386 -1.8227 0 -0 0</wrench>
          </link>
          <model name='Grabber2'>
            <pose>-5.45074 -5.02906 0.609264 3.14159 -0.003567 -9.5e-05</pose>
            <scale>1 1 1</scale>
            <link name='BasePlate'>
              <pose>-5.42424 -5.02803 0.677308 -0.251262 -0.00158 1.56299</pose>
              <velocity>-0.032424 0.01455 0.045903 0.001565 0.004756 0.000422</velocity>
              <acceleration>-28.3653 9.53597 19.9866 2.79255 0.216758 -2.95649</acceleration>
              <wrench>-2.83653 0.953597 1.99866 0 -0 0</wrench>
            </link>
            <link name='LeftArmIn'>
              <pose>-5.39004 -4.97116 0.777678 -0.780122 -0.607779 1.91407</pose>
              <velocity>-0.017043 0.006862 0.067943 0.020147 -0.006516 0.005143</velocity>
              <acceleration>-19.9551 -17.2543 57.7088 -1.83895 1.27822 -2.66277</acceleration>
              <wrench>-0.199551 -0.172543 0.577088 0 -0 0</wrench>
            </link>
            <link name='LeftArmOut'>
              <pose>-5.37359 -4.94264 0.781205 -0.778159 -0.606467 1.91249</pose>
              <velocity>0.024546 0.027528 0.061332 0.001725 0.00463 0.000392</velocity>
              <acceleration>-1.31744 -24.7783 28.698 -2.77954 0.706266 -2.90724</acceleration>
              <wrench>-0.013174 -0.247783 0.28698 0 -0 0</wrench>
            </link>
            <link name='LeftGrabber'>
              <pose>-5.43989 -4.97523 0.95794 -0.236318 0.023652 1.55672</pose>
              <velocity>0.103116 0.001534 0.039286 0.005325 0.00236 0.001322</velocity>
              <acceleration>31.3174 -22.6959 -51.4643 -2.06305 1.18359 -2.72637</acceleration>
              <wrench>0.313174 -0.226959 -0.514643 0 -0 0</wrench>
            </link>
            <link name='LeftWheel'>
              <pose>-5.48648 -4.95726 1.05188 -0.233623 0.028239 1.55562</pose>
              <velocity>-0.027877 0.001721 0.069193 -0.000786 0.006189 -0.000226</velocity>
              <acceleration>-28.6533 -9.31911 64.8281 -2.03797 1.16064 -2.7149</acceleration>
              <wrench>-0.131176 -0.042663 0.296786 0 -0 0</wrench>
            </link>
            <link name='Piston'>
              <pose>-5.4179 -5.03493 0.735422 -0.251261 -0.00158 1.56299</pose>
              <velocity>-0.037855 -0.000656 0.076357 0.001489 0.004773 0.00036</velocity>
              <acceleration>-47.6152 0.865157 78.1671 2.61841 0.288912 -3.11395</acceleration>
              <wrench>-0.476152 0.008652 0.781671 0 -0 0</wrench>
            </link>
            <link name='PistonLeft'>
              <pose>-5.37979 -4.97364 0.73192 -1.79927 -0.815163 2.79817</pose>
              <velocity>-0.039117 -0.004606 0.073251 0.019795 -0.006339 0.005078</velocity>
              <acceleration>-38.0499 -7.83937 75.9667 -1.85689 1.49924 -2.68578</acceleration>
              <wrench>-0.380499 -0.078394 0.759667 0 -0 0</wrench>
            </link>
            <link name='PistonRight'>
              <pose>-5.38049 -5.09667 0.731537 -1.78638 0.815273 0.338518</pose>
              <velocity>-0.045243 0.020772 0.063258 -0.005948 0.000503 -0.001509</velocity>
              <acceleration>-46.8243 24.9286 59.1874 -1.2098 -0.059518 1.39827</acceleration>
              <wrench>-0.468243 0.249286 0.591874 0 -0 0</wrench>
            </link>
            <link name='PistonTop'>
              <pose>-5.48107 -5.03423 0.704536 1.41749 -0.001581 1.56299</pose>
              <velocity>-0.037324 -0.003557 0.079865 0.0013 -0.014852 0.000321</velocity>
              <acceleration>-52.0196 0.197441 82.0167 -0.651844 -0.28007 0.010876</acceleration>
              <wrench>-0.520196 0.001974 0.820167 0 -0 0</wrench>
            </link>
            <link name='RightArmIn'>
              <pose>-5.39075 -5.0994 0.777655 -0.773186 0.601027 1.21718</pose>
              <velocity>-0.134118 0.084227 0.308681 -0.007203 -0.000202 -0.002047</velocity>
              <acceleration>-236.307 159.222 548.819 2.1988 1.0661 -1.29622</acceleration>
              <wrench>-2.36307 1.59222 5.48819 0 -0 0</wrench>
            </link>
            <link name='RightArmOut'>
              <pose>-5.37477 -5.12795 0.780919 -0.77408 0.601634 1.21646</pose>
              <velocity>-0.009573 0.083914 -0.153746 -0.005327 0.000511 -0.001194</velocity>
              <acceleration>-12.4928 191.139 -379.494 3.12437 0.90204 -0.248809</acceleration>
              <wrench>-0.124928 1.91139 -3.79494 0 -0 0</wrench>
            </link>
            <link name='RightGrabber'>
              <pose>-5.436 -5.1007 0.958647 -0.200298 -0.089092 1.58311</pose>
              <velocity>0.10428 -0.000642 0.03727 -0.005548 0.000396 -0.001218</velocity>
              <acceleration>31.8305 -22.2001 -54.9799 -2.72902 1.3409 -0.103846</acceleration>
              <wrench>0.318305 -0.222001 -0.549799 0 -0 0</wrench>
            </link>
            <link name='RightWheel'>
              <pose>-5.43168 -5.09713 1.06511 -0.19659 -0.095595 1.58442</pose>
              <velocity>0.118611 -0.222636 -0.094323 0.007195 0.008064 0.002071</velocity>
              <acceleration>233.298 -386.227 -292.954 1.70002 0.83585 -2.85686</acceleration>
              <wrench>1.06805 -1.76816 -1.34116 0 -0 0</wrench>
            </link>
            <link name='TopArmIn'>
              <pose>-5.49303 -5.03442 0.74979 0.617485 -0.001581 1.56299</pose>
              <velocity>-0.065508 0.018638 0.00731 0.001235 -0.01252 0.00032</velocity>
              <acceleration>-81.2929 17.9383 -55.886 -0.717405 -0.93522 0.023976</acceleration>
              <wrench>-0.812929 0.179383 -0.55886 0 -0 0</wrench>
            </link>
            <link name='TopArmOut'>
              <pose>-5.52475 -5.03433 0.741224 0.611252 -0.001582 1.56299</pose>
              <velocity>-0.115914 0.100865 0.047719 0.001435 -0.015794 0.000382</velocity>
              <acceleration>-132.625 131.118 40.108 2.88247 -0.856247 -2.97219</acceleration>
              <wrench>-1.32624 1.31118 0.40108 0 -0 0</wrench>
            </link>
            <link name='TopGrabber'>
              <pose>-5.52974 -5.03577 0.93195 -0.282516 -0.001581 1.56299</pose>
              <velocity>0.10295 0.000557 0.036346 0.001409 -0.012279 0.000402</velocity>
              <acceleration>31.495 -22.5682 -51.5254 2.89388 -0.250917 -3.04641</acceleration>
              <wrench>0.31495 -0.225682 -0.515254 0 -0 0</wrench>
            </link>
            <link name='TopWheel'>
              <pose>-5.55804 -5.06377 1.03059 -0.286925 -0.001581 1.56299</pose>
              <velocity>0.022261 -0.036064 0.074894 0.001379 -0.01144 0.000328</velocity>
              <acceleration>215.937 -189.837 114.438 -0.445019 -0.001632 0.014621</acceleration>
              <wrench>0.988569 -0.869079 0.523901 0 -0 0</wrench>
            </link>
          </model>
        </model>
      </model>
      <model name='TapePatterns'>
        <pose>13.2 -3.85 4.5797 1.57 -0 0</pose>
        <scale>1 1 1</scale>
        <link name='All'>
          <pose>1.9224 -3.85364 0.007701 1.57 -0 0</pose>
          <velocity>0 0 0 0 -0 0</velocity>
          <acceleration>0 0 0 0 -0 0</acceleration>
          <wrench>0 0 0 0 -0 0</wrench>
        </link>
      </model>
      <model name='ground_plane'>
        <pose>0 0 0 0 -0 0</pose>
        <scale>1 1 1</scale>
        <link name='link'>
          <pose>0 0 0 0 -0 0</pose>
          <velocity>0 0 0 0 -0 0</velocity>
          <acceleration>0 0 0 0 -0 0</acceleration>
          <wrench>0 0 0 0 -0 0</wrench>
        </link>
      </model>
      <light name='sun'>
        <pose>0 0 10 0 -0 0</pose>
      </light>
    </state>
    <model name='HatchPlate'>
      <!--<pose>-3.03081 -4.88295 0.1 0 -0 0</pose>-->
      <pose>-5.425 -5.034 0.8566 -0.0405 -0.184 -0.074</pose>
      <link name='SolidBody'>
        <gravity>1</gravity>
        <self_collide>0</self_collide>
        <pose>1.5e-05 -7e-06 -0.006191 1.5708 0 0.785398</pose>
        <must_be_base_link>1</must_be_base_link>
        <velocity_decay>
          <linear>0</linear>
          <angular>0</angular>
        </velocity_decay>
        <inertial>
          <mass>0.336287</mass>
          <pose>0 0 0 0 -0 0</pose>
          <inertia>
            <ixx>0.1</ixx>
            <ixy>0</ixy>
            <ixz>0</ixz>
            <iyy>0.1</iyy>
            <iyz>0</iyz>
            <izz>0.1</izz>
          </inertia>
        </inertial>
        <collision name='SolidBody_collision'>
          <pose>0 -0 8e-06 0 -0 0</pose>
          <geometry>
            <mesh>
              <scale>1 1 1</scale>
              <uri>model://HatchPlate/meshes/SolidBody_col.STL</uri>
            </mesh>
          </geometry>
          <surface>
            <contact>
              <ode>
                <max_vel>0</max_vel>
                <kp>1e+06</kp>
                <kd>10</kd>
              </ode>
            </contact>
            <friction>
              <ode>
                <mu>1</mu>
                <mu2>1</mu2>
              </ode>
              <torsional>
                <ode/>
              </torsional>
            </friction>
            <bounce/>
          </surface>
          <max_contacts>10</max_contacts>
        </collision>
        <visual name='SolidBody_visual'>
          <pose>0 -0 8e-06 0 -0 0</pose>
          <material>
            <ambient>1 1 1 1</ambient>
            <diffuse>1 1 1 1</diffuse>
          </material>
          <geometry>
            <mesh>
              <scale>1 1 1</scale>
              <uri>model://HatchPlate/meshes/SolidBody.STL</uri>
            </mesh>
          </geometry>
        </visual>
        <enable_wind>0</enable_wind>
        <kinematic>0</kinematic>
      </link>
      <link name='Yellow'>
        <gravity>1</gravity>
        <self_collide>0</self_collide>
        <pose>0 0 0 1.5708 0 0.785398</pose>
        <must_be_base_link>0</must_be_base_link>
        <velocity_decay>
          <linear>0</linear>
          <angular>0</angular>
        </velocity_decay>
        <inertial>
          <mass>0.0378969</mass>
          <pose>0 0 0 0 -0 0</pose>
          <inertia>
            <ixx>0</ixx>
            <ixy>0</ixy>
            <ixz>0</ixz>
            <iyy>0</iyy>
            <iyz>0</iyz>
            <izz>0</izz>
          </inertia>
        </inertial>
        <visual name='Yellow_visual'>
          <pose>-0 0.002631 -0 0 -0 0</pose>
          <material>
            <ambient>1 1 0 1</ambient>
            <diffuse>1 1 0 1</diffuse>
          </material>
          <geometry>
            <mesh>
              <scale>1 1 1</scale>
              <uri>model://HatchPlate/meshes/Yellow.STL</uri>
            </mesh>
          </geometry>
        </visual>
        <enable_wind>0</enable_wind>
        <kinematic>0</kinematic>
      </link>
      <joint name='SolidBody-Yellow' type='fixed'>
        <parent>SolidBody</parent>
        <child>Yellow</child>
        <pose>-0 0 -0 0 -0 0</pose>
      </joint>
      <link name='Black'>
        <gravity>1</gravity>
        <self_collide>0</self_collide>
        <pose>0 0 0 1.57 -0 0.785</pose>
        <must_be_base_link>0</must_be_base_link>
        <velocity_decay>
          <linear>0</linear>
          <angular>0</angular>
        </velocity_decay>
        <inertial>
          <mass>0.014228</mass>
          <pose>-0 -0.002631 0.074282 0 -0 0</pose>
          <inertia>
            <ixx>0</ixx>
            <ixy>0</ixy>
            <ixz>0</ixz>
            <iyy>0</iyy>
            <iyz>0</iyz>
            <izz>0</izz>
          </inertia>
        </inertial>
        <visual name='Black_visual'>
          <pose>0 0 0 0 -0 0</pose>
          <material>
            <ambient>0 0 0 1</ambient>
            <diffuse>0 0 0 1</diffuse>
          </material>
          <geometry>
            <mesh>
              <scale>1 1 1</scale>
              <uri>model://HatchPlate/meshes/Black_col.STL</uri>
            </mesh>
          </geometry>
        </visual>
        <enable_wind>0</enable_wind>
        <kinematic>0</kinematic>
      </link>
      <joint name='SolidBody-Black' type='fixed'>
        <parent>SolidBody</parent>
        <child>Black</child>
        <pose>0 -0.002631 0 0 -0 0</pose>
      </joint>
    </model>
  </world>
</sdf>
