<?xml version="1.0" encoding="utf-8"?>
<sdf version="1.5">

  <model name="SimBot2023">
    <pose>-0.308699 -0.320561 -0 0 -0 0</pose>
    
    <link name="Body">
      <gravity>1</gravity>
      <self_collide>0</self_collide>
      <pose>0.00985477473661245 0.0248042978721778 0.0167947827536739 0 0 0</pose>
      <must_be_base_link>1</must_be_base_link>
      <velocity_decay>
        <linear>0</linear>
        <angular>0</angular>
      </velocity_decay>
      <inertial>
        <mass>200</mass>
        <pose>0 0 0 0 0 0</pose>
        
      </inertial>
      <collision name="Body_collision">
         <!--<pose>-0.466349031070791 -0.0248042978721789 -1.93717245563794 0 0 0</pose>-->
        <pose>0 -0.05 0 1.57 0 0</pose>
        <geometry>
         <box>
            <size>1.0 0.589446 0.048094</size>
          </box>
          <!--
          <mesh>
            <scale>1 1 1</scale>
            <uri>model://SimBot2023/meshes/Body_col.STL</uri>
          </mesh>
          -->
        </geometry>
        <surface>
        <contact>
             <ode>
              <!-- 
              <max_vel>0.1</max_vel>
              <min_depth>0.001</min_depth>
              <soft_cfm>0.2</soft_cfm>
              <soft_erp>0.2</soft_erp>
              --> 
              <kd>1</kd>
              <kp>5e8</kp>
            </ode>          
          </contact>
        
          <friction>
            <ode>
              <mu>0</mu>
              <mu2>0</mu2>
            </ode>
          </friction>
        </surface>
      </collision>
      <visual name="Body_visual">
        <pose>-0.466349031070791 -0.0248042978721789 -1.93717245563794 0 0 0</pose>
        <material>
          <ambient>0.501960784313725 0.501960784313725 0.501960784313725 1</ambient>
          <diffuse>0.501960784313725 0.501960784313725 0.501960784313725 1</diffuse>
        </material>
        <geometry>
          <mesh>
            <scale>1 1 1</scale>
            <uri>model://SimBot2023/meshes/Body.STL</uri>
          </mesh>
        </geometry>
      </visual>
      <!---->
      <sensor name="Camera" type="camera">
        <visualize>0</visualize>
        <always_on>1</always_on>
        <pose>0 0.6 -0.28 -1.57 -0.2 -0.3</pose>
        <camera name="camera">
          <horizontal_fov>1.5707963267949</horizontal_fov>
          <image>
             <width>640</width>
            <height>480</height>
          </image>
          <clip>
            <near>0.05</near>
            <far>30</far>
          </clip>
        </camera>
         <plugin name="camera1" filename="sim_camera.dll">
          <topic>~/gazebo/frc/simulator/camera/0</topic>
          <port>9000</port>
          <fps>20</fps>
          <enabled>true</enabled>
          <savepath>tmp</savepath>
          <maxframes>1</maxframes>
        </plugin>
      </sensor>
      
    </link>
    <link name="FRdrive">
      <gravity>1</gravity>
      <self_collide>0</self_collide>
      <pose>0.390522917980719 -0.00811354847564073 0.237847957013419 0 0 0</pose>
      <must_be_base_link>0</must_be_base_link>
      <velocity_decay>
        <linear>0</linear>
        <angular>0.01</angular>
      </velocity_decay>
      <inertial>
        <mass>0.0891523549879112</mass>
        <pose>0 0 0 0 0 0</pose>
        
      </inertial>
      <visual name="FRdrive_visual">
        <pose>-0.847017174314898 0.00811354847563964 -2.15822562989768 0 0 0</pose>
        <material>
          <ambient>0.501960784313725 0.501960784313725 0.501960784313725 1</ambient>
          <diffuse>0.501960784313725 0.501960784313725 0.501960784313725 1</diffuse>
        </material>
        <geometry>
          <mesh>
            <scale>1 1 1</scale>
            <uri>model://SimBot2023/meshes/FRdrive.STL</uri>
          </mesh>
        </geometry>
      </visual>
    </link>
    <joint name="Body-FRdrive" type="revolute">
      <parent>Body</parent>
      <child>FRdrive</child>
      <pose>2.08201928120211E-06 -1.73472347597681E-18 0.000277042986581488 0 0 0</pose>
      <axis>
        <xyz>0 1 0</xyz>
        <dynamics>
          <damping>1</damping>
          <friction>1</friction>
        </dynamics>
      </axis>
    </joint>
    <link name="FRwheel">
      <gravity>1</gravity>
      <self_collide>0</self_collide>
      <pose>0.390524894652224 -0.045440778296 0.239779131380306 0 0 0</pose>
      <must_be_base_link>0</must_be_base_link>
      <velocity_decay>
        <linear>0</linear>
        <angular>0.002</angular>
      </velocity_decay>
      <inertial>
        <mass>0.123981366006225</mass>
        <pose>0 0 0 0 0 0</pose>
        
      </inertial>
      <collision name="FRwheel_collision">
        <pose>-0.847019150986402 0.0454407782959989 -2.16015680426457 0 0 0</pose>
        <geometry>
          <mesh>
            <scale>1 1 1</scale>
            <uri>model://SimBot2023/meshes/FRwheel_col.STL</uri>
          </mesh>
        </geometry>
        <surface>
        <!--
          <contact>
             <ode>
              <max_vel>0.1</max_vel>
              <soft_cfm>0.8</soft_cfm>
              <soft_erp>0.8</soft_erp>
              <kd>25</kd>
              <kp>1e6</kp>
              <min_depth>0.0001</min_depth>
            </ode>          
          </contact>
          -->
          <friction>
            <ode>
              <mu>2</mu>
              <mu2>2</mu2>
            </ode>
          </friction>
        </surface>
      </collision>
      <visual name="FRwheel_visual">
        <pose>-0.847019150986402 0.0454407782959989 -2.16015680426457 0 0 0</pose>
        <material>
          <ambient>0 1 0 1</ambient>
          <diffuse>0 1 0 1</diffuse>
        </material>
        <geometry>
          <mesh>
            <scale>1 1 1</scale>
            <uri>model://SimBot2023/meshes/FRwheel.STL</uri>
          </mesh>
        </geometry>
      </visual>
    </link>
    <joint name="FRdrive-FRwheel" type="revolute">
      <parent>FRdrive</parent>
      <child>FRwheel</child>
      <pose>3.5053368525606E-06 0.000114295457558644 -0.00120273472992993 0 0 0</pose>
      <axis>
        <xyz>0 0 -1</xyz>
        <dynamics>
          <damping>1</damping>
          <friction>1</friction>
        </dynamics>  
      </axis>
    </joint>
    <link name="FLdrive">
      <gravity>1</gravity>
      <self_collide>0</self_collide>
      <pose>0.390526514220831 -0.00811354846782578 -0.238402046668222 0 0 0</pose>
      <must_be_base_link>0</must_be_base_link>
      <velocity_decay>
        <linear>0</linear>
        <angular>0.01</angular>
      </velocity_decay>
      <inertial>
        <mass>0.0891523549651857</mass>
        <pose>0 0 0 0 0 0</pose>     
      </inertial>
      <visual name="FLdrive_visual">
        <pose>-0.84702077055501 0.0081135484678247 -1.68197562621604 0 0 0</pose>
        <material>
          <ambient>0.501960784313725 0.501960784313725 0.501960784313725 1</ambient>
          <diffuse>0.501960784313725 0.501960784313725 0.501960784313725 1</diffuse>
        </material>
        <geometry>
          <mesh>
            <scale>1 1 1</scale>
            <uri>model://SimBot2023/meshes/FLdrive.STL</uri>
          </mesh>
        </geometry>
      </visual>
    </link>
    <joint name="Body-FLdrive" type="revolute">
      <parent>Body</parent>
      <child>FLdrive</child>
      <pose>-1.51422083138897E-06 6.93889390390723E-18 0.000277046668222258 0 0 0</pose>
      <axis>
        <xyz>0 1 0</xyz>
        <dynamics>
          <damping>1</damping>
          <friction>1</friction>
        </dynamics>
      </axis>
    </joint>
    <link name="FLwheel">
      <gravity>1</gravity>
      <self_collide>0</self_collide>
      <pose>0.390532719294217 -0.0453594163528396 -0.237673541862736 0 0 0</pose>
      <must_be_base_link>0</must_be_base_link>
      <velocity_decay>
        <linear>0</linear>
        <angular>0.002</angular>
      </velocity_decay>
      <inertial>
        <mass>0.413564687541818</mass>
        <pose>0 0 0 0 0 0</pose>       
      </inertial>
      <collision name="FLwheel_collision">
        <pose>-0.847026975628395 0.0453594163528385 -1.68270413102153 0 0 0</pose>
        <geometry>
          <mesh>
            <scale>1 1 1</scale>
            <uri>model://SimBot2023/meshes/FLwheel_col.STL</uri>
          </mesh>
        </geometry>
        <surface>
        <!--
          <contact>
             <ode>
              <max_vel>0.1</max_vel>
              <soft_cfm>0.8</soft_cfm>
              <soft_erp>0.8</soft_erp>
              <kd>25</kd>
              <kp>1e6</kp>
              <min_depth>0.001</min_depth>
            </ode>          
          </contact>
          -->
          <friction>
            <ode>
              <mu>2</mu>
              <mu2>2</mu2>
            </ode>
          </friction>
        </surface>
      </collision>
      <visual name="FLwheel_visual">
        <pose>-0.847026975628395 0.0453594163528385 -1.68270413102153 0 0 0</pose>
        <material>
          <ambient>0 1 0 1</ambient>
          <diffuse>0 1 0 1</diffuse>
        </material>
        <geometry>
          <mesh>
            <scale>1 1 1</scale>
            <uri>model://SimBot2023/meshes/FLwheel.STL</uri>
          </mesh>
        </geometry>
      </visual>
    </link>
    <joint name="FLdrive-FLwheel" type="revolute">
      <parent>FLdrive</parent>
      <child>FLwheel</child>
      <pose>-1.01787932659247E-05 3.29335143967324E-05 -5.54598669211259E-08 0 0 0</pose>
      <axis>
        <xyz>0 0 -1</xyz>
        <dynamics>
          <damping>1</damping>
          <friction>1</friction>
        </dynamics>
      </axis>
    </joint>
    <link name="BRdrive">
      <gravity>1</gravity>
      <self_collide>0</self_collide>
      <pose>-0.38981757481044 -0.0081135495114501 0.238402047413451 0 0 0</pose>
      <must_be_base_link>0</must_be_base_link>
      <velocity_decay>
        <linear>0</linear>
        <angular>0.01</angular>
      </velocity_decay>
      <inertial>
        <mass>0.0891523590073493</mass>
        <pose>0 0 0 0 0 0</pose>
      </inertial>
      <visual name="BRdrive_visual">
        <pose>-0.066676681523738 0.00811354951144901 -2.15877972029771 0 0 0</pose>
        <material>
          <ambient>0.501960784313725 0.501960784313725 0.501960784313725 1</ambient>
          <diffuse>0.501960784313725 0.501960784313725 0.501960784313725 1</diffuse>
        </material>
        <geometry>
          <mesh>
            <scale>1 1 1</scale>
            <uri>model://SimBot2023/meshes/BRdrive.STL</uri>
          </mesh>
        </geometry>
      </visual>
    </link>
    <joint name="Body-BRdrive" type="revolute">
      <parent>Body</parent>
      <child>BRdrive</child>
      <pose>-1.68152373801467E-06 -8.67361737988404E-18 -0.000277047413450582 0 0 0</pose>
      <axis>
        <xyz>0 1 0</xyz>
        <dynamics>
          <damping>1</damping>
          <friction>1</friction>
        </dynamics>
      </axis>
    </joint>
    <link name="BRwheel">
      <gravity>1</gravity>
      <self_collide>0</self_collide>
      <pose>-0.389818236008278 -0.0453607471440594 0.237673576041824 0 0 0</pose>
      <must_be_base_link>0</must_be_base_link>
      <velocity_decay>
        <linear>0</linear>
        <angular>0.002</angular>
      </velocity_decay>
      <inertial>
        <mass>0.413564688849332</mass>
        <pose>0 0 0 0 0 0</pose>
      </inertial>
      <collision name="BRwheel_collision">
        <pose>-0.0666760203259 0.0453607471440583 -2.15805124892609 0 0 0</pose>
        <geometry>
          <mesh>
            <scale>1 1 1</scale>
            <uri>model://SimBot2023/meshes/BRwheel_col.STL</uri>
          </mesh>
        </geometry>
        <surface>
        <!--
          <contact>
            <ode>
              <max_vel>0.1</max_vel>
              <soft_cfm>0.8</soft_cfm>
              <soft_erp>0.8</soft_erp>
              <kd>25</kd>
              <kp>1e6</kp>
              <min_depth>0.0001</min_depth>
            </ode>          
          </contact>
          -->
          <friction>
            <ode>
              <mu>2</mu>
              <mu2>2</mu2>
            </ode>
          </friction>
        </surface>
      </collision>
      <visual name="BRwheel_visual">
        <pose>-0.0666760203259 0.0453607471440583 -2.15805124892609 0 0 0</pose>
        <material>
          <ambient>0 1 0 1</ambient>
          <diffuse>0 1 0 1</diffuse>
        </material>
        <geometry>
          <mesh>
            <scale>1 1 1</scale>
            <uri>model://SimBot2023/meshes/BRwheel.STL</uri>
          </mesh>
        </geometry>
      </visual>
    </link>
    <joint name="BRdrive-BRwheel" type="revolute">
      <parent>BRdrive</parent>
      <child>BRwheel</child>
      <pose>-3.7665044388957E-06 3.42643056162745E-05 2.29141998708826E-08 0 0 0</pose>
      <axis>
        <xyz>0 0 -1</xyz>
        <dynamics>
          <damping>1</damping>
          <friction>1</friction>
        </dynamics>
      </axis>
    </joint>
    <link name="BLdrive">
      <gravity>1</gravity>
      <self_collide>0</self_collide>
      <pose>-0.389815880758476 -0.0071726820171026 -0.237676179491394 0 0 0</pose>
      <must_be_base_link>0</must_be_base_link>
      <velocity_decay>
        <linear>0</linear>
        <angular>0.01</angular>
      </velocity_decay>
      <inertial>
        <mass>0.0869538722262852</mass>
        <pose>0 0 0 0 0 0</pose>
      </inertial>
      <visual name="BLdrive_visual">
        <pose>-0.0666783755757028 0.00717268201710151 -1.68270149339287 0 0 0</pose>
        <material>
          <ambient>0.501960784313725 0.501960784313725 0.501960784313725 1</ambient>
          <diffuse>0.501960784313725 0.501960784313725 0.501960784313725 1</diffuse>
        </material>
        <geometry>
          <mesh>
            <scale>1 1 1</scale>
            <uri>model://SimBot2023/meshes/BLdrive.STL</uri>
          </mesh>
        </geometry>
      </visual>
    </link>
    <joint name="Body-BLdrive" type="revolute">
      <parent>Body</parent>
      <child>BLdrive</child>
      <pose>-3.37557570311009E-06 -1.73472347597681E-18 -0.00044882050860573 0 0 0</pose>
      <axis>
        <xyz>0 1 0</xyz>
        <dynamics>
          <damping>1</damping>
          <friction>1</friction>
        </dynamics>
      </axis>
    </joint>
    <link name="BLwheel">
      <gravity>1</gravity>
      <self_collide>0</self_collide>
      <pose>-0.389819150986402 -0.0454407782960015 -0.239779131380305 0 0 0</pose>
      <must_be_base_link>0</must_be_base_link>
      <velocity_decay>
        <linear>0</linear>
        <angular>0.002</angular>
      </velocity_decay>
      <inertial>
        <mass>0.123981366006226</mass>
        <pose>0 0 0 0 0 0</pose>
      </inertial>
      <collision name="BLwheel_collision">
        <pose>-0.0666751053477763 0.0454407782960004 -1.68059854150396 0 0 0</pose>
        <geometry>
          <mesh>
            <scale>1 1 1</scale>
            <uri>model://SimBot2023/meshes/BLwheel_col.STL</uri>
          </mesh>
        </geometry>
        <surface>
        <!--
          <contact>
             <ode>
              <max_vel>0.1</max_vel>
              <soft_cfm>0.8</soft_cfm>
              <soft_erp>0.8</soft_erp>
              <kd>25</kd>
              <kp>1e6</kp>
              <min_depth>0.0001</min_depth>
            </ode>          
          </contact>
          -->
          <friction>
            <ode>
              <mu>2</mu>
              <mu2>2</mu2>
            </ode>
          </friction>
        </surface>
      </collision>
      <visual name="BLwheel_visual">
        <pose>-0.0666751053477763 0.0454407782960004 -1.68059854150396 0 0 0</pose>
        <material>
          <ambient>0 1 0 1</ambient>
          <diffuse>0 1 0 1</diffuse>
        </material>
        <geometry>
          <mesh>
            <scale>1 1 1</scale>
            <uri>model://SimBot2023/meshes/BLwheel.STL</uri>
          </mesh>
        </geometry>
      </visual>
    </link>
    <joint name="BLdrive-BLwheel" type="revolute">
      <parent>BLdrive</parent>
      <child>BLwheel</child>
      <pose>-3.50533685232468E-06 0.000114295457558339 0.00120273472992949 0 0 0</pose>
      <axis>
        <xyz>0 0 -1</xyz>
        <dynamics>
          <damping>1</damping>
          <friction>1</friction>
        </dynamics>
      </axis>
    </joint>
    <link name="LowerArm">
      <gravity>1</gravity>
      <self_collide>0</self_collide>
      <pose>-0.128555 0.642258 0.201682058992895 0 0 0.05305</pose>
      <must_be_base_link>0</must_be_base_link>
      <velocity_decay>
        <linear>0</linear>
        <angular>0.1</angular>
      </velocity_decay>
      <inertial>
        <mass>3.1900657983711</mass>
        <pose>0 0 0 0 0 0</pose>
       
      </inertial>
      <collision name="LowerArm_collision">
        <pose>-0.354426715365301 -0.648286652228779 -2.12205973187716 0 0 0</pose>
        <geometry>
          <mesh>
            <scale>1 1 1</scale>
            <uri>model://SimBot2023/meshes/LowerArm_col.STL</uri>
          </mesh>
        </geometry>
        <surface>
          <contact>
            <ode />
          </contact>
          <friction>
            <ode>
              <mu>0</mu>
              <mu2>0</mu2>
            </ode>
          </friction>
        </surface>
      </collision>
      <visual name="LowerArm_visual">
        <pose>-0.354426715365301 -0.648286652228779 -2.12205973187716 0 0 0</pose>
        <material>
          <ambient>0.250980392156863 0.501960784313725 0.501960784313725 1</ambient>
          <diffuse>0.250980392156863 0.501960784313725 0.501960784313725 1</diffuse>
        </material>
        <geometry>
          <mesh>
            <scale>1 1 1</scale>
            <uri>model://SimBot2023/meshes/LowerArm.STL</uri>
          </mesh>
        </geometry>
      </visual>
      
    </link>
    <joint name="Body-LowerArm" type="revolute">
      <parent>Body</parent>
      <child>LowerArm</child>
      <pose>0.1003602846347 -0.502236652228779 0 0 0 0</pose>
      <axis>
        <xyz>0 0 1</xyz>
        <dynamics>
          <damping>2</damping>
          <friction>1</friction>
        </dynamics>
        <limit>
         <lower>-1.3</lower>
         <upper>0.08</upper>
        </limit>
      </axis>
    </joint>
    <link name="UpperArm">
      <gravity>1</gravity>
      <self_collide>0</self_collide>
      <pose>-0.065 0.9198 0.132747045366589 0 0 .6</pose>
      <must_be_base_link>0</must_be_base_link>
      <velocity_decay>
        <linear>0</linear>
        <angular>0.1</angular>
      </velocity_decay>
      <inertial>
        <mass>2.35701643914108</mass>
        <pose>0 0 0 0 0 0</pose>
        
      </inertial>
      <collision name="UpperArm_collision">
        <pose>-0.247749308369066 -0.86599122836257 -2.05312471825085 0 0 0</pose>
        <geometry>
          <mesh>
            <scale>1 1 1</scale>
            <uri>model://SimBot2023/meshes/UpperArm_col.STL</uri>
          </mesh>
        </geometry>
        <surface>
          <contact>
            <ode />
          </contact>
          <friction>
            <ode>
              <mu>1</mu>
              <mu2>1</mu2>
            </ode>
          </friction>
        </surface>
      </collision>
      <visual name="UpperArm_visual">
        <pose>-0.247749308369066 -0.86599122836257 -2.05312471825085 0 0 0</pose>
        <material>
          <ambient>0.250980392156863 0.501960784313725 0.501960784313725 1</ambient>
          <diffuse>0.250980392156863 0.501960784313725 0.501960784313725 1</diffuse>
        </material>
        <geometry>
          <mesh>
            <scale>1 1 1</scale>
            <uri>model://SimBot2023/meshes/UpperArm.STL</uri>
          </mesh>
        </geometry>
      </visual>
    </link>
    <joint name="LowerArm-UpperArm" type="revolute">
      <parent>LowerArm</parent>
      <child>UpperArm</child>
      <pose>-0.0078763379280225 0.355568315938512 0 0 0 0</pose>
      <axis>
        <xyz>0 0 1</xyz>
        <dynamics>
          <damping>2</damping>
          <friction>1</friction>
        </dynamics>
         <limit>
         <lower>-0.08</lower>
         <upper>2.0</upper>
        </limit>
      </axis>
    </joint>
    <link name="GripperRotate">
      <gravity>1</gravity>
      <self_collide>0</self_collide>
      <pose>0.1827 0.5786 0.023460469661692 0 0 -1.47154</pose>
      <must_be_base_link>0</must_be_base_link>
      <velocity_decay>
        <linear>0</linear>
        <angular>0.05</angular>
      </velocity_decay>
      <inertial>
        <mass>0.14389059238857</mass>
        <pose>0 0 0 0 0 0</pose>
       
      </inertial>
      <collision name="GripperRotate_collision">
        <pose>-0.258073873233665 -0.446967540730029 -1.94383814254595 0 0 0</pose>
        <geometry>
          <mesh>
            <scale>1 1 1</scale>
            <uri>model://SimBot2023/meshes/GripperRotate_col.STL</uri>
          </mesh>
        </geometry>
        <surface>
          <contact>
            <ode />
          </contact>
          <friction>
            <ode>
              <mu>1</mu>
              <mu2>1</mu2>
            </ode>
          </friction>
        </surface>
      </collision>
      <visual name="GripperRotate_visual">
        <pose>-0.258073873233665 -0.446967540730029 -1.94383814254595 0 0 0</pose>
        <material>
          <ambient>0.752941176470588 0.752941176470588 0.752941176470588 1</ambient>
          <diffuse>0.752941176470588 0.752941176470588 0.752941176470588 1</diffuse>
        </material>
        <geometry>
          <mesh>
            <scale>1 1 1</scale>
            <uri>model://SimBot2023/meshes/GripperRotate.STL</uri>
          </mesh>
        </geometry>
      </visual>
    </link>
    <joint name="UpperArm-GripperRotate" type="revolute">
      <parent>UpperArm</parent>
      <child>GripperRotate</child>
      <pose>-0.000595887983165122 -0.00219462585143981 0 0 0 0</pose>
      <axis>
        <xyz>0 0 1</xyz>
        <dynamics>
          <damping>1</damping>
          <friction>1</friction>
        </dynamics>
      </axis>
    </joint>
  <model name="Gripper">
    <pose>1.216 0.996 -0.058 0.0052 -0.0028 2</pose>
    <link name="GripperTwist">
      <gravity>1</gravity>
      <self_collide>0</self_collide>
      <pose>-0.13 1.118 0.01306 0.0018 0.00 -2.38</pose>
      <must_be_base_link>0</must_be_base_link>
      <velocity_decay>
        <linear>0</linear>
        <angular>0</angular>
      </velocity_decay>
      <inertial>
        <mass>0.1</mass>
        <pose>0 0 0 0 0 0</pose>
      </inertial>
      <collision name="GripperTwist_collision">
      <pose>0.0  -0.04 0.0  0  1.57 0.67 </pose>
      <!--<pose>-0.602543047746872 -1.0967249869109 -1.91914278295272 0 0 0</pose>-->
        <geometry>
         <box>
            <size>0.334186 0.18325 0.055666</size>
        </box>
      
        </geometry>
        <surface>
          <contact>
            <ode />
          </contact>
          <friction>
            <ode>
              <mu>4</mu>
              <mu2>4</mu2>
            </ode>
          </friction>
        </surface>
      </collision>
      <visual name="GripperTwist_visual">
        <pose>-0.602543047746872 -1.0967249869109 -1.91914278295272 0 0 0</pose>
        <material>
          <ambient>0.752941176470588 0.752941176470588 0.752941176470588 1</ambient>
          <diffuse>0.752941176470588 0.752941176470588 0.752941176470588 1</diffuse>
        </material>
        <geometry>
          <mesh>
            <scale>1 1 1</scale>
            <uri>model://Gripper/meshes/GripperTwist.STL</uri>
          </mesh>
        </geometry>
      </visual>
      
    </link>
    <joint name="GripperRotate-GripperTwist" type="fixed">
      <parent>GripperRotate</parent>
      <child>GripperTwist</child>
      <pose>-0.038351588966394 -0.0753937915180227 0.0266113955059517 0 0 4.71238898038469</pose>
      <axis>
        <xyz>0.887836308761871 0.460159416772162 0</xyz>
        <dynamics>
          <damping>2</damping>
          <friction>1</friction>
        </dynamics>
      </axis>
    </joint>
    <link name="LeftGripper">
      <gravity>1</gravity>
      <self_collide>0</self_collide>
       <!--<pose>0.241320498086195 0.969184291056408 -0.158494078621501 0 0 0</pose>-->
     <pose>-0.293 1.146 -0.1574 -0.0915 -0.0753 -2.385</pose>
      <must_be_base_link>0</must_be_base_link>
      <velocity_decay>
        <linear>0</linear>
        <angular>0.0</angular>
      </velocity_decay>
      <inertial>
        <mass>0.05</mass>
        <pose>0 0 0 0 0 0</pose>
      </inertial>
      
      <visual name="LeftGripper_visual">
        <pose>-0.697814754420374 -0.969184291056409 -1.7405664858757 0 0 0</pose>
        <material>
          <ambient>0.752941176470588 0.752941176470588 0.752941176470588 1</ambient>
          <diffuse>0.752941176470588 0.752941176470588 0.752941176470588 1</diffuse>
        </material>
        <geometry>
          <mesh>
            <scale>1 1 1</scale>
            <uri>model://Gripper/meshes/LeftGripper.STL</uri>
          </mesh>
        </geometry>
      </visual>
    </link>
    <joint name="GripperTwist-LeftGripper" type="revolute">
      <parent>GripperTwist</parent>
      <child>LeftGripper</child>
      <pose>-0.054185747678801 0.0570231645355036 0.0238046710258071 0 0.0158713592468967 1.59696957940531</pose>
      <axis>
        <xyz>0.585394002287998 -0.810722241994805 -0.00658091332233763</xyz>
        <dynamics>
          <damping>2</damping>
          <friction>2</friction>
        </dynamics>
        <limit>
          <upper>0.2</upper>
          <lower>-0.5</lower>
        </limit>
      </axis>
    </joint>
    <link name="RightGripper">
      <gravity>1</gravity>
      <self_collide>0</self_collide>
      <!--<pose>0.246191175008786 0.971708729210025 0.181958210199892 0 0 0</pose>-->
      <pose>-0.294 1.142 0.167 0.0668 0.0444 -2.401</pose>
      <must_be_base_link>0</must_be_base_link>
      <velocity_decay>
        <linear>0</linear>
        <angular>0.0</angular>
      </velocity_decay>
      <inertial>
        <mass>0.05</mass>
        <pose>0 0 0 0 0 0</pose>
      </inertial>
     
      <visual name="RightGripper_visual">
        <pose>-0.702685431342964 -0.971708729210026 -2.0810187746971 0 0 0</pose>
        <material>
          <ambient>0.752941176470588 0.752941176470588 0.752941176470588 1</ambient>
          <diffuse>0.752941176470588 0.752941176470588 0.752941176470588 1</diffuse>
        </material>
        <geometry>
          <mesh>
            <scale>1 1 1</scale>
            <uri>model://Gripper/meshes/RightGripper.STL</uri>
          </mesh>
        </geometry>
      </visual>
    </link>
    <joint name="GripperTwist-RightGripper" type="revolute">
      <parent>GripperTwist</parent>
      <child>RightGripper</child>
      <pose>-0.0548566132662593 0.0566754595425552 -0.0230877277876074 0 0.0158713592468967 1.59696957940531</pose>
      <axis>
        <xyz>-0.585394002287996 0.810722241994806 -0.00658091332233764</xyz>
        <dynamics>
          <damping>2</damping>
          <friction>2</friction>
        </dynamics>
        <limit>
          <upper>0.2</upper>
          <lower>-0.5</lower>
        </limit>
      </axis>
    </joint>
    <link name="LeftPad">
      <gravity>1</gravity>
      <self_collide>0</self_collide>
      <!--<pose>0.334045450628088 0.846041003834395 -0.21678381156418 0 0 0</pose>-->
      <pose>-0.431 1.167 -0.193 0.388 0.278 -2.34</pose>
      <must_be_base_link>0</must_be_base_link>
      <velocity_decay>
        <linear>0</linear>
        <angular>0</angular>
      </velocity_decay>
      <inertial>
        <mass>0.01</mass>
        <pose>0 0 0 0 0 0</pose>
      </inertial>
      <collision name="LeftPad_collision">
      <pose>0.0  0 0.0  0  1.57 0.67 </pose>
        <!--<pose>-0.790539706962267 -0.846041003834396 -1.68227675293302 0 0 0</pose>-->
        <geometry>
         <cylinder>
            <radius>0.06</radius>
            <length>0.11</length>
        </cylinder>
        </geometry>
        <surface>
         <contact>
            <ode>
              <min_depth>0.001</min_depth>
              <kp>1e3</kp>
              <kd>1e7</kd>
            </ode>          
          </contact>
          <torsional>
            <ode>
              <coefficient>1</coefficient>
              <slip>0</slip>
            </ode>
          </torsional>
          <friction>
            <ode>
              <mu>10</mu>
              <mu2>10</mu2>
            </ode>
          </friction>
        </surface>
      </collision>
      <visual name="LeftPad_visual">
        <pose>-0.790539706962267 -0.846041003834396 -1.68227675293302 0 0 0</pose>
        <material>
          <ambient>0 0.501960784313725 0.501960784313725 1</ambient>
          <diffuse>0 0.501960784313725 0.501960784313725 1</diffuse>
        </material>
        <geometry>
          <mesh>
            <scale>1 1 1</scale>
            <uri>model://Gripper/meshes/LeftPad.STL</uri>
          </mesh>
        </geometry>
      </visual>
    </link>
    <joint name="LeftGripper-LeftPad" type="fixed">
      <parent>LeftGripper</parent>
      <child>LeftPad</child>
      <pose>-0.00707124173938922 -0.00539133761890198 0.000141142572698261 0 0.0158713592468798 1.59696957940528</pose>
      <axis>
        <xyz>0.585394002288015 -0.810722241994793 -0.00658091332233035</xyz>
        <dynamics>
          <damping>1</damping>
          <friction>1</friction>
        </dynamics>
      </axis>
    </joint>
    <link name="RightPad">
      <gravity>1</gravity>
      <self_collide>0</self_collide>
      <!--<pose>0.3306064908218 0.847323504491162 0.220265006162646 0 0 0</pose>-->
      <pose>-0.425 1.175 0.224 2.2 0.574 -1.385</pose>
      <must_be_base_link>0</must_be_base_link>
      <velocity_decay>
        <linear>0</linear>
        <angular>0</angular>
      </velocity_decay>
      <inertial>
        <mass>0.01</mass>
        <pose>0 0 0 0 0 0</pose>
      </inertial>
      <collision name="RightPad_collision">
      <pose>0.012  -0.0 0.02  0  1.57 0.67 </pose>
        <!--<pose>-0.787100747155979 -0.847323504491163 -2.11932557065985 0 0 0</pose>-->
        <geometry>
        <cylinder>
            <radius>0.06</radius>
            <length>0.11</length>
        </cylinder>
       
        </geometry>
        <surface>
        <!-- -->
          <contact>
            <ode>
              <min_depth>0.001</min_depth>
              <kp>1e3</kp>
              <kd>1e7</kd>
            </ode>          
          </contact>
          <torsional>
            <ode>
              <coefficient>1</coefficient>
              <slip>0</slip>
            </ode>
          </torsional>
         
          <friction>
            <ode>
              <mu>10</mu>
              <mu2>10</mu2>
            </ode>
          </friction>
        </surface>
        
      </collision>
      <visual name="RightPad_visual">
        <pose>-0.787100747155979 -0.847323504491163 -2.11932557065985 0 0 0</pose>
        <material>
          <ambient>0 0.501960784313725 0.501960784313725 1</ambient>
          <diffuse>0 0.501960784313725 0.501960784313725 1</diffuse>
        </material>
        <geometry>
          <mesh>
            <scale>1 1 1</scale>
            <uri>model://Gripper/meshes/RightPad.STL</uri>
          </mesh>
        </geometry>
      </visual>
    </link>
    <joint name="RightGripper-RightPad" type="fixed">
      <parent>RightGripper</parent>
      <child>RightPad</child>
      <pose>0.0 0.0 0.02 0 0.0158713592468729 1.59696957940527</pose>
      <axis>
        <xyz>0.585394002288031 -0.810722241994781 -0.00658091332232724</xyz>
        <dynamics>
          <damping>1</damping>
          <friction>1</friction>
        </dynamics>
      </axis>
    </joint> 
    <link name="LeftPad2">
      <gravity>1</gravity>
      <self_collide>0</self_collide>
      <!--<pose>0.267729827818469 0.934037484108341 -0.177919376276616 0 0 0</pose>-->
      <pose>-0.3386 1.153 -0.171 0.158 0.1148 -2.384</pose>
      <must_be_base_link>0</must_be_base_link>
      <velocity_decay>
        <linear>0</linear>
        <angular>0</angular>
      </velocity_decay>
      <inertial>
        <mass>0.01</mass>
        <pose>0 0 0 0 0 0</pose>
      </inertial>
      <collision name="LeftPad2_collision">
        <pose>0.0  0 0.0  0  1.57 0.67 </pose>
        <!--<pose>-0.724224084152647 -0.934037484108342 -1.72114118822059 0 0 0</pose>-->
        <geometry>
           <cylinder>
            <radius>0.06</radius>
            <length>0.11</length>
        </cylinder>
        </geometry>
        <surface>
         <contact>
            <ode>
              <min_depth>0.001</min_depth>
              <kp>1e3</kp>
              <kd>1e7</kd>
            </ode>          
          </contact>
          <torsional>
            <ode>
              <coefficient>1</coefficient>
              <slip>0</slip>
            </ode>
          </torsional>
          <friction>
            <ode>
              <mu>10</mu>
              <mu2>10</mu2>
            </ode>
          </friction>
          
        </surface>
      </collision>
      <visual name="LeftPad2_visual">
        <pose>-0.724224084152647 -0.934037484108342 -1.72114118822059 0 0 0</pose>
        <material>
          <ambient>0.250980392156863 0.501960784313725 0.501960784313725 1</ambient>
          <diffuse>0.250980392156863 0.501960784313725 0.501960784313725 1</diffuse>
        </material>
        <geometry>
          <mesh>
            <scale>1 1 1</scale>
            <uri>model://Gripper/meshes/LeftPad2.STL</uri>
          </mesh>
        </geometry>
      </visual>
    </link>
    <joint name="LeftGripper-LeftPad2" type="fixed">
      <parent>LeftGripper</parent>
      <child>LeftPad2</child>
      <pose>-0.00707123917503549 -0.00539134103551542 0.000141140539531293 0 0.0158713592468895 1.5969695794053</pose>
      <axis>
        <xyz>0.585394002288009 -0.810722241994798 -0.00658091332233447</xyz>
        <dynamics>
          <damping>1</damping>
          <friction>1</friction>
        </dynamics>
      </axis>
    </joint>
    <link name="RightPad2">
      <gravity>1</gravity>
      <self_collide>0</self_collide>
      <!--<pose>0.273152825042775 0.936848188163066 0.201139058060381 0 0 0</pose>-->
      <pose>-0.339 1.149 0.183 0.0183 0.0109 -2.39</pose>
      <must_be_base_link>0</must_be_base_link>
      <velocity_decay>
        <linear>0</linear>
        <angular>0</angular>
      </velocity_decay>
      <inertial>
        <mass>0.01</mass>
        <pose>0 0 0 0 0 0</pose>
      </inertial>
      <collision name="RightPad2_collision">
      <pose>0.0  0 0.0  0  1.57 0.67 </pose>
        <!--<pose>-0.729647081376953 -0.936848188163068 -2.10019962255758 0 0 0</pose>-->
        <geometry>
         <cylinder>
            <radius>0.06</radius>
            <length>0.11</length>
        </cylinder>
        </geometry>
        <surface>
         <contact>
            <ode>
              <min_depth>0.001</min_depth>
              <kp>1e3</kp>
              <kd>1e7</kd>
            </ode>          
          </contact>
          <torsional>
            <ode>
              <coefficient>1</coefficient>
              <slip>0</slip>
            </ode>
          </torsional>
          <friction>
            <ode>
              <mu>10</mu>
              <mu2>10</mu2>
            </ode>
          </friction>
          
        </surface>
      </collision>
      <visual name="RightPad2_visual">
        <pose>-0.729647081376953 -0.936848188163068 -2.10019962255758 0 0 0</pose>
        <material>
          <ambient>0.250980392156863 0.501960784313725 0.501960784313725 1</ambient>
          <diffuse>0.250980392156863 0.501960784313725 0.501960784313725 1</diffuse>
        </material>
        <geometry>
          <mesh>
            <scale>1 1 1</scale>
            <uri>model://Gripper/meshes/RightPad2.STL</uri>
          </mesh>
        </geometry>
      </visual>
    </link>
    <joint name="RightGripper-RightPad2" type="fixed">
      <parent>RightGripper</parent>
      <child>RightPad2</child>
      <pose>-0.00707123836826895 -0.00539134206835934 0.000141141506121656 0 0.0158713592468928 1.5969695794053</pose>
      <axis>
        <xyz>0.585394002288003 -0.810722241994801 -0.00658091332233593</xyz>
        <dynamics>
          <damping>1</damping>
          <friction>1</friction>
        </dynamics>
      </axis>
    </joint>

    <plugin name="GripperTwist-LeftGripper" filename="sim_piston.dll">
        <joint>GripperTwist-LeftGripper</joint>
        <topic>~/gazebo/frc/simulator/piston/0</topic>
        <forward-force>20</forward-force>
        <reverse-force>20</reverse-force>
    </plugin>
     <plugin name="GripperTwist-RightGripper" filename="sim_piston.dll">
        <joint>GripperTwist-RightGripper</joint>
        <topic>~/gazebo/frc/simulator/piston/0</topic>
        <forward-force>20</forward-force>
        <reverse-force>20</reverse-force>    
      </plugin>
 <!--
       <plugin name="left_pad" filename="sim_motor.dll">
        <joint>LeftGripper-LeftPad</joint>
        <topic>~/gazebo/frc/simulator/motor/12</topic>
        <multiplier>10</multiplier>
    </plugin>

     <plugin name="left_pad2" filename="sim_motor.dll">
        <joint>LeftGripper-LeftPad2</joint>
        <topic>~/gazebo/frc/simulator/motor/12</topic>
        <multiplier>10</multiplier>
    </plugin>

     <plugin name="right_pad" filename="sim_motor.dll">
        <joint>RightGripper-RightPad</joint>
        <topic>~/gazebo/frc/simulator/motor/12</topic>
        <multiplier>-10</multiplier>
    </plugin>

    <plugin name="right_pad2" filename="sim_motor.dll">
        <joint>RightGripper-RightPad2</joint>
        <topic>~/gazebo/frc/simulator/motor/12</topic>
        <multiplier>-10</multiplier>
    </plugin>
   
      <plugin name="GripperRotate-GripperTwist_motor" filename="sim_motor.dll">
        <joint>GripperRotate-GripperTwist</joint>
        <topic>~/gazebo/frc/simulator/motor/12</topic>
        <multiplier>50</multiplier>
    </plugin>
    -->
  
  </model>
  <plugin name="clock" filename="sim_clock.dll">
      <topic>~/gazebo/frc/simulator/clock</topic>
    </plugin>
   <plugin name="Body_gyro" filename="sim_gyro.dll">
      <link>Body</link>
      <topic>~/gazebo/frc/simulator/gyro/0</topic>
      <units>degrees</units>
      <axis>yaw</axis>
    </plugin>
   
    <plugin name="Frame-FL-drive_motor" filename="sim_motor.dll">
      <joint>FLdrive-FLwheel</joint>
      <topic>~/gazebo/frc/simulator/motor/1</topic>
      <multiplier>25</multiplier>
    </plugin>
    <plugin name="Frame-FL-drive_encoder" filename="sim_encoder.dll">
        <joint>FLdrive-FLwheel</joint>
        <topic>~/gazebo/frc/simulator/encoder/1</topic>
        <multiplier>1</multiplier>
    </plugin> 
    <plugin name="Frame-FL-turn_motor" filename="sim_motor.dll">
        <joint>Body-FLdrive</joint>
        <topic>~/gazebo/frc/simulator/motor/2</topic>
        <multiplier>25</multiplier>
    </plugin>
      <plugin name="Frame-FL-turn_encoder" filename="sim_encoder.dll">
      <joint>Body-FLdrive</joint>
       <topic>~/gazebo/frc/simulator/encoder/2</topic>
      <multiplier>1</multiplier>
    </plugin>
 
    <plugin name="Frame-FR-drive_motor" filename="sim_motor.dll">
        <joint>FRdrive-FRwheel</joint>
        <topic>~/gazebo/frc/simulator/motor/3</topic>
        <multiplier>25</multiplier>
    </plugin>
    <plugin name="Frame-FR-drive_encoder" filename="sim_encoder.dll">
        <joint>FRdrive-FRwheel</joint>
        <topic>~/gazebo/frc/simulator/encoder/3</topic>
        <multiplier>1</multiplier>
    </plugin> 
    <plugin name="Frame-FR-turn_motor" filename="sim_motor.dll">
        <joint>Body-FRdrive</joint>
        <topic>~/gazebo/frc/simulator/motor/4</topic>
        <multiplier>25</multiplier>
    </plugin>
    <plugin name="Frame-FR-turn_encoder" filename="sim_encoder.dll">
      <joint>Body-FRdrive</joint>
       <topic>~/gazebo/frc/simulator/encoder/4</topic>
      <multiplier>1</multiplier>
    </plugin>

    <plugin name="Frame-BL-drive_motor" filename="sim_motor.dll">
        <joint>BLdrive-BLwheel</joint>
        <topic>~/gazebo/frc/simulator/motor/5</topic>
        <multiplier>25</multiplier>
    </plugin>
    <plugin name="Frame-BL-drive_encoder" filename="sim_encoder.dll">
        <joint>BLdrive-BLwheel</joint>
        <topic>~/gazebo/frc/simulator/encoder/5</topic>
        <multiplier>1</multiplier>
    </plugin> 
    <plugin name="Frame-BL-turn_motor" filename="sim_motor.dll">
        <joint>Body-BLdrive</joint>
        <topic>~/gazebo/frc/simulator/motor/6</topic>
        <multiplier>25</multiplier>
    </plugin>
    <plugin name="Frame-BL-turn_encoder" filename="sim_encoder.dll">
        <joint>Body-BLdrive</joint>
        <topic>~/gazebo/frc/simulator/encoder/6</topic>
        <multiplier>1</multiplier>
    </plugin>

    <plugin name="Frame-BR-drive_motor" filename="sim_motor.dll">
        <joint>BRdrive-BRwheel</joint>
        <topic>~/gazebo/frc/simulator/motor/7</topic>
        <multiplier>25</multiplier>
    </plugin>
      <plugin name="Frame-BR-drive_encoder" filename="sim_encoder.dll">
        <joint>BRdrive-BRwheel</joint>
        <topic>~/gazebo/frc/simulator/encoder/7</topic>
        <multiplier>1</multiplier>
    </plugin> 
    <plugin name="Frame-BR-turn_motor" filename="sim_motor.dll">
        <joint>Body-BRdrive</joint>
        <topic>~/gazebo/frc/simulator/motor/8</topic>
        <multiplier>25</multiplier>
    </plugin>
    <plugin name="Frame-BR-turn_encoder" filename="sim_encoder.dll">
        <joint>Body-BRdrive</joint>
        <topic>~/gazebo/frc/simulator/encoder/8</topic>
        <multiplier>1</multiplier>
    </plugin>

    <plugin name="Frame-lower-arm_motor" filename="sim_motor.dll">
        <joint>Body-LowerArm</joint>
        <topic>~/gazebo/frc/simulator/motor/9</topic>
        <multiplier>50</multiplier>
    </plugin>
    <plugin name="Frame-lower-arm_encoder" filename="sim_encoder.dll">
        <joint>Body-LowerArm</joint>
        <topic>~/gazebo/frc/simulator/encoder/9</topic>
        <multiplier>1</multiplier>
    </plugin>

    <plugin name="LowerArm-UpperArm_motor" filename="sim_motor.dll">
        <joint>LowerArm-UpperArm</joint>
        <topic>~/gazebo/frc/simulator/motor/10</topic>
        <multiplier>50</multiplier>
    </plugin>
    <plugin name="LowerArm-UpperArm_encoder" filename="sim_encoder.dll">
        <joint>LowerArm-UpperArm</joint>
        <topic>~/gazebo/frc/simulator/encoder/10</topic>
        <multiplier>1</multiplier>
    </plugin>

    <plugin name="UpperArm-Wrist_motor" filename="sim_motor.dll">
        <joint>UpperArm-GripperRotate</joint>
        <topic>~/gazebo/frc/simulator/motor/11</topic>
        <multiplier>60</multiplier>
    </plugin>
    <plugin name="UpperArm-Wrist_encoder" filename="sim_encoder.dll">
        <joint>UpperArm-GripperRotate</joint>
        <topic>~/gazebo/frc/simulator/encoder/11</topic>
        <multiplier>1</multiplier>
    </plugin>

    
   
  
  </model>
  
</sdf>