<?xml version="1.0" encoding="utf-8"?>
<sdf version="1.5">
  <model name="SimBot2022-2">
    <pose>0 0 0 0 0 0</pose>
    <link name="Frame">
      <gravity>1</gravity>
      <self_collide>0</self_collide>
      <pose>-0.0916854891449772 0 -0.0184942437490389 1.5707963267949 0 -1.5707963267949</pose>
      <must_be_base_link>1</must_be_base_link>
      <velocity_decay>
        <linear>0</linear>
        <angular>0</angular>
      </velocity_decay>
      <inertial>
        <mass>80</mass>
        <pose>0 0 0 0 0 0</pose>
        <inertia>
          <ixx>0.5</ixx>
          <ixy>0.0</ixy>
          <ixz>0.0</ixz>
          <iyy>0.5</iyy>
          <iyz>0</iyz>
          <izz>0.5</izz>
        </inertia>
      </inertial>
      <collision name="Frame_collision">
        <pose>0.087928821262285 -0.0052889773385317 0.00114418280918003 0 0 0</pose>
        <geometry>
          <mesh>
            <scale>1 1 1</scale>
            <uri>model://SimBot2022-2/meshes/Frame_col.STL</uri>
          </mesh>
        </geometry>
        <surface>
          <contact>
            <ode />
          </contact>
          <friction>
            <ode>
              <mu>0</mu>
              <mu2>0</mu2>
            </ode>
          </friction>
        </surface>
      </collision>
      <visual name="Frame_visual">
        <pose>0.087928821262285 -0.0052889773385317 0.00114418280918003 0 0 0</pose>
        <material>
         <ambient>0 0.5 1 1</ambient>
          <diffuse>0 0.5 1 1</diffuse>
        </material>
        <geometry>
          <mesh>
            <scale>1 1 1</scale>
            <uri>model://SimBot2022-2/meshes/Frame.STL</uri>
          </mesh>
        </geometry>
      </visual>
    </link>
    <link name="shooter">  
      <self_collide>0</self_collide>    
      <pose>-0.339857661155341 0.00613558288465832 0.112751803631496 1.5707963267949 0 -1.5707963267949</pose>
      <must_be_base_link>0</must_be_base_link>    
      <gravity>0</gravity>
      <velocity_decay>
        <linear>0</linear>
        <angular>0</angular>
      </velocity_decay>
      <inertial>
        <mass>5</mass>
        <pose>0 0 0 0 0 0</pose>
        <inertia>
          <ixx>0.1</ixx>
          <ixy>0</ixy>
          <ixz>0</ixz>
          <iyy>0.1</iyy>
          <iyz>0</iyz>
          <izz>0.1</izz>
        </inertia>
      </inertial>
      <collision name="shooter_collision">
        <pose>0.094064405138414 -0.136535024719067 -0.247027989201184 0 0 0</pose>
        <geometry>
          <mesh>
            <scale>1 1 1</scale>
            <uri>model://SimBot2022-2/meshes/shooter_col.STL</uri>
          </mesh>
        </geometry>
        
        <surface>
           <ode>       
            <kd>0.1</kd>
            <kp>5000000</kp>
          </ode>
          <friction>
            <ode>
              <mu>0</mu>
              <mu2>0</mu2>
            </ode>
          </friction>
        </surface>
      </collision>
      <visual name="shooter_visual">
        <pose>0.094064405138414 -0.136535024719067 -0.247027989201184 0 0 0</pose>
        <material>
         <ambient>1 0.5 0.25 1</ambient>
          <diffuse>1 0.5 0.25 1</diffuse>
        </material>
        <geometry>
          <mesh>
            <scale>1 1 1</scale>
            <uri>model://SimBot2022-2/meshes/shooter.STL</uri>
          </mesh>
        </geometry>
      </visual>
      <sensor name="shooterCamera" type="camera">
        <visualize>1</visualize>
        <always_on>1</always_on>
        <pose>0.0104563713437772 0.114878062181823 0.0771053248601615 0 4.71238898038469 4.71238898038469</pose>
        <camera name="shootercamera">
          <horizontal_fov>1.5707963267949</horizontal_fov>
          <image>
            <width>640</width>
            <height>480</height>
            <format>R8G8B8</format>
          </image>
          <clip>
            <near>0.1</near>
            <far>100</far>
          </clip>
        </camera>
        <plugin name="camera1" filename="sim_camera.dll">
          <topic>~/gazebo/frc/simulator/camera/0</topic>
          <port>9000</port>
          <fps>20</fps>
          <enabled>true</enabled>
          <savepath>tmp</savepath>
          <maxframes>0</maxframes>
          <video>front.avi</video>
        </plugin>
      </sensor>
      <sensor name="IntakeCamera" type="camera">
        <visualize>0</visualize>
        <always_on>1</always_on>
        <pose>0.00613558288465925 0.161899190938801 0.132500680005632 0 4.71238898038469 4.71238898038469</pose>
        <camera name="intakecamera">
          <horizontal_fov>1.5707963267949</horizontal_fov>
           <image>
            <width>640</width>
            <height>480</height>
            <format>R8G8B8</format>
          </image>
          <clip>
            <near>0.1</near>
            <far>100</far>
          </clip>
        </camera>
        <plugin name="camera2" filename="sim_camera.dll">
          <topic>~/gazebo/frc/simulator/camera/1</topic>
          <port>9001</port>
          <fps>20</fps>
          <enabled>true</enabled>
          <savepath>tmp</savepath>
          <maxframes>0</maxframes>
          <video>back.avi</video>
        </plugin>
      </sensor>
    </link>
<!---->
    <joint name="Frame-shooter" type="revolute">
      <parent>Frame</parent>
      <child>shooter</child>
      <axis>
    <xyz>0 0 1</xyz>
    <limit>
      <upper>0</upper>
      <lower>0</lower>
    </limit>
  </axis>
    </joint>

    <link name="IntakeWheels">
      <gravity>1</gravity>
      <self_collide>0</self_collide>
      <pose>-0.469753566757535 -0.0108552498965759 0.120727981986896 1.5707963267949 0 -1.5707963267949</pose>
      <must_be_base_link>0</must_be_base_link>
      <velocity_decay>
        <linear>0</linear>
        <angular>0</angular>
      </velocity_decay>
      <inertial>
        <mass>0.185936472459736</mass>
        <pose>0 0 0 0 0 0</pose>
        <inertia>
          <ixx>0</ixx>
          <ixy>0</ixy>
          <ixz>0</ixz>
          <iyy>0</iyy>
          <iyz>0</iyz>
          <izz>0</izz>
        </inertia>
      </inertial>
      <collision name="IntakeWheels_collision">
        <pose>0.0770735723571798 -0.144511203074467 -0.376923894803378 0 0 0</pose>
        <geometry>
          <mesh>
            <scale>1 1 1</scale>
            <uri>model://SimBot2022-2/meshes/IntakeWheels_col.STL</uri>
          </mesh>
        </geometry>
        
        <surface>
        <!-- -->
          <contact>
          <ode>
            <max_vel>0.1</max_vel>
            <soft_cfm>0.1</soft_cfm>
            <soft_erp>0.1</soft_erp>
            <kd>0.1</kd>
            <kp>5000000</kp>
            <min_depth>0.001</min_depth>
          </ode>
          </contact>
         
          <friction>
            <ode>
              <mu>5</mu>
              <mu2>5</mu2>
            </ode>
          </friction>
        </surface>
      </collision>
      <visual name="IntakeWheels_visual">
        <pose>0.0770735723571798 -0.144511203074467 -0.376923894803378 0 0 0</pose>
        <material>
          <ambient>0 0.250980392156863 1 1</ambient>
          <diffuse>0 0.250980392156863 1 1</diffuse>
        </material>
        <geometry>
          <mesh>
            <scale>1 1 1</scale>
            <uri>model://SimBot2022-2/meshes/IntakeWheels.STL</uri>
          </mesh>
        </geometry>
      </visual>
    </link>
    <joint name="Intake-IntakeWheels" type="revolute">
      <parent>Intake</parent>
      <child>IntakeWheels</child>
      <pose>0 0 0 0 0 0</pose>
      <axis>
        <xyz>1 0 0</xyz>
        <dynamics>
          <damping>1</damping>
          <friction>1</friction>
        </dynamics>
       
      </axis>
    </joint>
    
    <link name="ShooterWheels">
      <gravity>1</gravity>
      <self_collide>0</self_collide>
      <pose>-0.177655024091721 -0.00250787604435686 0.196849999999108 1.5707963267949 0 -1.5707963267949</pose>
      <must_be_base_link>0</must_be_base_link>
      <velocity_decay>
        <linear>0</linear>
        <angular>0</angular>
      </velocity_decay>
      <inertial>
        <mass>0.142802443720399</mass>
        <pose>0 0 0 0 0 0</pose>
          <inertia>
          <ixx>0</ixx>
          <ixy>0</ixy>
          <ixz>0</ixz>
          <iyy>0</iyy>
          <iyz>0</iyz>
          <izz>0</izz>
        </inertia>
      </inertial>
      <collision name="ShooterWheels_collision">
        <pose>0.0854209462093988 -0.220633221086678 -0.0848253521375637 0 0 0</pose>
        <geometry>
          <mesh>
            <scale>1 1 1</scale>
            <uri>model://SimBot2022-2/meshes/ShooterWheels_col.STL</uri>
          </mesh>
        </geometry>
        <surface>
         
          <contact>
          <ode>
           <!-- <max_vel>0.1</max_vel>-->
            <soft_cfm>0.1</soft_cfm>
            <soft_erp>0.1</soft_erp>
            <kd>0.0</kd>
            <kp>500000</kp>
            <min_depth>0.001</min_depth>
          </ode>
          </contact>
         
          <friction>
            <ode>
              <mu>1</mu>
              <mu2>1</mu2>
            </ode>
          </friction>
        </surface>
      </collision>
      <visual name="ShooterWheels_visual">
        <pose>0.0854209462093988 -0.220633221086678 -0.0848253521375637 0 0 0</pose>
        <material>
          <ambient>0.501960784313725 0.501960784313725 0.501960784313725 1</ambient>
          <diffuse>0.501960784313725 0.501960784313725 0.501960784313725 1</diffuse>
        </material>
        <geometry>
          <mesh>
            <scale>1 1 1</scale>
            <uri>model://SimBot2022-2/meshes/ShooterWheels.STL</uri>
          </mesh>
        </geometry>
      </visual>
    </link>
    
    <joint name="shooter-ShooterWheels" type="revolute">
      <parent>shooter</parent>
      <child>ShooterWheels</child>
      <pose>0 0 0 0 0 0</pose>
      <axis>
        <xyz>1 0 0</xyz>
        <dynamics>
          <damping>1</damping>
          <friction>1</friction>
        </dynamics>
        
      </axis>
    </joint>

    <link name="LFWheel">
      <gravity>1</gravity>
      <self_collide>0</self_collide>
      <pose>-0.383733921516064 -0.315899209940694 -0.0302259999999987 1.5707963267949 0 -1.5707963267949</pose>
      <must_be_base_link>0</must_be_base_link>
      <velocity_decay>
        <linear>0</linear>
        <angular>0</angular>
      </velocity_decay>
      <inertial>
        <mass>0.255325203825891</mass>
        <pose>0 0 0 0 0 0</pose>
        <inertia>
          <ixx>0</ixx>
          <ixy>0</ixy>
          <ixz>0</ixz>
          <iyy>0</iyy>
          <iyz>0</iyz>
          <izz>0</izz>
        </inertia>
      </inertial>
      <collision name="LFWheel_collision">
        <pose>-0.227970387686939 0.00644277891242817 -0.290904249561907 0 0 0</pose>
        <geometry>
          <mesh>
            <scale>1 1 1</scale>
            <uri>model://SimBot2022-2/meshes/LFWheel_col.STL</uri>
          </mesh>
        </geometry>
        <surface>
          <contact>
          <ode>
            <max_vel>0.1</max_vel>
            <soft_cfm>0.8</soft_cfm>
            <soft_erp>0.8</soft_erp>
            <kd>200</kd>
            <kp>50000</kp>
            <min_depth>0.0001</min_depth>
          </ode>
          </contact>
          <friction>
            <ode>
              <mu>2</mu>
              <mu2>2</mu2>
            </ode>
          </friction>
        </surface>
      </collision>
      <visual name="LFWheel_visual">
        <pose>-0.227970387686939 0.00644277891242817 -0.290904249561907 0 0 0</pose>
        <material>
          <ambient>0.752941176470588 0.752941176470588 0.752941176470588 1</ambient>
          <diffuse>0.752941176470588 0.752941176470588 0.752941176470588 1</diffuse>
        </material>
        <geometry>
          <mesh>
            <scale>1 1 1</scale>
            <uri>model://SimBot2022-2/meshes/LFWheel.STL</uri>
          </mesh>
        </geometry>
      </visual>
    </link>
    <joint name="Frame-LFWheel" type="revolute">
      <parent>Frame</parent>
      <child>LFWheel</child>
      <pose>0 0 0 0 0 0</pose>
      <axis>
        <xyz>-1 0 0</xyz>
        <dynamics>
          <damping>1</damping>
          <friction>1</friction>
        </dynamics>
        <limit>
          <effort>100</effort>
        </limit>
      </axis>
    </joint>
    <link name="LCWheel">
      <gravity>1</gravity>
      <self_collide>0</self_collide>
      <pose>-0.129733921516064 -0.311136709940694 -0.0302259999999999 1.5707963267949 0 -1.5707963267949</pose>
      <must_be_base_link>0</must_be_base_link>
      <velocity_decay>
        <linear>0</linear>
        <angular>0</angular>
      </velocity_decay>
      <inertial>
        <mass>0.255325203825891</mass>
        <pose>0 0 0 0 0 0</pose>
        <inertia>
          <ixx>0</ixx>
          <ixy>0</ixy>
          <ixz>0</ixz>
          <iyy>0</iyy>
          <iyz>0</iyz>
          <izz>0</izz>
        </inertia>
      </inertial>
      <collision name="LCWheel_collision">
        <pose>-0.223207887686939 0.00644277891242926 -0.0369042495619069 0 0 0</pose>
        <geometry>
          <mesh>
            <scale>1 1 1</scale>
            <uri>model://SimBot2022-2/meshes/LCWheel_col.STL</uri>
          </mesh>
        </geometry>
        <surface>
          <contact>
          <ode>
            <max_vel>0.1</max_vel>
            <soft_cfm>0.8</soft_cfm>
            <soft_erp>0.8</soft_erp>
            <kd>200</kd>
            <kp>50000</kp>
            <min_depth>0.0001</min_depth>
          </ode>
          </contact>
          <friction>
            <ode>
              <mu>2</mu>
              <mu2>2</mu2>
            </ode>
          </friction>
        </surface>
      </collision>
      <visual name="LCWheel_visual">
        <pose>-0.223207887686939 0.00644277891242926 -0.0369042495619069 0 0 0</pose>
        <material>
          <ambient>0.752941176470588 0.752941176470588 0.752941176470588 1</ambient>
          <diffuse>0.752941176470588 0.752941176470588 0.752941176470588 1</diffuse>
        </material>
        <geometry>
          <mesh>
            <scale>1 1 1</scale>
            <uri>model://SimBot2022-2/meshes/LCWheel.STL</uri>
          </mesh>
        </geometry>
      </visual>
    </link>
    <joint name="Frame-LCWheel" type="revolute">
      <parent>Frame</parent>
      <child>LCWheel</child>
      <pose>0 0 0 0 0 0</pose>
      <axis>
        <xyz>-1 0 0</xyz>
        <dynamics>
          <damping>1</damping>
          <friction>1</friction>
        </dynamics>
        <limit>
          <effort>100</effort>
        </limit>
      </axis>
    </joint>
    <link name="LBWheel">
      <gravity>1</gravity>
      <self_collide>0</self_collide>
      <pose>0.124266078483936 -0.315899209940694 -0.030226000000001 1.5707963267949 0 -1.5707963267949</pose>
      <must_be_base_link>0</must_be_base_link>
      <velocity_decay>
        <linear>0</linear>
        <angular>0</angular>
      </velocity_decay>
      <inertial>
        <mass>0.255325203825891</mass>
        <pose>0 0 0 0 0 0</pose>
        <inertia>
          <ixx>0</ixx>
          <ixy>0</ixy>
          <ixz>0</ixz>
          <iyy>0</iyy>
          <iyz>0</iyz>
          <izz>0</izz>
        </inertia>
      </inertial>
      <collision name="LBWheel_collision">
        <pose>-0.227970387686938 0.00644277891243034 0.217095750438093 0 0 0</pose>
        <geometry>
          <mesh>
            <scale>1 1 1</scale>
            <uri>model://SimBot2022-2/meshes/LBWheel_col.STL</uri>
          </mesh>
        </geometry>
        <surface>
          <contact>
          <ode>
            <max_vel>0.1</max_vel>
            <soft_cfm>0.8</soft_cfm>
            <soft_erp>0.8</soft_erp>
            <kd>200</kd>
            <kp>50000</kp>
            <min_depth>0.0001</min_depth>
          </ode>
          </contact>
          <friction>
            <ode>
              <mu>2</mu>
              <mu2>2</mu2>
            </ode>
          </friction>
        </surface>
      </collision>
      <visual name="LBWheel_visual">
        <pose>-0.227970387686938 0.00644277891243034 0.217095750438093 0 0 0</pose>
        <material>
          <ambient>0.752941176470588 0.752941176470588 0.752941176470588 1</ambient>
          <diffuse>0.752941176470588 0.752941176470588 0.752941176470588 1</diffuse>
        </material>
        <geometry>
          <mesh>
            <scale>1 1 1</scale>
            <uri>model://SimBot2022-2/meshes/LBWheel.STL</uri>
          </mesh>
        </geometry>
      </visual>
    </link>
    <joint name="Frame-LBWheel" type="revolute">
      <parent>Frame</parent>
      <child>LBWheel</child>
      <pose>0 0 0 0 0 0</pose>
      <axis>
        <xyz>-1 0 0</xyz>
        <dynamics>
          <damping>1</damping>
          <friction>1</friction>
        </dynamics>
        <limit>
          <effort>100</effort>
        </limit>
      </axis>
    </joint>
    <link name="RFWheel">
      <gravity>1</gravity>
      <self_collide>0</self_collide>
      <pose>-0.383645321120682 0.315899209940691 -0.0302259999999987 1.5707963267949 0 -1.5707963267949</pose>
      <must_be_base_link>0</must_be_base_link>
      <velocity_decay>
        <linear>0</linear>
        <angular>0</angular>
      </velocity_decay>
      <inertial>
        <mass>0.255325203825891</mass>
        <pose>0 0 0 0 0 0</pose>
        <inertia>
          <ixx>0</ixx>
          <ixy>0</ixy>
          <ixz>0</ixz>
          <iyy>0</iyy>
          <iyz>0</iyz>
          <izz>0</izz>
        </inertia>
      </inertial>
      <collision name="RFWheel_collision">
        <pose>0.403828032194447 0.0064427789124282 -0.290815649166525 0 0 0</pose>
        <geometry>
          <mesh>
            <scale>1 1 1</scale>
            <uri>model://SimBot2022-2/meshes/RFWheel_col.STL</uri>
          </mesh>
        </geometry>
        <surface>
          <contact>
          <ode>
            <max_vel>0.1</max_vel>
            <soft_cfm>0.8</soft_cfm>
            <soft_erp>0.8</soft_erp>
            <kd>200</kd>
            <kp>50000</kp>
            <min_depth>0.0001</min_depth>
          </ode>
          </contact>
          <friction>
            <ode>
              <mu>2</mu>
              <mu2>2</mu2>
            </ode>
          </friction>
        </surface>
      </collision>
      <visual name="RFWheel_visual">
        <pose>0.403828032194447 0.0064427789124282 -0.290815649166525 0 0 0</pose>
        <material>
          <ambient>0.752941176470588 0.752941176470588 0.752941176470588 1</ambient>
          <diffuse>0.752941176470588 0.752941176470588 0.752941176470588 1</diffuse>
        </material>
        <geometry>
          <mesh>
            <scale>1 1 1</scale>
            <uri>model://SimBot2022-2/meshes/RFWheel.STL</uri>
          </mesh>
        </geometry>
      </visual>
    </link>
    <joint name="Frame-RFWheel" type="revolute">
      <parent>Frame</parent>
      <child>RFWheel</child>
     <pose>0 0 0 0 0 0</pose>
      <axis>
        <xyz>-1 0 0</xyz>
        <dynamics>
          <damping>1</damping>
          <friction>1</friction>
        </dynamics>
        <limit>
          <effort>100</effort>
        </limit>
      </axis>
    </joint>
    <link name="RCWheel">
      <gravity>1</gravity>
      <self_collide>0</self_collide>
      <pose>-0.129645321120682 0.311136709940692 -0.0302259999999999 1.5707963267949 0 -1.5707963267949</pose>
      <must_be_base_link>0</must_be_base_link>
      <velocity_decay>
        <linear>0</linear>
        <angular>0</angular>
      </velocity_decay>
      <inertial>
        <mass>0.255325203825891</mass>
        <pose>0 0 0 0 0 0</pose>
        <inertia>
          <ixx>0</ixx>
          <ixy>0</ixy>
          <ixz>0</ixz>
          <iyy>0</iyy>
          <iyz>0</iyz>
          <izz>0</izz>
        </inertia>
      </inertial>
      <collision name="RCWheel_collision">
        <pose>0.399065532194447 0.00644277891242927 -0.0368156491665249 0 0 0</pose>
        <geometry>
          <mesh>
            <scale>1 1 1</scale>
            <uri>model://SimBot2022-2/meshes/RCWheel_col.STL</uri>
          </mesh>
        </geometry>
        <surface>
          <contact>
          <ode>
            <max_vel>0.1</max_vel>
            <soft_cfm>0.8</soft_cfm>
            <soft_erp>0.8</soft_erp>
            <kd>200</kd>
            <kp>50000</kp>
            <min_depth>0.0001</min_depth>
          </ode>
          </contact>
          <friction>
            <ode>
              <mu>2</mu>
              <mu2>2</mu2>
            </ode>
          </friction>
        </surface>
      </collision>
      <visual name="RCWheel_visual">
        <pose>0.399065532194447 0.00644277891242927 -0.0368156491665249 0 0 0</pose>
        <material>
          <ambient>0.752941176470588 0.752941176470588 0.752941176470588 1</ambient>
          <diffuse>0.752941176470588 0.752941176470588 0.752941176470588 1</diffuse>
        </material>
        <geometry>
          <mesh>
            <scale>1 1 1</scale>
            <uri>model://SimBot2022-2/meshes/RCWheel.STL</uri>
          </mesh>
        </geometry>
      </visual>
    </link>
    <joint name="Frame-RCWheel" type="revolute">
      <parent>Frame</parent>
      <child>RCWheel</child>
      <pose>0 0 0 0 0 0</pose>
      <axis>
        <xyz>-1 0 0</xyz>
        <dynamics>
          <damping>1</damping>
          <friction>1</friction>
        </dynamics>
        <limit>
          <effort>100</effort>
        </limit>
      </axis>
    </joint>
    <link name="RBWheel">
      <gravity>1</gravity>
      <self_collide>0</self_collide>
      <pose>0.124354678879318 0.315899209940692 -0.0302259999999999 1.5707963267949 0 -1.5707963267949</pose>
      <must_be_base_link>0</must_be_base_link>
      <velocity_decay>
        <linear>0</linear>
        <angular>0</angular>
      </velocity_decay>
      <inertial>
        <mass>0.255325203825891</mass>
        <pose>0 0 0 0 0 0</pose>
        <inertia>
          <ixx>0</ixx>
          <ixy>0</ixy>
          <ixz>0</ixz>
          <iyy>0</iyy>
          <iyz>0</iyz>
          <izz>0</izz>
        </inertia>
      </inertial>
      <collision name="RBWheel_collision">
        <pose>0.403828032194447 0.00644277891242929 0.217184350833475 0 0 0</pose>
        <geometry>
          <mesh>
            <scale>1 1 1</scale>
            <uri>model://SimBot2022-2/meshes/RBWheel_col.STL</uri>
          </mesh>
        </geometry>
       <surface>
          <contact>
          <ode>
            <max_vel>0.1</max_vel>
            <soft_cfm>0.8</soft_cfm>
            <soft_erp>0.8</soft_erp>
            <kd>200</kd>
            <kp>50000</kp>
            <min_depth>0.0001</min_depth>
          </ode>
          </contact>
          <friction>
            <ode>
              <mu>2</mu>
              <mu2>2</mu2>
            </ode>
          </friction>
        </surface>
      </collision>
      <visual name="RBWheel_visual">
        <pose>0.403828032194447 0.00644277891242929 0.217184350833475 0 0 0</pose>
        <material>
          <ambient>0.752941176470588 0.752941176470588 0.752941176470588 1</ambient>
          <diffuse>0.752941176470588 0.752941176470588 0.752941176470588 1</diffuse>
        </material>
        <geometry>
          <mesh>
            <scale>1 1 1</scale>
            <uri>model://SimBot2022-2/meshes/RBWheel.STL</uri>
          </mesh>
        </geometry>
      </visual>
    </link>
    <joint name="Frame-RBWheel" type="revolute">
      <parent>Frame</parent>
      <child>RBWheel</child>
      <pose>0 0 0 0 0 0</pose>
      <axis>
        <xyz>-1 0 0</xyz>
        <dynamics>
          <damping>1</damping>
          <friction>1</friction>
        </dynamics>
        <limit>
          <effort>100</effort>
        </limit>
      </axis>
    </joint>
    <link name="Intake">
      <gravity>1</gravity>
      <self_collide>0</self_collide>
      <pose>-0.424484874242734 9.92754253803518E-09 0.120699564654734 1.5707963267949 0 -1.5707963267949</pose>
      <must_be_base_link>0</must_be_base_link>
      <velocity_decay>
        <linear>0</linear>
        <angular>1</angular>
      </velocity_decay>
      <inertial>
        <mass>10</mass>
        <pose>0 0 0 0 0 0</pose>
        <inertia>
          <ixx>0</ixx>
          <ixy>0</ixy>
          <ixz>0</ixz>
          <iyy>1</iyy>
          <iyz>0</iyz>
          <izz>0</izz>
        </inertia>
      </inertial>
      <collision name="Intake_collision">
        <pose>0.0879288321812983 -0.144482785742305 -0.331655202288577 0 0 0</pose>
        <geometry>
          <mesh>
            <scale>1 1 1</scale>
            <uri>model://SimBot2022-2/meshes/Intake_col.STL</uri>
          </mesh>
        </geometry>
        <surface>
        <!--
          <contact>
          <ode>
            <max_vel>0.1</max_vel>
            <soft_cfm>0.1</soft_cfm>
            <soft_erp>0.1</soft_erp>
            <kd>0</kd>
            <kp>100000</kp>
            <min_depth>0.001</min_depth>
          </ode>
          </contact>
          -->
          <friction>
            <ode>
              <mu>2</mu>
              <mu2>2</mu2>
            </ode>
          </friction>
        </surface>
        
      </collision>
      <visual name="Intake_visual">
        <pose>0.0879288321812983 -0.144482785742305 -0.331655202288577 0 0 0</pose>
        <material>
          <ambient>1 0.250980392156863 0.501960784313725 1</ambient>
          <diffuse>1 0.250980392156863 0.501960784313725 1</diffuse>
        </material>
        <geometry>
          <mesh>
            <scale>1 1 1</scale>
            <uri>model://SimBot2022-2/meshes/Intake.STL</uri>
          </mesh>
        </geometry>
      </visual>
    </link>
    <joint name="shooter-Intake" type="revolute">
      <parent>shooter</parent>
      <child>Intake</child>
      <pose>0.0879288321812983 -0.144482785742305 -0.331655202288577 0 0 0</pose>
      <axis>
        <xyz>-1 0 0</xyz>
        <dynamics>
          <damping>2</damping>
          <friction>1</friction>
        </dynamics>
        
        <limit>
          <upper>0.05</upper>
          <lower>0</lower>
          <!--
          <effort>80</effort>
          -->
        </limit>
        
      </axis>
    </joint>
     <plugin name="Intake-IntakeWheels_motor" filename="sim_motor.dll">
      <joint>Intake-IntakeWheels</joint>
      <topic>~/gazebo/frc/simulator/motor/7</topic>
      <multiplier>500</multiplier>
    </plugin>
    <plugin name="shooter-ShooterWheels_motor" filename="sim_motor.dll">
      <joint>shooter-ShooterWheels</joint>
      <topic>~/gazebo/frc/simulator/motor/8</topic>
      <multiplier>500</multiplier>
    </plugin>

    <plugin name="clock" filename="sim_clock.dll">
      <topic>~/gazebo/frc/simulator/clock</topic>
    </plugin>
    
    <plugin name="Body_gyro" filename="sim_gyro.dll">
      <link>Frame</link>
      <topic>~/gazebo/frc/simulator/gyro</topic>
      <units>degrees</units>
      <axis>yaw</axis>
    </plugin>

    <plugin name="Frame-LFWheel_motor" filename="sim_motor.dll">
      <joint>Frame-LFWheel</joint>
      <topic>~/gazebo/frc/simulator/motor/1</topic>
      <multiplier>100</multiplier>
    </plugin>
    <plugin name="Frame-LCWheel_motor" filename="sim_motor.dll">
      <joint>Frame-LCWheel</joint>
      <topic>~/gazebo/frc/simulator/motor/1</topic>
      <multiplier>100</multiplier>
    </plugin>
    <plugin name="Frame-LBWheel_motor" filename="sim_motor.dll">
      <joint>Frame-LBWheel</joint>
      <topic>~/gazebo/frc/simulator/motor/1</topic>
      <multiplier>100</multiplier>
    </plugin>
    <plugin name="Frame-RFWheel_motor" filename="sim_motor.dll">
      <joint>Frame-RFWheel</joint>
      <topic>~/gazebo/frc/simulator/motor/2</topic>
      <multiplier>100</multiplier>
    </plugin>
    <plugin name="Frame-RCWheel_motor" filename="sim_motor.dll">
      <joint>Frame-RCWheel</joint>
      <topic>~/gazebo/frc/simulator/motor/2</topic>
      <multiplier>100</multiplier>
    </plugin>
    <plugin name="Frame-RBWheel_motor" filename="sim_motor.dll">
      <joint>Frame-RBWheel</joint>
      <topic>~/gazebo/frc/simulator/motor/2</topic>
      <multiplier>100</multiplier>
    </plugin>
  </model>
</sdf>