<?xml version="1.0" encoding="utf-8"?>
<sdf version="1.5">
  <model name="SimSwerveBot3">
    <pose>0 0 0.372289921204834 0 0 0</pose>
   
    <link name="Body">
      <gravity>1</gravity>
      <self_collide>0</self_collide>
      <pose>0.0103185969497103 0.0270555915724389 0.00229909099591104 0 0 0</pose>
      <must_be_base_link>1</must_be_base_link>
      <velocity_decay>
        <linear>0.0</linear>
        <angular>0.0</angular>
      </velocity_decay>
      <inertial>
        <mass>150</mass>
        <pose>0 0 0 0 0 0</pose>
        
      </inertial>
      <collision name="Body_collision">
        <pose>-0.466812853283889 -0.02705559157244 -0.00301802987182291 0 0 0</pose>
        <geometry>
          <mesh>
            <scale>1 1 1</scale>
            <uri>model://SimSwerveBot3/meshes/Body_col.STL</uri>
          </mesh>
        </geometry>
        <surface>
          <contact>
            <ode />
          </contact>
          <friction>
            <ode>
              <mu>1</mu>
              <mu2>1</mu2>
            </ode>
          </friction>
        </surface>
      </collision>
      <visual name="Body_visual">
        <pose>-0.466812853283889 -0.02705559157244 -0.00301802987182291 0 0 0</pose>
        <material>
          <ambient>0.501960784313725 0.501960784313725 0.501960784313725 1</ambient>
          <diffuse>0.501960784313725 0.501960784313725 0.501960784313725 1</diffuse>
        </material>
        <geometry>
          <mesh>
            <scale>1 1 1</scale>
            <uri>model://SimSwerveBot3/meshes/Body.STL</uri>
          </mesh>
        </geometry>
      </visual>
    </link>
    
    <link name="FRdrive">
      <gravity>1</gravity>
      <self_collide>0</self_collide>
      <pose>0.363496387518542 0.00308940755423762 0.210899192814309 0 0 0</pose>
      <must_be_base_link>0</must_be_base_link>
       <velocity_decay>
        <linear>0</linear>
        <angular>0.01</angular>
      </velocity_decay>
      <inertial>
        <mass>1</mass>
        <pose>0 0 0 0 0 0</pose>
      </inertial>
      <visual name="FRdrive_visual">
        <pose>-0.81999064385272 -0.00308940755423872 -0.211618131690221 0 0 0</pose>
        <material>
          <ambient>1 0.501960784313725 0.501960784313725 1</ambient>
          <diffuse>1 0.501960784313725 0.501960784313725 1</diffuse>
        </material>
        <geometry>
          <mesh>
            <scale>1 1 1</scale>
            <uri>model://SimSwerveBot3/meshes/FRdrive.STL</uri>
          </mesh>
        </geometry>
      </visual>
    </link>
    <joint name="Body-FRdrive" type="revolute">
      <parent>Body</parent>
      <child>FRdrive</child>
      <pose>0.0270286124814588 0 0.027225807185676 0 0 4.71238898038469</pose>
      <axis>
        <xyz>-1 0 0</xyz>
        <dynamics>
          <damping>1</damping>
          <friction>1</friction>
        </dynamics>   
      </axis>
    </joint>
    <link name="FRwheel">
      <gravity>1</gravity>
      <self_collide>0</self_collide>
      <pose>0.390524894652224 -0.045440778296 0.239779131380291 0 0 0</pose>
      <must_be_base_link>0</must_be_base_link>
      <velocity_decay>
        <linear>0</linear>
        <angular>0.002</angular>
      </velocity_decay>
      <inertial>
        <mass>1</mass>
        <pose>0 0 0 0 0 0</pose>      
      </inertial>
      <collision name="FRwheel_collision">
        <pose>-0.847019150986402 0.0454407782959989 -0.240498070256203 0 0 0</pose>
        <geometry>
          <mesh>
            <scale>1 1 1</scale>
            <uri>model://SimSwerveBot3/meshes/FRwheel_col.STL</uri>
          </mesh>
        </geometry>
        <surface>
          <contact>
             <ode>
              <max_vel>0.1</max_vel>
              <soft_cfm>0.8</soft_cfm>
              <soft_erp>0.8</soft_erp>
              <kd>25</kd>
              <kp>1e6</kp>
              <min_depth>0.0001</min_depth>
            </ode>          
          </contact>
          <friction>
            <ode>
              <mu>1</mu>
              <mu2>1</mu2>
            </ode>
          </friction>
        </surface>
      </collision>
      <visual name="FRwheel_visual">
        <pose>-0.847019150986402 0.0454407782959989 -0.240498070256203 0 0 0</pose>
        <material>
          <ambient>0 1 0 1</ambient>
          <diffuse>0 1 0 1</diffuse>
        </material>
        <geometry>
          <mesh>
            <scale>1 1 1</scale>
            <uri>model://SimSwerveBot3/meshes/FRwheel.STL</uri>
          </mesh>
        </geometry>
      </visual>
    </link>
    <joint name="FRdrive-FRwheel" type="revolute">
      <parent>FRdrive</parent>
      <child>FRwheel</child>
      <pose>1.25638072463463E-05 0.00011429545755863 -9.46325306450113E-08 0 4.7199209919262 6.28318530717959</pose>
      <axis>
        <xyz>-1 0 0</xyz>
        <dynamics>
          <damping>1</damping>
          <friction>1</friction>
        </dynamics>
      </axis>
    </joint>
    <link name="FLdrive">
      <gravity>1</gravity>
      <self_collide>0</self_collide>
      <pose>0.390516175212258 -0.00398782218945136 -0.236504732283261 0 0 0</pose>
      <must_be_base_link>0</must_be_base_link>
      <velocity_decay>
        <linear>0</linear>
        <angular>0.01</angular>
      </velocity_decay>
      <inertial>
        <mass>1</mass>
        <pose>0 0 0 0 0 0</pose>      
      </inertial>
      <visual name="FLdrive_visual">
        <pose>-0.847010431546437 0.00398782218945027 0.235785793407349 0 0 0</pose>
        <material>
          <ambient>0.501960784313725 0.501960784313725 0.501960784313725 1</ambient>
          <diffuse>0.501960784313725 0.501960784313725 0.501960784313725 1</diffuse>
        </material>
        <geometry>
          <mesh>
            <scale>1 1 1</scale>
            <uri>model://SimSwerveBot3/meshes/FLdrive.STL</uri>
          </mesh>
        </geometry>
      </visual>
    </link>
    <joint name="Body-FLdrive" type="revolute">
      <parent>Body</parent>
      <child>FLdrive</child>
      <pose>8.82478774166806E-06 5.20417042793042E-18 -0.00162026771675042 0 6.28318530717959 4.71238898038469</pose>
      <axis>
        <xyz>-1 0 0</xyz>
        <dynamics>
          <damping>1</damping>
          <friction>1</friction>
        </dynamics>       
      </axis>
    </joint>
    <link name="FLwheel">
      <gravity>1</gravity>
      <self_collide>0</self_collide>
      <pose>0.390549941149665 -0.0454363391768118 -0.236470756117954 0 0 0</pose>
      <must_be_base_link>0</must_be_base_link>
      <velocity_decay>
        <linear>0</linear>
        <angular>0.002</angular>
      </velocity_decay>
      <inertial>
        <mass>0.123981363237525</mass>
        <pose>0 0 0 0 0 0</pose>
      </inertial>
      <collision name="FLwheel_collision">
        <pose>-0.847044197483843 0.0454363391768107 0.235751817242042 0 0 0</pose>
        <geometry>
          <mesh>
            <scale>1 1 1</scale>
            <uri>model://SimSwerveBot3/meshes/FLwheel_col.STL</uri>
          </mesh>
        </geometry>
        <surface>
          <contact>
             <ode>
              <max_vel>0.1</max_vel>
              <soft_cfm>0.8</soft_cfm>
              <soft_erp>0.8</soft_erp>
              <kd>25</kd>
              <kp>1e6</kp>
              <min_depth>0.001</min_depth>
            </ode>          
          </contact>
          <friction>
            <ode>
              <mu>1</mu>
              <mu2>1</mu2>
            </ode>
          </friction>
        </surface>
      </collision>
      <visual name="FLwheel_visual">
        <pose>-0.847044197483843 0.0454363391768107 0.235751817242042 0 0 0</pose>
        <material>
          <ambient>0 1 0 1</ambient>
          <diffuse>0 1 0 1</diffuse>
        </material>
        <geometry>
          <mesh>
            <scale>1 1 1</scale>
            <uri>model://SimSwerveBot3/meshes/FLwheel.STL</uri>
          </mesh>
        </geometry>
      </visual>
    </link>
    <joint name="FLdrive-FLwheel" type="revolute">
      <parent>FLdrive</parent>
      <child>FLwheel</child>
      <pose>-3.39534051447821E-05 0.000109856338368929 -1.84997501873063E-07 0 4.71783749638594 5.39814581483388E-16</pose>
      <axis>
        <xyz>-1 0 0</xyz>
        <dynamics>
          <damping>1</damping>
          <friction>1</friction>
        </dynamics> 
      </axis>
    </joint>
    <link name="BRdrive">
      <gravity>1</gravity>
      <self_collide>0</self_collide>
      <pose>-0.389820351374971 -0.0252568719347456 0.23794658223208 0 0 0</pose>
      <must_be_base_link>0</must_be_base_link>
      <velocity_decay>
        <linear>0</linear>
        <angular>0.01</angular>
      </velocity_decay>
      <inertial>
        <mass>1</mass>
        <pose>0 0 0 0 0 0</pose>
      </inertial>
      <visual name="BRdrive_visual">
        <pose>-0.0666739049592076 0.0252568719347445 -0.238665521107992 0 0 0</pose>
        <material>
          <ambient>0.501960784313725 0.501960784313725 0.501960784313725 1</ambient>
          <diffuse>0.501960784313725 0.501960784313725 0.501960784313725 1</diffuse>
        </material>
        <geometry>
          <mesh>
            <scale>1 1 1</scale>
            <uri>model://SimSwerveBot3/meshes/BRdrive.STL</uri>
          </mesh>
        </geometry>
      </visual>
    </link>
    <joint name="Body-BRdrive" type="revolute">
      <parent>Body</parent>
      <child>BRdrive</child>
      <pose>1.09504079234823E-06 0 0.000178417767905031 0 6.28318530717959 4.71238898038469</pose>
      <axis>
        <xyz>-1 0 0</xyz>
        <dynamics>
          <damping>1</damping>
          <friction>1</friction>
        </dynamics>      
      </axis>
    </joint>
    <link name="BRwheel">
      <gravity>1</gravity>
      <self_collide>0</self_collide>
      <pose>-0.38981675512866 -0.0454407782968198 0.236470870684926 0 0 0</pose>
      <must_be_base_link>0</must_be_base_link>
      <velocity_decay>
        <linear>0</linear>
        <angular>0.002</angular>
      </velocity_decay>
      <inertial>
        <mass>1</mass>
        <pose>0 0 0 0 0 0</pose>
      </inertial>
      <collision name="BRwheel_collision">
        <pose>-0.066677501205518 0.0454407782968187 -0.237189809560838 0 0 0</pose>
        <geometry>
          <mesh>
            <scale>1 1 1</scale>
            <uri>model://SimSwerveBot3/meshes/BRwheel_col.STL</uri>
          </mesh>
        </geometry>
        <surface>
          <contact>
            <ode>
              <max_vel>0.1</max_vel>
              <soft_cfm>0.8</soft_cfm>
              <soft_erp>0.8</soft_erp>
              <kd>25</kd>
              <kp>1e6</kp>
              <min_depth>0.0001</min_depth>
            </ode>          
          </contact>
          <friction>
            <ode>
              <mu>1</mu>
              <mu2>1</mu2>
            </ode>
          </friction>
        </surface>
      </collision>
      <visual name="BRwheel_visual">
        <pose>-0.066677501205518 0.0454407782968187 -0.237189809560838 0 0 0</pose>
        <material>
          <ambient>0 1 0 1</ambient>
          <diffuse>0 1 0 1</diffuse>
        </material>
        <geometry>
          <mesh>
            <scale>1 1 1</scale>
            <uri>model://SimSwerveBot3/meshes/BRwheel.STL</uri>
          </mesh>
        </geometry>
      </visual>
    </link>
    <joint name="BRdrive-BRwheel" type="revolute">
      <parent>BRdrive</parent>
      <child>BRwheel</child>
      <pose>-1.25639304105613E-05 0.000114295458376691 7.6434905293965E-08 0 1.56471272398399 3.14159265358979</pose>
      <axis>
        <xyz>1 0 0</xyz>
        <dynamics>
          <damping>1</damping>
          <friction>1</friction>
        </dynamics>   
      </axis>
    </joint>
    <link name="BLdrive">
      <gravity>1</gravity>
      <self_collide>0</self_collide>
      <pose>-0.389831464443077 -0.00398782097182753 -0.239745247576255 0 0 0</pose>
      <must_be_base_link>0</must_be_base_link>
      <velocity_decay>
        <linear>0</linear>
        <angular>0.01</angular>
      </velocity_decay>
      <inertial>
        <mass>1</mass>
        <pose>0 0 0 0 0 0</pose>
      </inertial>
      <visual name="BLdrive_visual">
        <pose>-0.0666627918911016 0.00398782097182643 0.239026308700343 0 0 0</pose>
        <material>
          <ambient>0.501960784313725 0.501960784313725 0.501960784313725 1</ambient>
          <diffuse>0.501960784313725 0.501960784313725 0.501960784313725 1</diffuse>
        </material>
        <geometry>
          <mesh>
            <scale>1 1 1</scale>
            <uri>model://SimSwerveBot3/meshes/BLdrive.STL</uri>
          </mesh>
        </geometry>
      </visual>
    </link>
    <joint name="Body-BLdrive" type="revolute">
      <parent>Body</parent>
      <child>BLdrive</child>
      <pose>-1.25638072462075E-05 0.00011429545755838 9.46325307560336E-08 0 1.56326431525339 3.14159265358979</pose>
      <axis>
        <xyz>0 -1 0</xyz>
        <dynamics>
          <damping>1</damping>
          <friction>1</friction>
        </dynamics>      
      </axis>
    </joint>
    <link name="BLwheel">
      <gravity>1</gravity>
      <self_collide>0</self_collide>
      <pose>-0.389819150986402 -0.045440778296001 -0.239779131380316 0 0 0</pose>
      <must_be_base_link>0</must_be_base_link>
      <velocity_decay>
        <linear>0</linear>
        <angular>0.002</angular>
      </velocity_decay>
      <inertial>
        <mass>0.123981366006227</mass>
        <pose>0 0 0 0 0 0</pose>
      </inertial>
      <collision name="BLwheel_collision">
        <pose>-0.0666751053477765 0.0454407782959999 0.239060192504404 0 0 0</pose>
        <geometry>
          <mesh>
            <scale>1 1 1</scale>
            <uri>model://SimSwerveBot3/meshes/BLwheel_col.STL</uri>
          </mesh>
        </geometry>
        <surface>
         <contact>
             <ode>
              <max_vel>0.1</max_vel>
              <soft_cfm>0.8</soft_cfm>
              <soft_erp>0.8</soft_erp>
              <kd>25</kd>
              <kp>1e6</kp>
              <min_depth>0.0001</min_depth>
            </ode>          
          </contact>
          <friction>
            <ode>
              <mu>1</mu>
              <mu2>1</mu2>
            </ode>
          </friction>
        </surface>
      </collision>
      <visual name="BLwheel_visual">
        <pose>-0.0666751053477765 0.0454407782959999 0.239060192504404 0 0 0</pose>
        <material>
          <ambient>0 1 0 1</ambient>
          <diffuse>0 1 0 1</diffuse>
        </material>
        <geometry>
          <mesh>
            <scale>1 1 1</scale>
            <uri>model://SimSwerveBot3/meshes/BLwheel.STL</uri>
          </mesh>
        </geometry>
      </visual>
    </link>
    <joint name="BLdrive-BLwheel" type="revolute">
      <parent>BLdrive</parent>
      <child>BLwheel</child>
      <pose>-1.25638072462075E-05 0.00011429545755836 9.4632530728278E-08 0 1.56326431525339 3.14159265358979</pose>
      <axis>
        <xyz>1 0 0</xyz>
        <dynamics>
          <damping>1</damping>
          <friction>1</friction>
        </dynamics>     
      </axis>
    </joint>
     
    <link name="LowerArm">
      <gravity>1</gravity>
      <self_collide>0</self_collide>
      <pose>0.286613438363416 0.569352514264946 0.201682058992877 0 0 0</pose>
      <must_be_base_link>0</must_be_base_link>
      <velocity_decay>
        <linear>0</linear>
        <angular>0.03</angular>
      </velocity_decay>
      <inertial>
        <mass>3.19006579837111</mass>
        <pose>0 0 0 0 0 0</pose>
        <!--
        <inertia>
          <ixx>0.0573004752158579</ixx>
          <ixy>0.0388509565035045</ixy>
          <ixz>0.00215756738631079</ixz>
          <iyy>0.0267256940750842</iyy>
          <iyz>0.0031675240564386</iyz>
          <izz>0.0835009253183463</izz>
        </inertia>
        -->
      </inertial>
      <collision name="LowerArm_collision">
        <pose>-0.743107694697595 -0.569352514264947 -0.202400997868789 0 0 0</pose>
        <geometry>
          <mesh>
            <scale>1 1 1</scale>
            <uri>model://SimSwerveBot3/meshes/LowerArm_col.STL</uri>
          </mesh>
        </geometry>
        <surface>
          <contact>
            <ode />
          </contact>
          <friction>
            <ode>
              <mu>1</mu>
              <mu2>1</mu2>
            </ode>
          </friction>
        </surface>
      </collision>
      <visual name="LowerArm_visual">
        <pose>-0.743107694697595 -0.569352514264947 -0.202400997868789 0 0 0</pose>
        <material>
          <ambient>0.250980392156863 0.501960784313725 0.501960784313725 1</ambient>
          <diffuse>0.250980392156863 0.501960784313725 0.501960784313725 1</diffuse>
        </material>
        <geometry>
          <mesh>
            <scale>1 1 1</scale>
            <uri>model://SimSwerveBot3/meshes/LowerArm.STL</uri>
          </mesh>
        </geometry>
      </visual>
    </link>
    <joint name="Body-LowerArm" type="revolute">
      <parent>Body</parent>
      <child>LowerArm</child>
      <pose>-0.288320694697595 -0.423302514264947 0 0 1.5707963267949 0</pose>
      <axis>
        <xyz>-1 0 0</xyz>
        <dynamics>
          <damping>10</damping>
          <friction>10</friction>
        </dynamics>
        <!-- -->
        <limit>
         <lower>-0.8</lower>
         <upper>0.8</upper>
        </limit>
       
      </axis>
    </joint>
    
    <link name="UpperArm">
      <gravity>1</gravity>
      <self_collide>0</self_collide>
      <pose>0.520807370409663 0.709767313781582 0.132747045366564 0 0 0</pose>
      <must_be_base_link>0</must_be_base_link>
      <velocity_decay>
        <linear>0</linear>
        <angular>0.1</angular>
      </velocity_decay>
      <inertial>
        <mass>2.3570164391411</mass>
        <pose>0 0 0 0 0 0</pose>
        <!--
        <inertia>
          <ixx>0.0327522810455929</ixx>
          <ixy>0.00899866466757545</ixy>
          <ixz>0.000721787313956972</ixz>
          <iyy>0.00274871570596632</iyy>
          <iyz>0.00260642623951405</iyz>
          <izz>0.0349873948280755</izz>
        </inertia>
        -->
      </inertial>
      <collision name="UpperArm_collision">
        <pose>-0.977301626743842 -0.709767313781583 -0.133465984242475 0 0 0</pose>
        <geometry>
          <mesh>
            <scale>1 1 1</scale>
            <uri>model://SimSwerveBot3/meshes/UpperArm_col.STL</uri>
          </mesh>
        </geometry>
        <surface>
          <contact>
            <ode />
          </contact>
          <friction>
            <ode>
              <mu>1</mu>
              <mu2>1</mu2>
            </ode>
          </friction>
        </surface>
      </collision>
      <visual name="UpperArm_visual">
        <pose>-0.977301626743842 -0.709767313781583 -0.133465984242475 0 0 0</pose>
        <material>
          <ambient>0.250980392156863 0.501960784313725 0.501960784313725 1</ambient>
          <diffuse>0.250980392156863 0.501960784313725 0.501960784313725 1</diffuse>
        </material>
        <geometry>
          <mesh>
            <scale>1 1 1</scale>
            <uri>model://SimSwerveBot3/meshes/UpperArm.STL</uri>
          </mesh>
        </geometry>
      </visual>
    </link>
    <joint name="LowerArm-UpperArm" type="revolute">
      <parent>LowerArm</parent>
      <child>UpperArm</child>
      <pose>0.0949078106668886 0.34275847396224 0 0 4.71238898038469 0</pose>
      <axis>
        <xyz>1 0 0</xyz>
        <dynamics>
          <damping>1</damping>
          <friction>1</friction>
        </dynamics>
<!-- --> 
        <limit>
         <lower>-2.85</lower>
         <upper>2.85</upper>
        </limit>
      
      </axis>
    </joint>
   
   <!-- Gripper -->
    <link name="GripperRotate">
      <gravity>1</gravity>
      <self_collide>0</self_collide>
      <pose>0.410644632079937 0.304251355032236 0.0335850565029148 0 0 0</pose>
      <must_be_base_link>0</must_be_base_link>
      <velocity_decay>
        <linear>0</linear>
        <angular>0.1</angular>
      </velocity_decay>
      <inertial>
        <mass>0.1</mass>
        <pose>0 0 0 0 0 0</pose>        
      </inertial>
    
      <collision name="GripperRotate_collision">
        <pose>-0.867138888414116 -0.304251355032237 -0.0343039953788267 0 0 0</pose>
        <geometry>
          <mesh>
            <scale>1 1 1</scale>
            <uri>model://SimSwerveBot3/meshes/GripperRotate_col.STL</uri>
          </mesh>
        </geometry>
        <surface>
          <contact>
            <ode />
          </contact>
          <friction>
            <ode>
              <mu>1</mu>
              <mu2>1</mu2>
            </ode>
          </friction>
        </surface>
      </collision>
      
      <visual name="GripperRotate_visual">
        <pose>-0.867138888414116 -0.304251355032237 -0.0343039953788267 0 0 0</pose>
        <material>
          <ambient>0.752941176470588 0.752941176470588 0.752941176470588 1</ambient>
          <diffuse>0.752941176470588 0.752941176470588 0.752941176470588 1</diffuse>
        </material>
        <geometry>
          <mesh>
            <scale>1 1 1</scale>
            <uri>model://SimSwerveBot3/meshes/GripperRotate.STL</uri>
          </mesh>
        </geometry>
      </visual>
    </link>
    
    <joint name="UpperArm-GripperRotate" type="revolute">
      <parent>UpperArm</parent>
      <child>GripperRotate</child>
        <pose>-0.001887 -0.000642 -0 3.14159 1.57079 3.14159</pose>
      <axis>
        <xyz>1 0 0</xyz>
        
        <dynamics>
          <damping>2</damping>
          <friction>2</friction>
        </dynamics>
        <!---->
        <limit>
          <upper>1.5</upper>
          <lower>-1.5</lower>
        </limit>
        
      </axis>
    </joint>
     
    <link name="GripperTwist">
      <gravity>1</gravity>
      <self_collide>0</self_collide>
      <pose>0.513843964560248 0.209879195510605 -0.0171770373937321 0 0 0</pose>
      <must_be_base_link>0</must_be_base_link>
      <velocity_decay>
        <linear>0</linear>
        <angular>0.1</angular>
      </velocity_decay>
      <inertial>
       <mass>0.01</mass>
        <pose>0 0 0 0 0 0</pose>      
      </inertial>
      <!--
      <inertia>
          <ixx>0.000144179290386782</ixx>
          <ixy>5.90870697792821E-05</ixy>
          <ixz>4.10715642258176E-06</ixz>
          <iyy>0.000240011662145135</iyy>
          <iyz>3.63816895023731E-05</iyz>
          <izz>0.000362956457253779</izz>
        </inertia>
      -->
      <collision name="GripperTwist_collision">
        <pose>-0.970338220894427 -0.209879195510606 0.0164580985178202 0 0 0</pose>
        <geometry>
          <mesh>
            <scale>1 1 1</scale>
            <uri>model://SimSwerveBot3/meshes/GripperTwist_col.STL</uri>
          </mesh>
        </geometry>
        <surface>
          <contact>
            <ode />
          </contact>
          <friction>
            <ode>
              <mu>1</mu>
              <mu2>1</mu2>
            </ode>
          </friction>
        </surface>
      </collision>
      
      <visual name="GripperTwist_visual">
        <pose>-0.970338220894427 -0.209879195510606 0.0164580985178202 0 0 0</pose>
        <material>
          <ambient>0.752941176470588 0.752941176470588 0.752941176470588 1</ambient>
          <diffuse>0.752941176470588 0.752941176470588 0.752941176470588 1</diffuse>
        </material>
        <geometry>
          <mesh>
            <scale>1 1 1</scale>
            <uri>model://SimSwerveBot3/meshes/GripperTwist.STL</uri>
          </mesh>
        </geometry>
      </visual>
  
      <sensor name="GripperTwistCamera" type="camera">
        <visualize>1</visualize>
        <always_on>1</always_on>
                <pose>0.027422507856745 -0.00627316013977647 0.00272223138191047 -1.57 0.0 -1.0</pose>

        <camera name="GripperTwistcamera">
          <horizontal_fov>1.5707963267949</horizontal_fov>
          <image>
             <width>640</width>
            <height>480</height>
          </image>
          <clip>
            <near>0.1</near>
            <far>100</far>
          </clip>
        </camera>
        <plugin name="camera1" filename="sim_camera.dll">
          <topic>~/gazebo/frc/simulator/camera/0</topic>
          <port>9000</port>
          <fps>20</fps>
          <enabled>true</enabled>
          <savepath>tmp</savepath>
          <maxframes>1</maxframes>
      </plugin>
      </sensor>
    </link>
 
    <joint name="GripperRotate-GripperTwist" type="revolute">
      <parent>GripperRotate</parent>
      <child>GripperTwist</child>
      <pose>-0.020871891120782 -0.0149869750218195 0.00672065135518525 0 0 0</pose>
      <axis>
       <xyz>-0.8122 1.0 0</xyz>
       <dynamics>
          <damping>0.1</damping>
          <friction>0.1</friction>
        </dynamics>
        <limit>
          <upper>3.14</upper>
          <lower>-3.14</lower>
        </limit>
      </axis>
    </joint>
    
    <link name="LeftGripper">
      <gravity>1</gravity>
      <self_collide>0</self_collide>
      <pose>0.557320667154498 0.0719869069981106 -0.193435240872313 0 0 0</pose>
      <must_be_base_link>0</must_be_base_link>
      <velocity_decay>
        <linear>0</linear>
        <angular>0.1</angular>
      </velocity_decay>
      <inertial>
        <mass>0.01</mass>
        <pose>0 0 0 0 0 0</pose>
        
      </inertial>
      <collision name="LeftGripper_collision">
        <pose>-1.01381492348868 -0.0719869069981117 0.192716301996401 0 0 0</pose>
        <geometry>
          <mesh>
            <scale>1 1 1</scale>
            <uri>model://SimSwerveBot3/meshes/LeftGripper_col.STL</uri>
          </mesh>
        </geometry>
        <surface>
          <contact>
            <ode />
          </contact>
          <friction>
            <ode>
              <mu>0</mu>
              <mu2>0</mu2>
            </ode>
          </friction>
        </surface>
      </collision>
      <visual name="LeftGripper_visual">
        <pose>-1.01381492348868 -0.0719869069981117 0.192716301996401 0 0 0</pose>
        <material>
          <ambient>0.752941176470588 0.752941176470588 0.752941176470588 1</ambient>
          <diffuse>0.752941176470588 0.752941176470588 0.752941176470588 1</diffuse>
        </material>
        <geometry>
          <mesh>
            <scale>1 1 1</scale>
            <uri>model://SimSwerveBot3/meshes/LeftGripper.STL</uri>
          </mesh>
        </geometry>
      </visual>
    </link>
    <joint name="GripperTwist-LeftGripper" type="revolute">
      <parent>GripperTwist</parent>
      <child>LeftGripper</child>
      <pose>-0.0728289790912465 0.0982768539036823 0.0192775555177667 0 0.0950125221191799 4.55042876026699</pose>
      <axis>
        <xyz>-0.6 0.6 0</xyz>
        <dynamics>
          <damping>0.0</damping>
          <friction>0.0</friction>
        </dynamics>
         <limit>
          <upper>0.25</upper>
          <lower>0</lower>
        </limit>  
      </axis>
    </joint>
   
    <link name="RightGripper">
      <gravity>1</gravity>
      <self_collide>0</self_collide>
      <pose>0.535309594713599 0.0523854190468442 0.133776452201924 0 0 0</pose>
      <must_be_base_link>0</must_be_base_link>
      <velocity_decay>
        <linear>0</linear>
        <angular>0.1</angular>
      </velocity_decay>
      <inertial>
        <mass>0.01</mass>
        <pose>0 0 0 0 0 0</pose>
        
      </inertial>
      <collision name="RightGripper_collision">
        <pose>-0.991803851047778 -0.0523854190468453 -0.134495391077836 0 0 0</pose>
        <geometry>
          <mesh>
            <scale>1 1 1</scale>
            <uri>model://SimSwerveBot3/meshes/RightGripper_col.STL</uri>
          </mesh>
        </geometry>
        <surface>
          <contact>
            <ode />
          </contact>
          <friction>
            <ode>
              <mu>0</mu>
              <mu2>0</mu2>
            </ode>
          </friction>
        </surface>
      </collision>
      <visual name="RightGripper_visual">
        <pose>-0.991803851047778 -0.0523854190468453 -0.134495391077836 0 0 0</pose>
        <material>
          <ambient>0.752941176470588 0.752941176470588 0.752941176470588 1</ambient>
          <diffuse>0.752941176470588 0.752941176470588 0.752941176470588 1</diffuse>
        </material>
        <geometry>
          <mesh>
            <scale>1 1 1</scale>
            <uri>model://SimSwerveBot3/meshes/RightGripper.STL</uri>
          </mesh>
        </geometry>
      </visual>
    </link>
    <joint name="GripperTwist-RightGripper" type="revolute">
      <parent>GripperTwist</parent>
      <child>RightGripper</child>
      <pose>-0.0702210082292961 0.100570244506764 -0.0169877012766035 0 0.0950125221191799 4.55042876026699</pose>
      <axis>
        <xyz>0.6 -0.6 0</xyz>
        <dynamics>
          <damping>0.0</damping>
          <friction>0.0</friction>
        </dynamics>
        <limit>
          <upper>0.25</upper>
          <lower>0</lower>
        </limit>
       
      </axis>
    </joint>

    
    <link name="LeftPad">
      <gravity>1</gravity>
      <self_collide>0</self_collide>
      <pose>0.65045406809633 -0.061857243117229 -0.158044572202814 0 0 0</pose>
      <must_be_base_link>0</must_be_base_link>
      <velocity_decay>
        <linear>0</linear>
        <angular>0</angular>
      </velocity_decay>
      <inertial>
        <mass>0.01</mass>
        <pose>0 0 0 0 0 0</pose>
       
      </inertial>
      <collision name="LeftPad_collision">
        <pose>-1.10694832443051 0.0618572431172279 0.157325633326903 0 0 0</pose>
        <geometry>
          <mesh>
            <scale>1 1 1</scale>
            <uri>model://SimSwerveBot3/meshes/LeftPad_col.STL</uri>
          </mesh>
        </geometry>
        <surface>
          <contact>
            <ode />
          </contact>
          <friction>
            <ode>
              <mu>1</mu>
              <mu2>1</mu2>
            </ode>
          </friction>
        </surface>
      </collision>
      <visual name="LeftPad_visual">
        <pose>-1.10694832443051 0.0618572431172279 0.157325633326903 0 0 0</pose>
        <material>
          <ambient>0 0.501960784313725 0.501960784313725 1</ambient>
          <diffuse>0 0.501960784313725 0.501960784313725 1</diffuse>
        </material>
        <geometry>
          <mesh>
            <scale>1 1 1</scale>
            <uri>model://SimSwerveBot3/meshes/LeftPad.STL</uri>
          </mesh>
        </geometry>
      </visual>
    </link>
    <joint name="LeftGripper-LeftPad" type="fixed">
      <parent>LeftGripper</parent>
      <child>LeftPad</child>
      <pose>-4.9427129056312E-13 2.73212008572443E-13 5.72319969194268E-14 0 4.8944800425346 6.10164737499982</pose>
      <axis>
        <xyz>0.975649643624355 -0.174982960358412 0.132244986596373</xyz>
        <dynamics>
          <damping>0</damping>
          <friction>0</friction>
        </dynamics>
        <limit>
          <upper>0</upper>
          <lower>0</lower>
          <effort>1</effort>
        </limit>
      </axis>
    </joint>
    <link name="RightPad">
      <gravity>1</gravity>
      <self_collide>0</self_collide>
      <pose>0.632231615928298 -0.0778836267017213 0.0953488079418481 0 0 0</pose>
      <must_be_base_link>0</must_be_base_link>
      <velocity_decay>
        <linear>0</linear>
        <angular>0</angular>
      </velocity_decay>
      <inertial>
        <mass>0.01</mass>
        <pose>0 0 0 0 0 0</pose>    
      </inertial>
      <collision name="RightPad_collision">
        <pose>-1.08872587226248 0.0778836267017202 -0.0960677468177599 0 0 0</pose>
        <geometry>
          <mesh>
            <scale>1 1 1</scale>
            <uri>model://SimSwerveBot3/meshes/RightPad_col.STL</uri>
          </mesh>
        </geometry>
        <surface>
          <contact>
            <ode />
          </contact>
          <friction>
            <ode>
              <mu>1</mu>
              <mu2>1</mu2>
            </ode>
          </friction>
        </surface>
      </collision>
      <visual name="RightPad_visual">
        <pose>-1.08872587226248 0.0778836267017202 -0.0960677468177599 0 0 0</pose>
        <material>
          <ambient>0 0.501960784313725 0.501960784313725 1</ambient>
          <diffuse>0 0.501960784313725 0.501960784313725 1</diffuse>
        </material>
        <geometry>
          <mesh>
            <scale>1 1 1</scale>
            <uri>model://SimSwerveBot3/meshes/RightPad.STL</uri>
          </mesh>
        </geometry>
      </visual>
    </link>
    <joint name="RightGripper-RightPad" type="fixed">
      <parent>RightGripper</parent>
      <child>RightPad</child>
      <pose>5.08260100673397E-13 9.14296416354432E-13 2.84910983694431E-14 0 1.40438960444019 3.19826400892906</pose>
      <axis>
        <xyz>0.94730578747141 0.0646892133902353 -0.313730857095894</xyz>
        <dynamics>
          <damping>0</damping>
          <friction>0</friction>
        </dynamics>
        <limit>
          <upper>0</upper>
          <lower>0</lower>
          <effort>1</effort>
        </limit>
      </axis>
    </joint>
  <!---->
    <plugin name="clock" filename="sim_clock.dll">
      <topic>~/gazebo/frc/simulator/clock</topic>
    </plugin>

    <plugin name="Body_gyro" filename="sim_gyro.dll">
      <link>Body</link>
      <topic>~/gazebo/frc/simulator/gyro/0</topic>
      <units>degrees</units>
      <axis>yaw</axis>
    </plugin>
    
    <plugin name="Frame-FL-drive_motor" filename="sim_motor.dll">
      <joint>FLdrive-FLwheel</joint>
      <topic>~/gazebo/frc/simulator/motor/1</topic>
      <multiplier>25</multiplier>
    </plugin>
    <plugin name="Frame-FL-drive_encoder" filename="sim_encoder.dll">
        <joint>FLdrive-FLwheel</joint>
        <topic>~/gazebo/frc/simulator/encoder/1</topic>
        <multiplier>1</multiplier>
    </plugin> 
    <plugin name="Frame-FL-turn_motor" filename="sim_motor.dll">
        <joint>Body-FLdrive</joint>
        <topic>~/gazebo/frc/simulator/motor/2</topic>
        <multiplier>25</multiplier>
    </plugin>
      <plugin name="Frame-FL-turn_encoder" filename="sim_encoder.dll">
      <joint>Body-FLdrive</joint>
       <topic>~/gazebo/frc/simulator/encoder/2</topic>
      <multiplier>1</multiplier>
    </plugin>
 
    <plugin name="Frame-FR-drive_motor" filename="sim_motor.dll">
        <joint>FRdrive-FRwheel</joint>
        <topic>~/gazebo/frc/simulator/motor/3</topic>
        <multiplier>25</multiplier>
    </plugin>
    <plugin name="Frame-FR-drive_encoder" filename="sim_encoder.dll">
        <joint>FRdrive-FRwheel</joint>
        <topic>~/gazebo/frc/simulator/encoder/3</topic>
        <multiplier>1</multiplier>
    </plugin> 
    <plugin name="Frame-FR-turn_motor" filename="sim_motor.dll">
        <joint>Body-FRdrive</joint>
        <topic>~/gazebo/frc/simulator/motor/4</topic>
        <multiplier>25</multiplier>
    </plugin>
    <plugin name="Frame-FR-turn_encoder" filename="sim_encoder.dll">
      <joint>Body-FRdrive</joint>
       <topic>~/gazebo/frc/simulator/encoder/4</topic>
      <multiplier>1</multiplier>
    </plugin>

    <plugin name="Frame-BL-drive_motor" filename="sim_motor.dll">
        <joint>BLdrive-BLwheel</joint>
        <topic>~/gazebo/frc/simulator/motor/5</topic>
        <multiplier>25</multiplier>
    </plugin>
    <plugin name="Frame-BL-drive_encoder" filename="sim_encoder.dll">
        <joint>BLdrive-BLwheel</joint>
        <topic>~/gazebo/frc/simulator/encoder/5</topic>
        <multiplier>1</multiplier>
    </plugin> 
    <plugin name="Frame-BL-turn_motor" filename="sim_motor.dll">
        <joint>Body-BLdrive</joint>
        <topic>~/gazebo/frc/simulator/motor/6</topic>
        <multiplier>25</multiplier>
    </plugin>
    <plugin name="Frame-BL-turn_encoder" filename="sim_encoder.dll">
        <joint>Body-BLdrive</joint>
        <topic>~/gazebo/frc/simulator/encoder/6</topic>
        <multiplier>1</multiplier>
    </plugin>

    <plugin name="Frame-BR-drive_motor" filename="sim_motor.dll">
        <joint>BRdrive-BRwheel</joint>
        <topic>~/gazebo/frc/simulator/motor/7</topic>
        <multiplier>25</multiplier>
    </plugin>
      <plugin name="Frame-BR-drive_encoder" filename="sim_encoder.dll">
        <joint>BRdrive-BRwheel</joint>
        <topic>~/gazebo/frc/simulator/encoder/7</topic>
        <multiplier>1</multiplier>
    </plugin> 
    <plugin name="Frame-BR-turn_motor" filename="sim_motor.dll">
        <joint>Body-BRdrive</joint>
        <topic>~/gazebo/frc/simulator/motor/8</topic>
        <multiplier>25</multiplier>
    </plugin>
    <plugin name="Frame-BR-turn_encoder" filename="sim_encoder.dll">
        <joint>Body-BRdrive</joint>
        <topic>~/gazebo/frc/simulator/encoder/8</topic>
        <multiplier>1</multiplier>
    </plugin>

    <plugin name="Frame-lower-arm_motor" filename="sim_motor.dll">
        <joint>Body-LowerArm</joint>
        <topic>~/gazebo/frc/simulator/motor/9</topic>
        <multiplier>40</multiplier>
    </plugin>
    <plugin name="Frame-lower-arm_encoder" filename="sim_encoder.dll">
        <joint>Body-LowerArm</joint>
        <topic>~/gazebo/frc/simulator/encoder/9</topic>
        <multiplier>1</multiplier>
    </plugin>

    <plugin name="LowerArm-UpperArm_motor" filename="sim_motor.dll">
        <joint>LowerArm-UpperArm</joint>
        <topic>~/gazebo/frc/simulator/motor/10</topic>
        <multiplier>30</multiplier>
    </plugin>
    <plugin name="LowerArm-UpperArm_encoder" filename="sim_encoder.dll">
        <joint>LowerArm-UpperArm</joint>
        <topic>~/gazebo/frc/simulator/encoder/10</topic>
        <multiplier>1</multiplier>
    </plugin>

    <plugin name="UpperArm-Wrist_motor" filename="sim_motor.dll">
        <joint>UpperArm-GripperRotate</joint>
        <topic>~/gazebo/frc/simulator/motor/11</topic>
        <multiplier>40</multiplier>
    </plugin>
    <plugin name="UpperArm-Wrist_encoder" filename="sim_encoder.dll">
        <joint>UpperArm-GripperRotate</joint>
        <topic>~/gazebo/frc/simulator/encoder/11</topic>
        <multiplier>1</multiplier>
    </plugin>

    <plugin name="GripperRotate-GripperTwist_motor" filename="sim_motor.dll">
        <joint>GripperRotate-GripperTwist</joint>
        <topic>~/gazebo/frc/simulator/motor/12</topic>
        <multiplier>20</multiplier>
    </plugin>
    <plugin name="GripperRotate-GripperTwist_encoder" filename="sim_encoder.dll">
        <joint>GripperRotate-GripperTwist</joint>
        <topic>~/gazebo/frc/simulator/encoder/12</topic>
        <multiplier>1</multiplier>
    </plugin>

    <plugin name="GripperTwist-LeftGripper" filename="sim_piston.dll">
        <joint>GripperTwist-LeftGripper</joint>
        <topic>~/gazebo/frc/simulator/piston/0</topic>
        <forward-force>20</forward-force>
        <reverse-force>20</reverse-force>
    </plugin>

     <plugin name="GripperTwist-RightGripper" filename="sim_piston.dll">
        <joint>GripperTwist-RightGripper</joint>
        <topic>~/gazebo/frc/simulator/piston/0</topic>
        <forward-force>20</forward-force>
        <reverse-force>20</reverse-force>    
      </plugin>

  </model>
</sdf>