<?xml version="1.0" encoding="utf-8"?>
<sdf version="1.5">
  <model name="SimSwerveBot3">
        <pose>-0.000197 -0.000161 0.095369 1.56818 -0.000125 1.55183</pose>
   
    <link name="Body">
      <gravity>1</gravity>
      <self_collide>0</self_collide>
      <pose>0.002226 0.01011 0.122431 1.56818 -0.000125 1.55183</pose>
      <must_be_base_link>1</must_be_base_link>
      <velocity_decay>
        <linear>0</linear>
        <angular>0</angular>
      </velocity_decay>
      <inertial>
        <mass>100</mass>
        <pose>0 0 0 0 0 0</pose>
        <inertia>
          <ixx>0.281462866767804</ixx>
          <ixy>0.00534071773862858</ixy>
          <ixz>0.00063191111485271</ixz>
          <iyy>0.688565334814199</iyy>
          <iyz>0.00210804924810935</iyz>
          <izz>0.474279088453001</izz>
        </inertia>
      </inertial>
      <collision name="Body_collision">
        <pose>-0.466812853283889 -0.02705559157244 -0.00301802987182291 0 0 0</pose>
        <geometry>
          <mesh>
            <scale>1 1 1</scale>
            <uri>model://SimSwerveBot3/meshes/Body_col.STL</uri>
          </mesh>
        </geometry>
        <surface>
          <contact>
            <ode />
          </contact>
          <friction>
            <ode>
              <mu>0</mu>
              <mu2>0</mu2>
            </ode>
          </friction>
        </surface>
      </collision>
      <visual name="Body_visual">
        <pose>-0.466812853283889 -0.02705559157244 -0.00301802987182291 0 0 0</pose>
        <material>
          <ambient>0.501960784313725 0.501960784313725 0.501960784313725 1</ambient>
          <diffuse>0.501960784313725 0.501960784313725 0.501960784313725 1</diffuse>
        </material>
        <geometry>
          <mesh>
            <scale>1 1 1</scale>
            <uri>model://SimSwerveBot3/meshes/Body.STL</uri>
          </mesh>
        </geometry>
      </visual>
    </link>
    
    <link name="FRdrive">
      <gravity>1</gravity>
      <self_collide>0</self_collide>
          <pose>0.217549 0.359272 0.098944 1.56413 -0.000125 1.55183</pose>
      <must_be_base_link>0</must_be_base_link>
       <velocity_decay>
        <linear>0</linear>
        <angular>0.01</angular>
      </velocity_decay>
      <inertial>
        <mass>1</mass>
        <pose>0 0 0 0 0 0</pose>
      </inertial>
      <visual name="FRdrive_visual">
        <pose>-0.81999064385272 -0.00308940755423872 -0.211618131690221 0 0 0</pose>
        <material>
          <ambient>0.501960784313725 0.501960784313725 0.501960784313725 1</ambient>
          <diffuse>0.501960784313725 0.501960784313725 0.501960784313725 1</diffuse>
        </material>
        <geometry>
          <mesh>
            <scale>1 1 1</scale>
            <uri>model://SimSwerveBot3/meshes/FRdrive.STL</uri>
          </mesh>
        </geometry>
      </visual>
    </link>
    <joint name="Body-FRdrive" type="revolute">
      <parent>Body</parent>
      <child>FRdrive</child>
      <pose>0.0270286124814588 0 0.027225807185676 0 0 4.71238898038469</pose>
      <axis>
        <xyz>0 1 0</xyz>
        <dynamics>
          <damping>1</damping>
          <friction>1</friction>
        </dynamics>   
      </axis>
    </joint>
    <link name="FRwheel">
      <gravity>1</gravity>
      <self_collide>0</self_collide>
          <pose>0.247258 0.38575 0.05061 1.57334 -5.6e-05 1.55183</pose>
      <must_be_base_link>0</must_be_base_link>
      <velocity_decay>
        <linear>0</linear>
        <angular>0.002</angular>
      </velocity_decay>
      <inertial>
        <mass>1</mass>
        <pose>0 0 0 0 0 0</pose>      
      </inertial>
      <collision name="FRwheel_collision">
        <pose>-0.847019150986402 0.0454407782959989 -0.240498070256203 0 0 0</pose>
        <geometry>
          <mesh>
            <scale>1 1 1</scale>
            <uri>model://SimSwerveBot3/meshes/FRwheel_col.STL</uri>
          </mesh>
        </geometry>
        <surface>
          <contact>
             <ode>
              <max_vel>0.1</max_vel>
              <soft_cfm>0.8</soft_cfm>
              <soft_erp>0.8</soft_erp>
              <kd>25</kd>
              <kp>1e6</kp>
              <min_depth>0.0001</min_depth>
            </ode>          
          </contact>
          <friction>
            <ode>
              <mu>1</mu>
              <mu2>1</mu2>
            </ode>
          </friction>
        </surface>
      </collision>
      <visual name="FRwheel_visual">
        <pose>-0.847019150986402 0.0454407782959989 -0.240498070256203 0 0 0</pose>
        <material>
          <ambient>0 1 0 1</ambient>
          <diffuse>0 1 0 1</diffuse>
        </material>
        <geometry>
          <mesh>
            <scale>1 1 1</scale>
            <uri>model://SimSwerveBot3/meshes/FRwheel.STL</uri>
          </mesh>
        </geometry>
      </visual>
    </link>
    <joint name="FRdrive-FRwheel" type="revolute">
      <parent>FRdrive</parent>
      <child>FRwheel</child>
      <pose>1.25638072463463E-05 0.00011429545755863 -9.46325306450113E-08 0 4.7199209919262 6.28318530717959</pose>
      <axis>
        <xyz>0 0 -1</xyz>
        <dynamics>
          <damping>1</damping>
          <friction>1</friction>
        </dynamics>
      </axis>
    </joint>
    <link name="FLdrive">
      <gravity>1</gravity>
      <self_collide>0</self_collide>
          <pose>-0.229243 0.394774 0.090841 1.56414 -0.000127 1.55183</pose>
      <must_be_base_link>0</must_be_base_link>
      <velocity_decay>
        <linear>0</linear>
        <angular>0.01</angular>
      </velocity_decay>
      <inertial>
        <mass>1</mass>
        <pose>0 0 0 0 0 0</pose>      
      </inertial>
      <visual name="FLdrive_visual">
        <pose>-0.847010431546437 0.00398782218945027 0.235785793407349 0 0 0</pose>
        <material>
          <ambient>0.501960784313725 0.501960784313725 0.501960784313725 1</ambient>
          <diffuse>0.501960784313725 0.501960784313725 0.501960784313725 1</diffuse>
        </material>
        <geometry>
          <mesh>
            <scale>1 1 1</scale>
            <uri>model://SimSwerveBot3/meshes/FLdrive.STL</uri>
          </mesh>
        </geometry>
      </visual>
    </link>
    <joint name="Body-FLdrive" type="revolute">
      <parent>Body</parent>
      <child>FLdrive</child>
      <pose>8.82478774166806E-06 5.20417042793042E-18 -0.00162026771675042 0 6.28318530717959 4.71238898038469</pose>
      <axis>
        <xyz>0 1 0</xyz>
        <dynamics>
          <damping>1</damping>
          <friction>1</friction>
        </dynamics>       
      </axis>
    </joint>
    <link name="FLwheel">
      <gravity>1</gravity>
      <self_collide>0</self_collide>
          <pose>-0.228939 0.394843 0.049572 1.56975 -9.7e-05 1.55183</pose>
      <must_be_base_link>0</must_be_base_link>
      <velocity_decay>
        <linear>0</linear>
        <angular>0.002</angular>
      </velocity_decay>
      <inertial>
        <mass>0.123981363237525</mass>
        <pose>0 0 0 0 0 0</pose>
      </inertial>
      <collision name="FLwheel_collision">
        <pose>-0.847044197483843 0.0454363391768107 0.235751817242042 0 0 0</pose>
        <geometry>
          <mesh>
            <scale>1 1 1</scale>
            <uri>model://SimSwerveBot3/meshes/FLwheel_col.STL</uri>
          </mesh>
        </geometry>
        <surface>
          <contact>
             <ode>
              <max_vel>0.1</max_vel>
              <soft_cfm>0.8</soft_cfm>
              <soft_erp>0.8</soft_erp>
              <kd>25</kd>
              <kp>1e6</kp>
              <min_depth>0.001</min_depth>
            </ode>          
          </contact>
          <friction>
            <ode>
              <mu>1</mu>
              <mu2>1</mu2>
            </ode>
          </friction>
        </surface>
      </collision>
      <visual name="FLwheel_visual">
        <pose>-0.847044197483843 0.0454363391768107 0.235751817242042 0 0 0</pose>
        <material>
          <ambient>0 1 0 1</ambient>
          <diffuse>0 1 0 1</diffuse>
        </material>
        <geometry>
          <mesh>
            <scale>1 1 1</scale>
            <uri>model://SimSwerveBot3/meshes/FLwheel.STL</uri>
          </mesh>
        </geometry>
      </visual>
    </link>
    <joint name="FLdrive-FLwheel" type="revolute">
      <parent>FLdrive</parent>
      <child>FLwheel</child>
      <pose>-3.39534051447821E-05 0.000109856338368929 -1.84997501873063E-07 0 4.71783749638594 5.39814581483388E-16</pose>
      <axis>
        <xyz>0 0 -1</xyz>
        <dynamics>
          <damping>1</damping>
          <friction>1</friction>
        </dynamics> 
      </axis>
    </joint>
    <link name="BRdrive">
      <gravity>1</gravity>
      <self_collide>0</self_collide>
          <pose>0.230385 -0.394431 0.070702 1.57706 -0.000104 1.55183</pose>
      <must_be_base_link>0</must_be_base_link>
      <velocity_decay>
        <linear>0</linear>
        <angular>0.01</angular>
      </velocity_decay>
      <inertial>
        <mass>1</mass>
        <pose>0 0 0 0 0 0</pose>
      </inertial>
      <visual name="BRdrive_visual">
        <pose>-0.0666739049592076 0.0252568719347445 -0.238665521107992 0 0 0</pose>
        <material>
          <ambient>0.501960784313725 0.501960784313725 0.501960784313725 1</ambient>
          <diffuse>0.501960784313725 0.501960784313725 0.501960784313725 1</diffuse>
        </material>
        <geometry>
          <mesh>
            <scale>1 1 1</scale>
            <uri>model://SimSwerveBot3/meshes/BRdrive.STL</uri>
          </mesh>
        </geometry>
      </visual>
    </link>
    <joint name="Body-BRdrive" type="revolute">
      <parent>Body</parent>
      <child>BRdrive</child>
      <pose>1.09504079234823E-06 0 0.000178417767905031 0 6.28318530717959 4.71238898038469</pose>
      <axis>
        <xyz>0 1 0</xyz>
        <dynamics>
          <damping>1</damping>
          <friction>1</friction>
        </dynamics>      
      </axis>
    </joint>
    <link name="BRwheel">
      <gravity>1</gravity>
      <self_collide>0</self_collide>
          <pose>0.228787 -0.394401 0.050531 1.57028 -0.000146 1.55183</pose>
      <must_be_base_link>0</must_be_base_link>
      <velocity_decay>
        <linear>0</linear>
        <angular>0.002</angular>
      </velocity_decay>
      <inertial>
        <mass>1</mass>
        <pose>0 0 0 0 0 0</pose>
      </inertial>
      <collision name="BRwheel_collision">
        <pose>-0.066677501205518 0.0454407782968187 -0.237189809560838 0 0 0</pose>
        <geometry>
          <mesh>
            <scale>1 1 1</scale>
            <uri>model://SimSwerveBot3/meshes/BRwheel_col.STL</uri>
          </mesh>
        </geometry>
        <surface>
          <contact>
            <ode>
              <max_vel>0.1</max_vel>
              <soft_cfm>0.8</soft_cfm>
              <soft_erp>0.8</soft_erp>
              <kd>25</kd>
              <kp>1e6</kp>
              <min_depth>0.0001</min_depth>
            </ode>          
          </contact>
          <friction>
            <ode>
              <mu>1</mu>
              <mu2>1</mu2>
            </ode>
          </friction>
        </surface>
      </collision>
      <visual name="BRwheel_visual">
        <pose>-0.066677501205518 0.0454407782968187 -0.237189809560838 0 0 0</pose>
        <material>
          <ambient>0 1 0 1</ambient>
          <diffuse>0 1 0 1</diffuse>
        </material>
        <geometry>
          <mesh>
            <scale>1 1 1</scale>
            <uri>model://SimSwerveBot3/meshes/BRwheel.STL</uri>
          </mesh>
        </geometry>
      </visual>
    </link>
    <joint name="BRdrive-BRwheel" type="revolute">
      <parent>BRdrive</parent>
      <child>BRwheel</child>
      <pose>-1.25639304105613E-05 0.000114295458376691 7.6434905293965E-08 0 1.56471272398399 3.14159265358979</pose>
      <axis>
        <xyz>0 0 -1</xyz>
        <dynamics>
          <damping>1</damping>
          <friction>1</friction>
        </dynamics>   
      </axis>
    </joint>
    <link name="BLdrive">
      <gravity>1</gravity>
      <self_collide>0</self_collide>
          <pose>-0.247272 -0.385174 0.092077 1.56817 -0.000119 1.55183</pose>
      <must_be_base_link>0</must_be_base_link>
      <velocity_decay>
        <linear>0</linear>
        <angular>0.01</angular>
      </velocity_decay>
      <inertial>
        <mass>1</mass>
        <pose>0 0 0 0 0 0</pose>
      </inertial>
      <visual name="BLdrive_visual">
        <pose>-0.0666627918911016 0.00398782097182643 0.239026308700343 0 0 0</pose>
        <material>
          <ambient>0.501960784313725 0.501960784313725 0.501960784313725 1</ambient>
          <diffuse>0.501960784313725 0.501960784313725 0.501960784313725 1</diffuse>
        </material>
        <geometry>
          <mesh>
            <scale>1 1 1</scale>
            <uri>model://SimSwerveBot3/meshes/BLdrive.STL</uri>
          </mesh>
        </geometry>
      </visual>
    </link>
    <joint name="Body-BLdrive" type="revolute">
      <parent>Body</parent>
      <child>BLdrive</child>
      <pose>1.22081088980014E-05 -1.84389346673253E-10 138.334863892454 0 0 0</pose>
      <axis>
        <xyz>0 1 0</xyz>
        <dynamics>
          <damping>1</damping>
          <friction>1</friction>
        </dynamics>      
      </axis>
    </joint>
    <link name="BLwheel">
      <gravity>1</gravity>
      <self_collide>0</self_collide>
          <pose>-0.247199 -0.385159 0.050624 1.57298 -8.3e-05 1.55183</pose>
      <must_be_base_link>0</must_be_base_link>
      <velocity_decay>
        <linear>0</linear>
        <angular>0.002</angular>
      </velocity_decay>
      <inertial>
        <mass>0.123981366006227</mass>
        <pose>0 0 0 0 0 0</pose>
      </inertial>
      <collision name="BLwheel_collision">
        <pose>-0.0666751053477765 0.0454407782959999 0.239060192504404 0 0 0</pose>
        <geometry>
          <mesh>
            <scale>1 1 1</scale>
            <uri>model://SimSwerveBot3/meshes/BLwheel_col.STL</uri>
          </mesh>
        </geometry>
        <surface>
         <contact>
             <ode>
              <max_vel>0.1</max_vel>
              <soft_cfm>0.8</soft_cfm>
              <soft_erp>0.8</soft_erp>
              <kd>25</kd>
              <kp>1e6</kp>
              <min_depth>0.0001</min_depth>
            </ode>          
          </contact>
          <friction>
            <ode>
              <mu>1</mu>
              <mu2>1</mu2>
            </ode>
          </friction>
        </surface>
      </collision>
      <visual name="BLwheel_visual">
        <pose>-0.0666751053477765 0.0454407782959999 0.239060192504404 0 0 0</pose>
        <material>
          <ambient>0 1 0 1</ambient>
          <diffuse>0 1 0 1</diffuse>
        </material>
        <geometry>
          <mesh>
            <scale>1 1 1</scale>
            <uri>model://SimSwerveBot3/meshes/BLwheel.STL</uri>
          </mesh>
        </geometry>
      </visual>
    </link>
    <joint name="BLdrive-BLwheel" type="revolute">
      <parent>BLdrive</parent>
      <child>BLwheel</child>
      <pose>-1.25638072462075E-05 0.00011429545755836 9.4632530728278E-08 0 1.56326431525339 3.14159265358979</pose>
      <axis>
        <xyz>0 0 -1</xyz>
        <dynamics>
          <damping>1</damping>
          <friction>1</friction>
        </dynamics>     
      </axis>
    </joint>
    
    <link name="LowerArm">
      <gravity>1</gravity>
      <self_collide>0</self_collide>
          <pose>0.205244 0.282543 0.665276 1.56815 -0.000128 1.55182</pose>
      <must_be_base_link>0</must_be_base_link>
      <velocity_decay>
        <linear>0</linear>
        <angular>0</angular>
      </velocity_decay>
      <inertial>
        <mass>3.19006579837111</mass>
        <pose>0 0 0 0 0 0</pose>
        <inertia>
          <ixx>0.0573004752158579</ixx>
          <ixy>0.0388509565035045</ixy>
          <ixz>0.00215756738631079</ixz>
          <iyy>0.0267256940750842</iyy>
          <iyz>0.0031675240564386</iyz>
          <izz>0.0835009253183463</izz>
        </inertia>
      </inertial>
      <collision name="LowerArm_collision">
        <pose>-0.743107694697595 -0.569352514264947 -0.202400997868789 0 0 0</pose>
        <geometry>
          <mesh>
            <scale>1 1 1</scale>
            <uri>model://SimSwerveBot3/meshes/LowerArm_col.STL</uri>
          </mesh>
        </geometry>
        <surface>
          <contact>
            <ode />
          </contact>
          <friction>
            <ode>
              <mu>0</mu>
              <mu2>0</mu2>
            </ode>
          </friction>
        </surface>
      </collision>
      <visual name="LowerArm_visual">
        <pose>-0.743107694697595 -0.569352514264947 -0.202400997868789 0 0 0</pose>
        <material>
          <ambient>0.250980392156863 0.501960784313725 0.501960784313725 1</ambient>
          <diffuse>0.250980392156863 0.501960784313725 0.501960784313725 1</diffuse>
        </material>
        <geometry>
          <mesh>
            <scale>1 1 1</scale>
            <uri>model://SimSwerveBot3/meshes/LowerArm.STL</uri>
          </mesh>
        </geometry>
      </visual>
    </link>
    <joint name="Body-LowerArm" type="revolute">
      <parent>Body</parent>
      <child>LowerArm</child>
      <pose>-0.288320694697595 -0.423302514264947 0 0 1.5707963267949 0</pose>
      <axis>
        <xyz>1 0 0</xyz>
        <dynamics>
          <damping>0</damping>
          <friction>0</friction>
        </dynamics>
        <limit>
          <upper>0</upper>
          <lower>0</lower>
          <effort>1</effort>
        </limit>
      </axis>
    </joint>
    
    <link name="UpperArm">
      <gravity>1</gravity>
      <self_collide>0</self_collide>
          <pose>0.140511 0.51799 0.805536 1.56787 -9.5e-05 1.55222</pose>
      <must_be_base_link>0</must_be_base_link>
      <velocity_decay>
        <linear>0</linear>
        <angular>0</angular>
      </velocity_decay>
      <inertial>
        <mass>2.3570164391411</mass>
        <pose>0 0 0 0 0 0</pose>
        <inertia>
          <ixx>0.0327522810455929</ixx>
          <ixy>0.00899866466757545</ixy>
          <ixz>0.000721787313956972</ixz>
          <iyy>0.00274871570596632</iyy>
          <iyz>0.00260642623951405</iyz>
          <izz>0.0349873948280755</izz>
        </inertia>
      </inertial>
      <collision name="UpperArm_collision">
        <pose>-0.977301626743842 -0.709767313781583 -0.133465984242475 0 0 0</pose>
        <geometry>
          <mesh>
            <scale>1 1 1</scale>
            <uri>model://SimSwerveBot3/meshes/UpperArm_col.STL</uri>
          </mesh>
        </geometry>
        <surface>
          <contact>
            <ode />
          </contact>
          <friction>
            <ode>
              <mu>0</mu>
              <mu2>0</mu2>
            </ode>
          </friction>
        </surface>
      </collision>
      <visual name="UpperArm_visual">
        <pose>-0.977301626743842 -0.709767313781583 -0.133465984242475 0 0 0</pose>
        <material>
          <ambient>0.250980392156863 0.501960784313725 0.501960784313725 1</ambient>
          <diffuse>0.250980392156863 0.501960784313725 0.501960784313725 1</diffuse>
        </material>
        <geometry>
          <mesh>
            <scale>1 1 1</scale>
            <uri>model://SimSwerveBot3/meshes/UpperArm.STL</uri>
          </mesh>
        </geometry>
      </visual>
    </link>
    <joint name="LowerArm-UpperArm" type="revolute">
      <parent>LowerArm</parent>
      <child>UpperArm</child>
      <pose>0.0949078106668886 0.34275847396224 0 0 4.71238898038469 0</pose>
      <axis>
        <xyz>1 0 0</xyz>
        <dynamics>
          <damping>0</damping>
          <friction>0</friction>
        </dynamics>
        <limit>
          <upper>0</upper>
          <lower>0</lower>
          <effort>1</effort>
        </limit>
      </axis>
    </joint>
   
    <link name="GripperRotate">
      <gravity>1</gravity>
      <self_collide>0</self_collide>
          <pose>0.040448 0.408546 0.400952 1.56618 -0.886088 1.55572</pose>
      <must_be_base_link>0</must_be_base_link>
      <velocity_decay>
        <linear>0</linear>
        <angular>0.1</angular>
      </velocity_decay>
      <inertial>
        <mass>0.01</mass>
        <pose>0 0 0 0 0 0</pose>        
      </inertial>
     
      <collision name="GripperRotate_collision">
        <pose>-0.867138888414116 -0.304251355032237 -0.0343039953788267 0 0 0</pose>
        <geometry>
          <mesh>
            <scale>1 1 1</scale>
            <uri>model://SimSwerveBot3/meshes/GripperRotate_col.STL</uri>
          </mesh>
        </geometry>
        <surface>
          <contact>
            <ode />
          </contact>
          <friction>
            <ode>
              <mu>1</mu>
              <mu2>1</mu2>
            </ode>
          </friction>
        </surface>
      </collision>
      
      <visual name="GripperRotate_visual">
        <pose>-0.867138888414116 -0.304251355032237 -0.0343039953788267 0 0 0</pose>
        <material>
          <ambient>0.752941176470588 0.752941176470588 0.752941176470588 1</ambient>
          <diffuse>0.752941176470588 0.752941176470588 0.752941176470588 1</diffuse>
        </material>
        <geometry>
          <mesh>
            <scale>1 1 1</scale>
            <uri>model://SimSwerveBot3/meshes/GripperRotate.STL</uri>
          </mesh>
        </geometry>
      </visual>
    </link>
    
    <joint name="UpperArm-GripperRotate" type="revolute">
      <parent>UpperArm</parent>
      <child>GripperRotate</child>
        <pose>-0.001887 -0.000642 -0 3.14159 1.57079 3.14159</pose>
      <axis>
        <xyz>1 0 0</xyz>
        
        <dynamics>
          <damping>1</damping>
          <friction>1</friction>
        </dynamics>
        <limit>
          <upper>1.5</upper>
          <lower>-0.9</lower>
        </limit>
      </axis>
    </joint>
      
    <link name="GripperTwist">
      <gravity>1</gravity>
      <self_collide>0</self_collide>
          <pose>-0.00706 0.547837 0.421238 1.6105 -0.885688 1.51965</pose>
      <must_be_base_link>0</must_be_base_link>
      <velocity_decay>
        <linear>0</linear>
        <angular>0.1</angular>
      </velocity_decay>
      <inertial>
       <mass>0.0106209522650121</mass>
        <pose>0 0 0 0 0 0</pose>      
      </inertial>
      
      <collision name="GripperTwist_collision">
        <pose>-0.970338220894427 -0.209879195510606 0.0164580985178202 0 0 0</pose>
        <geometry>
          <mesh>
            <scale>1 1 1</scale>
            <uri>model://SimSwerveBot3/meshes/GripperTwist_col.STL</uri>
          </mesh>
        </geometry>
        <surface>
          <contact>
            <ode />
          </contact>
          <friction>
            <ode>
              <mu>1</mu>
              <mu2>1</mu2>
            </ode>
          </friction>
        </surface>
      </collision>
      
      <visual name="GripperTwist_visual">
        <pose>-0.970338220894427 -0.209879195510606 0.0164580985178202 0 0 0</pose>
        <material>
          <ambient>0.752941176470588 0.752941176470588 0.752941176470588 1</ambient>
          <diffuse>0.752941176470588 0.752941176470588 0.752941176470588 1</diffuse>
        </material>
        <geometry>
          <mesh>
            <scale>1 1 1</scale>
            <uri>model://SimSwerveBot3/meshes/GripperTwist.STL</uri>
          </mesh>
        </geometry>
      </visual>
  
      <sensor name="GripperTwistCamera" type="camera">
        <visualize>1</visualize>
        <always_on>1</always_on>
        <pose>0.027422507856745 -0.00627316013977647 0.00272223138191047 0 0 0</pose>
        <camera name="GripperTwistcamera">
          <horizontal_fov>1.5707963267949</horizontal_fov>
          <image>
            <width>320</width>
            <height>240</height>
          </image>
          <clip>
            <near>0.1</near>
            <far>100</far>
          </clip>
        </camera>
      </sensor>
    </link>
  
    <joint name="GripperRotate-GripperTwist" type="revolute">
      <parent>GripperRotate</parent>
      <child>GripperTwist</child>
      <pose>-0.020871891120782 -0.0149869750218195 0.00672065135518525 0 0 0</pose>
      <axis>
      <xyz>0.812286349216375 0.583258850663008 0</xyz>
       <dynamics>
          <damping>1</damping>
          <friction>1</friction>
        </dynamics>
        <limit>
          <upper>0.1</upper>
          <lower>0</lower>

        </limit>
      </axis>
    </joint>
     
    <link name="LeftGripper">
      <gravity>1</gravity>
      <self_collide>0</self_collide>
      <pose>0.557320667154498 0.0719869069981106 -0.193435240872313 0 0 0</pose>
      <must_be_base_link>0</must_be_base_link>
      <velocity_decay>
        <linear>0</linear>
        <angular>0.1</angular>
      </velocity_decay>
      <inertial>
        <mass>0.528149142135129</mass>
        <pose>0 0 0 0 0 0</pose>
        
      </inertial>
      <collision name="LeftGripper_collision">
        <pose>-1.01381492348868 -0.0719869069981117 0.192716301996401 0 0 0</pose>
        <geometry>
          <mesh>
            <scale>1 1 1</scale>
            <uri>model://SimSwerveBot3/meshes/LeftGripper_col.STL</uri>
          </mesh>
        </geometry>
        <surface>
          <contact>
            <ode />
          </contact>
          <friction>
            <ode>
              <mu>0</mu>
              <mu2>0</mu2>
            </ode>
          </friction>
        </surface>
      </collision>
      <visual name="LeftGripper_visual">
        <pose>-1.01381492348868 -0.0719869069981117 0.192716301996401 0 0 0</pose>
        <material>
          <ambient>0.752941176470588 0.752941176470588 0.752941176470588 1</ambient>
          <diffuse>0.752941176470588 0.752941176470588 0.752941176470588 1</diffuse>
        </material>
        <geometry>
          <mesh>
            <scale>1 1 1</scale>
            <uri>model://SimSwerveBot3/meshes/LeftGripper.STL</uri>
          </mesh>
        </geometry>
      </visual>
    </link>
    <joint name="GripperTwist-LeftGripper" type="revolute">
      <parent>GripperTwist</parent>
      <child>LeftGripper</child>
      <pose>0.111890652409923 -0.0215624740650626 138.35185961093 0 0 0</pose>
      <axis>
        <xyz>-0.808622698046812 -0.580628181106082 -0.0948696342827216</xyz>
        <dynamics>
          <damping>0</damping>
          <friction>0</friction>
        </dynamics>
        <limit>
          <upper>0</upper>
          <lower>0</lower>
          <effort>1</effort>
        </limit>
      </axis>
    </joint>
    <!--
    <link name="RightGripper">
      <gravity>1</gravity>
      <self_collide>0</self_collide>
      <pose>0.535309594713599 0.0523854190468442 0.133776452201924 0 0 0</pose>
      <must_be_base_link>0</must_be_base_link>
      <velocity_decay>
        <linear>0</linear>
        <angular>0</angular>
      </velocity_decay>
      <inertial>
        <mass>0.52814914213513</mass>
        <pose>0 0 0 0 0 0</pose>
        <inertia>
          <ixx>0</ixx>
          <ixy>0</ixy>
          <ixz>0</ixz>
          <iyy>0</iyy>
          <iyz>0</iyz>
          <izz>0</izz>
        </inertia>
      </inertial>
      <collision name="RightGripper_collision">
        <pose>-0.991803851047778 -0.0523854190468453 -0.134495391077836 0 0 0</pose>
        <geometry>
          <mesh>
            <scale>1 1 1</scale>
            <uri>model://SimSwerveBot3/meshes/RightGripper_col.STL</uri>
          </mesh>
        </geometry>
        <surface>
          <contact>
            <ode />
          </contact>
          <friction>
            <ode>
              <mu>0</mu>
              <mu2>0</mu2>
            </ode>
          </friction>
        </surface>
      </collision>
      <visual name="RightGripper_visual">
        <pose>-0.991803851047778 -0.0523854190468453 -0.134495391077836 0 0 0</pose>
        <material>
          <ambient>0.752941176470588 0.752941176470588 0.752941176470588 1</ambient>
          <diffuse>0.752941176470588 0.752941176470588 0.752941176470588 1</diffuse>
        </material>
        <geometry>
          <mesh>
            <scale>1 1 1</scale>
            <uri>model://SimSwerveBot3/meshes/RightGripper.STL</uri>
          </mesh>
        </geometry>
      </visual>
    </link>
    <joint name="GripperTwist-RightGripper" type="revolute">
      <parent>GripperTwist</parent>
      <child>RightGripper</child>
      <pose>0.131168146676638 -0.0382658693857197 138.314476087231 0 0 0</pose>
      <axis>
        <xyz>-0.808622698046812 -0.580628181106082 -0.0948696342827216</xyz>
        <dynamics>
          <damping>0</damping>
          <friction>0</friction>
        </dynamics>
        <limit>
          <upper>0</upper>
          <lower>0</lower>
          <effort>1</effort>
        </limit>
      </axis>
    </joint>
    <link name="LeftPad">
      <gravity>1</gravity>
      <self_collide>0</self_collide>
      <pose>0.65045406809633 -0.061857243117229 -0.158044572202814 0 0 0</pose>
      <must_be_base_link>0</must_be_base_link>
      <velocity_decay>
        <linear>0</linear>
        <angular>0</angular>
      </velocity_decay>
      <inertial>
        <mass>0.0254993671569944</mass>
        <pose>0 0 0 0 0 0</pose>
        <inertia>
          <ixx>0</ixx>
          <ixy>0</ixy>
          <ixz>0</ixz>
          <iyy>0</iyy>
          <iyz>0</iyz>
          <izz>0</izz>
        </inertia>
      </inertial>
      <collision name="LeftPad_collision">
        <pose>-1.10694832443051 0.0618572431172279 0.157325633326903 0 0 0</pose>
        <geometry>
          <mesh>
            <scale>1 1 1</scale>
            <uri>model://SimSwerveBot3/meshes/LeftPad_col.STL</uri>
          </mesh>
        </geometry>
        <surface>
          <contact>
            <ode />
          </contact>
          <friction>
            <ode>
              <mu>0</mu>
              <mu2>0</mu2>
            </ode>
          </friction>
        </surface>
      </collision>
      <visual name="LeftPad_visual">
        <pose>-1.10694832443051 0.0618572431172279 0.157325633326903 0 0 0</pose>
        <material>
          <ambient>0 0.501960784313725 0.501960784313725 1</ambient>
          <diffuse>0 0.501960784313725 0.501960784313725 1</diffuse>
        </material>
        <geometry>
          <mesh>
            <scale>1 1 1</scale>
            <uri>model://SimSwerveBot3/meshes/LeftPad.STL</uri>
          </mesh>
        </geometry>
      </visual>
    </link>
    <joint name="LeftGripper-LeftPad" type="prismatic">
      <parent>LeftGripper</parent>
      <child>LeftPad</child>
      <pose>0.300698114297486 0.0683516039871302 138.3325519293 0 0 0</pose>
      <axis>
        <xyz>0.0142604132425631 -0.180524087546997 0.983467180148619</xyz>
        <dynamics>
          <damping>0</damping>
          <friction>0</friction>
        </dynamics>
        <limit>
          <upper>0</upper>
          <lower>0</lower>
          <effort>1</effort>
        </limit>
      </axis>
    </joint>
    <link name="RightPad">
      <gravity>1</gravity>
      <self_collide>0</self_collide>
      <pose>0.632231615928298 -0.0778836267017213 0.0953488079418481 0 0 0</pose>
      <must_be_base_link>0</must_be_base_link>
      <velocity_decay>
        <linear>0</linear>
        <angular>0</angular>
      </velocity_decay>
      <inertial>
        <mass>0.0254993671569936</mass>
        <pose>0 0 0 0 0 0</pose>
        <inertia>
          <ixx>0</ixx>
          <ixy>0</ixy>
          <ixz>0</ixz>
          <iyy>0</iyy>
          <iyz>0</iyz>
          <izz>0</izz>
        </inertia>
      </inertial>
      <collision name="RightPad_collision">
        <pose>-1.08872587226248 0.0778836267017202 -0.0960677468177599 0 0 0</pose>
        <geometry>
          <mesh>
            <scale>1 1 1</scale>
            <uri>model://SimSwerveBot3/meshes/RightPad_col.STL</uri>
          </mesh>
        </geometry>
        <surface>
          <contact>
            <ode />
          </contact>
          <friction>
            <ode>
              <mu>0</mu>
              <mu2>0</mu2>
            </ode>
          </friction>
        </surface>
      </collision>
      <visual name="RightPad_visual">
        <pose>-1.08872587226248 0.0778836267017202 -0.0960677468177599 0 0 0</pose>
        <material>
          <ambient>0 0.501960784313725 0.501960784313725 1</ambient>
          <diffuse>0 0.501960784313725 0.501960784313725 1</diffuse>
        </material>
        <geometry>
          <mesh>
            <scale>1 1 1</scale>
            <uri>model://SimSwerveBot3/meshes/RightPad.STL</uri>
          </mesh>
        </geometry>
      </visual>
    </link>
    <joint name="RightGripper-RightPad" type="prismatic">
      <parent>RightGripper</parent>
      <child>RightPad</child>
      <pose>0.316296975863962 0.0511474732792853 138.331519317753 0 0 0</pose>
      <axis>
        <xyz>0.1559048176831 -0.0559484237584419 -0.986186322001145</xyz>
        <dynamics>
          <damping>0</damping>
          <friction>0</friction>
        </dynamics>
        <limit>
          <upper>0</upper>
          <lower>0</lower>
          <effort>1</effort>
        </limit>
      </axis>
    </joint>
    -->
    
  </model>
  
</sdf>