<?xml version="1.0" encoding="utf-8"?>
<sdf version="1.5">
  <model name="SimBot2022-2">
    <pose>0 0 0 0 0 0</pose>
    <plugin name="clock" filename="libgz_clock.so">
      <topic>/gazebo/frc/time</topic>
    </plugin>
    <link name="Frame">
      <gravity>1</gravity>
      <self_collide>0</self_collide>
      <pose>-0.0916854891449772 -9.9147065557581E-10 -0.0184942437490389 1.5707963267949 0 -1.5707963267949</pose>
      <must_be_base_link>1</must_be_base_link>
      <velocity_decay>
        <linear>0</linear>
        <angular>0</angular>
      </velocity_decay>
      <inertial>
        <mass>1.21135152753261</mass>
        <pose>0 0 0 0 0 0</pose>
        <inertia>
          <ixx>0</ixx>
          <ixy>0</ixy>
          <ixz>0</ixz>
          <iyy>0</iyy>
          <iyz>0</iyz>
          <izz>0</izz>
        </inertia>
      </inertial>
      <collision name="Frame_collision">
        <pose>0.087928821262285 -0.0052889773385317 0.00114418280918003 0 0 0</pose>
        <geometry>
          <mesh>
            <scale>1 1 1</scale>
            <uri>model://SimBot2022-2/meshes/Frame_col.STL</uri>
          </mesh>
        </geometry>
        <surface>
          <contact>
            <ode />
          </contact>
          <friction>
            <ode>
              <mu>0</mu>
              <mu2>0</mu2>
            </ode>
          </friction>
        </surface>
      </collision>
      <visual name="Frame_visual">
        <pose>0.087928821262285 -0.0052889773385317 0.00114418280918003 0 0 0</pose>
        <material>
          <ambient>0.501960784313725 1 0.501960784313725 1</ambient>
          <diffuse>0.501960784313725 1 0.501960784313725 1</diffuse>
        </material>
        <geometry>
          <mesh>
            <scale>1 1 1</scale>
            <uri>model://SimBot2022-2/meshes/Frame.STL</uri>
          </mesh>
        </geometry>
      </visual>
    </link>
    <link name="shooter">
      <gravity>1</gravity>
      <self_collide>0</self_collide>
      <pose>-0.339857661155341 0.00613558288465832 0.112751803631496 1.5707963267949 0 -1.5707963267949</pose>
      <must_be_base_link>0</must_be_base_link>
      <velocity_decay>
        <linear>0</linear>
        <angular>0</angular>
      </velocity_decay>
      <inertial>
        <mass>5.22101990724176</mass>
        <pose>0 0 0 0 0 0</pose>
        <inertia>
          <ixx>0.114299340025415</ixx>
          <ixy>0.00269283476076011</ixy>
          <ixz>0.00519033218114686</ixz>
          <iyy>0.134101261463111</iyy>
          <iyz>0.0125219035483829</iyz>
          <izz>0.182046035406737</izz>
        </inertia>
      </inertial>
      <collision name="shooter_collision">
        <pose>0.094064405138414 -0.136535024719067 -0.247027989201184 0 0 0</pose>
        <geometry>
          <mesh>
            <scale>1 1 1</scale>
            <uri>model://SimBot2022-2/meshes/shooter_col.STL</uri>
          </mesh>
        </geometry>
        <surface>
          <contact>
            <ode />
          </contact>
          <friction>
            <ode>
              <mu>0</mu>
              <mu2>0</mu2>
            </ode>
          </friction>
        </surface>
      </collision>
      <visual name="shooter_visual">
        <pose>0.094064405138414 -0.136535024719067 -0.247027989201184 0 0 0</pose>
        <material>
          <ambient>0 0 0.250980392156863 1</ambient>
          <diffuse>0 0 0.250980392156863 1</diffuse>
        </material>
        <geometry>
          <mesh>
            <scale>1 1 1</scale>
            <uri>model://SimBot2022-2/meshes/shooter.STL</uri>
          </mesh>
        </geometry>
      </visual>
      <sensor name="shooterCamera" type="camera">
        <visualize>1</visualize>
        <always_on>1</always_on>
        <pose>0.00613558288465925 0.235523017514098 0.102322528854874 0 1.05088798349683 4.71238898038469</pose>
        <camera name="shootercamera">
          <horizontal_fov>1.5707963267949</horizontal_fov>
          <image>
            <width>320</width>
            <height>240</height>
          </image>
          <clip>
            <near>0.1</near>
            <far>100</far>
          </clip>
        </camera>
      </sensor>
      <sensor name="shooterCamera" type="camera">
        <visualize>1</visualize>
        <always_on>1</always_on>
        <pose>0.00613558288465925 0.161899190938801 0.132500680005632 0 4.71238898038469 4.71238898038469</pose>
        <camera name="shootercamera">
          <horizontal_fov>1.5707963267949</horizontal_fov>
          <image>
            <width>320</width>
            <height>240</height>
          </image>
          <clip>
            <near>0.1</near>
            <far>100</far>
          </clip>
        </camera>
      </sensor>
    </link>
    <joint name="Frame-shooter" type="prismatic">
      <parent>Frame</parent>
      <child>shooter</child>
      <pose>0.094064405138414 -0.136535024719067 -0.247027989201184 0 0 0</pose>
      <axis>
        <xyz>0 0 0</xyz>
        <dynamics>
          <damping>0</damping>
          <friction>0</friction>
        </dynamics>
        <limit>
          <upper>0</upper>
          <lower>0</lower>
          <effort>1</effort>
        </limit>
      </axis>
    </joint>
    <link name="IntakeWheels">
      <gravity>1</gravity>
      <self_collide>0</self_collide>
      <pose>-0.469753566757535 -0.0108552498965759 0.120727981986896 1.5707963267949 0 -1.5707963267949</pose>
      <must_be_base_link>0</must_be_base_link>
      <velocity_decay>
        <linear>0</linear>
        <angular>0</angular>
      </velocity_decay>
      <inertial>
        <mass>0.185936472459736</mass>
        <pose>0 0 0 0 0 0</pose>
        <inertia>
          <ixx>4.32007196756767E-12</ixx>
          <ixy>1.36577276677943E-08</ixy>
          <ixz>2.0703738127366E-08</ixz>
          <iyy>0.00145906709110178</iyy>
          <iyz>1.99737918558412E-12</iyz>
          <izz>0.00145906708945723</izz>
        </inertia>
      </inertial>
      <collision name="IntakeWheels_collision">
        <pose>0.0770735723571798 -0.144511203074467 -0.376923894803378 0 0 0</pose>
        <geometry>
          <mesh>
            <scale>1 1 1</scale>
            <uri>model://SimBot2022-2/meshes/IntakeWheels_col.STL</uri>
          </mesh>
        </geometry>
        <surface>
          <contact>
            <ode />
          </contact>
          <friction>
            <ode>
              <mu>0</mu>
              <mu2>0</mu2>
            </ode>
          </friction>
        </surface>
      </collision>
      <visual name="IntakeWheels_visual">
        <pose>0.0770735723571798 -0.144511203074467 -0.376923894803378 0 0 0</pose>
        <material>
          <ambient>0 0 1 1</ambient>
          <diffuse>0 0 1 1</diffuse>
        </material>
        <geometry>
          <mesh>
            <scale>1 1 1</scale>
            <uri>model://SimBot2022-2/meshes/IntakeWheels.STL</uri>
          </mesh>
        </geometry>
      </visual>
    </link>
    <joint name="Intake-IntakeWheels" type="revolute">
      <parent>Intake</parent>
      <child>IntakeWheels</child>
      <pose>2.77555756156289E-17 -1.04954748192387E-06 1.43377473854622E-06 0 0 0</pose>
      <axis>
        <xyz>1 1.01794992361837E-16 -3.5595649871299E-15</xyz>
        <dynamics>
          <damping>0</damping>
          <friction>0</friction>
        </dynamics>
        <limit>
          <effort>1</effort>
        </limit>
      </axis>
    </joint>
    <link name="ShooterWheels">
      <gravity>1</gravity>
      <self_collide>0</self_collide>
      <pose>-0.177655024091721 -0.00250787604435686 0.196849999999108 1.5707963267949 0 -1.5707963267949</pose>
      <must_be_base_link>0</must_be_base_link>
      <velocity_decay>
        <linear>0</linear>
        <angular>0</angular>
      </velocity_decay>
      <inertial>
        <mass>0.142802443720399</mass>
        <pose>0 0 0 0 0 0</pose>
        <inertia>
          <ixx>6.73817381107333E-34</ixx>
          <ixy>0</ixy>
          <ixz>1.7809619411406E-19</ixz>
          <iyy>5.69518878781941E-05</iyy>
          <iyz>2.75027502492789E-35</iyz>
          <izz>5.69518878781941E-05</izz>
        </inertia>
      </inertial>
      <collision name="ShooterWheels_collision">
        <pose>0.0854209462093988 -0.220633221086678 -0.0848253521375637 0 0 0</pose>
        <geometry>
          <mesh>
            <scale>1 1 1</scale>
            <uri>model://SimBot2022-2/meshes/ShooterWheels_col.STL</uri>
          </mesh>
        </geometry>
        <surface>
          <contact>
            <ode />
          </contact>
          <friction>
            <ode>
              <mu>0</mu>
              <mu2>0</mu2>
            </ode>
          </friction>
        </surface>
      </collision>
      <visual name="ShooterWheels_visual">
        <pose>0.0854209462093988 -0.220633221086678 -0.0848253521375637 0 0 0</pose>
        <material>
          <ambient>0.501960784313725 0.501960784313725 0.501960784313725 1</ambient>
          <diffuse>0.501960784313725 0.501960784313725 0.501960784313725 1</diffuse>
        </material>
        <geometry>
          <mesh>
            <scale>1 1 1</scale>
            <uri>model://SimBot2022-2/meshes/ShooterWheels.STL</uri>
          </mesh>
        </geometry>
      </visual>
    </link>
    <joint name="shooter-ShooterWheels" type="revolute">
      <parent>shooter</parent>
      <child>ShooterWheels</child>
      <pose>0.0861427824221615 -4.94881913226664E-14 0.0163724058753235 0 0 0</pose>
      <axis>
        <xyz>-1 0 0</xyz>
        <dynamics>
          <damping>0</damping>
          <friction>0</friction>
        </dynamics>
        <limit>
          <effort>1</effort>
        </limit>
      </axis>
    </joint>
    <link name="LFWheel">
      <gravity>1</gravity>
      <self_collide>0</self_collide>
      <pose>-0.383733921516064 -0.315899209940694 -0.0302259999999987 1.5707963267949 0 -1.5707963267949</pose>
      <must_be_base_link>0</must_be_base_link>
      <velocity_decay>
        <linear>0</linear>
        <angular>0</angular>
      </velocity_decay>
      <inertial>
        <mass>0.255325203825891</mass>
        <pose>0 0 0 0 0 0</pose>
        <inertia>
          <ixx>0</ixx>
          <ixy>0</ixy>
          <ixz>0</ixz>
          <iyy>0</iyy>
          <iyz>0</iyz>
          <izz>0</izz>
        </inertia>
      </inertial>
      <collision name="LFWheel_collision">
        <pose>-0.227970387686939 0.00644277891242817 -0.290904249561907 0 0 0</pose>
        <geometry>
          <mesh>
            <scale>1 1 1</scale>
            <uri>model://SimBot2022-2/meshes/LFWheel_col.STL</uri>
          </mesh>
        </geometry>
        <surface>
          <contact>
            <ode />
          </contact>
          <friction>
            <ode>
              <mu>0</mu>
              <mu2>0</mu2>
            </ode>
          </friction>
        </surface>
      </collision>
      <visual name="LFWheel_visual">
        <pose>-0.227970387686939 0.00644277891242817 -0.290904249561907 0 0 0</pose>
        <material>
          <ambient>0.752941176470588 0.752941176470588 0.752941176470588 1</ambient>
          <diffuse>0.752941176470588 0.752941176470588 0.752941176470588 1</diffuse>
        </material>
        <geometry>
          <mesh>
            <scale>1 1 1</scale>
            <uri>model://SimBot2022-2/meshes/LFWheel.STL</uri>
          </mesh>
        </geometry>
      </visual>
    </link>
    <joint name="Frame-LFWheel" type="revolute">
      <parent>Frame</parent>
      <child>LFWheel</child>
      <pose>-0.543869597627631 -1.11542719505309E-15 -0.50804430019769 0 0 0</pose>
      <axis>
        <xyz>-1 5.46369598732857E-17 0</xyz>
        <dynamics>
          <damping>0</damping>
          <friction>0</friction>
        </dynamics>
        <limit>
          <effort>1</effort>
        </limit>
      </axis>
    </joint>
    <link name="LCWheel">
      <gravity>1</gravity>
      <self_collide>0</self_collide>
      <pose>-0.129733921516064 -0.311136709940694 -0.0302259999999999 1.5707963267949 0 -1.5707963267949</pose>
      <must_be_base_link>0</must_be_base_link>
      <velocity_decay>
        <linear>0</linear>
        <angular>0</angular>
      </velocity_decay>
      <inertial>
        <mass>0.255325203825891</mass>
        <pose>0 0 0 0 0 0</pose>
        <inertia>
          <ixx>0</ixx>
          <ixy>0</ixy>
          <ixz>0</ixz>
          <iyy>0</iyy>
          <iyz>0</iyz>
          <izz>0</izz>
        </inertia>
      </inertial>
      <collision name="LCWheel_collision">
        <pose>-0.223207887686939 0.00644277891242926 -0.0369042495619069 0 0 0</pose>
        <geometry>
          <mesh>
            <scale>1 1 1</scale>
            <uri>model://SimBot2022-2/meshes/LCWheel_col.STL</uri>
          </mesh>
        </geometry>
        <surface>
          <contact>
            <ode />
          </contact>
          <friction>
            <ode>
              <mu>0</mu>
              <mu2>0</mu2>
            </ode>
          </friction>
        </surface>
      </collision>
      <visual name="LCWheel_visual">
        <pose>-0.223207887686939 0.00644277891242926 -0.0369042495619069 0 0 0</pose>
        <material>
          <ambient>0.752941176470588 0.752941176470588 0.752941176470588 1</ambient>
          <diffuse>0.752941176470588 0.752941176470588 0.752941176470588 1</diffuse>
        </material>
        <geometry>
          <mesh>
            <scale>1 1 1</scale>
            <uri>model://SimBot2022-2/meshes/LCWheel.STL</uri>
          </mesh>
        </geometry>
      </visual>
    </link>
    <joint name="Frame-LCWheel" type="revolute">
      <parent>Frame</parent>
      <child>LCWheel</child>
      <pose>-0.534344597627632 -3.46944695195361E-18 -4.4300197690951E-05 0 0 0</pose>
      <axis>
        <xyz>1 0 0</xyz>
        <dynamics>
          <damping>0</damping>
          <friction>0</friction>
        </dynamics>
        <limit>
          <effort>1</effort>
        </limit>
      </axis>
    </joint>
    <link name="LBWheel">
      <gravity>1</gravity>
      <self_collide>0</self_collide>
      <pose>0.124266078483936 -0.315899209940694 -0.030226000000001 1.5707963267949 0 -1.5707963267949</pose>
      <must_be_base_link>0</must_be_base_link>
      <velocity_decay>
        <linear>0</linear>
        <angular>0</angular>
      </velocity_decay>
      <inertial>
        <mass>0.255325203825891</mass>
        <pose>0 0 0 0 0 0</pose>
        <inertia>
          <ixx>0</ixx>
          <ixy>0</ixy>
          <ixz>0</ixz>
          <iyy>0</iyy>
          <iyz>0</iyz>
          <izz>0</izz>
        </inertia>
      </inertial>
      <collision name="LBWheel_collision">
        <pose>-0.227970387686938 0.00644277891243034 0.217095750438093 0 0 0</pose>
        <geometry>
          <mesh>
            <scale>1 1 1</scale>
            <uri>model://SimBot2022-2/meshes/LBWheel_col.STL</uri>
          </mesh>
        </geometry>
        <surface>
          <contact>
            <ode />
          </contact>
          <friction>
            <ode>
              <mu>0</mu>
              <mu2>0</mu2>
            </ode>
          </friction>
        </surface>
      </collision>
      <visual name="LBWheel_visual">
        <pose>-0.227970387686938 0.00644277891243034 0.217095750438093 0 0 0</pose>
        <material>
          <ambient>0.752941176470588 0.752941176470588 0.752941176470588 1</ambient>
          <diffuse>0.752941176470588 0.752941176470588 0.752941176470588 1</diffuse>
        </material>
        <geometry>
          <mesh>
            <scale>1 1 1</scale>
            <uri>model://SimBot2022-2/meshes/LBWheel.STL</uri>
          </mesh>
        </geometry>
      </visual>
    </link>
    <joint name="Frame-LBWheel" type="revolute">
      <parent>Frame</parent>
      <child>LBWheel</child>
      <pose>-0.543869597627631 9.33281230075522E-16 0.507955699802309 0 0 0</pose>
      <axis>
        <xyz>-1 0 0</xyz>
        <dynamics>
          <damping>0</damping>
          <friction>0</friction>
        </dynamics>
        <limit>
          <effort>1</effort>
        </limit>
      </axis>
    </joint>
    <link name="RFWheel">
      <gravity>1</gravity>
      <self_collide>0</self_collide>
      <pose>-0.383645321120682 0.315899209940691 -0.0302259999999987 1.5707963267949 0 -1.5707963267949</pose>
      <must_be_base_link>0</must_be_base_link>
      <velocity_decay>
        <linear>0</linear>
        <angular>0</angular>
      </velocity_decay>
      <inertial>
        <mass>0.255325203825891</mass>
        <pose>0 0 0 0 0 0</pose>
        <inertia>
          <ixx>0</ixx>
          <ixy>0</ixy>
          <ixz>0</ixz>
          <iyy>0</iyy>
          <iyz>0</iyz>
          <izz>0</izz>
        </inertia>
      </inertial>
      <collision name="RFWheel_collision">
        <pose>0.403828032194447 0.0064427789124282 -0.290815649166525 0 0 0</pose>
        <geometry>
          <mesh>
            <scale>1 1 1</scale>
            <uri>model://SimBot2022-2/meshes/RFWheel_col.STL</uri>
          </mesh>
        </geometry>
        <surface>
          <contact>
            <ode />
          </contact>
          <friction>
            <ode>
              <mu>0</mu>
              <mu2>0</mu2>
            </ode>
          </friction>
        </surface>
      </collision>
      <visual name="RFWheel_visual">
        <pose>0.403828032194447 0.0064427789124282 -0.290815649166525 0 0 0</pose>
        <material>
          <ambient>0.752941176470588 0.752941176470588 0.752941176470588 1</ambient>
          <diffuse>0.752941176470588 0.752941176470588 0.752941176470588 1</diffuse>
        </material>
        <geometry>
          <mesh>
            <scale>1 1 1</scale>
            <uri>model://SimBot2022-2/meshes/RFWheel.STL</uri>
          </mesh>
        </geometry>
      </visual>
    </link>
    <joint name="Frame-RFWheel" type="revolute">
      <parent>Frame</parent>
      <child>RFWheel</child>
      <pose>0.71972724213514 -1.25073562617928E-15 -0.507955699802309 0 0 0</pose>
      <axis>
        <xyz>1 5.46369598732854E-17 0</xyz>
        <dynamics>
          <damping>0</damping>
          <friction>0</friction>
        </dynamics>
        <limit>
          <effort>1</effort>
        </limit>
      </axis>
    </joint>
    <link name="RCWheel">
      <gravity>1</gravity>
      <self_collide>0</self_collide>
      <pose>-0.129645321120682 0.311136709940692 -0.0302259999999999 1.5707963267949 0 -1.5707963267949</pose>
      <must_be_base_link>0</must_be_base_link>
      <velocity_decay>
        <linear>0</linear>
        <angular>0</angular>
      </velocity_decay>
      <inertial>
        <mass>0.255325203825891</mass>
        <pose>0 0 0 0 0 0</pose>
        <inertia>
          <ixx>0</ixx>
          <ixy>0</ixy>
          <ixz>0</ixz>
          <iyy>0</iyy>
          <iyz>0</iyz>
          <izz>0</izz>
        </inertia>
      </inertial>
      <collision name="RCWheel_collision">
        <pose>0.399065532194447 0.00644277891242927 -0.0368156491665249 0 0 0</pose>
        <geometry>
          <mesh>
            <scale>1 1 1</scale>
            <uri>model://SimBot2022-2/meshes/RCWheel_col.STL</uri>
          </mesh>
        </geometry>
        <surface>
          <contact>
            <ode />
          </contact>
          <friction>
            <ode>
              <mu>0</mu>
              <mu2>0</mu2>
            </ode>
          </friction>
        </surface>
      </collision>
      <visual name="RCWheel_visual">
        <pose>0.399065532194447 0.00644277891242927 -0.0368156491665249 0 0 0</pose>
        <material>
          <ambient>0.752941176470588 0.752941176470588 0.752941176470588 1</ambient>
          <diffuse>0.752941176470588 0.752941176470588 0.752941176470588 1</diffuse>
        </material>
        <geometry>
          <mesh>
            <scale>1 1 1</scale>
            <uri>model://SimBot2022-2/meshes/RCWheel.STL</uri>
          </mesh>
        </geometry>
      </visual>
    </link>
    <joint name="Frame-RCWheel" type="revolute">
      <parent>Frame</parent>
      <child>RCWheel</child>
      <pose>0.71020224213514 -8.67361737988404E-19 4.43001976909163E-05 0 0 0</pose>
      <axis>
        <xyz>-1 0 0</xyz>
        <dynamics>
          <damping>0</damping>
          <friction>0</friction>
        </dynamics>
        <limit>
          <effort>1</effort>
        </limit>
      </axis>
    </joint>
    <link name="RBWheel">
      <gravity>1</gravity>
      <self_collide>0</self_collide>
      <pose>0.124354678879318 0.315899209940692 -0.0302259999999999 1.5707963267949 0 -1.5707963267949</pose>
      <must_be_base_link>0</must_be_base_link>
      <velocity_decay>
        <linear>0</linear>
        <angular>0</angular>
      </velocity_decay>
      <inertial>
        <mass>0.255325203825891</mass>
        <pose>0 0 0 0 0 0</pose>
        <inertia>
          <ixx>0</ixx>
          <ixy>0</ixy>
          <ixz>0</ixz>
          <iyy>0</iyy>
          <iyz>0</iyz>
          <izz>0</izz>
        </inertia>
      </inertial>
      <collision name="RBWheel_collision">
        <pose>0.403828032194447 0.00644277891242929 0.217184350833475 0 0 0</pose>
        <geometry>
          <mesh>
            <scale>1 1 1</scale>
            <uri>model://SimBot2022-2/meshes/RBWheel_col.STL</uri>
          </mesh>
        </geometry>
        <surface>
          <contact>
            <ode />
          </contact>
          <friction>
            <ode>
              <mu>0</mu>
              <mu2>0</mu2>
            </ode>
          </friction>
        </surface>
      </collision>
      <visual name="RBWheel_visual">
        <pose>0.403828032194447 0.00644277891242929 0.217184350833475 0 0 0</pose>
        <material>
          <ambient>0.752941176470588 0.752941176470588 0.752941176470588 1</ambient>
          <diffuse>0.752941176470588 0.752941176470588 0.752941176470588 1</diffuse>
        </material>
        <geometry>
          <mesh>
            <scale>1 1 1</scale>
            <uri>model://SimBot2022-2/meshes/RBWheel.STL</uri>
          </mesh>
        </geometry>
      </visual>
    </link>
    <joint name="Frame-RBWheel" type="revolute">
      <parent>Frame</parent>
      <child>RBWheel</child>
      <pose>2.22044604925031E-16 -6.24500451351651E-17 0.50804430019769 0 0 0</pose>
      <axis>
        <xyz>1 0 0</xyz>
        <dynamics>
          <damping>0</damping>
          <friction>0</friction>
        </dynamics>
        <limit>
          <effort>1</effort>
        </limit>
      </axis>
    </joint>
    <link name="Intake">
      <gravity>1</gravity>
      <self_collide>0</self_collide>
      <pose>-0.424484874242734 9.92754253803518E-09 0.120699564654734 1.5707963267949 0 -1.5707963267949</pose>
      <must_be_base_link>0</must_be_base_link>
      <velocity_decay>
        <linear>0</linear>
        <angular>0</angular>
      </velocity_decay>
      <inertial>
        <mass>0.567217955867027</mass>
        <pose>0 0 0 0 0 0</pose>
        <inertia>
          <ixx>0.000712176134742695</ixx>
          <ixy>4.45759710971862E-07</ixy>
          <ixz>0.000735322723547995</ixz>
          <iyy>0.00973894125620462</iyy>
          <iyz>4.32831821129935E-07</iyz>
          <izz>0.00902676564765968</izz>
        </inertia>
      </inertial>
      <collision name="Intake_collision">
        <pose>0.0879288321812983 -0.144482785742305 -0.331655202288577 0 0 0</pose>
        <geometry>
          <mesh>
            <scale>1 1 1</scale>
            <uri>model://SimBot2022-2/meshes/Intake_col.STL</uri>
          </mesh>
        </geometry>
        <surface>
          <contact>
            <ode />
          </contact>
          <friction>
            <ode>
              <mu>0</mu>
              <mu2>0</mu2>
            </ode>
          </friction>
        </surface>
      </collision>
      <visual name="Intake_visual">
        <pose>0.0879288321812983 -0.144482785742305 -0.331655202288577 0 0 0</pose>
        <material>
          <ambient>1 0.250980392156863 0.501960784313725 1</ambient>
          <diffuse>1 0.250980392156863 0.501960784313725 1</diffuse>
        </material>
        <geometry>
          <mesh>
            <scale>1 1 1</scale>
            <uri>model://SimBot2022-2/meshes/Intake.STL</uri>
          </mesh>
        </geometry>
      </visual>
    </link>
    <joint name="shooter-Intake" type="revolute">
      <parent>shooter</parent>
      <child>Intake</child>
      <pose>0.0879288321812983 -0.144482785742305 -0.331655202288577 0 0 0</pose>
      <axis>
        <xyz>0 0 0</xyz>
        <dynamics>
          <damping>0</damping>
          <friction>0</friction>
        </dynamics>
        <limit>
          <upper>0</upper>
          <lower>0</lower>
          <effort>1</effort>
        </limit>
      </axis>
    </joint>
    <plugin name="Intake-IntakeWheels_motor" filename="libgz_dc_motor.so">
      <joint>Intake-IntakeWheels</joint>
      <topic>/gazebo/frc/simulator/pwm/7</topic>
      <multiplier>1</multiplier>
    </plugin>
    <plugin name="shooter-ShooterWheels_motor" filename="libgz_dc_motor.so">
      <joint>shooter-ShooterWheels</joint>
      <topic>/gazebo/frc/simulator/pwm/8</topic>
      <multiplier>0</multiplier>
    </plugin>
    <plugin name="Frame-LFWheel_motor" filename="libgz_dc_motor.so">
      <joint>Frame-LFWheel</joint>
      <topic>/gazebo/frc/simulator/pwm/1</topic>
      <multiplier>0</multiplier>
    </plugin>
    <plugin name="Frame-LCWheel_motor" filename="libgz_dc_motor.so">
      <joint>Frame-LCWheel</joint>
      <topic>/gazebo/frc/simulator/pwm/1</topic>
      <multiplier>0</multiplier>
    </plugin>
    <plugin name="Frame-LBWheel_motor" filename="libgz_dc_motor.so">
      <joint>Frame-LBWheel</joint>
      <topic>/gazebo/frc/simulator/pwm/1</topic>
      <multiplier>0</multiplier>
    </plugin>
    <plugin name="Frame-RFWheel_motor" filename="libgz_dc_motor.so">
      <joint>Frame-RFWheel</joint>
      <topic>/gazebo/frc/simulator/pwm/2</topic>
      <multiplier>0</multiplier>
    </plugin>
    <plugin name="Frame-RCWheel_motor" filename="libgz_dc_motor.so">
      <joint>Frame-RCWheel</joint>
      <topic>/gazebo/frc/simulator/pwm/2</topic>
      <multiplier>0</multiplier>
    </plugin>
    <plugin name="Frame-RBWheel_motor" filename="libgz_dc_motor.so">
      <joint>Frame-RBWheel</joint>
      <topic>/gazebo/frc/simulator/pwm/2</topic>
      <multiplier>0</multiplier>
    </plugin>
  </model>
</sdf>