<?xml version="1.0" encoding="utf-8"?>
<sdf version="1.5">
  <model name="Gripper">

    <pose>0 0 -1.08924292772216E-15 0 0 0</pose>
    
    <link name="GripperTwist">
      <gravity>1</gravity>
      <self_collide>0</self_collide>
      <pose>0.146048791412694 1.0967249869109 0.0200822184555187 0 0 0</pose>
      <must_be_base_link>0</must_be_base_link>
      <velocity_decay>
        <linear>0</linear>
        <angular>0</angular>
      </velocity_decay>
      <inertial>
        <mass>0.1</mass>
        <pose>0 0 0 0 0 0</pose>
      </inertial>
      <collision name="GripperTwist_collision">
        <pose>-0.602543047746872 -1.0967249869109 -1.91914278295272 0 0 0</pose>
        <geometry>
          <mesh>
            <scale>1 1 1</scale>
            <uri>model://Gripper/meshes/GripperTwist_col.STL</uri>
          </mesh>
        </geometry>
        <surface>
          <contact>
            <ode />
          </contact>
          <friction>
            <ode>
              <mu>1</mu>
              <mu2>1</mu2>
            </ode>
          </friction>
        </surface>
      </collision>
      <visual name="GripperTwist_visual">
        <pose>-0.602543047746872 -1.0967249869109 -1.91914278295272 0 0 0</pose>
        <material>
          <ambient>0.752941176470588 0.752941176470588 0.752941176470588 1</ambient>
          <diffuse>0.752941176470588 0.752941176470588 0.752941176470588 1</diffuse>
        </material>
        <geometry>
          <mesh>
            <scale>1 1 1</scale>
            <uri>model://Gripper/meshes/GripperTwist.STL</uri>
          </mesh>
        </geometry>
      </visual>
      <sensor name="GripperTwistCamera" type="camera">
        <visualize>1</visualize>
        <always_on>1</always_on>
        <pose>0.0205235796459304 0.1 -0.15 -1.57 -0.1 -0.8</pose>
        <camera name="GripperTwistcamera">
          <horizontal_fov>1.5707963267949</horizontal_fov>
          <image>
             <width>640</width>
            <height>480</height>
          </image>
          <clip>
            <near>0.05</near>
            <far>30</far>
          </clip>
        </camera>
         <plugin name="camera1" filename="sim_camera.dll">
          <topic>~/gazebo/frc/simulator/camera/0</topic>
          <port>9000</port>
          <fps>20</fps>
          <enabled>true</enabled>
          <savepath>tmp</savepath>
          <maxframes>1</maxframes>
        </plugin>
      </sensor>
    </link>
    <joint name="GripperRotate-GripperTwist" type="fixed">
      <parent>GripperRotate</parent>
      <child>GripperTwist</child>
      <pose>-0.038351588966394 -0.0753937915180227 0.0266113955059517 0 0 4.71238898038469</pose>
      <axis>
        <xyz>0.887836308761871 0.460159416772162 0</xyz>
        <dynamics>
          <damping>2</damping>
          <friction>1</friction>
        </dynamics>
      </axis>
    </joint>
    
    <link name="LeftGripper">
      <gravity>1</gravity>
      <self_collide>0</self_collide>
      <pose>0.241320498086195 0.969184291056408 -0.158494078621501 0 0 0</pose>
      <must_be_base_link>0</must_be_base_link>
      <velocity_decay>
        <linear>0</linear>
        <angular>0.01</angular>
      </velocity_decay>
      <inertial>
        <mass>0.1</mass>
        <pose>0 0 0 0 0 0</pose>
      </inertial>
      <collision name="LeftGripper_collision">
        <pose>-0.697814754420374 -0.969184291056409 -1.7405664858757 0 0 0</pose>
        <geometry>
          <mesh>
            <scale>1 1 1</scale>
            <uri>model://Gripper/meshes/LeftGripper_col.STL</uri>
          </mesh>
        </geometry>
        <surface>
          <contact>
           <ode>
              <kp>1e8</kp>
              <kd>100</kd>
              <max_vel>0.01</max_vel>
              <min_depth>0.01</min_depth>
            </ode>
          </contact>
          <friction>
            <ode>
              <mu>1</mu>
              <mu2>1</mu2>
            </ode>
          </friction>
        </surface>
      </collision>
      <visual name="LeftGripper_visual">
        <pose>-0.697814754420374 -0.969184291056409 -1.7405664858757 0 0 0</pose>
        <material>
          <ambient>0.752941176470588 0.752941176470588 0.752941176470588 1</ambient>
          <diffuse>0.752941176470588 0.752941176470588 0.752941176470588 1</diffuse>
        </material>
        <geometry>
          <mesh>
            <scale>1 1 1</scale>
            <uri>model://Gripper/meshes/LeftGripper.STL</uri>
          </mesh>
        </geometry>
      </visual>
    </link>
    <joint name="GripperTwist-LeftGripper" type="revolute">
      <parent>GripperTwist</parent>
      <child>LeftGripper</child>
      <pose>-0.054185747678801 0.0570231645355036 0.0238046710258071 0 0.0158713592468967 1.59696957940531</pose>
      <axis>
        <xyz>0.585394002287998 -0.810722241994805 -0.00658091332233763</xyz>
        <dynamics>
          <damping>0</damping>
          <friction>0</friction>
        </dynamics>
        <limit>
          <upper>0.3</upper>
          <lower>-0.6</lower>
        </limit>
      </axis>
    </joint>
    <link name="RightGripper">
      <gravity>1</gravity>
      <self_collide>0</self_collide>
      <pose>0.246191175008786 0.971708729210025 0.181958210199892 0 0 0</pose>
      <must_be_base_link>0</must_be_base_link>
      <velocity_decay>
        <linear>0</linear>
        <angular>0</angular>
      </velocity_decay>
      <inertial>
        <mass>0.1</mass>
        <pose>0 0 0 0 0 0</pose>
      </inertial>
      <collision name="RightGripper_collision">
        <pose>-0.702685431342964 -0.971708729210026 -2.0810187746971 0 0 0</pose>
        <geometry>
          <mesh>
            <scale>1 1 1</scale>
            <uri>model://Gripper/meshes/RightGripper_col.STL</uri>
          </mesh>
        </geometry>
        <surface>
          <contact>
           <ode>
              <kp>1e8</kp>
              <kd>100</kd>
              <max_vel>0.01</max_vel>
              <min_depth>0.01</min_depth>
            </ode>      
          </contact>
          <friction>
            <ode>
              <mu>1</mu>
              <mu2>1</mu2>
            </ode>
          </friction>
        </surface>
      </collision>
      <visual name="RightGripper_visual">
        <pose>-0.702685431342964 -0.971708729210026 -2.0810187746971 0 0 0</pose>
        <material>
          <ambient>0.752941176470588 0.752941176470588 0.752941176470588 1</ambient>
          <diffuse>0.752941176470588 0.752941176470588 0.752941176470588 1</diffuse>
        </material>
        <geometry>
          <mesh>
            <scale>1 1 1</scale>
            <uri>model://Gripper/meshes/RightGripper.STL</uri>
          </mesh>
        </geometry>
      </visual>
    </link>
    <joint name="GripperTwist-RightGripper" type="revolute">
      <parent>GripperTwist</parent>
      <child>RightGripper</child>
      <pose>-0.0548566132662593 0.0566754595425552 -0.0230877277876074 0 0.0158713592468967 1.59696957940531</pose>
      <axis>
        <xyz>-0.585394002287996 0.810722241994806 -0.00658091332233764</xyz>
        <dynamics>
          <damping>0</damping>
          <friction>0</friction>
        </dynamics>
        <limit>
          <upper>0.3</upper>
          <lower>-0.6</lower>
        </limit>
      </axis>
    </joint>
    <link name="LeftPad">
      <gravity>1</gravity>
      <self_collide>0</self_collide>
      <pose>0.334045450628088 0.846041003834395 -0.21678381156418 0 0 0</pose>
      <must_be_base_link>0</must_be_base_link>
      <velocity_decay>
        <linear>0</linear>
        <angular>0</angular>
      </velocity_decay>
      <inertial>
        <mass>0.01</mass>
        <pose>0 0 0 0 0 0</pose>
      </inertial>
      <collision name="LeftPad_collision">
        <pose>-0.790539706962267 -0.846041003834396 -1.68227675293302 0 0 0</pose>
        <geometry>
          <mesh>
            <scale>1 1 1</scale>
            <uri>model://Gripper/meshes/LeftPad_col.STL</uri>
          </mesh>
        </geometry>
        <surface>
          <contact>
            <ode>
              <kp>1e3</kp>
              <kd>1e7</kd>
              <min_depth>0.001</min_depth>
            </ode>          
          </contact>
          <torsional>
            <ode>
              <coefficient>1</coefficient>
              <slip>0</slip>
            </ode>
          </torsional>
          <friction>
            <ode>
              <mu>4</mu>
              <mu2>4</mu2>
            </ode>
          </friction>
        </surface>
      </collision>
      <visual name="LeftPad_visual">
        <pose>-0.790539706962267 -0.846041003834396 -1.68227675293302 0 0 0</pose>
        <material>
          <ambient>0 0.501960784313725 0.501960784313725 1</ambient>
          <diffuse>0 0.501960784313725 0.501960784313725 1</diffuse>
        </material>
        <geometry>
          <mesh>
            <scale>1 1 1</scale>
            <uri>model://Gripper/meshes/LeftPad.STL</uri>
          </mesh>
        </geometry>
      </visual>
    </link>
    <joint name="LeftGripper-LeftPad" type="revolute">
      <parent>LeftGripper</parent>
      <child>LeftPad</child>
      <pose>-0.00707124173938922 -0.00539133761890198 0.000141142572698261 0 0.0158713592468798 1.59696957940528</pose>
      <axis>
        <xyz>0.585394002288015 -0.810722241994793 -0.00658091332233035</xyz>
        <dynamics>
          <damping>0</damping>
          <friction>0</friction>
        </dynamics>
      </axis>
    </joint>
    <link name="RightPad">
      <gravity>1</gravity>
      <self_collide>0</self_collide>
      <pose>0.3306064908218 0.847323504491162 0.220265006162646 0 0 0</pose>
      <must_be_base_link>0</must_be_base_link>
      <velocity_decay>
        <linear>0</linear>
        <angular>0</angular>
      </velocity_decay>
      <inertial>
        <mass>0.01</mass>
        <pose>0 0 0 0 0 0</pose>
      </inertial>
      <collision name="RightPad_collision">
        <pose>-0.787100747155979 -0.847323504491163 -2.11932557065985 0 0 0</pose>
        <geometry>
          <mesh>
            <scale>1 1 1</scale>
            <uri>model://Gripper/meshes/RightPad_col.STL</uri>
          </mesh>
        </geometry>
        <surface>
          <contact>
            <ode>
              <min_depth>0.001</min_depth>
              <kp>1e3</kp>
              <kd>1e7</kd>
            </ode>          
          </contact>
          <torsional>
            <ode>
              <coefficient>1</coefficient>
              <slip>0</slip>
            </ode>
          </torsional>
          <friction>
            <ode>
              <mu>4</mu>
              <mu2>4</mu2>
            </ode>
          </friction>
        </surface>
      </collision>
      <visual name="RightPad_visual">
        <pose>-0.787100747155979 -0.847323504491163 -2.11932557065985 0 0 0</pose>
        <material>
          <ambient>0 0.501960784313725 0.501960784313725 1</ambient>
          <diffuse>0 0.501960784313725 0.501960784313725 1</diffuse>
        </material>
        <geometry>
          <mesh>
            <scale>1 1 1</scale>
            <uri>model://Gripper/meshes/RightPad.STL</uri>
          </mesh>
        </geometry>
      </visual>
    </link>
   
    <joint name="RightGripper-RightPad" type="revolute">
      <parent>RightGripper</parent>
      <child>RightPad</child>
      <pose>-0.00707123868382553 -0.00539134138354158 0.000141145112782848 0 0.0158713592468729 1.59696957940527</pose>
      <axis>
        <xyz>0.585394002288031 -0.810722241994781 -0.00658091332232724</xyz>
        <dynamics>
          <damping>0</damping>
          <friction>0</friction>
        </dynamics>
      </axis>
    </joint>
    
    <link name="LeftPad2">
      <gravity>1</gravity>
      <self_collide>0</self_collide>
      <pose>0.267729827818469 0.934037484108341 -0.177919376276616 0 0 0</pose>
      <must_be_base_link>0</must_be_base_link>
      <velocity_decay>
        <linear>0</linear>
        <angular>0</angular>
      </velocity_decay>
      <inertial>
        <mass>0.01</mass>
        <pose>0 0 0 0 0 0</pose>
      </inertial>
      <collision name="LeftPad2_collision">
        <pose>-0.724224084152647 -0.934037484108342 -1.72114118822059 0 0 0</pose>
        <geometry>
          <mesh>
            <scale>1 1 1</scale>
            <uri>model://Gripper/meshes/LeftPad2_col.STL</uri>
          </mesh>
        </geometry>
        <surface>
          <contact>
            <ode>
              <kp>1e3</kp>
              <kd>1e7</kd>
              <min_depth>0.001</min_depth>
            </ode>          
          </contact>
          <torsional>
            <ode>
              <coefficient>1</coefficient>
              <slip>0</slip>
            </ode>
          </torsional>
          <friction>
            <ode>
              <mu>4</mu>
              <mu2>4</mu2>
            </ode>
          </friction>
        </surface>
      </collision>
      <visual name="LeftPad2_visual">
        <pose>-0.724224084152647 -0.934037484108342 -1.72114118822059 0 0 0</pose>
        <material>
          <ambient>0.250980392156863 0.501960784313725 0.501960784313725 1</ambient>
          <diffuse>0.250980392156863 0.501960784313725 0.501960784313725 1</diffuse>
        </material>
        <geometry>
          <mesh>
            <scale>1 1 1</scale>
            <uri>model://Gripper/meshes/LeftPad2.STL</uri>
          </mesh>
        </geometry>
      </visual>
    </link>
    <joint name="LeftGripper-LeftPad2" type="revolute">
      <parent>LeftGripper</parent>
      <child>LeftPad2</child>
      <pose>-0.00707123917503549 -0.00539134103551542 0.000141140539531293 0 0.0158713592468895 1.5969695794053</pose>
      <axis>
        <xyz>0.585394002288009 -0.810722241994798 -0.00658091332233447</xyz>
        <dynamics>
          <damping>0</damping>
          <friction>0</friction>
        </dynamics>
      </axis>
    </joint>
    <link name="RightPad2">
      <gravity>1</gravity>
      <self_collide>0</self_collide>
      <pose>0.273152825042775 0.936848188163066 0.201139058060381 0 0 0</pose>
      <must_be_base_link>0</must_be_base_link>
      <velocity_decay>
        <linear>0</linear>
        <angular>0</angular>
      </velocity_decay>
      <inertial>
        <mass>0.01</mass>
        <pose>0 0 0 0 0 0</pose>
      </inertial>
      <collision name="RightPad2_collision">
        <pose>-0.729647081376953 -0.936848188163068 -2.10019962255758 0 0 0</pose>
        <geometry>
          <mesh>
            <scale>1 1 1</scale>
            <uri>model://Gripper/meshes/RightPad2_col.STL</uri>
          </mesh>
        </geometry>
        <surface>
          <contact>
            <ode>
              <kp>1e3</kp>
              <kd>1e7</kd>
              <min_depth>0.001</min_depth>
            </ode>          
          </contact>
          <torsional>
            <ode>
              <coefficient>1</coefficient>
              <slip>0</slip>
            </ode>
          </torsional>
          <friction>
            <ode>
              <mu>4</mu>
              <mu2>4</mu2>
            </ode>
          </friction>
        </surface>
      </collision>
      <visual name="RightPad2_visual">
        <pose>-0.729647081376953 -0.936848188163068 -2.10019962255758 0 0 0</pose>
        <material>
          <ambient>0.250980392156863 0.501960784313725 0.501960784313725 1</ambient>
          <diffuse>0.250980392156863 0.501960784313725 0.501960784313725 1</diffuse>
        </material>
        <geometry>
          <mesh>
            <scale>1 1 1</scale>
            <uri>model://Gripper/meshes/RightPad2.STL</uri>
          </mesh>
        </geometry>
      </visual>
    </link>
    <joint name="RightGripper-RightPad2" type="revolute">
      <parent>RightGripper</parent>
      <child>RightPad2</child>
      <pose>-0.00707123836826895 -0.00539134206835934 0.000141141506121656 0 0.0158713592468928 1.5969695794053</pose>
      <axis>
        <xyz>0.585394002288003 -0.810722241994801 -0.00658091332233593</xyz>
        <dynamics>
          <damping>0</damping>
          <friction>0</friction>
        </dynamics>
      </axis>
    </joint>

  </model>
</sdf>